Workbook

Sheet Read.ME
A1: Biomass data from study Gibberellins 1
A2: conducted by Yin Hoon Chew, University of Edinburgh
A3: Metabolite analysis by Virginie Mengin et al, MPIMP.
A4: Sheets in this workbook | B4: Contents
A5: Biomass Summary | B5: mean dry and fresh biomass at day 35 of Col and prr7prr9, control or GA-treated, with SD, charts, derived from GA_Biomass of full sets_AJM.xlsx
A6: Metabolite Data, stats | B6: Metabolite data for individual samples for end of day and end of night, day 28, Col and prr7prr9, n=3 with mean and SD and t-test stats
A7: Metabolite Summary | B7: charts derived from data in Metabolite Data, stats
A10: note on GA-treated Col at day 35, and biomass data
A11: The Col plants flowered early when treated with GA, as expected, mostly between day 28 and day 35
A12: The flowering risked complicating the biomass measurements at day 35, so the Col control plants tested for dry (and fresh) mass were the last 4 to be pre-flowering.
A13: In hindsight, this sampling caused a severe bias towards the youngest i.e. smallest plants in only this genotype-treatment combination, whereas poorly-growing or outlier plants were avoided in normal sampling
A14: GA did not appear to stimulate the biomass of Col in this biased sample, relative to the control, contradicting expectation from the literature.
A16: However when the mean FW of all Col plants was included in the comparison (both for control and GA-treated; 'Full Sets'), not just the 5/4 with DW data, GA stimulated the biomass of Col in line with expectation, and of both Col and prr7prr9 genotypes similarly
A17: Therefore the mean water content of the 4 Col GA plants with DW data was applied to estimate DW for all the Col GA plants, to allow a less-biased comparison of DW in Col control versus GA
A19: The early flowering of Col GA didn't affect the sampling of plants for metabolite measurements at day 28, as the plants hadn't flowered.

Sheet Biomass Summary
A1: Photoperiod | B1: 12 | C1: h
A2: Temperature | C2: deg C
A4: Sets of plants with dry mass and images | G4: Sets of plants with dry mass and images | M4: Full sets | U4: For plotting
A5: n=5 | G5: n=5 (except Col with GA treatment, n = 4) | U5: Put DW on secondary Y axis! Move columns to right??!
A7: Genotype | B7: Control | D7: + GA | G7: Genotype | H7: Control | J7: + GA | M7: Genotype | N7: Control | Q7: + GA | U7: =A7 -> Genotype | V7: Control (n=5) | X7: ="+GA (n=5)" -> +GA (n=5) | Z7: Control (n=15,40) | AB7: ="+GA (n=21,38)" -> +GA (n=21,38)
B8: FW | C8: SD | D8: FW | E8: SD | H8: FW | I8: SD | J8: FW | K8: SD | N8: FW | O8: SD | P8: n | Q8: FW | R8: SD | V8: =B8 -> FW | W8: =C8 -> SD | X8: =D8 -> FW | Y8: =E8 -> SD | Z8: FW | AA8: SD | AB8: FW | AC8: SD
A9: Col (n=5) | B9: 0.92116 | C9: 0.10272066 | D9: 1.04668 | E9: 0.21839557 | G9: Col | H9: 0.92116 | I9: 0.10272066 | J9: 0.957275 | K9: 0.1015241 | M9: Col (n=15,21) | N9: 0.82156667 | O9: 0.11767017 | P9: 15 | Q9: 1.2193571 | R9: 0.17837443 | S9: 21 | U9: Col FW | V9: =B9 -> 0.92116 | W9: =C9 -> 0.10272066 | X9: =D9 -> 1.04668 | Y9: =E9 -> 0.21839557 | Z9: =N9 -> 0.82156667 | AA9: =O9 -> 0.11767017 | AB9: =Q9 -> 1.2193571 | AC9: =R9 -> 0.17837443
A10: prr7prr9 (n=5) | B10: 0.48434 | C10: 0.030674305 | D10: 0.76724 | E10: 0.078785297 | G10: prr7prr9 | H10: 0.48434 | I10: 0.030674305 | J10: 0.76724 | K10: 0.078785297 | M10: prr7prr9 (n=40,38) | N10: 0.4517275 | O10: 0.063714483 | P10: 40 | Q10: 0.77337632 | R10: 0.083511603 | S10: 38 | U10: prr7prr9 FW | V10: =B10 -> 0.48434 | W10: =C10 -> 0.030674305 | X10: =D10 -> 0.76724 | Y10: =E10 -> 0.078785297 | Z10: =N10 -> 0.4517275 | AA10: =O10 -> 0.063714483 | AB10: =Q10 -> 0.77337632 | AC10: =R10 -> 0.083511603
U11: Col estDW | Z11: =N38 -> 0.071033911 | AA11: =O38 -> 0.010173943 | AB11: =P38 -> 0.10088839 | AC11: =Q38 -> 0.014758522
U12: prr7prr9 estDW | Z12: =N39 -> 0.047660164 | AA12: =O39 -> 0.0067222888 | AB12: =P39 -> 0.07336056 | AC12: =Q39 -> 0.0079217036
S27: Water content at 35 days, from the 5 plants each measured for dry biomass
A28: Fold change | G28: Fold change | M28: Fold change | S28: Genotype | T28: Control | V28: + GA
B29: Control | C29: +GA | H29: Control | I29: +GA | N29: Control | O29: +GA | T29: Col | U29: prr7prr9 | V29: Col | W29: prr7prr9
A30: Col | B30: =B9/B9 -> 1 | C30: =D9/B9 -> 1.136263 | G30: Col | H30: =H9/H9 -> 1 | I30: =J9/H9 -> 1.039206 | M30: Col | N30: =N9/N9 -> 1 | O30: =Q9/N9 -> 1.4841853 | S30: % water content | T30: ='[1]Col control no GA'!H11 -> 91.353847 | U30: ='[1]prr7prr9 control no GA'!H11 -> 89.449355 | V30: ='[1]Col GA'!H11 -> 91.7261 | W30: ='[1]prr7prr9 GA'!H11 -> 90.514248
A31: prr7prr9 | B31: =B10/B9 -> 0.52579356 | C31: =D10/B10 -> 1.5840938 | D31: =D10/D9 -> 0.73302251 | G31: prr7prr9 | H31: =H10/H9 -> 0.52579356 | I31: =J10/H10 -> 1.5840938 | J31: =J10/J9 -> 0.80148338 | M31: prr7prr9 | N31: =N10/N9 -> 0.54983669 | O31: =Q10/N31 -> 1.4065564 | P31: =Q10/Q9 -> 0.63424922 | S31: SD | T31: ='[1]Col control no GA'!H12 -> 0.12940583 | U31: ='[1]prr7prr9 control no GA'!H12 -> 0.43099487 | V31: ='[1]Col GA'!H12 -> 0.34177361 | W31: ='[1]prr7prr9 GA'!H12 -> 0.46976386
M34: Calculated Dry biomass, from FW + water content
B35: Measured Dry biomass | M35: Note SD is also corrected by water content; fractional SD of WC is 10x < biomass | S35: Water content at 35 days, from the 5 plants each measured for dry biomass
A36: Genotype | B36: Control | D36: + GA | G36: Genotype | H36: Control | J36: + GA | M36: Genotype | N36: Control | P36: + GA | S36: Genotype | T36: Control | V36: + GA
B37: DW | C37: SD | D37: DW | E37: SD | H37: DW | I37: SD | J37: DW | K37: SD | N37: DW | O37: SD | P37: DW | Q37: SD | T37: water content | U37: SD | V37: water content | W37: SD
A38: Col | B38: 0.07968 | C38: 0.0093801386 | D38: 0.0864 | E38: 0.016877944 | G38: Col | H38: 0.07968 | I38: 0.0093801386 | J38: 0.0796 | K38: 0.0084589203 | L38: n=4 non-flowering (=smallest) plants for Col+GA | M38: Col | N38: =N9*(1-T38) -> 0.071033911 | O38: =O9*(1-T38) -> 0.010173943 | P38: =Q9*(1-V38) -> 0.10088839 | Q38: =R9*(1-V38) -> 0.014758522 | S38: Col | T38: =0.01*T30 -> 0.91353847 | U38: =0.01*T31 -> 0.0012940583 | V38: =0.01*V30 -> 0.917261 | W38: =0.01*V31 -> 0.0034177361
A39: prr7prr9 | B39: 0.0511 | C39: 0.0038203403 | D39: 0.07252 | E39: 0.004484083 | G39: prr7prr9 | H39: 0.0511 | I39: 0.0038203403 | J39: 0.07252 | K39: 0.004484083 | M39: prr7prr9 | N39: =N10*(1-T39) -> 0.047660164 | O39: =O10*(1-T39) -> 0.0067222888 | P39: =Q10*(1-V39) -> 0.07336056 | Q39: =R10*(1-V39) -> 0.0079217036 | S39: prr7prr9 | T39: =0.01*U30 -> 0.89449355 | U39: =0.01*U31 -> 0.0043099487 | V39: =0.01*W30 -> 0.90514248 | W39: =0.01*W31 -> 0.0046976386
A57: Fold change | G57: Fold change | M57: Fold change
B58: Control | C58: +GA | H58: Control | I58: +GA | N58: Control | O58: +GA
A59: Col | B59: =B38/B38 -> 1 | C59: =D38/B38 -> 1.0843373 | G59: Col | H59: =H38/H38 -> 1 | I59: =J38/H38 -> 0.99899598 | M59: Col | N59: =N38/N38 -> 1 | O59: =P38/N38 -> 1.4202849
A60: prr7prr9 | B60: =B39/B38 -> 0.64131526 | C60: =D39/B39 -> 1.4191781 | D60: =D39/D38 -> 0.83935185 | G60: prr7prr9 | H60: =H39/H38 -> 0.64131526 | I60: =J39/H39 -> 1.4191781 | J60: =J39/J38 -> 0.91105528 | M60: prr7prr9 | N60: =N39/N38 -> 0.67094946 | O60: =P39/N39 -> 1.5392427 | P60: =P39/P38 -> 0.72714568

Sheet Metabolite Data, stats
A2: Genotype | B2: Time of Harvest | C2: Treatment | D2: Replicate | E2: chl a (mg/g FW) | F2: mg chl b/g FW | G2: starch (µmol/gFW) | H2: malate (µmol/g FW) | I2: fumarate (µmol/g FW) | J2: glucose (µmol/g FW) | K2: fructose (µmol/g FW) | L2: sucrose (µmol/g FW) | M2: total protein (mg/gFW) | N2: AA (µmol/gFW) | O2: G6P (nmol/g FW) | P2: NO3 (µmol/g FW)
A3: prr7prr9 | B3: 28D_EoD | C3: GA | D3: 3 | E3: 0.96542931 | F3: 0.27856142 | G3: 60.865632 | H3: 22.051579 | I3: 20.820266 | J3: 0.80435351 | K3: 0.04826121 | L3: 2.52567 | M3: 16.650061 | N3: 37.042765 | O3: 171.62923 | P3: 99.777942
A4: prr7prr9 | B4: 28D_EoD | C4: GA | D4: 2 | E4: 0.95105263 | F4: 0.31579395 | G4: 57.960914 | H4: 21.141807 | I4: 21.108263 | J4: 0.78572637 | K4: 0.058929478 | L4: 2.1509259 | M4: 17.855056 | N4: 36.282372 | O4: 212.49683 | P4: 104.28178
A5: prr7prr9 | B5: 28D_EoD | C5: GA | D5: 1 | E5: 0.95299485 | F5: 0.2725118 | G5: 58.309328 | H5: 22.559475 | I5: 20.372711 | J5: 0.78488332 | K5: 0.032036054 | L5: 2.4747852 | M5: 16.847671 | N5: 36.446917 | O5: 175.9808 | P5: 106.53157
A6: prr7prr9 | B6: 28D_EoD | C6: Control | D6: 3 | E6: 1.1476068 | F6: 0.29598511 | G6: 66.488595 | H6: 22.929889 | I6: 20.19754 | J6: 1.175246 | K6: 0.25410725 | L6: 2.9619377 | M6: 17.58765 | N6: 37.344213 | O6: 192.54347 | P6: 110.01627
A7: prr7prr9 | B7: 28D_EoD | C7: Control | D7: 2 | E7: 1.2141472 | F7: 0.32995254 | G7: 63.535873 | H7: 21.734491 | I7: 21.37749 | J7: 0.96620413 | K7: 0.18945179 | L7: 2.747051 | M7: 18.888677 | N7: 36.255049 | O7: 186.50625 | P7: 116.66759
A8: prr7prr9 | B8: 28D_EoD | C8: Control | D8: 1 | E8: 1.1676737 | F8: 0.31392512 | G8: 65.404921 | H8: 21.802701 | I8: 21.344051 | J8: 0.9107283 | K8: 0.17857418 | L8: 2.9375452 | M8: 18.674889 | N8: 36.82849 | O8: 196.11647 | P8: 108.27739
A9: Col0 | B9: 28D_EoD | C9: GA | D9: 3 | E9: 0.85483819 | F9: 0.27291508 | G9: 42.155481 | H9: 12.308249 | I9: 10.66746 | J9: 0.2250573 | K9: 0.037509551 | L9: 1.8848549 | M9: 15.578024 | N9: 25.822603 | O9: 185.69425 | P9: 107.52601
A10: Col0 | B10: 28D_EoD | C10: GA | D10: 2 | E10: 0.88032864 | F10: 0.27814447 | G10: 45.514484 | H10: 13.06348 | I10: 10.850343 | J10: 0.33758595 | K10: 0.018754775 | L10: 2.1661765 | M10: 18.494086 | N10: 26.299737 | O10: 183.72786 | P10: 117.89753
A11: Col0 | B11: 28D_EoD | C11: GA | D11: 1 | E11: 0.84772188 | F11: 0.28689375 | G11: 43.6924 | H11: 10.95982 | I11: 8.7555289 | J11: 0.15550834 | K11: 0.097192716 | L11: 1.8563809 | M11: 14.018504 | N11: 29.309852 | O11: 160.38122 | P11: 121.45938
A12: Col0 | B12: 28D_EoD | C12: Control | D12: 3 | E12: 1.0017508 | F12: 0.30414439 | G12: 42.805277 | H12: 11.587616 | I12: 7.7581111 | J12: 0.35924922 | K12: 0 | L12: 2.0058082 | M12: 17.244391 | N12: 29.087782 | O12: 148.08978 | P12: 137.90453
A13: Col0 | B13: 28D_EoD | C13: Control | D13: 2 | E13: 1.0921798 | F13: 0.31970319 | G13: 44.35536 | H13: 13.361385 | I13: 9.0397252 | J13: 0.29778194 | K13: 0 | L13: 2.8190023 | M13: 18.379019 | N13: 30.903672 | O13: 164.6536 | P13: 143.49296
A14: Col0 | B14: 28D_EoD | C14: Control | D14: 1 | E14: 1.0431389 | F14: 0.30295725 | G14: 43.725771 | H14: 13.337411 | I14: 8.1867051 | J14: 0.42543216 | K14: 0 | L14: 2.3302079 | M14: 20.85063 | N14: 31.091168 | O14: 137.53928 | P14: 146.9805
... A26: Col0 | B26: 28D_EoN | C26: Control | D26: 1 | E26: 0.90016415 | F26: 0.27988019 | G26: 5.9907492 | H26: 4.9614629 | I26: 3.6771159 | J26: 0.10562831 | K26: 0 | L26: 1.3995751 | M26: 17.216699 | N26: 28.272337 | O26: 112.36552 | P26: 127.78053
A28: GA : GA treatment | K28: Value less than 0
A29: EoD: End of Day | K29: Replace these values with 0, but I would tend to not use the Fructose data
A30: EoN: End of Night
A31: D: days
A32: t-test probabilities - <0.05 red font, <0.001 red shading
A33: Genotype | B33: Time of Harvest | C33: Treatment | D33: Compared to | E33: chl a (mg/g FW) | F33: mg chl b/g FW | G33: starch (µmol/gFW) | H33: malate (µmol/g FW) | I33: fumarate (µmol/g FW) | J33: glucose (µmol/g FW) | K33: fructose (µmol/g FW) | L33: sucrose (µmol/g FW) | M33: total protein (mg/gFW) | N33: AA (µmol/gFW) | O33: G6P (nmol/g FW) | P33: NO3 (µmol/g FW)
A34: prr7prr9 | B34: 28D_EoD | C34: GA | D34: =[3]Sheet1!D$34 -> 79 control | E34: =[3]Sheet1!E$34 -> 0.00040473416 | F34: =[3]Sheet1!F$34 -> 0.219171 | G34: =[3]Sheet1!G$34 -> 0.0083527498 | H34: =[3]Sheet1!H$34 -> 0.69645565 | I34: =[3]Sheet1!I$34 -> 0.666175 | J34: =[3]Sheet1!J$34 -> 0.049095912 | L34: =[3]Sheet1!L$34 -> 0.021289204 | M34: =[3]Sheet1!M$34 -> 0.082390966 | N34: =[3]Sheet1!N$34 -> 0.60532002 | O34: =[3]Sheet1!O$34 -> 0.72421267 | P34: =[3]Sheet1!P$34 -> 0.066095884
A35: prr7prr9 | B35: 28D_EoD | C35: Control | D35: =[3]Sheet1!D$37 -> Col control | E35: =[3]Sheet1!E$37 -> 0.01618918 | F35: =[3]Sheet1!F$37 -> 0.71726175 | G35: =[3]Sheet1!G$37 -> 2.4738113e-05 | H35: =[3]Sheet1!H$37 -> 0.00018207022 | I35: =[3]Sheet1!I$37 -> 1.9812508e-05 | J35: =[3]Sheet1!J$37 -> 0.001766886 | L35: =[3]Sheet1!L$37 -> 0.11327097 | M35: =[3]Sheet1!M$37 -> 0.71820398 | N35: =[3]Sheet1!N$37 -> 0.00082409582 | O35: =[3]Sheet1!O$37 -> 0.0076477426 | P35: =[3]Sheet1!P$37 -> 0.001066071
A36: Col0 | B36: 28D_EoD | C36: GA | D36: =[3]Sheet1!D$40 -> Col control | E36: =[3]Sheet1!E$40 -> 0.0027156166 | F36: =[3]Sheet1!F$40 -> 0.011879588 | G36: =[3]Sheet1!G$40 -> 0.8893104 | H36: =[3]Sheet1!H$40 -> 0.48633011 | I36: =[3]Sheet1!I$40 -> 0.083493358 | J36: =[3]Sheet1!J$40 -> 0.13328397 | L36: =[3]Sheet1!L$40 -> 0.17984594 | M36: =[3]Sheet1!M$40 -> 0.1734266 | N36: =[3]Sheet1!N$40 -> 0.063756431 | O36: =[3]Sheet1!O$40 -> 0.079414717 | P36: =[3]Sheet1!P$40 -> 0.0053512821
A37: Col0 | B37: 28D_EoD | C37: Control
A38: prr7prr9 | B38: 28D_EoN | C38: GA | D38: =[3]Sheet1!D$46 -> 79 control | E38: =[3]Sheet1!E$46 -> 0.042464709 | F38: =[3]Sheet1!F$46 -> 0.1595584 | G38: =[3]Sheet1!G$46 -> 0.26902837 | H38: =[3]Sheet1!H$46 -> 0.52618691 | I38: =[3]Sheet1!I$46 -> 0.0010430404 | J38: =[3]Sheet1!J$46 -> 0.19364378 | L38: =[3]Sheet1!L$46 -> 0.11657307 | M38: =[3]Sheet1!M$46 -> 0.58898652 | N38: =[3]Sheet1!N$46 -> 0.33193293 | O38: =[3]Sheet1!O$46 -> 0.69874482 | P38: =[3]Sheet1!P$46 -> 0.24638124
A39: prr7prr9 | B39: 28D_EoN | C39: Control | D39: =[3]Sheet1!D$49 -> Col control | E39: =[3]Sheet1!E$49 -> 0.021209224 | F39: =[3]Sheet1!F$49 -> 0.16053577 | G39: =[3]Sheet1!G$49 -> 0.00050088295 | H39: =[3]Sheet1!H$49 -> 0.00063308497 | I39: =[3]Sheet1!I$49 -> 1.2626582e-05 | J39: =[3]Sheet1!J$49 -> 0.24896894 | L39: =[3]Sheet1!L$49 -> 0.071198222 | M39: =[3]Sheet1!M$49 -> 0.26526484 | N39: =[3]Sheet1!N$49 -> 0.028443621 | O39: =[3]Sheet1!O$49 -> 0.18704841 | P39: =[3]Sheet1!P$49 -> 0.0535901
A40: Col0 | B40: 28D_EoN | C40: GA | D40: =[3]Sheet1!D$52 -> Col control | E40: =[3]Sheet1!E$52 -> 0.036418414 | F40: =[3]Sheet1!F$52 -> 0.27843832 | G40: =[3]Sheet1!G$52 -> 0.39266889 | H40: =[3]Sheet1!H$52 -> 0.32050613 | I40: =[3]Sheet1!I$52 -> 0.34322225 | J40: =[3]Sheet1!J$52 -> 0.86963712 | L40: =[3]Sheet1!L$52 -> 0.30579673 | M40: =[3]Sheet1!M$52 -> 0.061371421 | N40: =[3]Sheet1!N$52 -> 0.0064795749 | O40: =[3]Sheet1!O$52 -> 0.46534798 | P40: =[3]Sheet1!P$52 -> 0.066337095
A41: Col0 | B41: 28D_EoN | C41: Control
A43: Mean
A44: Genotype | B44: Time of Harvest | C44: Treatment | D44: Replicate | E44: chl a (mg/g FW) | F44: mg chl b/g FW | G44: starch (µmol/gFW) | H44: malate (µmol/g FW) | I44: fumarate (µmol/g FW) | J44: glucose (µmol/g FW) | K44: fructose (µmol/g FW) | L44: sucrose (µmol/g FW) | M44: total protein (mg/gFW) | N44: AA (µmol/gFW) | O44: G6P (nmol/g FW) | P44: NO3 (µmol/g FW)
A45: prr7prr9 | B45: 28D_EoD | C45: GA | E45: =AVERAGE(E3:E5) -> 0.95649226 | F45: =AVERAGE(F3:F5) -> 0.28895572 | G45: =AVERAGE(G3:G5) -> 59.045291 | H45: =AVERAGE(H3:H5) -> 21.91762 | I45: =AVERAGE(I3:I5) -> 20.76708 | J45: =AVERAGE(J3:J5) -> 0.7916544 | K45: =AVERAGE(K3:K5) -> 0.046408914 | L45: =AVERAGE(L3:L5) -> 2.3837937 | ... P45: =AVERAGE(P3:P5) -> 103.53043
A46: prr7prr9 | B46: 28D_EoD | C46: Control | E46: =AVERAGE(E6:E8) -> 1.1764759 | F46: =AVERAGE(F6:F8) -> 0.31328759 | G46: =AVERAGE(G6:G8) -> 65.14313 | H46: =AVERAGE(H6:H8) -> 22.155694 | I46: =AVERAGE(I6:I8) -> 20.973027 | J46: =AVERAGE(J6:J8) -> 1.0173928 | K46: =AVERAGE(K6:K8) -> 0.20737774 | L46: =AVERAGE(L6:L8) -> 2.8821779 | ... P46: =AVERAGE(P6:P8) -> 111.65375
A47: Col0 | B47: 28D_EoD | C47: GA | E47: =AVERAGE(E9:E11) -> 0.8609629 | F47: =AVERAGE(F9:F11) -> 0.27931777 | G47: =AVERAGE(G9:G11) -> 43.787455 | H47: =AVERAGE(H9:H11) -> 12.110517 | I47: =AVERAGE(I9:I11) -> 10.091111 | J47: =AVERAGE(J9:J11) -> 0.23938387 | K47: =AVERAGE(K9:K11) -> 0.051152347 | L47: =AVERAGE(L9:L11) -> 1.9691374 | ... P47: =AVERAGE(P9:P11) -> 115.62764
A48: Col0 | B48: 28D_EoD | C48: Control | E48: =AVERAGE(E12:E14) -> 1.0456898 | F48: =AVERAGE(F12:F14) -> 0.30893494 | G48: =AVERAGE(G12:G14) -> 43.628803 | H48: =AVERAGE(H12:H14) -> 12.762137 | I48: =AVERAGE(I12:I14) -> 8.3281805 | J48: =AVERAGE(J12:J14) -> 0.36082111 | K48: =AVERAGE(K12:K14) -> 0 | L48: =AVERAGE(L12:L14) -> 2.3850061 | ... P48: =AVERAGE(P12:P14) -> 142.79266
A49: prr7prr9 | B49: 28D_EoN | C49: GA | E49: =AVERAGE(E15:E17) -> 0.9037389 | F49: =AVERAGE(F15:F17) -> 0.27706381 | G49: =AVERAGE(G15:G17) -> 12.680685 | H49: =AVERAGE(H15:H17) -> 10.62675 | I49: =AVERAGE(I15:I17) -> 13.264252 | J49: =AVERAGE(J15:J17) -> 0.36086779 | K49: =AVERAGE(K15:K17) -> 0 | L49: =AVERAGE(L15:L17) -> 1.6294087 | ... P49: =AVERAGE(P15:P17) -> 120.76767
A50: prr7prr9 | B50: 28D_EoN | C50: Control | E50: =AVERAGE(E18:E20) -> 0.9867915 | F50: =AVERAGE(F18:F20) -> 0.28669254 | G50: =AVERAGE(G18:G20) -> 13.622909 | H50: =AVERAGE(H18:H20) -> 10.224952 | I50: =AVERAGE(I18:I20) -> 11.260776 | J50: =AVERAGE(J18:J20) -> 0.17442226 | K50: =AVERAGE(K18:K20) -> 0 | L50: =AVERAGE(L18:L20) -> 1.4998486 | ... P50: =AVERAGE(P18:P20) -> 110.86932
A51: Col0 | B51: 28D_EoN | C51: GA | E51: =AVERAGE(E21:E23) -> 0.78881587 | F51: =AVERAGE(F21:F23) -> 0.26937583 | G51: =AVERAGE(G21:G23) -> 3.5794044 | H51: =AVERAGE(H21:H23) -> 4.2179721 | I51: =AVERAGE(I21:I23) -> 3.6299776 | J51: =AVERAGE(J21:J23) -> 0.10787351 | K51: =AVERAGE(K21:K23) -> 0 | L51: =AVERAGE(L21:L23) -> 0.91376551 | ... P51: =AVERAGE(P21:P23) -> 133.12245
A52: Col0 | B52: 28D_EoN | C52: Control | E52: =AVERAGE(E24:E26) -> 0.88181992 | F52: =AVERAGE(F24:F26) -> 0.27620305 | G52: =AVERAGE(G24:G26) -> 4.3936204 | H52: =AVERAGE(H24:H26) -> 4.5673903 | I52: =AVERAGE(I24:I26) -> 3.0944448 | J52: =AVERAGE(J24:J26) -> 0.11548022 | K52: =AVERAGE(K24:K26) -> 0 | L52: =AVERAGE(L24:L26) -> 1.0999139 | ... P52: =AVERAGE(P24:P26) -> 122.78439
A54: Standard deviation
A55: Genotype | B55: Time of Harvest | C55: Treatment | D55: Replicate | E55: chl a (mg/g FW) | F55: mg chl b/g FW | G55: starch (µmol/gFW) | H55: malate (µmol/g FW) | I55: fumarate (µmol/g FW) | J55: glucose (µmol/g FW) | K55: fructose (µmol/g FW) | L55: sucrose (µmol/g FW) | M55: total protein (mg/gFW) | N55: AA (µmol/gFW) | O55: G6P (nmol/g FW) | P55: NO3 (µmol/g FW)
...

Sheet Metabolite Summary
A1: Mean | C1: mg/g FW | D1: mg/g FW | E1: umol C6/gFW | F1: umol C4/gFW | G1: umol C4/gFW | H1: umol/gFW | I1: umol/gFW | J1: umol/gFW | K1: mg/gFW | L1: umol/gFW | M1: nmol/gFW | N1: umol/gFW | P1: umol C/gFW | Q1: umol C/gFW | R1: umol C/gFW
A2: Treatment | B2: Genotype | C2: chl a | D2: chl b | E2: Starch | F2: Malate | G2: Fumarate | H2: Glucose | I2: Fructose | J2: Sucrose | K2: Total protein | L2: AA | M2: G6P | N2: NO3 | P2: Starch | Q2: Malate | R2: Fumarate
A3: Control | B3: Col ED | C3: ='Metabolite Data, stats'!E48 -> 1.0456898 | D3: ='Metabolite Data, stats'!F48 -> 0.30893494 | E3: ='Metabolite Data, stats'!G48 -> 43.628803 | F3: ='Metabolite Data, stats'!H48 -> 12.762137 | G3: ='Metabolite Data, stats'!I48 -> 8.3281805 | H3: ='Metabolite Data, stats'!J48 -> 0.36082111 | I3: ='Metabolite Data, stats'!K48 -> 0 | J3: ='Metabolite Data, stats'!L48 -> 2.3850061 | ... N3: ='Metabolite Data, stats'!P48 -> 142.79266 | P3: =E3*6 -> 261.77282 | Q3: =F3*4 -> 51.04855 | R3: =G3*4 -> 33.312722 | W3: Col Ctl
A4: Control | B4: Col EN | C4: ='Metabolite Data, stats'!E52 -> 0.88181992 | D4: ='Metabolite Data, stats'!F52 -> 0.27620305 | E4: ='Metabolite Data, stats'!G52 -> 4.3936204 | F4: ='Metabolite Data, stats'!H52 -> 4.5673903 | G4: ='Metabolite Data, stats'!I52 -> 3.0944448 | H4: ='Metabolite Data, stats'!J52 -> 0.11548022 | I4: ='Metabolite Data, stats'!K52 -> 0 | J4: ='Metabolite Data, stats'!L52 -> 1.0999139 | ... N4: ='Metabolite Data, stats'!P52 -> 122.78439 | P4: =E4*6 -> 26.361722 | Q4: =F4*4 -> 18.269561 | R4: =G4*4 -> 12.377779 | W4: Col GA
A5: GA | B5: Col ED | C5: ='Metabolite Data, stats'!E47 -> 0.8609629 | D5: ='Metabolite Data, stats'!F47 -> 0.27931777 | E5: ='Metabolite Data, stats'!G47 -> 43.787455 | F5: ='Metabolite Data, stats'!H47 -> 12.110517 | G5: ='Metabolite Data, stats'!I47 -> 10.091111 | H5: ='Metabolite Data, stats'!J47 -> 0.23938387 | I5: ='Metabolite Data, stats'!K47 -> 0.051152347 | J5: ='Metabolite Data, stats'!L47 -> 1.9691374 | ... N5: ='Metabolite Data, stats'!P47 -> 115.62764 | P5: =E5*6 -> 262.72473 | Q5: =F5*4 -> 48.442066 | R5: =G5*4 -> 40.364443 | W5: prr Ctl
A6: GA | B6: Col EN | C6: ='Metabolite Data, stats'!E51 -> 0.78881587 | D6: ='Metabolite Data, stats'!F51 -> 0.26937583 | E6: ='Metabolite Data, stats'!G51 -> 3.5794044 | F6: ='Metabolite Data, stats'!H51 -> 4.2179721 | G6: ='Metabolite Data, stats'!I51 -> 3.6299776 | H6: ='Metabolite Data, stats'!J51 -> 0.10787351 | I6: ='Metabolite Data, stats'!K51 -> 0 | J6: ='Metabolite Data, stats'!L51 -> 0.91376551 | ... N6: ='Metabolite Data, stats'!P51 -> 133.12245 | P6: =E6*6 -> 21.476426 | Q6: =F6*4 -> 16.871888 | R6: =G6*4 -> 14.51991 | W6: prr GA
A7: Control | B7: prr7prr9 ED | C7: ='Metabolite Data, stats'!E46 -> 1.1764759 | D7: ='Metabolite Data, stats'!F46 -> 0.31328759 | E7: ='Metabolite Data, stats'!G46 -> 65.14313 | F7: ='Metabolite Data, stats'!H46 -> 22.155694 | G7: ='Metabolite Data, stats'!I46 -> 20.973027 | H7: ='Metabolite Data, stats'!J46 -> 1.0173928 | I7: ='Metabolite Data, stats'!K46 -> 0.20737774 | J7: ='Metabolite Data, stats'!L46 -> 2.8821779 | ... N7: ='Metabolite Data, stats'!P46 -> 111.65375 | P7: =E7*6 -> 390.85878 | Q7: =F7*4 -> 88.622775 | R7: =G7*4 -> 83.892108
A8: Control | B8: prr7prr9 EN | C8: ='Metabolite Data, stats'!E50 -> 0.9867915 | D8: ='Metabolite Data, stats'!F50 -> 0.28669254 | E8: ='Metabolite Data, stats'!G50 -> 13.622909 | F8: ='Metabolite Data, stats'!H50 -> 10.224952 | G8: ='Metabolite Data, stats'!I50 -> 11.260776 | H8: ='Metabolite Data, stats'!J50 -> 0.17442226 | I8: ='Metabolite Data, stats'!K50 -> 0 | J8: ='Metabolite Data, stats'!L50 -> 1.4998486 | ... N8: ='Metabolite Data, stats'!P50 -> 110.86932 | P8: =E8*6 -> 81.737455 | Q8: =F8*4 -> 40.899806 | R8: =G8*4 -> 45.043105
A9: GA | B9: prr7prr9 ED | C9: ='Metabolite Data, stats'!E45 -> 0.95649226 | D9: ='Metabolite Data, stats'!F45 -> 0.28895572 | E9: ='Metabolite Data, stats'!G45 -> 59.045291 | F9: ='Metabolite Data, stats'!H45 -> 21.91762 | G9: ='Metabolite Data, stats'!I45 -> 20.76708 | H9: ='Metabolite Data, stats'!J45 -> 0.7916544 | I9: ='Metabolite Data, stats'!K45 -> 0.046408914 | J9: ='Metabolite Data, stats'!L45 -> 2.3837937 | ... N9: ='Metabolite Data, stats'!P45 -> 103.53043 | P9: =E9*6 -> 354.27175 | Q9: =F9*4 -> 87.670481 | R9: =G9*4 -> 83.068319
A10: GA | B10: prr7prr9 EN | C10: ='Metabolite Data, stats'!E49 -> 0.9037389 | D10: ='Metabolite Data, stats'!F49 -> 0.27706381 | E10: ='Metabolite Data, stats'!G49 -> 12.680685 | F10: ='Metabolite Data, stats'!H49 -> 10.62675 | G10: ='Metabolite Data, stats'!I49 -> 13.264252 | H10: ='Metabolite Data, stats'!J49 -> 0.36086779 | I10: ='Metabolite Data, stats'!K49 -> 0 | J10: ='Metabolite Data, stats'!L49 -> 1.6294087 | ... N10: ='Metabolite Data, stats'!P49 -> 120.76767 | P10: =E10*6 -> 76.084112 | Q10: =F10*4 -> 42.507 | R10: =G10*4 -> 53.057009
A13: SD | C13: mg/g FW | D13: mg/g FW | E13: umol C6/gFW | F13: umol C4/gFW | G13: umol C4/gFW | H13: umol/gFW | I13: umol/gFW | J13: umol/gFW | K13: mg/gFW | L13: umol/gFW | M13: nmol/gFW | N13: umol/gFW | P13: umol C/gFW | Q13: umol C/gFW | R13: umol C/gFW
A14: Treatment | B14: Genotype | C14: chl a | D14: chl b | E14: Starch | F14: Malate | G14: Fumarate | H14: Glucose | I14: Fructose | J14: Sucrose | K14: Total protein | L14: AA | M14: G6P | N14: NO3 | P14: Starch | Q14: Malate | R14: Fumarate
A15: Control | B15: Col ED | C15: ='Metabolite Data, stats'!E59 -> 0.045268431 | D15: ='Metabolite Data, stats'!F59 -> 0.0093444472 | E15: ='Metabolite Data, stats'!G59 -> 0.77957741 | F15: ='Metabolite Data, stats'!H59 -> 1.0172357 | G15: ='Metabolite Data, stats'!I59 -> 0.65241483 | H15: ='Metabolite Data, stats'!J59 -> 0.063839625 | I15: ='Metabolite Data, stats'!K59 -> 0 | J15: ='Metabolite Data, stats'!L59 -> 0.4093572 | ... N15: ='Metabolite Data, stats'!P59 -> 4.5783284 | P15: =E15*6 -> 4.6774644 | Q15: =F15*4 -> 4.0689428 | R15: =G15*4 -> 2.6096593
A16: Control | B16: Col EN | C16: ='Metabolite Data, stats'!E63 -> 0.020528843 | D16: ='Metabolite Data, stats'!F63 -> 0.0091799357 | E16: ='Metabolite Data, stats'!G63 -> 1.4008862 | F16: ='Metabolite Data, stats'!H63 -> 0.35980856 | G16: ='Metabolite Data, stats'!I63 -> 0.50477249 | H16: ='Metabolite Data, stats'!J63 -> 0.069570773 | I16: ='Metabolite Data, stats'!K63 -> 0 | J16: ='Metabolite Data, stats'!L63 -> 0.26077314 | ... N16: ='Metabolite Data, stats'!P63 -> 4.3413127 | P16: =E16*6 -> 8.405317 | Q16: =F16*4 -> 1.4392342 | R16: =G16*4 -> 2.01909
A17: GA | B17: Col ED | C17: ='Metabolite Data, stats'!E58 -> 0.017144515 | D17: ='Metabolite Data, stats'!F58 -> 0.007062811 | E17: ='Metabolite Data, stats'!G58 -> 1.6815175 | F17: ='Metabolite Data, stats'!H58 -> 1.065678 | G17: ='Metabolite Data, stats'!I58 -> 1.1602568 | H17: ='Metabolite Data, stats'!J58 -> 0.091880367 | I17: ='Metabolite Data, stats'!K58 -> 0.040960005 | J17: ='Metabolite Data, stats'!L58 -> 0.17123375 | ... N17: ='Metabolite Data, stats'!P58 -> 7.2387138 | P17: =E17*6 -> 10.089105 | Q17: =F17*4 -> 4.262712 | R17: =G17*4 -> 4.6410271
A18: GA | B18: Col EN | C18: ='Metabolite Data, stats'!E62 -> 0.04783915 | D18: ='Metabolite Data, stats'!F62 -> 0.0021878179 | E18: ='Metabolite Data, stats'!G62 -> 0.45625508 | F18: ='Metabolite Data, stats'!H62 -> 0.39477829 | G18: ='Metabolite Data, stats'!I62 -> 0.70061531 | H18: ='Metabolite Data, stats'!J62 -> 0.028861506 | I18: ='Metabolite Data, stats'!K62 -> 0 | J18: ='Metabolite Data, stats'!L62 -> 0.086712246 | ... N18: ='Metabolite Data, stats'!P62 -> 5.6750443 | P18: =E18*6 -> 2.7375305 | Q18: =F18*4 -> 1.5791132 | R18: =G18*4 -> 2.8024613
A19: Control | B19: prr7prr9 ED | C19: ='Metabolite Data, stats'!E57 -> 0.034132323 | D19: ='Metabolite Data, stats'!F57 -> 0.016992688 | E19: ='Metabolite Data, stats'!G57 -> 1.4936678 | F19: ='Metabolite Data, stats'!H57 -> 0.67133975 | G19: ='Metabolite Data, stats'!I57 -> 0.6717999 | H19: ='Metabolite Data, stats'!J57 -> 0.13949058 | I19: ='Metabolite Data, stats'!K57 -> 0.040832783 | J19: ='Metabolite Data, stats'!L57 -> 0.11765723 | ... N19: ='Metabolite Data, stats'!P57 -> 4.4283053 | P19: =E19*6 -> 8.9620068 | Q19: =F19*4 -> 2.685359 | R19: =G19*4 -> 2.6871996
A20: Control | B20: prr7prr9 EN | C20: ='Metabolite Data, stats'!E61 -> 0.044943838 | D20: ='Metabolite Data, stats'!F61 -> 0.0052245204 | E20: ='Metabolite Data, stats'!G61 -> 0.66744886 | F20: ='Metabolite Data, stats'!H61 -> 0.94433741 | G20: ='Metabolite Data, stats'!I61 -> 0.19194952 | H20: ='Metabolite Data, stats'!J61 -> 0.029942655 | I20: ='Metabolite Data, stats'!K61 -> 0 | J20: ='Metabolite Data, stats'!L61 -> 0.11218615 | ... N20: ='Metabolite Data, stats'!P61 -> 6.2599403 | P20: =E20*6 -> 4.0046931 | Q20: =F20*4 -> 3.7773497 | R20: =G20*4 -> 0.76779807
A21: GA | B21: prr7prr9 ED | C21: ='Metabolite Data, stats'!E56 -> 0.0078003944 | D21: ='Metabolite Data, stats'!F56 -> 0.023438582 | E21: ='Metabolite Data, stats'!G56 -> 1.5860574 | F21: ='Metabolite Data, stats'!H56 -> 0.7182646 | G21: ='Metabolite Data, stats'!I56 -> 0.37064926 | H21: ='Metabolite Data, stats'!J56 -> 0.011005825 | I21: ='Metabolite Data, stats'!K56 -> 0.013542057 | J21: ='Metabolite Data, stats'!L56 -> 0.20326796 | ... N21: ='Metabolite Data, stats'!P56 -> 3.438935 | P21: =E21*6 -> 9.5163445 | Q21: =F21*4 -> 2.8730584 | R21: =G21*4 -> 1.4825971
A22: GA | B22: prr7prr9 EN | C22: ='Metabolite Data, stats'!E60 -> 0.01941688 | D22: ='Metabolite Data, stats'!F60 -> 0.0081329233 | E22: ='Metabolite Data, stats'!G60 -> 1.0837123 | F22: ='Metabolite Data, stats'!H60 -> 0.33969691 | G22: ='Metabolite Data, stats'!I60 -> 0.35943962 | H22: ='Metabolite Data, stats'!J60 -> 0.20475474 | I22: ='Metabolite Data, stats'!K60 -> 0 | J22: ='Metabolite Data, stats'!L60 -> 0.0068564799 | ... N22: ='Metabolite Data, stats'!P60 -> 10.976974 | P22: =E22*6 -> 6.5022738 | Q22: =F22*4 -> 1.3587877 | R22: =G22*4 -> 1.4377585
