Workbook

Sheet Read.ME
A1: Biomass data from study Gibberellins 1
A2: conducted by Yin Hoon Chew, University of Edinburgh
A4: Sheets in this workbook | B4: Contents
A5: Summary | B5: mean, SD, charts
A6: Col control no GA | B6: biomass as FW for all plants, DW for 5 plants, of Col WT controls at day 35
A7: Col GA | B7: biomass as FW for all plants, DW for 5 plants, of Col WT treated with GA at day 35
A8: prr7prr9 control no GA | B8: biomass as FW for all plants, DW for 5 plants, of prr7prr9 mutant controls at day 35
A9: prr7prr9 GA | B9: biomass as FW for all plants, DW for 5 plants, of prr7prr9 mutant treated with GA at day 35
A11: note on GA-treated Col at day 35, and biomass data
A12: The Col plants flowered early when treated with GA, as expected, mostly between day 28 and day 35
A13: The flowering risked complicating the biomass measurements at day 35, so the Col control plants tested for dry (and fresh) mass were the last 4 to be pre-flowering.
A14: In hindsight, this sampling caused a severe bias towards the youngest i.e. smallest plants in only this genotype-treatment combination, whereas poorly-growing or outlier plants were avoided in normal sampling
A15: GA did not appear to stimulate the biomass of Col in this biased sample, relative to the control, contradicting expectation from the literature.
A17: However when the mean FW of all Col plants was included in the comparison (both for control and GA-treated; 'Full Sets'), not just the 5/4 with DW data, GA stimulated the biomass of Col in line with expectation, and of both Col and prr7prr9 genotypes similarly
A18: Therefore the mean water content of the 4 Col GA plants with DW data was applied to estimate DW for all the Col GA plants, to allow a less-biased comparison of DW in Col control versus GA
A19: See full charts in file GA experiment - biomass+metabolite_AJM.xlsx

Sheet Summary
A1: Photoperiod | B1: 12 | C1: h
A2: Temperature | C2: deg C
A4: Sets of plants with dry mass and images | G4: Sets of plants with dry mass and images | M4: Full sets | U4: t-test P
A5: n=5 | G5: n=5 (except Col with GA treatment, n = 4)
V6: Subset n=5
A7: Genotype | B7: Control | D7: + GA | G7: Genotype | H7: Control | J7: + GA | M7: Genotype | N7: Control | Q7: + GA | V7: Control | W7: + GA | X7: Control | Y7: + GA
B8: FW | C8: SD | D8: FW | E8: SD | H8: FW | I8: SD | J8: FW | K8: SD | N8: FW | O8: SD | P8: n | Q8: FW | R8: SD | S8: n | V8: FW | W8: FW | X8: DW | Y8: DW
A9: Col | B9: ='Col control no GA'!F11 -> 0.92116 | C9: ='Col control no GA'!F12 -> 0.10272066 | D9: ='Col GA'!F11 -> 1.04668 | E9: ='Col GA'!F12 -> 0.21839557 | G9: Col | H9: =B9 -> 0.92116 | I9: =C9 -> 0.10272066 | J9: ='Col GA'!F13 -> 0.957275 | K9: ='Col GA'!F14 -> 0.1015241 | M9: Col | N9: ='Col control no GA'!F48 -> 0.82156667 | O9: ='Col control no GA'!F49 -> 0.11767017 | P9: 15 | Q9: ='Col GA'!F50 -> 1.2193571 | R9: ='Col GA'!F51 -> 0.17837443 | S9: 21 | U9: Col | W9: =_xlfn.T.TEST('Col control no GA'!F6:F10,'Col GA'!F6:F10,2,2) -> 0.2783675 | Y9: =_xlfn.T.TEST('Col control no GA'!G6:G10,'Col GA'!G6:G10,2,2) -> 0.45885148
A10: prr7prr9 | B10: ='prr7prr9 control no GA'!F11 -> 0.48434 | C10: ='prr7prr9 control no GA'!F12 -> 0.030674305 | D10: ='prr7prr9 GA'!F11 -> 0.76724 | E10: ='prr7prr9 GA'!F12 -> 0.078785297 | G10: prr7prr9 | H10: =B10 -> 0.48434 | I10: =C10 -> 0.030674305 | J10: =D10 -> 0.76724 | K10: =E10 -> 0.078785297 | M10: prr7prr9 | N10: ='prr7prr9 control no GA'!F48 -> 0.4517275 | O10: ='prr7prr9 control no GA'!F49 -> 0.063714483 | P10: 40 | Q10: ='prr7prr9 GA'!F48 -> 0.77337632 | R10: ='prr7prr9 GA'!F49 -> 0.083511603 | S10: 38 | U10: prr7prr9 | V10: =_xlfn.T.TEST('Col control no GA'!F6:F10,'prr7prr9 control no GA'!F6:F10,2,2) -> 1.6928372e-05 | W10: =_xlfn.T.TEST('prr7prr9 GA'!F6:F10,'prr7prr9 control no GA'!F6:F10,2,2) -> 7.04615e-05 | X10: =_xlfn.T.TEST('Col control no GA'!G6:G10,'prr7prr9 control no GA'!G6:G10,2,2) -> 0.00023035739 | Y10: =_xlfn.T.TEST('prr7prr9 GA'!G6:G10,'prr7prr9 control no GA'!G6:G10,2,2) -> 3.8853341e-05
V12: Full sets
V13: Control | W13: + GA | X13: Control | Y13: + GA
V14: FW | W14: FW | X14: est DW | Y14: est DW
U15: Col | W15: =_xlfn.T.TEST('Col control no GA'!J6:J20,'Col GA'!J6:J28,2,2) -> 0.00014483794 | X15: Need to apply average water content
U16: prr7prr9 | V16: =_xlfn.T.TEST('Col control no GA'!J6:J20,'prr7prr9 control no GA'!J6:J45,2,2) -> 1.0620554e-20 | W16: =_xlfn.T.TEST('prr7prr9 GA'!J6:J43,'prr7prr9 control no GA'!J6:J45,2,2) -> 7.4133209e-31 | X16: to get these data from FW
A28: Fold change | G28: Fold change | M28: Fold change
B29: Control | C29: +GA | H29: Control | I29: +GA | N29: Control | O29: +GA
A30: Col | B30: =B9/B9 -> 1 | C30: =D9/B9 -> 1.136263 | G30: Col | H30: =H9/H9 -> 1 | I30: =J9/H9 -> 1.039206 | M30: Col | N30: =N9/N9 -> 1 | O30: =Q9/N9 -> 1.4841853
A31: prr7prr9 | B31: =B10/B9 -> 0.52579356 | C31: =D10/B10 -> 1.5840938 | D31: =D10/D9 -> 0.73302251 | G31: prr7prr9 | H31: =H10/H9 -> 0.52579356 | I31: =J10/H10 -> 1.5840938 | J31: =J10/J9 -> 0.80148338 | M31: prr7prr9 | N31: =N10/N9 -> 0.54983669 | O31: =Q10/N31 -> 1.4065564 | P31: =Q10/Q9 -> 0.63424922
A36: Genotype | B36: Control | D36: + GA | G36: Genotype | H36: Control | J36: + GA
B37: DW | C37: SD | D37: DW | E37: SD | H37: DW | I37: SD | J37: DW | K37: SD
A38: Col | B38: ='Col control no GA'!G11 -> 0.07968 | C38: ='Col control no GA'!G12 -> 0.0093801386 | D38: ='Col GA'!G11 -> 0.0864 | E38: ='Col GA'!G12 -> 0.016877944 | G38: Col | H38: =B38 -> 0.07968 | I38: =C38 -> 0.0093801386 | J38: ='Col GA'!G13 -> 0.0796 | K38: ='Col GA'!G14 -> 0.0084589203
A39: prr7prr9 | B39: ='prr7prr9 control no GA'!G11 -> 0.0511 | C39: ='prr7prr9 control no GA'!G12 -> 0.0038203403 | D39: ='prr7prr9 GA'!G11 -> 0.07252 | E39: ='prr7prr9 GA'!G12 -> 0.004484083 | G39: prr7prr9 | H39: =B39 -> 0.0511 | I39: =C39 -> 0.0038203403 | J39: =D39 -> 0.07252 | K39: =E39 -> 0.004484083
A57: Fold change | G57: Fold change
B58: Control | C58: +GA | H58: Control | I58: +GA
A59: Col | B59: =B38/B38 -> 1 | C59: =D38/B38 -> 1.0843373 | G59: Col | H59: =H38/H38 -> 1 | I59: =J38/H38 -> 0.99899598
A60: prr7prr9 | B60: =B39/B38 -> 0.64131526 | C60: =D39/B39 -> 1.4191781 | D60: =D39/D38 -> 0.83935185 | G60: prr7prr9 | H60: =H39/H38 -> 0.64131526 | I60: =J39/H39 -> 1.4191781 | J60: =J39/J38 -> 0.91105528

Sheet Col control no GA
A1: Date | B1: 42219
A2: Day | B2: 35
A3: Treatment | B3: Control
A4: Genotype | B4: Col wt
C5: Foil | D5: Foil + FW | E5: Foil + DW | F5: FW (g) | G5: DW (g) | H5: Water (%) | I5: Rosette area (mm2) | J5: FW for t.test
B6: R1 | C6: 1.2611 | D6: 2.1144 | E6: 1.3349 | F6: =D6-C6 -> 0.8533 | G6: =E6-C6 -> 0.0738 | H6: =100-G6/F6*100 -> 91.351225 | J6: =F6 -> 0.8533
B7: R2 | C7: 1.2736 | D7: 2.1556 | E7: 1.3513 | F7: =D7-C7 -> 0.882 | G7: =E7-C7 -> 0.0777 | H7: =100-G7/F7*100 -> 91.190476 | J7: =F7 -> 0.882
B8: R3 | C8: 1.2828 | D8: 2.1199 | E8: 1.354 | F8: =D8-C8 -> 0.8371 | G8: =E8-C8 -> 0.0712 | H8: =100-G8/F8*100 -> 91.494445 | J8: =F8 -> 0.8371
B9: R4 | C9: 1.1551 | D9: 2.2451 | E9: 1.2503 | F9: =D9-C9 -> 1.09 | G9: =E9-C9 -> 0.0952 | H9: =100-G9/F9*100 -> 91.266055 | J9: =F9 -> 1.09
B10: R5 | C10: 1.3181 | D10: 2.2615 | E10: 1.3986 | F10: =D10-C10 -> 0.9434 | G10: =E10-C10 -> 0.0805 | H10: =100-G10/F10*100 -> 91.467034 | J10: =F10 -> 0.9434
E11: Average | F11: =AVERAGE(F6:F10) -> 0.92116 | G11: =AVERAGE(G6:G10) -> 0.07968 | H11: =AVERAGE(H6:H10) -> 91.353847 | I11: =AVERAGE(I6:I10) -> #DIV/0! | J11: =F13 -> 0.6736
E12: SD | F12: =STDEV(F6:F10) -> 0.10272066 | G12: =STDEV(G6:G10) -> 0.0093801386 | H12: =STDEV(H6:H10) -> 0.12940583 | I12: =STDEV(I6:I10) -> #DIV/0! | J12: =F14 -> 0.8115
B13: R6 | F13: 0.6736 | J13: =F15 -> 0.6083 | K13: Note: | L13: Many of the plants from R6 onwards had slightly distorted meristems
B14: R7 | F14: 0.8115 | J14: =F16 -> 0.817
B15: R8 | F15: 0.6083 | J15: =F17 -> 0.8673
B16: R9 | F16: 0.817 | J16: =F18 -> 0.8366
B17: R10 | F17: 0.8673 | J17: =F19 -> 0.8059
B18: R11 | F18: 0.8366 | J18: =F20 -> 0.6444
B19: R12 | F19: 0.8059 | J19: =F21 -> 0.81
B20: R13 | F20: 0.6444 | J20: =F22 -> 0.8431
B21: R14 | F21: 0.81 | J21: =F23 -> 0
B22: R15 | F22: 0.8431 | J22: =F24 -> 0
B23: R16 | J23: =F25 -> 0
B24: R17 | J24: =F26 -> 0
B25: R18 | J25: =F27 -> 0
B26: R19 | J26: =F28 -> 0
B27: R20 | J27: =F29 -> 0
B28: R21 | J28: =F30 -> 0
B29: R22 | J29: =F31 -> 0
B30: R23 | J30: =F32 -> 0
B31: R24 | J31: =F33 -> 0
B32: R25 | J32: =F34 -> 0
B33: R26 | J33: =F35 -> 0
B34: R27 | J34: =F36 -> 0
... B45: R38 | J45: =F47 -> 0
B46: R39
B47: R40
D48: Full set | E48: Average | F48: =AVERAGE(F6:F10,F13:F47) -> 0.82156667
E49: SD | F49: =STDEV(F6:F10,F13:F47) -> 0.11767017

Sheet Col GA
A1: Date | B1: 42219
A2: Day | B2: 35
A3: Treatment | B3: GA
A4: Genotype | B4: Col wt
C5: Foil | D5: Foil + FW | E5: Foil + DW | F5: FW (g) | G5: DW (g) | H5: Water (%) | I5: Rosette area (mm2) | J5: FW for t.test
B6: R1 | C6: 1.3762 | D6: 2.2697 | E6: 1.4496 | F6: =D6-C6 -> 0.8935 | G6: =E6-C6 -> 0.0734 | H6: =100-G6/F6*100 -> 91.785115 | J6: =F6 -> 0.8935
B7: R2 | C7: 1.3308 | D7: 2.2024 | E7: 1.4021 | F7: =D7-C7 -> 0.8716 | G7: =E7-C7 -> 0.0713 | H7: =100-G7/F7*100 -> 91.819642 | J7: =F7 -> 0.8716
B8: R3 | C8: 1.3577 | D8: 2.3251 | E8: 1.4435 | F8: =D8-C8 -> 0.9674 | G8: =E8-C8 -> 0.0858 | H8: =100-G8/F8*100 -> 91.130866 | J8: =F8 -> 0.9674
B9: R4 | C9: 1.3947 | D9: 2.4913 | E9: 1.4826 | F9: =D9-C9 -> 1.0966 | G9: =E9-C9 -> 0.0879 | H9: =100-G9/F9*100 -> 91.984315 | J9: =F9 -> 1.0966
B10: R5 | C10: 1.4558 | D10: 2.8601 | E10: 1.5694 | F10: =D10-C10 -> 1.4043 | G10: =E10-C10 -> 0.1136 | H10: =100-G10/F10*100 -> 91.91056 | J10: =F10 -> 1.4043 | K10: =K15 -> Note: | L10: =L15 -> All the plants from R5 onwards had shown sign of flowering
E11: Average 5 | F11: =AVERAGE(F6:F10) -> 1.04668 | G11: =AVERAGE(G6:G10) -> 0.0864 | H11: =AVERAGE(H6:H10) -> 91.7261 | I11: =AVERAGE(I6:I10) -> #DIV/0! | J11: =F13 -> 0.957275
E12: SD 5 | F12: =STDEV(F6:F10) -> 0.21839557 | G12: =STDEV(G6:G10) -> 0.016877944 | H12: =STDEV(H6:H10) -> 0.34177361 | I12: =STDEV(I6:I10) -> #DIV/0! | J12: =F14 -> 0.1015241
E13: Average 4 | F13: =AVERAGE(F6:F9) -> 0.957275 | G13: =AVERAGE(G6:G9) -> 0.0796 | H13: =AVERAGE(H6:H9) -> 91.679985 | I13: =AVERAGE(I6:I9) -> #DIV/0! | J13: =F15 -> 1.0586
E14: SD 4 | F14: =STDEV(F6:F9) -> 0.1015241 | G14: =STDEV(G6:G9) -> 0.0084589203 | H14: =STDEV(H6:H9) -> 0.3762555 | I14: =STDEV(I6:I9) -> #DIV/0! | J14: =F16 -> 1.2004
B15: R6 | F15: 1.0586 | J15: =F17 -> 1.3335 | K15: Note: | L15: All the plants from R5 onwards had shown sign of flowering
B16: R7 | F16: 1.2004 | J16: =F18 -> 1.2391
B17: R8 | F17: 1.3335 | J17: =F19 -> 1.1709
B18: R9 | F18: 1.2391 | J18: =F20 -> 1.365
B19: R10 | F19: 1.1709 | J19: =F21 -> 1.3743
B20: R11 | F20: 1.365 | J20: =F22 -> 1.3509
B21: R12 | F21: 1.3743 | J21: =F23 -> 1.5503
B22: R13 | F22: 1.3509 | J22: =F24 -> 1.4258
B23: R14 | F23: 1.5503 | J23: =F25 -> 1.1924
B24: R15 | F24: 1.4258 | J24: =F26 -> 1.2714
B25: R16 | F25: 1.1924 | J25: =F27 -> 1.0765
B26: R17 | F26: 1.2714 | J26: =F28 -> 1.1852
B27: R18 | F27: 1.0765 | J27: =F29 -> 1.2393
... B30: R21 | F30: 1.3395 | J30: =F32 -> 0
B31: R22 | J31: =F33 -> 0
B32: R23 | J32: =F34 -> 0
B33: R24 | J33: =F35 -> 0
B34: R25 | J34: =F36 -> 0
B35: R26 | J35: =F37 -> 0
B36: R27 | J36: =F38 -> 0
B37: R28 | J37: =F39 -> 0
B38: R29 | J38: =F40 -> 0
B39: R30 | J39: =F41 -> 0
B40: R31 | J40: =F42 -> 0
B41: R32 | J41: =F43 -> 0
B42: R33 | J42: =F44 -> 0
...

Sheet prr7prr9 control no GA
A1: Date | B1: 42219
A2: Day | B2: 35
A3: Treatment | B3: control
A4: Genotype | B4: prr7prr9
C5: Foil | D5: Foil + FW | E5: Foil + DW | F5: FW (g) | G5: DW (g) | H5: Water (%) | I5: Rosette area (mm2) | J5: FW for t.test
B6: R1 | C6: 1.0912 | D6: 1.59 | E6: 1.1423 | F6: =D6-C6 -> 0.4988 | G6: =E6-C6 -> 0.0511 | H6: =100-G6/F6*100 -> 89.755413 | J6: =F6 -> 0.4988
B7: R2 | C7: 1.0951 | D7: 1.5889 | E7: 1.1509 | F7: =D7-C7 -> 0.4938 | G7: =E7-C7 -> 0.0558 | H7: =100-G7/F7*100 -> 88.699878 | J7: =F7 -> 0.4938
B8: R3 | C8: 1.1255 | D8: 1.5724 | E8: 1.172 | F8: =D8-C8 -> 0.4469 | G8: =E8-C8 -> 0.0465 | H8: =100-G8/F8*100 -> 89.594988 | J8: =F8 -> 0.4469
B9: R4 | C9: 1.181 | D9: 1.6407 | E9: 1.2293 | F9: =D9-C9 -> 0.4597 | G9: =E9-C9 -> 0.0483 | H9: =100-G9/F9*100 -> 89.493148 | J9: =F9 -> 0.4597
B10: R5 | C10: 1.1499 | D10: 1.6724 | E10: 1.2037 | F10: =D10-C10 -> 0.5225 | G10: =E10-C10 -> 0.0538 | H10: =100-G10/F10*100 -> 89.703349 | J10: =F10 -> 0.5225
E11: Average | F11: =AVERAGE(F6:F10) -> 0.48434 | G11: =AVERAGE(G6:G10) -> 0.0511 | H11: =AVERAGE(H6:H10) -> 89.449355 | I11: =AVERAGE(I6:I10) -> #DIV/0! | J11: =F13 -> 0.5551
E12: SD | F12: =STDEV(F6:F10) -> 0.030674305 | G12: =STDEV(G6:G10) -> 0.0038203403 | H12: =STDEV(H6:H10) -> 0.43099487 | I12: =STDEV(I6:I10) -> #DIV/0! | J12: =F14 -> 0.4489
B13: R6 | F13: 0.5551 | J13: =F15 -> 0.4462
B14: R7 | F14: 0.4489 | J14: =F16 -> 0.4554
B15: R8 | F15: 0.4462 | J15: =F17 -> 0.5811
B16: R9 | F16: 0.4554 | J16: =F18 -> 0.392
B17: R10 | F17: 0.5811 | J17: =F19 -> 0.5824
B18: R11 | F18: 0.392 | J18: =F20 -> 0.4021
B19: R12 | F19: 0.5824 | J19: =F21 -> 0.4254
B20: R13 | F20: 0.4021 | J20: =F22 -> 0.322
B21: R14 | F21: 0.4254 | J21: =F23 -> 0.3965
B22: R15 | F22: 0.322 | J22: =F24 -> 0.3441
B23: R16 | F23: 0.3965 | J23: =F25 -> 0.4289
B24: R17 | F24: 0.3441 | J24: =F26 -> 0.425
... B45: R38 | F45: 0.4149 | J45: =F47 -> 0.4335
B46: R39 | F46: 0.4831
B47: R40 | F47: 0.4335
D48: Full set | E48: Average | F48: =AVERAGE(F6:F10,F13:F47) -> 0.4517275
E49: SD | F49: =STDEV(F6:F10,F13:F47) -> 0.063714483

Sheet prr7prr9 GA
A1: Date | B1: 42219
A2: Day | B2: 35
A3: Treatment | B3: GA
A4: Genotype | B4: prr7prr9
C5: Foil | D5: Foil + FW | E5: Foil + DW | F5: FW (g) | G5: DW (g) | H5: Water (%) | I5: Rosette area (mm2) | J5: FW for t.test
B6: R1 | C6: 1.3993 | D6: 2.097 | E6: 1.4674 | F6: =D6-C6 -> 0.6977 | G6: =E6-C6 -> 0.0681 | H6: =100-G6/F6*100 -> 90.239358 | J6: =F6 -> 0.6977
B7: R2 | C7: 1.5734 | D7: 2.3138 | E7: 1.6468 | F7: =D7-C7 -> 0.7404 | G7: =E7-C7 -> 0.0734 | H7: =100-G7/F7*100 -> 90.08644 | J7: =F7 -> 0.7404
B8: R3 | C8: 1.4642 | D8: 2.3491 | E8: 1.5412 | F8: =D8-C8 -> 0.8849 | G8: =E8-C8 -> 0.077 | H8: =100-G8/F8*100 -> 91.298452 | J8: =F8 -> 0.8849
B9: R4 | C9: 1.1568 | D9: 1.9644 | E9: 1.2333 | F9: =D9-C9 -> 0.8076 | G9: =E9-C9 -> 0.0765 | H9: =100-G9/F9*100 -> 90.527489 | J9: =F9 -> 0.8076
B10: R5 | C10: 1.3374 | D10: 2.043 | E10: 1.405 | F10: =D10-C10 -> 0.7056 | G10: =E10-C10 -> 0.0676 | H10: =100-G10/F10*100 -> 90.419501 | J10: =F10 -> 0.7056
E11: Average | F11: =AVERAGE(F6:F10) -> 0.76724 | G11: =AVERAGE(G6:G10) -> 0.07252 | H11: =AVERAGE(H6:H10) -> 90.514248 | I11: =AVERAGE(I6:I10) -> #DIV/0! | J11: =F13 -> 0.7114
E12: SD | F12: =STDEV(F6:F10) -> 0.078785297 | G12: =STDEV(G6:G10) -> 0.004484083 | H12: =STDEV(H6:H10) -> 0.46976386 | I12: =STDEV(I6:I10) -> #DIV/0! | J12: =F14 -> 0.7077
B13: R6 | F13: 0.7114 | J13: =F15 -> 0.8127
B14: R7 | F14: 0.7077 | J14: =F16 -> 0.7095
B15: R8 | F15: 0.8127 | J15: =F17 -> 0.57
B16: R9 | F16: 0.7095 | J16: =F18 -> 0.7346
B17: R10 | F17: 0.57 | J17: =F19 -> 0.8643
B18: R11 | F18: 0.7346 | J18: =F20 -> 0.7456
B19: R12 | F19: 0.8643 | J19: =F21 -> 0.6918
B20: R13 | F20: 0.7456 | J20: =F22 -> 0.8912
B21: R14 | F21: 0.6918 | J21: =F23 -> 0.961
B22: R15 | F22: 0.8912 | J22: =F24 -> 0.8388
B23: R16 | F23: 0.961 | J23: =F25 -> 0.8851
B24: R17 | F24: 0.8388 | J24: =F26 -> 0.7616
... B45: R38 | F45: 0.802 | J45: =F47 -> 0
B46: R39
B47: R40
D48: Full set | E48: Average | F48: =AVERAGE(F6:F10,F13:F47) -> 0.77337632
E49: SD | F49: =STDEV(F6:F10,F13:F47) -> 0.083511603
