Workbook

Sheet Metabolite samples
A3: Batch 1 | P3: ID | Q3: FW(mg)
A4: Metabolites | C4: 1 | D4: 2 | E4: 3 | F4: 4 | G4: 5 | H4: 6 | I4: 7 | J4: 8 | K4: 9 | L4: 10 | M4: 11 | N4: 12 | P4: Col 21ED1 | Q4: 17.3
B5: A | D5: Col 21ED1 | E5: prr7 21ED1 | F5: prr7/9 21ED1 | G5: lsf 21ED1 | I5: Col 21ED2 | J5: prr7 21ED2 | K5: prr7/9 21ED2 | L5: lsf 21ED2 | M5: Col 21ED3 | N5: prr7 21ED3 | P5: Col 21ED2 | Q5: 20.3
B6: B | D6: prr7/9 21ED3 | E6: lsf 21ED3 | F6: Col 21EN1 | G6: prr7 21EN1 | I6: prr7/9 21EN1 | J6: lsf 21EN1 | K6: Col 21EN2 | L6: prr7 21EN2 | M6: prr7/9 21EN2 | N6: lsf 21EN2 | P6: Col 21ED3 | Q6: 18.6
B7: C | D7: Col 21EN3 | E7: prr7 21EN3 | F7: prr7/9 21EN3 | G7: lsf 21EN3 | I7: Col 27EN1 | J7: prr7 27EN1 | K7: prr7/9 27EN1 | L7: lsf 27EN1 | M7: Col 27EN2 | N7: prr7 27EN2 | P7: Col 21EN1 | Q7: 9.3
B8: D | D8: prr7/9 27EN2 | E8: lsf 27EN2 | F8: Col 27EN3 | G8: prr7 27EN3 | I8: prr7/9 27EN3 | J8: lsf 27EN3 | K8: Col 28ED1 | L8: prr7 28ED1 | M8: prr7/9 28ED1 | N8: lsf 28ED1 | P8: Col 21EN2 | Q8: 19.5
B9: E | D9: Col 28ED2 | E9: prr7 28ED2 | F9: prr7/9 28ED2 | G9: lsf 28ED2 | I9: Col 28ED3 | J9: prr7 28ED3 | K9: prr7/9 28ED3 | L9: lsf 28ED3 | M9: Col 28EN1 | N9: prr7 28EN1 | P9: Col 21EN3 | Q9: 15.2
B10: F | D10: prr7/9 28EN1 | E10: lsf 28EN1 | F10: Col 28EN2 | G10: prr7 28EN2 | I10: prr7/9 28EN2 | J10: lsf 28EN2 | K10: Col 28EN3 | L10: prr7 28EN3 | M10: prr7/9 28EN3 | N10: lsf 28EN3 | P10: prr7 21ED1 | Q10: 5
B11: G | C11: GH6-35 | H11: GH6-37 | P11: prr7 21ED2 | Q11: 20.6
B12: H | C12: GH6-36 | H12: GH6-38 | P12: prr7 21ED3 | Q12: 18.8
P13: prr7 21EN1 | Q13: 18.5
P14: prr7 21EN2 | Q14: 18.9
P15: prr7 21EN3 | Q15: x
P16: prr7/9 21ED1 | Q16: 9.6
P17: prr7/9 21ED2 | Q17: 16.7
P18: prr7/9 21ED3 | Q18: 10.3
P19: prr7/9 21EN1 | Q19: 15.2
P20: prr7/9 21EN2 | Q20: 14.3
P21: prr7/9 21EN3 | Q21: 15.5
P22: lsf 21ED1 | Q22: 14.9
P23: lsf 21ED2 | Q23: 11.7
P24: lsf 21ED3 | Q24: 19.6
P25: lsf 21EN1 | Q25: 9.3
P26: lsf 21EN2 | Q26: 8.1
P27: lsf 21EN3 | Q27: 18.1
... P63: lsf 28EN3 | Q63: 19.8

Sheet Data Results
A1: All Samples | E1: Units
E2: mg chl a/g FW | F2: mg chl b/g FW | G2: (µmol/gFW) | H2: (µmol/g FW) | I2: (µmol/g FW) | J2: (µmol/g FW) | K2: (mg/gFW) | L2: (µmol/g FW) | M2: (µmol/g FW) | N2: (µmol/gFW) | O2: (nmol/g FW) | P2: (µmol/g FW)
A3: Genotype | B3: DAS | C3: Time harvest | D3: sample ID | E3: chlorophyll a | F3: chlorophyll b | G3: starch | H3: glucose | I3: fructose | J3: sucrose | K3: Total proteins | L3: malate | M3: fumarate | N3: Amino Acids | O3: G6P | P3: NO3
A4: Col | B4: 21 | C4: ED | D4: Col 21ED1 | E4: 0.95692023 | F4: 0.31902225 | G4: 47.042053 | H4: 0.30202777 | I4: 0.086293648 | J4: 1.5209255 | K4: 9.7351427 | L4: 8.3932146 | M4: 5.3432983 | N4: 27.57013 | O4: 292.94902 | P4: 92.342104
A5: Col | B5: 21 | C5: ED | D5: Col 21ED2 | E5: 0.83310148 | F5: 0.27567685 | G5: 43.712122 | H5: 0.20223745 | I5: 0.055155669 | J5: 1.5535513 | K5: 10.200749 | L5: 6.722867 | M5: 5.3639678 | N5: 25.190622 | O5: 242.00303 | P5: 83.652613
A6: Col | B6: 21 | C6: ED | D6: Col 21ED3 | E6: 0.78791183 | F6: 0.28824704 | G6: 36.566625 | H6: 0.18059034 | I6: 0.12039356 | J6: 1.5249851 | K6: 9.43225 | L6: 6.4385612 | M6: 4.922449 | N6: 21.455508 | O6: 279.61972 | P6: 78.110848
A7: Col | B7: 21 | C7: EN | D7: Col 21EN1 | E7: 0.97304301 | F7: 0.52601075 | G7: 5.0312801 | H7: 0 | I7: 0.040131186 | J7: 1.0032796 | K7: 13.122195 | L7: 2.3723838 | M7: 4.7907983 | N7: 17.846661 | O7: 187.84616 | P7: 109.98079
A8: Col | B8: 21 | C8: EN | D8: Col 21EN2 | E8: 0.68562667 | F8: 0.26915333 | G8: 3.7706956 | H8: 0.038278977 | I8: 0.076557954 | J8: 0.76557954 | K8: 8.5034768 | L8: 1.0104545 | M8: 1.1271366 | N8: 13.030058 | O8: 141.59038 | P8: 86.790648
A9: Col | B9: 21 | C9: EN | D9: Col 21EN3 | E9: 0.77478289 | F9: 0.32735625 | G9: 4.7274645 | H9: 0.024553949 | I9: 0.073661848 | J9: 0.8225573 | K9: 10.86536 | L9: 1.2425249 | M9: 0.79627535 | N9: 14.543899 | O9: 129.78196 | P9: 93.934971
A10: Col | B10: 27 | C10: EN | D10: Col 27EN1 | E10: 0.95709036 | F10: 0.29645279 | G10: 2.0358624 | H10: 0.13261625 | I10: 0 | J10: 0.86200565 | K10: 11.447799 | L10: 2.0890843 | M10: 2.1744263 | N10: 22.611543 | O10: 158.97936 | P10: 149.41039
A11: Col | B11: 27 | C11: EN | D11: Col 27EN2 | E11: 1.0279313 | F11: 0.29822065 | G11: 2.7436031 | H11: 0.27852241 | I11: -0.14854528 | J11: 1.9775091 | K11: 10.434454 | L11: 3.1530831 | M11: 2.0412132 | N11: 25.207475 | O11: 170.48192 | P11: 148.42768
A12: Col | B12: 27 | C12: EN | D12: Col 27EN3 | E12: 0.97751875 | F12: 0.29519479 | G12: 2.4370263 | H12: 0.15550834 | I12: 0.058315629 | J12: 1.2343475 | K12: 11.512644 | L12: 2.7233986 | M12: 2.3711209 | N12: 20.345056 | O12: 179.32457 | P12: 139.23466
A13: Col | B13: 28 | C13: ED | D13: Col 28ED1 | E13: 1.185451 | F13: 0.31751146 | G13: 45.084986 | H13: 0.31101669 | I13: 0.097192716 | J13: 3.0324127 | K13: 12.940936 | L13: 11.159323 | M13: 7.8734672 | N13: 33.204984 | O13: 255.98762 | P13: 134.02926
A14: Col | B14: 28 | C14: ED | D14: Col 28ED2 | E14: 1.0695259 | F14: 0.29580707 | G14: 40.351041 | H14: 0.3641171 | I14: 0.1638527 | J14: 2.4304816 | K14: 11.39446 | L14: 10.725498 | M14: 7.2881733 | N14: 27.989915 | O14: 257.55848 | P14: 133.1035
A15: Col | B15: 28 | C15: ED | D15: Col 28ED3 | E15: 1.0688398 | F15: 0.29454466 | G15: 42.66993 | H15: 0.18117477 | I15: 0.10870486 | J15: 2.771974 | K15: 11.441442 | L15: 9.3618674 | M15: 7.2121765 | N15: 27.111348 | O15: 234.80333 | P15: 134.15481
... A18: Col | B18: 28 | C18: EN | D18: Col 28EN3 | E18: 0.87237717 | F18: 0.27290205 | G18: 4.3494481 | H18: 0.22154614 | I18: 0 | J18: 1.0906887 | K18: 9.0265642 | L18: 2.495368 | M18: 2.5379211 | N18: 15.719902 | O18: 157.2836 | P18: 136.92698
A19: x | B19: x | C19: x | D19: GH6-35 | E19: 1.1159005 | F19: 0.30390399 | G19: 48.642456 | H19: 2.7684866 | I19: 0.56070614 | J19: 2.873619 | K19: 10.147757 | L19: 4.8042941 | M19: 7.1925986 | N19: 36.415888 | O19: 231.10345 | P19: 95.242894
A20: x | B20: x | C20: x | D20: GH6-36 | E20: 1.1349833 | F20: 0.31436946 | G20: 45.029248 | H20: 2.9232505 | I20: 0.58832714 | J20: 2.9048652 | K20: 10.148436 | L20: 4.7667153 | M20: 6.7410074 | N20: 34.471014 | O20: 266.41377 | P20: 94.244741
A21: x | B21: x | C21: x | D21: GH6-37 | E21: 1.1909981 | F21: 0.30951762 | G21: 52.281674 | H21: 3.4833869 | I21: 0.72866767 | J21: 3.5278179 | K21: 13.815286 | L21: 5.3237971 | M21: 8.0238841 | N21: 37.695042 | O21: 187.49433 | P21: 95.398388
A22: x | B22: x | C22: x | D22: GH6-38 | E22: 1.0470784 | F22: 0.28516101 | G22: 44.832695 | H22: 2.8443641 | I22: 0.59189079 | J22: 3.3129443 | K22: 11.838499 | L22: 4.961795 | M22: 6.6265833 | N22: 42.14537 | O22: 258.01181 | P22: 85.594957
A23: lsf | B23: 21 | C23: ED | D23: lsf 21ED1 | E23: 0.62508188 | F23: 0.33325369 | G23: 49.684494 | H23: 0.25048324 | I23: 0.025048324 | J23: 0.97688464 | K23: 8.405622 | L23: 5.3216089 | M23: 4.3278628 | N23: 17.522266 | O23: 212.56592 | P23: 48.849899
A24: lsf | B24: 21 | C24: ED | D24: lsf 21ED2 | E24: 0.79668889 | F24: 0.43345556 | G24: 57.988728 | H24: 0.15949574 | I24: 0.15949574 | J24: 1.3238146 | K24: 10.920319 | L24: 6.0956364 | M24: 5.8167511 | N24: 21.581546 | O24: 307.90305 | P24: 64.344269
A25: lsf | B25: 21 | C25: ED | D25: lsf 21ED3 | E25: 0.52728265 | F25: 0.25534719 | G25: 36.917751 | H25: 0.13329287 | I25: 0.095209191 | J25: 0.80927812 | K25: 7.6196588 | L25: 4.1650894 | M25: 3.3350339 | N25: 15.778923 | O25: 191.48389 | P25: 41.724701
A26: lsf | B26: 21 | C26: EN | D26: lsf 21EN1 | E26: 0.82484301 | F26: 0.51348602 | G26: 33.062698 | H26: 0.080262372 | I26: -0.040131186 | J26: 1.1036076 | K26: 11.4142 | L26: 2.9743402 | M26: 2.5625559 | N26: 18.995098 | O26: 182.46074 | P26: 86.317941
A27: lsf | B27: 21 | C27: EN | D27: lsf 21EN2 | E27: 0.8527037 | F27: 0.58070679 | G27: 35.897784 | H27: 0 | I27: -0.046076547 | J27: 1.0367223 | K27: 9.8274996 | L27: 2.2383942 | M27: 1.1567 | N27: 12.577898 | O27: 221.9014 | P27: 71.947911
A28: lsf | B28: 21 | C28: EN | D28: lsf 21EN3 | E28: 0.51379448 | F28: 0.27780856 | G28: 25.020393 | H28: 0.061859673 | I28: 0.061859673 | J28: 0.65983651 | K28: 7.410237 | L28: 1.4856604 | M28: 1.1119646 | N28: 10.885741 | O28: 108.41149 | P28: 53.755704
A29: lsf | B29: 27 | C29: EN | D29: lsf 27EN1 | E29: 0.98531975 | F29: 0.34057994 | G29: 44.769075 | H29: 0.23038273 | I29: 0 | J29: 2.0619255 | K29: 12.672331 | L29: 4.304355 | M29: 3.1394674 | N29: 23.485886 | O29: 248.70267 | P29: 127.6331
A30: lsf | B30: 27 | C30: EN | D30: lsf 27EN2 | E30: 0.97397857 | F30: 0.29411505 | G30: 44.591186 | H30: 0.19041838 | I30: 0 | J30: 1.4471797 | K30: 11.115024 | L30: 2.9518571 | M30: 2.3181599 | N30: 20.81194 | O30: 212.20345 | P30: 124.43264
A31: lsf | B31: 27 | C31: EN | D31: lsf 27EN3 | E31: 1.0481662 | F31: 0.38413627 | G31: 46.484928 | H31: 0.2365479 | I31: 0.078849302 | J31: 1.69526 | K31: 14.311449 | L31: 4.6325951 | M31: 2.5042363 | N31: 23.51703 | O31: 255.92149 | P31: 127.70396
A32: lsf | B32: 28 | C32: ED | D32: lsf 28ED1 | E32: 1.06432 | F32: 0.30758 | G32: 85.783325 | H32: 0.80385852 | I32: 0.22967386 | J32: 3.330271 | K32: 11.205115 | L32: 12.740939 | M32: 11.279848 | N32: 30.125518 | O32: 298.65384 | P32: 107.36226
A33: lsf | B33: 28 | C33: ED | D33: lsf 28ED2 | E33: 1.0552524 | F33: 0.31863556 | G33: 89.810655 | H33: 0.51891555 | I33: 0.27941606 | J33: 2.3051825 | K33: 13.000707 | L33: 12.053117 | M33: 11.135222 | N33: 29.997136 | O33: 312.3177 | P33: 110.05787
A34: lsf | B34: 28 | C34: ED | D34: lsf 28ED3 | E34: 1.1318074 | F34: 0.32275579 | G34: 94.989054 | H34: 0.84465585 | I34: 0.15714527 | J34: 3.4768392 | K34: 12.171208 | L34: 12.699619 | M34: 12.620957 | N34: 37.444306 | O34: 311.86779 | P34: 127.5295
... A42: prr7 | B42: 21 | C42: EN | D42: prr7 21EN2 | E42: 0.77426349 | F42: 0.28139153 | G42: 1.6799456 | H42: 0.11848255 | I42: 0.039494183 | J42: 0.80963075 | K42: 9.5506265 | L42: 1.7980897 | M42: 1.4546132 | N42: 16.827054 | O42: 140.74531 | P42: 109.42703
A43: prr7 | B43: 21 | C43: EN | D43: prr7 21EN3 | E43: x | F43: x | G43: x | H43: x | I43: x | J43: x | K43: x | L43: x | M43: x | N43: x | O43: x | P43: x
A44: prr7 | B44: 27 | C44: EN | D44: prr7 27EN1 | E44: 0.91521268 | F44: 0.28470951 | G44: 1.4673106 | H44: 0.10923513 | I44: 0.07282342 | J44: 1.3108216 | K44: 10.875147 | L44: 3.8280238 | M44: 3.8532902 | N44: 20.849017 | O44: 129.21747 | P44: 135.00927
A45: prr7 | B45: 27 | C45: EN | D45: prr7 27EN2 | E45: 0.98189091 | F45: 0.37179091 | G45: 1.4023248 | H45: 0.10439721 | I45: 0.052198605 | J45: 1.12227 | K45: 11.289104 | L45: 5.3755642 | M45: 4.6390043 | N45: 16.392141 | O45: 156.58691 | P45: 135.54575
A46: prr7 | B46: 27 | C46: EN | D46: prr7 27EN3 | E46: 0.86447143 | F46: 0.298025 | G46: 1.5609211 | H46: 0.14354616 | I46: 0.020506595 | J46: 0.86127699 | K46: 11.624897 | L46: 2.7849084 | M46: 3.0973844 | N46: 17.165943 | O46: 131.10132 | P46: 124.32727
A47: prr7 | B47: 28 | C47: ED | D47: prr7 28ED1 | E47: 1.1891094 | F47: 0.30604433 | G47: 58.28283 | H47: 0.75379414 | I47: 0.2390079 | J47: 3.6402742 | K47: 11.66378 | L47: 13.999752 | M47: 11.141497 | N47: 38.947753 | O47: 302.4884 | P47: 131.93841
A48: prr7 | B48: 28 | C48: ED | D48: prr7 28ED2 | E48: 1.1104237 | F48: 0.31657446 | G48: 60.015984 | H48: 0.88288609 | I48: 0.24078711 | J48: 2.6887894 | K48: 12.531911 | L48: 13.872325 | M48: 11.235257 | N48: 33.355791 | O48: 291.12745 | P48: 125.19302
A49: prr7 | B49: 28 | C49: ED | D49: prr7 28ED3 | E49: 1.054118 | F49: 0.296296 | G49: 52.389102 | H49: 1.0263551 | I49: 0.33589802 | J49: 3.1630397 | K49: 12.164234 | L49: 13.494194 | M49: 10.675885 | N49: 36.874807 | O49: 263.56223 | P49: 125.44501
...

Sheet Data Results processed
A1: All Samples | E1: Units
E2: mg chl a/g FW | F2: mg chl b/g FW | G2: (µmol/gFW) | H2: (µmol/g FW) | I2: (µmol/g FW) | J2: (µmol/g FW) | K2: (mg/gFW) | L2: (µmol/g FW) | M2: (µmol/g FW) | N2: (µmol/gFW) | O2: (nmol/g FW) | P2: (µmol/g FW) | R2: (µmol/g FW) | S2: (µmol/g FW)
A3: Genotype | B3: DAS | C3: Time harvest | D3: sample ID | E3: chlorophyll a | F3: chlorophyll b | G3: starch | H3: glucose | I3: fructose | J3: sucrose | K3: Total proteins | L3: malate | M3: fumarate | N3: Amino Acids | O3: G6P | P3: NO3 | R3: m+f | S3: glu + fruc
A4: Col | B4: 21 | C4: ED | D4: Col 21ED1 | E4: 0.95692023 | F4: 0.31902225 | G4: 47.042053 | H4: 0.30202777 | I4: 0.086293648 | J4: 1.5209255 | K4: 9.7351427 | L4: 8.3932146 | M4: 5.3432983 | N4: 27.57013 | O4: 292.94902 | P4: 92.342104 | R4: =L4+M4 -> 13.736513 | S4: =H4+I4 -> 0.38832142
A5: Col | B5: 21 | C5: ED | D5: Col 21ED2 | E5: 0.83310148 | F5: 0.27567685 | G5: 43.712122 | H5: 0.20223745 | I5: 0.055155669 | J5: 1.5535513 | K5: 10.200749 | L5: 6.722867 | M5: 5.3639678 | N5: 25.190622 | O5: 242.00303 | P5: 83.652613 | R5: =L5+M5 -> 12.086835 | S5: =H5+I5 -> 0.25739312
A6: Col | B6: 21 | C6: ED | D6: Col 21ED3 | E6: 0.78791183 | F6: 0.28824704 | G6: 36.566625 | H6: 0.18059034 | I6: 0.12039356 | J6: 1.5249851 | K6: 9.43225 | L6: 6.4385612 | M6: 4.922449 | N6: 21.455508 | O6: 279.61972 | P6: 78.110848 | R6: =L6+M6 -> 11.36101 | S6: =H6+I6 -> 0.30098389
A7: Col | B7: 21 | C7: EN | D7: Col 21EN1 | E7: 0.97304301 | F7: 0.52601075 | G7: 5.0312801 | H7: 0 | I7: 0.040131186 | J7: 1.0032796 | K7: 13.122195 | L7: 2.3723838 | M7: 4.7907983 | N7: 17.846661 | O7: 187.84616 | P7: 109.98079 | R7: =L7+M7 -> 7.1631821 | S7: =H7+I7 -> 0.040131186
A8: Col | B8: 21 | C8: EN | D8: Col 21EN2 | E8: 0.68562667 | F8: 0.26915333 | G8: 3.7706956 | H8: 0.038278977 | I8: 0.076557954 | J8: 0.76557954 | K8: 8.5034768 | L8: 1.0104545 | M8: 1.1271366 | N8: 13.030058 | O8: 141.59038 | P8: 86.790648 | R8: =L8+M8 -> 2.1375912 | S8: =H8+I8 -> 0.11483693
A9: Col | B9: 21 | C9: EN | D9: Col 21EN3 | E9: 0.77478289 | F9: 0.32735625 | G9: 4.7274645 | H9: 0.024553949 | I9: 0.073661848 | J9: 0.8225573 | K9: 10.86536 | L9: 1.2425249 | M9: 0.79627535 | N9: 14.543899 | O9: 129.78196 | P9: 93.934971 | R9: =L9+M9 -> 2.0388003 | S9: =H9+I9 -> 0.098215797
A10: Col | B10: 27 | C10: EN | D10: Col 27EN1 | E10: 0.95709036 | F10: 0.29645279 | G10: 2.0358624 | H10: 0.13261625 | I10: 0 | J10: 0.86200565 | K10: 11.447799 | L10: 2.0890843 | M10: 2.1744263 | N10: 22.611543 | O10: 158.97936 | P10: 149.41039 | R10: =L10+M10 -> 4.2635107 | S10: =H10+I10 -> 0.13261625
A11: Col | B11: 27 | C11: EN | D11: Col 27EN2 | E11: 1.0279313 | F11: 0.29822065 | G11: 2.7436031 | H11: 0.27852241 | I11: 0 | J11: 1.9775091 | K11: 10.434454 | L11: 3.1530831 | M11: 2.0412132 | N11: 25.207475 | O11: 170.48192 | P11: 148.42768 | R11: =L11+M11 -> 5.1942963 | S11: =H11+I11 -> 0.27852241
A12: Col | B12: 27 | C12: EN | D12: Col 27EN3 | E12: 0.97751875 | F12: 0.29519479 | G12: 2.4370263 | H12: 0.15550834 | I12: 0.058315629 | J12: 1.2343475 | K12: 11.512644 | L12: 2.7233986 | M12: 2.3711209 | N12: 20.345056 | O12: 179.32457 | P12: 139.23466 | R12: =L12+M12 -> 5.0945195 | S12: =H12+I12 -> 0.21382397
A13: Col | B13: 28 | C13: ED | D13: Col 28ED1 | E13: 1.185451 | F13: 0.31751146 | G13: 45.084986 | H13: 0.31101669 | I13: 0.097192716 | J13: 3.0324127 | K13: 12.940936 | L13: 11.159323 | M13: 7.8734672 | N13: 33.204984 | O13: 255.98762 | P13: 134.02926 | R13: =L13+M13 -> 19.03279 | S13: =H13+I13 -> 0.40820941 | U13: negative values corrected to 0
A14: Col | B14: 28 | C14: ED | D14: Col 28ED2 | E14: 1.0695259 | F14: 0.29580707 | G14: 40.351041 | H14: 0.3641171 | I14: 0.1638527 | J14: 2.4304816 | K14: 11.39446 | L14: 10.725498 | M14: 7.2881733 | N14: 27.989915 | O14: 257.55848 | P14: 133.1035 | R14: =L14+M14 -> 18.013671 | S14: =H14+I14 -> 0.5279698
A15: Col | B15: 28 | C15: ED | D15: Col 28ED3 | E15: 1.0688398 | F15: 0.29454466 | G15: 42.66993 | H15: 0.18117477 | I15: 0.10870486 | J15: 2.771974 | K15: 11.441442 | L15: 9.3618674 | M15: 7.2121765 | N15: 27.111348 | O15: 234.80333 | P15: 134.15481 | R15: =L15+M15 -> 16.574044 | S15: =H15+I15 -> 0.28987963
A16: Col | B16: 28 | C16: EN | D16: Col 28EN1 | E16: 0.95714845 | F16: 0.29502294 | G16: 4.3931078 | H16: 0 | I16: 0 | J16: 1.5582898 | K16: 9.8610904 | L16: 3.1452404 | M16: 3.0467274 | N16: 21.013003 | O16: 204.67571 | P16: 149.43374 | R16: =L16+M16 -> 6.1919678 | S16: =H16+I16 -> 0
A17: Col | B17: 28 | C17: EN | D17: Col 28EN2 | E17: 0.87102549 | F17: 0.2780152 | G17: 4.915011 | H17: 0.018295099 | I17: 0.1280657 | J17: 1.097706 | K17: 11.201933 | L17: 2.6418222 | M17: 2.2726587 | N17: 16.406395 | O17: 173.50128 | P17: 141.60981 | R17: =L17+M17 -> 4.9144809 | S17: =H17+I17 -> 0.1463608
A18: Col | B18: 28 | C18: EN | D18: Col 28EN3 | E18: 0.87237717 | F18: 0.27290205 | G18: 4.3494481 | H18: 0.22154614 | I18: 0 | J18: 1.0906887 | K18: 9.0265642 | L18: 2.495368 | M18: 2.5379211 | N18: 15.719902 | O18: 157.2836 | P18: 136.92698 | R18: =L18+M18 -> 5.0332891 | S18: =H18+I18 -> 0.22154614
A19: x | B19: x | C19: x | D19: GH6-35 | E19: 1.1159005 | F19: 0.30390399 | G19: 48.642456 | H19: 2.7684866 | I19: 0.56070614 | J19: 2.873619 | K19: 10.147757 | L19: 4.8042941 | M19: 7.1925986 | N19: 36.415888 | O19: 231.10345 | P19: 95.242894
A20: x | B20: x | C20: x | D20: GH6-36 | E20: 1.1349833 | F20: 0.31436946 | G20: 45.029248 | H20: 2.9232505 | I20: 0.58832714 | J20: 2.9048652 | K20: 10.148436 | L20: 4.7667153 | M20: 6.7410074 | N20: 34.471014 | O20: 266.41377 | P20: 94.244741
A21: x | B21: x | C21: x | D21: GH6-37 | E21: 1.1909981 | F21: 0.30951762 | G21: 52.281674 | H21: 3.4833869 | I21: 0.72866767 | J21: 3.5278179 | K21: 13.815286 | L21: 5.3237971 | M21: 8.0238841 | N21: 37.695042 | O21: 187.49433 | P21: 95.398388
A22: x | B22: x | C22: x | D22: GH6-38 | E22: 1.0470784 | F22: 0.28516101 | G22: 44.832695 | H22: 2.8443641 | I22: 0.59189079 | J22: 3.3129443 | K22: 11.838499 | L22: 4.961795 | M22: 6.6265833 | N22: 42.14537 | O22: 258.01181 | P22: 85.594957
A23: lsf | B23: 21 | C23: ED | D23: lsf 21ED1 | E23: 0.62508188 | F23: 0.33325369 | G23: 49.684494 | H23: 0.25048324 | I23: 0.025048324 | J23: 0.97688464 | K23: 8.405622 | L23: 5.3216089 | M23: 4.3278628 | N23: 17.522266 | O23: 212.56592 | P23: 48.849899 | R23: =L23+M23 -> 9.6494717 | S23: =H23+I23 -> 0.27553156
A24: lsf | B24: 21 | C24: ED | D24: lsf 21ED2 | E24: 0.79668889 | F24: 0.43345556 | G24: 57.988728 | H24: 0.15949574 | I24: 0.15949574 | J24: 1.3238146 | K24: 10.920319 | L24: 6.0956364 | M24: 5.8167511 | N24: 21.581546 | O24: 307.90305 | P24: 64.344269 | R24: =L24+M24 -> 11.912388 | S24: =H24+I24 -> 0.31899148
A25: lsf | B25: 21 | C25: ED | D25: lsf 21ED3 | E25: 0.52728265 | F25: 0.25534719 | G25: 36.917751 | H25: 0.13329287 | I25: 0.095209191 | J25: 0.80927812 | K25: 7.6196588 | L25: 4.1650894 | M25: 3.3350339 | N25: 15.778923 | O25: 191.48389 | P25: 41.724701 | R25: =L25+M25 -> 7.5001234 | S25: =H25+I25 -> 0.22850206
A26: lsf | B26: 21 | C26: EN | D26: lsf 21EN1 | E26: 0.82484301 | F26: 0.51348602 | G26: 33.062698 | H26: 0.080262372 | I26: 0 | J26: 1.1036076 | K26: 11.4142 | L26: 2.9743402 | M26: 2.5625559 | N26: 18.995098 | O26: 182.46074 | P26: 86.317941 | R26: =L26+M26 -> 5.5368962 | S26: =H26+I26 -> 0.080262372
A27: lsf | B27: 21 | C27: EN | D27: lsf 21EN2 | E27: 0.8527037 | F27: 0.58070679 | G27: 35.897784 | H27: 0 | I27: 0 | J27: 1.0367223 | K27: 9.8274996 | L27: 2.2383942 | M27: 1.1567 | N27: 12.577898 | O27: 221.9014 | P27: 71.947911 | R27: =L27+M27 -> 3.3950942 | S27: =H27+I27 -> 0
A28: lsf | B28: 21 | C28: EN | D28: lsf 21EN3 | E28: 0.51379448 | F28: 0.27780856 | G28: 25.020393 | H28: 0.061859673 | I28: 0.061859673 | J28: 0.65983651 | K28: 7.410237 | L28: 1.4856604 | M28: 1.1119646 | N28: 10.885741 | O28: 108.41149 | P28: 53.755704 | R28: =L28+M28 -> 2.597625 | S28: =H28+I28 -> 0.12371935
A29: lsf | B29: 27 | C29: EN | D29: lsf 27EN1 | E29: 0.98531975 | F29: 0.34057994 | G29: 44.769075 | H29: 0.23038273 | I29: 0 | J29: 2.0619255 | K29: 12.672331 | L29: 4.304355 | M29: 3.1394674 | N29: 23.485886 | O29: 248.70267 | P29: 127.6331 | R29: =L29+M29 -> 7.4438224 | S29: =H29+I29 -> 0.23038273
A30: lsf | B30: 27 | C30: EN | D30: lsf 27EN2 | E30: 0.97397857 | F30: 0.29411505 | G30: 44.591186 | H30: 0.19041838 | I30: 0 | J30: 1.4471797 | K30: 11.115024 | L30: 2.9518571 | M30: 2.3181599 | N30: 20.81194 | O30: 212.20345 | P30: 124.43264 | R30: =L30+M30 -> 5.270017 | S30: =H30+I30 -> 0.19041838
A31: lsf | B31: 27 | C31: EN | D31: lsf 27EN3 | E31: 1.0481662 | F31: 0.38413627 | G31: 46.484928 | H31: 0.2365479 | I31: 0.078849302 | J31: 1.69526 | K31: 14.311449 | L31: 4.6325951 | M31: 2.5042363 | N31: 23.51703 | O31: 255.92149 | P31: 127.70396 | R31: =L31+M31 -> 7.1368313 | S31: =H31+I31 -> 0.31539721
A32: lsf | B32: 28 | C32: ED | D32: lsf 28ED1 | E32: 1.06432 | F32: 0.30758 | G32: 85.783325 | H32: 0.80385852 | I32: 0.22967386 | J32: 3.330271 | K32: 11.205115 | L32: 12.740939 | M32: 11.279848 | N32: 30.125518 | O32: 298.65384 | P32: 107.36226 | R32: =L32+M32 -> 24.020787 | S32: =H32+I32 -> 1.0335324
A33: lsf | B33: 28 | C33: ED | D33: lsf 28ED2 | E33: 1.0552524 | F33: 0.31863556 | G33: 89.810655 | H33: 0.51891555 | I33: 0.27941606 | J33: 2.3051825 | K33: 13.000707 | L33: 12.053117 | M33: 11.135222 | N33: 29.997136 | O33: 312.3177 | P33: 110.05787 | R33: =L33+M33 -> 23.188339 | S33: =H33+I33 -> 0.79833161
A34: lsf | B34: 28 | C34: ED | D34: lsf 28ED3 | E34: 1.1318074 | F34: 0.32275579 | G34: 94.989054 | H34: 0.84465585 | I34: 0.15714527 | J34: 3.4768392 | K34: 12.171208 | L34: 12.699619 | M34: 12.620957 | N34: 37.444306 | O34: 311.86779 | P34: 127.5295 | R34: =L34+M34 -> 25.320576 | S34: =H34+I34 -> 1.0018011
... A42: prr7 | B42: 21 | C42: EN | D42: prr7 21EN2 | E42: 0.77426349 | F42: 0.28139153 | G42: 1.6799456 | H42: 0.11848255 | I42: 0.039494183 | J42: 0.80963075 | K42: 9.5506265 | L42: 1.7980897 | M42: 1.4546132 | N42: 16.827054 | O42: 140.74531 | P42: 109.42703 | R42: =L42+M42 -> 3.2527029 | S42: =H42+I42 -> 0.15797673
A43: prr7 | B43: 21 | C43: EN | D43: prr7 21EN3 | E43: x | F43: x | G43: x | H43: x | I43: x | J43: x | K43: x | L43: x | M43: x | N43: x | O43: x | P43: x | R43: x | S43: x
A44: prr7 | B44: 27 | C44: EN | D44: prr7 27EN1 | E44: 0.91521268 | F44: 0.28470951 | G44: 1.4673106 | H44: 0.10923513 | I44: 0.07282342 | J44: 1.3108216 | K44: 10.875147 | L44: 3.8280238 | M44: 3.8532902 | N44: 20.849017 | O44: 129.21747 | P44: 135.00927 | R44: =L44+M44 -> 7.681314 | S44: =H44+I44 -> 0.18205855
A45: prr7 | B45: 27 | C45: EN | D45: prr7 27EN2 | E45: 0.98189091 | F45: 0.37179091 | G45: 1.4023248 | H45: 0.10439721 | I45: 0.052198605 | J45: 1.12227 | K45: 11.289104 | L45: 5.3755642 | M45: 4.6390043 | N45: 16.392141 | O45: 156.58691 | P45: 135.54575 | R45: =L45+M45 -> 10.014568 | S45: =H45+I45 -> 0.15659582
A46: prr7 | B46: 27 | C46: EN | D46: prr7 27EN3 | E46: 0.86447143 | F46: 0.298025 | G46: 1.5609211 | H46: 0.14354616 | I46: 0.020506595 | J46: 0.86127699 | K46: 11.624897 | L46: 2.7849084 | M46: 3.0973844 | N46: 17.165943 | O46: 131.10132 | P46: 124.32727 | R46: =L46+M46 -> 5.8822928 | S46: =H46+I46 -> 0.16405276
A47: prr7 | B47: 28 | C47: ED | D47: prr7 28ED1 | E47: 1.1891094 | F47: 0.30604433 | G47: 58.28283 | H47: 0.75379414 | I47: 0.2390079 | J47: 3.6402742 | K47: 11.66378 | L47: 13.999752 | M47: 11.141497 | N47: 38.947753 | O47: 302.4884 | P47: 131.93841 | R47: =L47+M47 -> 25.141249 | S47: =H47+I47 -> 0.99280204
...

Sheet Analysis
A1: Mean | E1: Units
E2: mg chl a/g FW | F2: mg chl b/g FW | G2: (µmol/gFW) | H2: (µmol/g FW) | I2: (µmol/g FW) | J2: (µmol/g FW) | K2: (mg/gFW) | L2: (µmol/g FW) | M2: (µmol/g FW) | N2: (µmol/gFW) | O2: (nmol/g FW) | P2: (µmol/g FW) | R2: (µmol/g FW) | S2: (µmol/g FW)
A3: Genotype | B3: DAS | C3: Time harvest | D3: sample ID | E3: chlorophyll a | F3: chlorophyll b | G3: starch | H3: glucose | I3: fructose | J3: sucrose | K3: Total proteins | L3: malate | M3: fumarate | N3: Amino Acids | O3: G6P | P3: NO3 | R3: m+f | S3: glu+fruc
A4: Col | B4: 21 | C4: ED | D4: 21_ED | E4: =AVERAGE('Data Results processed'!E4:E6) -> 0.85931118 | F4: =AVERAGE('Data Results processed'!F4:F6) -> 0.29431538 | G4: =AVERAGE('Data Results processed'!G4:G6) -> 42.440267 | H4: =AVERAGE('Data Results processed'!H4:H6) -> 0.22828519 | I4: =AVERAGE('Data Results processed'!I4:I6) -> 0.087280958 | J4: =AVERAGE('Data Results processed'!J4:J6) -> 1.533154 | K4: =AVERAGE('Data Results processed'!K4:K6) -> 9.7893806 | L4: =AVERAGE('Data Results processed'!L4:L6) -> 7.1848809 | ... P4: =AVERAGE('Data Results processed'!P4:P6) -> 84.701855 | R4: =AVERAGE('Data Results processed'!R4:R6) -> 12.394786 | S4: =AVERAGE('Data Results processed'!S4:S6) -> 0.31556614
A5: Col | B5: 21 | C5: EN | D5: 21_EN | E5: =AVERAGE('Data Results processed'!E7:E9) -> 0.81115086 | F5: =AVERAGE('Data Results processed'!F7:F9) -> 0.37417345 | G5: =AVERAGE('Data Results processed'!G7:G9) -> 4.5098134 | H5: =AVERAGE('Data Results processed'!H7:H9) -> 0.020944309 | I5: =AVERAGE('Data Results processed'!I7:I9) -> 0.063450329 | J5: =AVERAGE('Data Results processed'!J7:J9) -> 0.8638055 | K5: =AVERAGE('Data Results processed'!K7:K9) -> 10.830344 | L5: =AVERAGE('Data Results processed'!L7:L9) -> 1.5417877 | ... P5: =AVERAGE('Data Results processed'!P7:P9) -> 96.902138 | R5: =AVERAGE('Data Results processed'!R7:R9) -> 3.7798578 | S5: =AVERAGE('Data Results processed'!S7:S9) -> 0.084394638
A6: Col | B6: 27 | C6: EN | D6: 27_EN | E6: =AVERAGE('Data Results processed'!E10:E12) -> 0.98751348 | F6: =AVERAGE('Data Results processed'!F10:F12) -> 0.29662274 | G6: =AVERAGE('Data Results processed'!G10:G12) -> 2.4054973 | H6: =AVERAGE('Data Results processed'!H10:H12) -> 0.18888234 | I6: =AVERAGE('Data Results processed'!I10:I12) -> 0.019438543 | J6: =AVERAGE('Data Results processed'!J10:J12) -> 1.3579541 | K6: =AVERAGE('Data Results processed'!K10:K12) -> 11.131632 | L6: =AVERAGE('Data Results processed'!L10:L12) -> 2.6551887 | ... P6: =AVERAGE('Data Results processed'!P10:P12) -> 145.69091 | R6: =AVERAGE('Data Results processed'!R10:R12) -> 4.8507755 | S6: =AVERAGE('Data Results processed'!S10:S12) -> 0.20832088
A7: Col | B7: 28 | C7: ED | D7: 28_ED | E7: =AVERAGE('Data Results processed'!E13:E15) -> 1.1079389 | F7: =AVERAGE('Data Results processed'!F13:F15) -> 0.30262106 | G7: =AVERAGE('Data Results processed'!G13:G15) -> 42.701986 | H7: =AVERAGE('Data Results processed'!H13:H15) -> 0.28543619 | I7: =AVERAGE('Data Results processed'!I13:I15) -> 0.12325009 | J7: =AVERAGE('Data Results processed'!J13:J15) -> 2.7449561 | K7: =AVERAGE('Data Results processed'!K13:K15) -> 11.925613 | L7: =AVERAGE('Data Results processed'!L13:L15) -> 10.415563 | ... P7: =AVERAGE('Data Results processed'!P13:P15) -> 133.76252 | R7: =AVERAGE('Data Results processed'!R13:R15) -> 17.873502 | S7: =AVERAGE('Data Results processed'!S13:S15) -> 0.40868628
A8: Col | B8: 28 | C8: EN | D8: 28_EN | E8: =AVERAGE('Data Results processed'!E16:E18) -> 0.9001837 | F8: =AVERAGE('Data Results processed'!F16:F18) -> 0.28198006 | G8: =AVERAGE('Data Results processed'!G16:G18) -> 4.5525223 | H8: =AVERAGE('Data Results processed'!H16:H18) -> 0.079947078 | I8: =AVERAGE('Data Results processed'!I16:I18) -> 0.042688565 | J8: =AVERAGE('Data Results processed'!J16:J18) -> 1.2488948 | K8: =AVERAGE('Data Results processed'!K16:K18) -> 10.029863 | L8: =AVERAGE('Data Results processed'!L16:L18) -> 2.7608102 | ... P8: =AVERAGE('Data Results processed'!P16:P18) -> 142.65685 | R8: =AVERAGE('Data Results processed'!R16:R18) -> 5.3799126 | S8: =AVERAGE('Data Results processed'!S16:S18) -> 0.12263564
A10: lsf | B10: 21 | C10: ED | E10: =AVERAGE('Data Results processed'!E23:E25) -> 0.64968447 | F10: =AVERAGE('Data Results processed'!F23:F25) -> 0.34068548 | G10: =AVERAGE('Data Results processed'!G23:G25) -> 48.196991 | H10: =AVERAGE('Data Results processed'!H23:H25) -> 0.18109062 | I10: =AVERAGE('Data Results processed'!I23:I25) -> 0.093251084 | J10: =AVERAGE('Data Results processed'!J23:J25) -> 1.0366591 | K10: =AVERAGE('Data Results processed'!K23:K25) -> 8.9818668 | L10: =AVERAGE('Data Results processed'!L23:L25) -> 5.1941116 | ... P10: =AVERAGE('Data Results processed'!P23:P25) -> 51.639623 | R10: =AVERAGE('Data Results processed'!R23:R25) -> 9.6873275 | S10: =AVERAGE('Data Results processed'!S23:S25) -> 0.2743417
A11: lsf | B11: 21 | C11: EN | E11: =AVERAGE('Data Results processed'!E26:E28) -> 0.73044706 | F11: =AVERAGE('Data Results processed'!F26:F28) -> 0.45733379 | G11: =AVERAGE('Data Results processed'!G26:G28) -> 31.326958 | H11: =AVERAGE('Data Results processed'!H26:H28) -> 0.047374015 | I11: =AVERAGE('Data Results processed'!I26:I28) -> 0.020619891 | J11: =AVERAGE('Data Results processed'!J26:J28) -> 0.93338881 | K11: =AVERAGE('Data Results processed'!K26:K28) -> 9.5506456 | L11: =AVERAGE('Data Results processed'!L26:L28) -> 2.2327983 | ... P11: =AVERAGE('Data Results processed'!P26:P28) -> 70.673852 | R11: =AVERAGE('Data Results processed'!R26:R28) -> 3.8432051 | S11: =AVERAGE('Data Results processed'!S26:S28) -> 0.067993906
A12: lsf | B12: 27 | C12: EN | E12: =AVERAGE('Data Results processed'!E29:E31) -> 1.0024882 | F12: =AVERAGE('Data Results processed'!F29:F31) -> 0.33961042 | G12: =AVERAGE('Data Results processed'!G29:G31) -> 45.28173 | H12: =AVERAGE('Data Results processed'!H29:H31) -> 0.21911634 | I12: =AVERAGE('Data Results processed'!I29:I31) -> 0.026283101 | J12: =AVERAGE('Data Results processed'!J29:J31) -> 1.7347884 | K12: =AVERAGE('Data Results processed'!K29:K31) -> 12.699601 | L12: =AVERAGE('Data Results processed'!L29:L31) -> 3.9629357 | ... P12: =AVERAGE('Data Results processed'!P29:P31) -> 126.5899 | R12: =AVERAGE('Data Results processed'!R29:R31) -> 6.6168902 | S12: =AVERAGE('Data Results processed'!S29:S31) -> 0.24539944
A13: lsf | B13: 28 | C13: ED | E13: =AVERAGE('Data Results processed'!E32:E34) -> 1.0837933 | F13: =AVERAGE('Data Results processed'!F32:F34) -> 0.31632378 | G13: =AVERAGE('Data Results processed'!G32:G34) -> 90.194345 | H13: =AVERAGE('Data Results processed'!H32:H34) -> 0.72247664 | I13: =AVERAGE('Data Results processed'!I32:I34) -> 0.2220784 | J13: =AVERAGE('Data Results processed'!J32:J34) -> 3.0374309 | K13: =AVERAGE('Data Results processed'!K32:K34) -> 12.125677 | L13: =AVERAGE('Data Results processed'!L32:L34) -> 12.497892 | ... P13: =AVERAGE('Data Results processed'!P32:P34) -> 114.98321 | R13: =AVERAGE('Data Results processed'!R32:R34) -> 24.176567 | S13: =AVERAGE('Data Results processed'!S32:S34) -> 0.94455504
A14: lsf | B14: 28 | C14: EN | E14: =AVERAGE('Data Results processed'!E35:E37) -> 0.94592341 | F14: =AVERAGE('Data Results processed'!F35:F37) -> 0.30060939 | G14: =AVERAGE('Data Results processed'!G35:G37) -> 44.250532 | H14: =AVERAGE('Data Results processed'!H35:H37) -> 0.10404019 | I14: =AVERAGE('Data Results processed'!I35:I37) -> 0.097436453 | J14: =AVERAGE('Data Results processed'!J35:J37) -> 1.390703 | K14: =AVERAGE('Data Results processed'!K35:K37) -> 11.402155 | L14: =AVERAGE('Data Results processed'!L35:L37) -> 4.5141086 | ... P14: =AVERAGE('Data Results processed'!P35:P37) -> 121.67188 | R14: =AVERAGE('Data Results processed'!R35:R37) -> 7.8549477 | S14: =AVERAGE('Data Results processed'!S35:S37) -> 0.20147664
A16: prr7 | B16: 21 | C16: ED | E16: =AVERAGE('Data Results processed'!E38:E40) -> 1.0380724 | F16: =AVERAGE('Data Results processed'!F38:F40) -> 0.50503212 | G16: =AVERAGE('Data Results processed'!G38:G40) -> 47.304594 | H16: =AVERAGE('Data Results processed'!H38:H40) -> 0.11362356 | I16: =AVERAGE('Data Results processed'!I38:I40) -> 0.15604416 | J16: =AVERAGE('Data Results processed'!J38:J40) -> 1.8741888 | K16: =AVERAGE('Data Results processed'!K38:K40) -> 9.9669442 | L16: =AVERAGE('Data Results processed'!L38:L40) -> 8.8186966 | ... P16: =AVERAGE('Data Results processed'!P38:P40) -> 89.885724 | R16: =AVERAGE('Data Results processed'!R38:R40) -> 14.804795 | S16: =AVERAGE('Data Results processed'!S38:S40) -> 0.26966772
A17: prr7 | B17: 21 | C17: EN | E17: =AVERAGE('Data Results processed'!E41:E42) -> 0.76352742 | F17: =AVERAGE('Data Results processed'!F41:F42) -> 0.28312658 | G17: =AVERAGE('Data Results processed'!G41:G42) -> 1.7432721 | H17: =AVERAGE('Data Results processed'!H41:H42) -> 0.069328302 | I17: =AVERAGE('Data Results processed'!I41:I42) -> 0.050008175 | J17: =AVERAGE('Data Results processed'!J41:J42) -> 0.69733918 | K17: =AVERAGE('Data Results processed'!K41:K42) -> 9.8067177 | L17: =AVERAGE('Data Results processed'!L41:L42) -> 1.6679043 | ... P17: =AVERAGE('Data Results processed'!P41:P42) -> 105.88006 | R17: =AVERAGE('Data Results processed'!R41:R42) -> 2.990453 | S17: =AVERAGE('Data Results processed'!S41:S42) -> 0.11933648
A18: prr7 | B18: 27 | C18: EN | E18: =AVERAGE('Data Results processed'!E44:E46) -> 0.92052501 | F18: =AVERAGE('Data Results processed'!F44:F46) -> 0.31817514 | G18: =AVERAGE('Data Results processed'!G44:G46) -> 1.4768522 | H18: =AVERAGE('Data Results processed'!H44:H46) -> 0.1190595 | I18: =AVERAGE('Data Results processed'!I44:I46) -> 0.04850954 | J18: =AVERAGE('Data Results processed'!J44:J46) -> 1.0981229 | K18: =AVERAGE('Data Results processed'!K44:K46) -> 11.263049 | L18: =AVERAGE('Data Results processed'!L44:L46) -> 3.9961654 | ... P18: =AVERAGE('Data Results processed'!P44:P46) -> 131.62743 | R18: =AVERAGE('Data Results processed'!R44:R46) -> 7.8593917 | S18: =AVERAGE('Data Results processed'!S44:S46) -> 0.16756904
A19: prr7 | B19: 28 | C19: ED | E19: =AVERAGE('Data Results processed'!E47:E49) -> 1.1178837 | F19: =AVERAGE('Data Results processed'!F47:F49) -> 0.30630493 | G19: =AVERAGE('Data Results processed'!G47:G49) -> 56.895972 | H19: =AVERAGE('Data Results processed'!H47:H49) -> 0.88767844 | I19: =AVERAGE('Data Results processed'!I47:I49) -> 0.27189768 | J19: =AVERAGE('Data Results processed'!J47:J49) -> 3.1640344 | K19: =AVERAGE('Data Results processed'!K47:K49) -> 12.119975 | L19: =AVERAGE('Data Results processed'!L47:L49) -> 13.788757 | ... P19: =AVERAGE('Data Results processed'!P47:P49) -> 127.52548 | R19: =AVERAGE('Data Results processed'!R47:R49) -> 24.806303 | S19: =AVERAGE('Data Results processed'!S47:S49) -> 1.1595761
A20: prr7 | B20: 28 | C20: EN | E20: =AVERAGE('Data Results processed'!E50:E52) -> 0.92592662 | F20: =AVERAGE('Data Results processed'!F50:F52) -> 0.2882368 | G20: =AVERAGE('Data Results processed'!G50:G52) -> 4.4479658 | H20: =AVERAGE('Data Results processed'!H50:H52) -> 0.31502443 | I20: =AVERAGE('Data Results processed'!I50:I52) -> 0.02475816 | J20: =AVERAGE('Data Results processed'!J50:J52) -> 1.4325626 | K20: =AVERAGE('Data Results processed'!K50:K52) -> 10.492508 | L20: =AVERAGE('Data Results processed'!L50:L52) -> 5.6959497 | ... P20: =AVERAGE('Data Results processed'!P50:P52) -> 148.26858 | R20: =AVERAGE('Data Results processed'!R50:R52) -> 10.899827 | S20: =AVERAGE('Data Results processed'!S50:S52) -> 0.33978259
A22: prr7/prr9 | B22: 21 | C22: ED | E22: =AVERAGE('Data Results processed'!E53:E55) -> 0.82936488 | F22: =AVERAGE('Data Results processed'!F53:F55) -> 0.43747487 | G22: =AVERAGE('Data Results processed'!G53:G55) -> 36.806335 | H22: =AVERAGE('Data Results processed'!H53:H55) -> 0.10879 | I22: =AVERAGE('Data Results processed'!I53:I55) -> 0.091951018 | J22: =AVERAGE('Data Results processed'!J53:J55) -> 1.1095832 | K22: =AVERAGE('Data Results processed'!K53:K55) -> 11.365806 | L22: =AVERAGE('Data Results processed'!L53:L55) -> 10.308315 | ... P22: =AVERAGE('Data Results processed'!P53:P55) -> 47.840087 | R22: =AVERAGE('Data Results processed'!R53:R55) -> 19.157514 | S22: =AVERAGE('Data Results processed'!S53:S55) -> 0.20074101
A23: prr7/prr9 | B23: 21 | C23: EN | E23: =AVERAGE('Data Results processed'!E56:E58) -> 0.53268419 | F23: =AVERAGE('Data Results processed'!F56:F58) -> 0.32662786 | G23: =AVERAGE('Data Results processed'!G56:G58) -> 5.9740052 | H23: =AVERAGE('Data Results processed'!H56:H58) -> 0.05685719 | I23: =AVERAGE('Data Results processed'!I56:I58) -> 0.032263361 | J23: =AVERAGE('Data Results processed'!J56:J58) -> 0.6357573 | K23: =AVERAGE('Data Results processed'!K56:K58) -> 6.9300756 | L23: =AVERAGE('Data Results processed'!L56:L58) -> 2.6986752 | ... P23: =AVERAGE('Data Results processed'!P56:P58) -> 41.392426 | R23: =AVERAGE('Data Results processed'!R56:R58) -> 5.170286 | S23: =AVERAGE('Data Results processed'!S56:S58) -> 0.089120552
A24: prr7/prr9 | B24: 27 | C24: EN | E24: =AVERAGE('Data Results processed'!E59:E61) -> 1.1352014 | F24: =AVERAGE('Data Results processed'!F59:F61) -> 0.40748091 | G24: =AVERAGE('Data Results processed'!G59:G61) -> 9.9255566 | H24: =AVERAGE('Data Results processed'!H59:H61) -> 0.13822359 | I24: =AVERAGE('Data Results processed'!I59:I61) -> 0.062238501 | J24: =AVERAGE('Data Results processed'!J59:J61) -> 1.9311798 | K24: =AVERAGE('Data Results processed'!K59:K61) -> 14.677011 | L24: =AVERAGE('Data Results processed'!L59:L61) -> 9.5100726 | ... P24: =AVERAGE('Data Results processed'!P59:P61) -> 125.87778 | R24: =AVERAGE('Data Results processed'!R59:R61) -> 18.651524 | S24: =AVERAGE('Data Results processed'!S59:S61) -> 0.20046209
A25: prr7/prr9 | B25: 28 | C25: ED | E25: =AVERAGE('Data Results processed'!E62:E64) -> 1.2101498 | F25: =AVERAGE('Data Results processed'!F62:F64) -> 0.33742333 | G25: =AVERAGE('Data Results processed'!G62:G64) -> 67.31396 | H25: =AVERAGE('Data Results processed'!H62:H64) -> 1.1979805 | I25: =AVERAGE('Data Results processed'!I62:I64) -> 0.32120576 | J25: =AVERAGE('Data Results processed'!J62:J64) -> 3.2790858 | K25: =AVERAGE('Data Results processed'!K62:K64) -> 12.553266 | L25: =AVERAGE('Data Results processed'!L62:L64) -> 20.311489 | ... P25: =AVERAGE('Data Results processed'!P62:P64) -> 94.503145 | R25: =AVERAGE('Data Results processed'!R62:R64) -> 41.79504 | S25: =AVERAGE('Data Results processed'!S62:S64) -> 1.5191863
A26: prr7/prr9 | B26: 28 | C26: EN | E26: =AVERAGE('Data Results processed'!E65:E67) -> 1.0935537 | F26: =AVERAGE('Data Results processed'!F65:F67) -> 0.38332722 | G26: =AVERAGE('Data Results processed'!G65:G67) -> 23.769579 | H26: =AVERAGE('Data Results processed'!H65:H67) -> 0.21947514 | I26: =AVERAGE('Data Results processed'!I65:I67) -> 0.094178827 | J26: =AVERAGE('Data Results processed'!J65:J67) -> 2.0885645 | K26: =AVERAGE('Data Results processed'!K65:K67) -> 13.356718 | L26: =AVERAGE('Data Results processed'!L65:L67) -> 11.891442 | ... P26: =AVERAGE('Data Results processed'!P65:P67) -> 108.54654 | R26: =AVERAGE('Data Results processed'!R65:R67) -> 25.313331 | S26: =AVERAGE('Data Results processed'!S65:S67) -> 0.31365397
A30: SD | E30: Units
E31: mg chl a/g FW | F31: mg chl b/g FW | G31: (µmol/gFW) | H31: (µmol/g FW) | I31: (µmol/g FW) | J31: (µmol/g FW) | K31: (mg/gFW) | L31: (µmol/g FW) | M31: (µmol/g FW) | N31: (µmol/gFW) | O31: (nmol/g FW) | P31: (µmol/g FW) | R31: (µmol/g FW)
A32: Genotype | B32: DAS | C32: Time harvest | D32: sample ID | E32: chlorophyll a | F32: chlorophyll b | G32: starch | H32: glucose | I32: fructose | J32: sucrose | K32: Total proteins | L32: malate | M32: fumarate | N32: Amino Acids | O32: G6P | P32: NO3 | R32: m+f | S32: glu+fruc
A33: Col | B33: 21 | C33: ED | E33: =STDEV('Data Results processed'!E4:E6) -> 0.087499551 | F33: =STDEV('Data Results processed'!F4:F6) -> 0.022300776 | G33: =STDEV('Data Results processed'!G4:G6) -> 5.3522764 | H33: =STDEV('Data Results processed'!H4:H6) -> 0.06477365 | I33: =STDEV('Data Results processed'!I4:I6) -> 0.032630149 | J33: =STDEV('Data Results processed'!J4:J6) -> 0.017780866 | K33: =STDEV('Data Results processed'!K4:K6) -> 0.38710985 | L33: =STDEV('Data Results processed'!L4:L6) -> 1.0560587 | ... P33: =STDEV('Data Results processed'!P4:P6) -> 7.1734122 | R33: =STDEV('Data Results processed'!R4:R6) -> 1.2173244 | S33: =STDEV('Data Results processed'!S4:S6) -> 0.066671103
A34: Col | B34: 21 | C34: EN | E34: =STDEV('Data Results processed'!E7:E9) -> 0.14711903 | F34: =STDEV('Data Results processed'!F7:F9) -> 0.13467673 | G34: =STDEV('Data Results processed'!G7:G9) -> 0.65787332 | H34: =STDEV('Data Results processed'!H7:H9) -> 0.019393095 | I34: =STDEV('Data Results processed'!I7:I9) -> 0.020246819 | J34: =STDEV('Data Results processed'!J7:J9) -> 0.12410236 | K34: =STDEV('Data Results processed'!K7:K9) -> 2.3095584 | L34: =STDEV('Data Results processed'!L7:L9) -> 0.72861616 | ... P34: =STDEV('Data Results processed'!P7:P9) -> 11.876396 | R34: =STDEV('Data Results processed'!R7:R9) -> 2.9304611 | S34: =STDEV('Data Results processed'!S7:S9) -> 0.039223787
A35: Col | B35: 27 | C35: EN | E35: =STDEV('Data Results processed'!E10:E12) -> 0.036462754 | F35: =STDEV('Data Results processed'!F10:F12) -> 0.0015200699 | G35: =STDEV('Data Results processed'!G10:G12) -> 0.35492224 | H35: =STDEV('Data Results processed'!H10:H12) -> 0.07846986 | I35: =STDEV('Data Results processed'!I10:I12) -> 0.033668544 | J35: =STDEV('Data Results processed'!J10:J12) -> 0.56793127 | K35: =STDEV('Data Results processed'!K10:K12) -> 0.60464395 | L35: =STDEV('Data Results processed'!L10:L12) -> 0.53526889 | ... P35: =STDEV('Data Results processed'!P10:P12) -> 5.6128253 | R35: =STDEV('Data Results processed'!R10:R12) -> 0.51102723 | S35: =STDEV('Data Results processed'!S10:S12) -> 0.073108581
A36: Col | B36: 28 | C36: ED | E36: =STDEV('Data Results processed'!E13:E15) -> 0.06712836 | F36: =STDEV('Data Results processed'!F13:F15) -> 0.012910899 | G36: =STDEV('Data Results processed'!G13:G15) -> 2.3671352 | H36: =STDEV('Data Results processed'!H13:H15) -> 0.094115597 | I36: =STDEV('Data Results processed'!I13:I15) -> 0.035630899 | J36: =STDEV('Data Results processed'!J13:J15) -> 0.3018737 | K36: =STDEV('Data Results processed'!K13:K15) -> 0.87960943 | L36: =STDEV('Data Results processed'!L13:L15) -> 0.93795321 | ... P36: =STDEV('Data Results processed'!P13:P15) -> 0.57417486 | R36: =STDEV('Data Results processed'!R13:R15) -> 1.2353516 | S36: =STDEV('Data Results processed'!S13:S15) -> 0.1190458
A37: Col | B37: 28 | C37: EN | E37: =STDEV('Data Results processed'!E16:E18) -> 0.049337549 | F37: =STDEV('Data Results processed'!F16:F18) -> 0.01158117 | G37: =STDEV('Data Results processed'!G16:G18) -> 0.31468253 | H37: =STDEV('Data Results processed'!H16:H18) -> 0.12296909 | I37: =STDEV('Data Results processed'!I16:I18) -> 0.073938764 | J37: =STDEV('Data Results processed'!J16:J18) -> 0.2679669 | K37: =STDEV('Data Results processed'!K16:K18) -> 1.0974608 | L37: =STDEV('Data Results processed'!L16:L18) -> 0.34088438 | ... P37: =STDEV('Data Results processed'!P16:P18) -> 6.3187795 | R37: =STDEV('Data Results processed'!R16:R18) -> 0.70576491 | S37: =STDEV('Data Results processed'!S16:S18) -> 0.11266248
A39: lsf | B39: 21 | C39: ED | E39: =STDEV('Data Results processed'!E23:E25) -> 0.13637777 | F39: =STDEV('Data Results processed'!F23:F25) -> 0.089286453 | G39: =STDEV('Data Results processed'!G23:G25) -> 10.613954 | H39: =STDEV('Data Results processed'!H23:H25) -> 0.061507316 | I39: =STDEV('Data Results processed'!I23:I25) -> 0.067245092 | J39: =STDEV('Data Results processed'!J23:J25) -> 0.26242465 | K39: =STDEV('Data Results processed'!K23:K25) -> 1.7241327 | L39: =STDEV('Data Results processed'!L23:L25) -> 0.97156811 | ... P39: =STDEV('Data Results processed'!P23:P25) -> 11.564953 | R39: =STDEV('Data Results processed'!R23:R25) -> 2.2063756 | S39: =STDEV('Data Results processed'!S23:S25) -> 0.045256442
A40: lsf | B40: 21 | C40: EN | E40: =STDEV('Data Results processed'!E26:E28) -> 0.18814306 | F40: =STDEV('Data Results processed'!F26:F28) -> 0.15906489 | G40: =STDEV('Data Results processed'!G26:G28) -> 5.642606 | H40: =STDEV('Data Results processed'!H26:H28) -> 0.042046258 | I40: =STDEV('Data Results processed'!I26:I28) -> 0.035714699 | J40: =STDEV('Data Results processed'!J26:J28) -> 0.23925207 | K40: =STDEV('Data Results processed'!K26:K28) -> 2.0162878 | L40: =STDEV('Data Results processed'!L26:L28) -> 0.74435569 | ... P40: =STDEV('Data Results processed'!P26:P28) -> 16.318463 | R40: =STDEV('Data Results processed'!R26:R28) -> 1.5200103 | S40: =STDEV('Data Results processed'!S26:S28) -> 0.062765481
A41: lsf | B41: 27 | C41: EN | E41: =STDEV('Data Results processed'!E29:E31) -> 0.039962695 | F41: =STDEV('Data Results processed'!F29:F31) -> 0.045018439 | G41: =STDEV('Data Results processed'!G29:G31) -> 1.0457892 | H41: =STDEV('Data Results processed'!H29:H31) -> 0.025043601 | I41: =STDEV('Data Results processed'!I29:I31) -> 0.045523666 | J41: =STDEV('Data Results processed'!J29:J31) -> 0.30927328 | K41: =STDEV('Data Results processed'!K29:K31) -> 1.598387 | L41: =STDEV('Data Results processed'!L29:L31) -> 0.89086779 | ... P41: =STDEV('Data Results processed'!P29:P31) -> 1.8685797 | R41: =STDEV('Data Results processed'!R29:R31) -> 1.1764827 | S41: =STDEV('Data Results processed'!S29:S31) -> 0.063828307
A42: lsf | B42: 28 | C42: ED | E42: =STDEV('Data Results processed'!E32:E34) -> 0.041827878 | F42: =STDEV('Data Results processed'!F32:F34) -> 0.0078475719 | G42: =STDEV('Data Results processed'!G32:G34) -> 4.6148431 | H42: =STDEV('Data Results processed'!H32:H34) -> 0.17746533 | I42: =STDEV('Data Results processed'!I32:I34) -> 0.061488249 | J42: =STDEV('Data Results processed'!J32:J34) -> 0.63836615 | K42: =STDEV('Data Results processed'!K32:K34) -> 0.89866141 | L42: =STDEV('Data Results processed'!L32:L34) -> 0.38573981 | ... P42: =STDEV('Data Results processed'!P32:P34) -> 10.948684 | R42: =STDEV('Data Results processed'!R32:R34) -> 1.0746206 | S42: =STDEV('Data Results processed'!S32:S34) -> 0.12762322
A43: lsf | B43: 28 | C43: EN | E43: =STDEV('Data Results processed'!E35:E37) -> 0.023138719 | F43: =STDEV('Data Results processed'!F35:F37) -> 0.0083103925 | G43: =STDEV('Data Results processed'!G35:G37) -> 2.0789977 | H43: =STDEV('Data Results processed'!H35:H37) -> 0.096430024 | I43: =STDEV('Data Results processed'!I35:I37) -> 0.023232309 | J43: =STDEV('Data Results processed'!J35:J37) -> 0.17422119 | K43: =STDEV('Data Results processed'!K35:K37) -> 0.84646307 | L43: =STDEV('Data Results processed'!L35:L37) -> 0.36535062 | ... P43: =STDEV('Data Results processed'!P35:P37) -> 3.8443172 | R43: =STDEV('Data Results processed'!R35:R37) -> 0.27064876 | S43: =STDEV('Data Results processed'!S35:S37) -> 0.11120958
A45: prr7 | B45: 21 | C45: ED | E45: =STDEV('Data Results processed'!E38:E40) -> 0.060225033 | F45: =STDEV('Data Results processed'!F38:F40) -> 0.34212661 | G45: =STDEV('Data Results processed'!G38:G40) -> 13.819915 | H45: =STDEV('Data Results processed'!H38:H40) -> 0.038702116 | I45: =STDEV('Data Results processed'!I38:I40) -> 0.063073112 | J45: =STDEV('Data Results processed'!J38:J40) -> 0.54832929 | K45: =STDEV('Data Results processed'!K38:K40) -> 1.070114 | L45: =STDEV('Data Results processed'!L38:L40) -> 2.0236889 | ... P45: =STDEV('Data Results processed'!P38:P40) -> 45.3545 | R45: =STDEV('Data Results processed'!R38:R40) -> 4.351482 | S45: =STDEV('Data Results processed'!S38:S40) -> 0.08968022
A46: prr7 | B46: 21 | C46: EN | E46: =STDEV('Data Results processed'!E41:E42) -> 0.015183096 | F46: =STDEV('Data Results processed'!F41:F42) -> 0.0024537222 | G46: =STDEV('Data Results processed'!G41:G42) -> 0.089557251 | H46: =STDEV('Data Results processed'!H41:H42) -> 0.069514602 | I46: =STDEV('Data Results processed'!I41:I42) -> 0.01486903 | J46: =STDEV('Data Results processed'!J41:J42) -> 0.15880426 | K46: =STDEV('Data Results processed'!K41:K42) -> 0.36216754 | L46: =STDEV('Data Results processed'!L41:L42) -> 0.18410998 | ... P46: =STDEV('Data Results processed'!P41:P42) -> 5.0161638 | R46: =STDEV('Data Results processed'!R41:R42) -> 0.37087736 | S46: =STDEV('Data Results processed'!S41:S42) -> 0.054645572
A47: prr7 | B47: 27 | C47: EN | E47: =STDEV('Data Results processed'!E44:E46) -> 0.058889721 | F47: =STDEV('Data Results processed'!F44:F46) -> 0.0469075 | G47: =STDEV('Data Results processed'!G44:G46) -> 0.079727501 | H47: =STDEV('Data Results processed'!H44:H46) -> 0.021343591 | I47: =STDEV('Data Results processed'!I44:I46) -> 0.026352788 | J47: =STDEV('Data Results processed'!J44:J46) -> 0.22574298 | K47: =STDEV('Data Results processed'!K44:K46) -> 0.37555334 | L47: =STDEV('Data Results processed'!L44:L46) -> 1.3034869 | ... P47: =STDEV('Data Results processed'!P44:P46) -> 6.3278111 | R47: =STDEV('Data Results processed'!R44:R46) -> 2.0718854 | S47: =STDEV('Data Results processed'!S44:S46) -> 0.013090489
A48: prr7 | B48: 28 | C48: ED | E48: =STDEV('Data Results processed'!E47:E49) -> 0.067804171 | F48: =STDEV('Data Results processed'!F47:F49) -> 0.010141743 | G48: =STDEV('Data Results processed'!G47:G49) -> 3.9981073 | H48: =STDEV('Data Results processed'!H47:H49) -> 0.13634365 | I48: =STDEV('Data Results processed'!I47:I49) -> 0.055433064 | J48: =STDEV('Data Results processed'!J47:J49) -> 0.47574314 | K48: =STDEV('Data Results processed'!K47:K49) -> 0.43575476 | L48: =STDEV('Data Results processed'!L47:L49) -> 0.26293521 | ... P48: =STDEV('Data Results processed'!P47:P49) -> 3.8237878 | R48: =STDEV('Data Results processed'!R47:R49) -> 0.55124343 | S48: =STDEV('Data Results processed'!S47:S49) -> 0.18732401
...

Sheet Analysis day 28
A1: Mean | E1: Units
E2: mg chl a/g FW | F2: mg chl b/g FW | G2: (µmol/gFW) | H2: (µmol/g FW) | I2: (µmol/g FW) | J2: (µmol/g FW) | K2: (mg/gFW) | L2: (µmol/g FW) | M2: (µmol/g FW) | N2: (µmol/gFW) | O2: (nmol/g FW) | P2: (µmol/g FW) | R2: (µmol/g FW) | S2: (µmol/g FW)
A3: Genotype | B3: DAS | C3: Time harvest | D3: sample ID | E3: chlorophyll a | F3: chlorophyll b | G3: starch | H3: glucose | I3: fructose | J3: sucrose | K3: Total proteins | L3: malate | M3: fumarate | N3: Amino Acids | O3: G6P | P3: NO3 | R3: m+f | S3: glu+fruc
A4: Col | B4: 27 | C4: EN | D4: 27_EN | E4: =AVERAGE('Data Results processed'!E10:E12) -> 0.98751348 | F4: =AVERAGE('Data Results processed'!F10:F12) -> 0.29662274 | G4: =AVERAGE('Data Results processed'!G10:G12) -> 2.4054973 | H4: =AVERAGE('Data Results processed'!H10:H12) -> 0.18888234 | I4: =AVERAGE('Data Results processed'!I10:I12) -> 0.019438543 | J4: =AVERAGE('Data Results processed'!J10:J12) -> 1.3579541 | K4: =AVERAGE('Data Results processed'!K10:K12) -> 11.131632 | L4: =AVERAGE('Data Results processed'!L10:L12) -> 2.6551887 | ... P4: =AVERAGE('Data Results processed'!P10:P12) -> 145.69091 | R4: =AVERAGE('Data Results processed'!R10:R12) -> 4.8507755 | S4: =AVERAGE('Data Results processed'!S10:S12) -> 0.20832088
A5: Col | B5: 28 | C5: ED | D5: 28_ED | E5: =AVERAGE('Data Results processed'!E13:E15) -> 1.1079389 | F5: =AVERAGE('Data Results processed'!F13:F15) -> 0.30262106 | G5: =AVERAGE('Data Results processed'!G13:G15) -> 42.701986 | H5: =AVERAGE('Data Results processed'!H13:H15) -> 0.28543619 | I5: =AVERAGE('Data Results processed'!I13:I15) -> 0.12325009 | J5: =AVERAGE('Data Results processed'!J13:J15) -> 2.7449561 | K5: =AVERAGE('Data Results processed'!K13:K15) -> 11.925613 | L5: =AVERAGE('Data Results processed'!L13:L15) -> 10.415563 | ... P5: =AVERAGE('Data Results processed'!P13:P15) -> 133.76252 | R5: =AVERAGE('Data Results processed'!R13:R15) -> 17.873502 | S5: =AVERAGE('Data Results processed'!S13:S15) -> 0.40868628
A6: Col | B6: 28 | C6: EN | D6: 28_EN | E6: =AVERAGE('Data Results processed'!E16:E18) -> 0.9001837 | F6: =AVERAGE('Data Results processed'!F16:F18) -> 0.28198006 | G6: =AVERAGE('Data Results processed'!G16:G18) -> 4.5525223 | H6: =AVERAGE('Data Results processed'!H16:H18) -> 0.079947078 | I6: =AVERAGE('Data Results processed'!I16:I18) -> 0.042688565 | J6: =AVERAGE('Data Results processed'!J16:J18) -> 1.2488948 | K6: =AVERAGE('Data Results processed'!K16:K18) -> 10.029863 | L6: =AVERAGE('Data Results processed'!L16:L18) -> 2.7608102 | ... P6: =AVERAGE('Data Results processed'!P16:P18) -> 142.65685 | R6: =AVERAGE('Data Results processed'!R16:R18) -> 5.3799126 | S6: =AVERAGE('Data Results processed'!S16:S18) -> 0.12263564
A8: lsf | B8: 27 | C8: EN | E8: =AVERAGE('Data Results processed'!E29:E31) -> 1.0024882 | F8: =AVERAGE('Data Results processed'!F29:F31) -> 0.33961042 | G8: =AVERAGE('Data Results processed'!G29:G31) -> 45.28173 | H8: =AVERAGE('Data Results processed'!H29:H31) -> 0.21911634 | I8: =AVERAGE('Data Results processed'!I29:I31) -> 0.026283101 | J8: =AVERAGE('Data Results processed'!J29:J31) -> 1.7347884 | K8: =AVERAGE('Data Results processed'!K29:K31) -> 12.699601 | L8: =AVERAGE('Data Results processed'!L29:L31) -> 3.9629357 | ... P8: =AVERAGE('Data Results processed'!P29:P31) -> 126.5899 | R8: =AVERAGE('Data Results processed'!R29:R31) -> 6.6168902 | S8: =AVERAGE('Data Results processed'!S29:S31) -> 0.24539944
A9: lsf | B9: 28 | C9: ED | E9: =AVERAGE('Data Results processed'!E32:E34) -> 1.0837933 | F9: =AVERAGE('Data Results processed'!F32:F34) -> 0.31632378 | G9: =AVERAGE('Data Results processed'!G32:G34) -> 90.194345 | H9: =AVERAGE('Data Results processed'!H32:H34) -> 0.72247664 | I9: =AVERAGE('Data Results processed'!I32:I34) -> 0.2220784 | J9: =AVERAGE('Data Results processed'!J32:J34) -> 3.0374309 | K9: =AVERAGE('Data Results processed'!K32:K34) -> 12.125677 | L9: =AVERAGE('Data Results processed'!L32:L34) -> 12.497892 | ... P9: =AVERAGE('Data Results processed'!P32:P34) -> 114.98321 | R9: =AVERAGE('Data Results processed'!R32:R34) -> 24.176567 | S9: =AVERAGE('Data Results processed'!S32:S34) -> 0.94455504
A10: lsf | B10: 28 | C10: EN | E10: =AVERAGE('Data Results processed'!E35:E37) -> 0.94592341 | F10: =AVERAGE('Data Results processed'!F35:F37) -> 0.30060939 | G10: =AVERAGE('Data Results processed'!G35:G37) -> 44.250532 | H10: =AVERAGE('Data Results processed'!H35:H37) -> 0.10404019 | I10: =AVERAGE('Data Results processed'!I35:I37) -> 0.097436453 | J10: =AVERAGE('Data Results processed'!J35:J37) -> 1.390703 | K10: =AVERAGE('Data Results processed'!K35:K37) -> 11.402155 | L10: =AVERAGE('Data Results processed'!L35:L37) -> 4.5141086 | ... P10: =AVERAGE('Data Results processed'!P35:P37) -> 121.67188 | R10: =AVERAGE('Data Results processed'!R35:R37) -> 7.8549477 | S10: =AVERAGE('Data Results processed'!S35:S37) -> 0.20147664
A12: prr7 | B12: 27 | C12: EN | E12: =AVERAGE('Data Results processed'!E44:E46) -> 0.92052501 | F12: =AVERAGE('Data Results processed'!F44:F46) -> 0.31817514 | G12: =AVERAGE('Data Results processed'!G44:G46) -> 1.4768522 | H12: =AVERAGE('Data Results processed'!H44:H46) -> 0.1190595 | I12: =AVERAGE('Data Results processed'!I44:I46) -> 0.04850954 | J12: =AVERAGE('Data Results processed'!J44:J46) -> 1.0981229 | K12: =AVERAGE('Data Results processed'!K44:K46) -> 11.263049 | L12: =AVERAGE('Data Results processed'!L44:L46) -> 3.9961654 | ... P12: =AVERAGE('Data Results processed'!P44:P46) -> 131.62743 | R12: =AVERAGE('Data Results processed'!R44:R46) -> 7.8593917 | S12: =AVERAGE('Data Results processed'!S44:S46) -> 0.16756904
A13: prr7 | B13: 28 | C13: ED | E13: =AVERAGE('Data Results processed'!E47:E49) -> 1.1178837 | F13: =AVERAGE('Data Results processed'!F47:F49) -> 0.30630493 | G13: =AVERAGE('Data Results processed'!G47:G49) -> 56.895972 | H13: =AVERAGE('Data Results processed'!H47:H49) -> 0.88767844 | I13: =AVERAGE('Data Results processed'!I47:I49) -> 0.27189768 | J13: =AVERAGE('Data Results processed'!J47:J49) -> 3.1640344 | K13: =AVERAGE('Data Results processed'!K47:K49) -> 12.119975 | L13: =AVERAGE('Data Results processed'!L47:L49) -> 13.788757 | ... P13: =AVERAGE('Data Results processed'!P47:P49) -> 127.52548 | R13: =AVERAGE('Data Results processed'!R47:R49) -> 24.806303 | S13: =AVERAGE('Data Results processed'!S47:S49) -> 1.1595761
A14: prr7 | B14: 28 | C14: EN | E14: =AVERAGE('Data Results processed'!E50:E52) -> 0.92592662 | F14: =AVERAGE('Data Results processed'!F50:F52) -> 0.2882368 | G14: =AVERAGE('Data Results processed'!G50:G52) -> 4.4479658 | H14: =AVERAGE('Data Results processed'!H50:H52) -> 0.31502443 | I14: =AVERAGE('Data Results processed'!I50:I52) -> 0.02475816 | J14: =AVERAGE('Data Results processed'!J50:J52) -> 1.4325626 | K14: =AVERAGE('Data Results processed'!K50:K52) -> 10.492508 | L14: =AVERAGE('Data Results processed'!L50:L52) -> 5.6959497 | ... P14: =AVERAGE('Data Results processed'!P50:P52) -> 148.26858 | R14: =AVERAGE('Data Results processed'!R50:R52) -> 10.899827 | S14: =AVERAGE('Data Results processed'!S50:S52) -> 0.33978259
A16: prr7/prr9 | B16: 27 | C16: EN | E16: =AVERAGE('Data Results processed'!E59:E61) -> 1.1352014 | F16: =AVERAGE('Data Results processed'!F59:F61) -> 0.40748091 | G16: =AVERAGE('Data Results processed'!G59:G61) -> 9.9255566 | H16: =AVERAGE('Data Results processed'!H59:H61) -> 0.13822359 | I16: =AVERAGE('Data Results processed'!I59:I61) -> 0.062238501 | J16: =AVERAGE('Data Results processed'!J59:J61) -> 1.9311798 | K16: =AVERAGE('Data Results processed'!K59:K61) -> 14.677011 | L16: =AVERAGE('Data Results processed'!L59:L61) -> 9.5100726 | ... P16: =AVERAGE('Data Results processed'!P59:P61) -> 125.87778 | R16: =AVERAGE('Data Results processed'!R59:R61) -> 18.651524 | S16: =AVERAGE('Data Results processed'!S59:S61) -> 0.20046209
A17: prr7/prr9 | B17: 28 | C17: ED | E17: =AVERAGE('Data Results processed'!E62:E64) -> 1.2101498 | F17: =AVERAGE('Data Results processed'!F62:F64) -> 0.33742333 | G17: =AVERAGE('Data Results processed'!G62:G64) -> 67.31396 | H17: =AVERAGE('Data Results processed'!H62:H64) -> 1.1979805 | I17: =AVERAGE('Data Results processed'!I62:I64) -> 0.32120576 | J17: =AVERAGE('Data Results processed'!J62:J64) -> 3.2790858 | K17: =AVERAGE('Data Results processed'!K62:K64) -> 12.553266 | L17: =AVERAGE('Data Results processed'!L62:L64) -> 20.311489 | ... P17: =AVERAGE('Data Results processed'!P62:P64) -> 94.503145 | R17: =AVERAGE('Data Results processed'!R62:R64) -> 41.79504 | S17: =AVERAGE('Data Results processed'!S62:S64) -> 1.5191863
A18: prr7/prr9 | B18: 28 | C18: EN | E18: =AVERAGE('Data Results processed'!E65:E67) -> 1.0935537 | F18: =AVERAGE('Data Results processed'!F65:F67) -> 0.38332722 | G18: =AVERAGE('Data Results processed'!G65:G67) -> 23.769579 | H18: =AVERAGE('Data Results processed'!H65:H67) -> 0.21947514 | I18: =AVERAGE('Data Results processed'!I65:I67) -> 0.094178827 | J18: =AVERAGE('Data Results processed'!J65:J67) -> 2.0885645 | K18: =AVERAGE('Data Results processed'!K65:K67) -> 13.356718 | L18: =AVERAGE('Data Results processed'!L65:L67) -> 11.891442 | ... P18: =AVERAGE('Data Results processed'!P65:P67) -> 108.54654 | R18: =AVERAGE('Data Results processed'!R65:R67) -> 25.313331 | S18: =AVERAGE('Data Results processed'!S65:S67) -> 0.31365397
A22: SD | E22: Units
E23: mg chl a/g FW | F23: mg chl b/g FW | G23: (µmol/gFW) | H23: (µmol/g FW) | I23: (µmol/g FW) | J23: (µmol/g FW) | K23: (mg/gFW) | L23: (µmol/g FW) | M23: (µmol/g FW) | N23: (µmol/gFW) | O23: (nmol/g FW) | P23: (µmol/g FW) | R23: (µmol/g FW) | S23: (µmol/g FW)
A24: Genotype | B24: DAS | C24: Time harvest | D24: sample ID | E24: chlorophyll a | F24: chlorophyll b | G24: starch | H24: glucose | I24: fructose | J24: sucrose | K24: Total proteins | L24: malate | M24: fumarate | N24: Amino Acids | O24: G6P | P24: NO3 | R24: m+f | S24: glu+fruc
A25: Col | B25: 27 | C25: EN | E25: =STDEV('Data Results processed'!E10:E12) -> 0.036462754 | F25: =STDEV('Data Results processed'!F10:F12) -> 0.0015200699 | G25: =STDEV('Data Results processed'!G10:G12) -> 0.35492224 | H25: =STDEV('Data Results processed'!H10:H12) -> 0.07846986 | I25: =STDEV('Data Results processed'!I10:I12) -> 0.033668544 | J25: =STDEV('Data Results processed'!J10:J12) -> 0.56793127 | K25: =STDEV('Data Results processed'!K10:K12) -> 0.60464395 | L25: =STDEV('Data Results processed'!L10:L12) -> 0.53526889 | ... P25: =STDEV('Data Results processed'!P10:P12) -> 5.6128253 | R25: =STDEV('Data Results processed'!R10:R12) -> 0.51102723 | S25: =STDEV('Data Results processed'!S10:S12) -> 0.073108581
