Workbook

Sheet Read.Me
A1: Experimental data compilation with stats and charts
A2: for Chew et al. BiorXiv 2017 and subsequent publication
A3: Note that the data files for the individual studies (available elsewhere) have additional mutants (prr7, pgm, lhycca1) and earlier analysis (21 days) that were not used in the publication and are not reproduced here.
A5: Sheets in this workbook | B5: Study | C5: Contents
A6: L&H1 | B6: Laurel and Hardy 1 | C6: Fresh and Dry rosette leaf biomass, and rosette area, measured in samples of 5 plants each on day 38 for Col Wild Type plants, lsf1 and prr7prr9 mutants; gas exchange measured on each of these plants.
A7: L&H2 | B7: Laurel and Hardy 2 | C7: Fresh and Dry rosette leaf biomass, and rosette area, measured in samples of 5 plants each on day 39 for Col Wild Type plants, lsf1 and prr7prr9 mutants; gas exchange measured on each of these plants.
A8: L&H3 | B8: Laurel and Hardy 3 | C8: Fresh and Dry rosette leaf biomass, and rosette area, measured in samples of 5 plants each on day 38 for Col Wild Type plants and prr7prr9 mutants; gas exchange measured on each of these plants.
A9: no GA controls | B9: Gibberellins 1 | C9: Fresh and Dry rosette leaf biomass data ONLY, measured in samples of 5 plants each on day 35 for Col Wild Type plants and prr7prr9 mutants.
A10: biomass ANOVA | B10: compilation | C10: statistical analysis and figures on the biomass data compiled from the four studies
A11: water content ANOVA | B11: compilation | C11: statistical analysis and figures on the water content data from L&H2, L&H3 and no GA studies
A12: SLA ANOVA | B12: compilation | C12: statistical analysis and figures on the specific leaf area (SLA, mass/area) data from L&H1, L&H2 and L&H3 studies
A14: Credits
A15: all data here | B15: Yin Hoon Chew, Millar group University of Edinburgh
A16: analysis and compilation figures | B16: Andrew Millar, University of Edinburgh

Sheet L&H 1
A1: Adjusted by soil respiration
A2: WHOLE-PLANT CHAMBER: | D2: AIR:
A3: Diameter (cm) | B3: 12 | D3: Density | E3: =101325/8.314/(20+273.15) -> 41.57351 | F3: mol m-3
A4: Height (cm) | B4: 3
A5: Volume (cm3) | B5: =PI()*(B3/2)^2*B4 -> 339.29201
F7: micromol/s | J7: adjusted by water content | K7: Fixed, from measurements day 21/28/29 (not sure which) | O7: micromol/h/g FW | R7: micromol/h/g DW | U7: micromol/h/cm2 | X7: m2/gDW
C8: Slope A | D8: Slope R | F8: A rate | G8: R rate | I8: FW (g) | J8: DW (g) | K8: Water content | L8: Rosette area (mm2) | O8: A rate | P8: R rate | R8: A rate | S8: R rate | U8: A rate | V8: R rate | X8: SLA
A9: Col | B9: #1 | C9: -0.6866 | D9: 0.3344 | F9: =-C9*$E$3*$B$5/10^6 -> 0.0096848773 | G9: =-D9*$E$3*$B$5/10^6 -> -0.0047168991 | I9: 0.8044 | J9: =I9*(1-0.91) -> 0.072396 | K9: =1-(J9/I9) -> 0.91 | L9: 2828.427 | O9: =(F9-$F$39)/I9*3600 -> 44.780768 | P9: =(G9-$G$39)/I9*3600 -> -15.920835 | R9: =(F9-$F$39)/J9*3600 -> 497.56409 | S9: =(G9-$G$39)/J9*3600 -> -176.89817 | U9: =(F9-$F$39)/L9*10^6*3600/10000 -> 1.2735577 | V9: =(G9-$G$39)/L9*10^6*3600/10000 -> -0.45278594 | X9: =R9/U9/10^4 -> 0.03906883
B10: #2 | C10: -0.7883 | D10: 0.2733 | F10: =-C10*$E$3*$B$5/10^6 -> 0.011119413 | G10: =-D10*$E$3*$B$5/10^6 -> -0.0038550495 | I10: 0.8362 | J10: =I10*(1-0.91) -> 0.075258 | K10: =1-(J10/I10) -> 0.91 | L10: 2629.16 | O10: =(F10-$F$39)/I10*3600 -> 49.25374 | P10: =(G10-$G$39)/I10*3600 -> -11.604952 | R10: =(F10-$F$39)/J10*3600 -> 547.26378 | S10: =(G10-$G$39)/J10*3600 -> -128.94391 | U10: =(F10-$F$39)/L10*10^6*3600/10000 -> 1.5665071 | V10: =(G10-$G$39)/L10*10^6*3600/10000 -> -0.36909358 | X10: =R10/U10/10^4 -> 0.034935289
B11: #3 | C11: -0.7778 | D11: 0.3483 | F11: =-C11*$E$3*$B$5/10^6 -> 0.010971304 | G11: =-D11*$E$3*$B$5/10^6 -> -0.0049129664 | I11: 1.0092 | J11: =I11*(1-0.91) -> 0.090828 | K11: =1-(J11/I11) -> 0.91 | L11: 3051.845 | O11: =(F11-$F$39)/I11*3600 -> 40.282191 | P11: =(G11-$G$39)/I11*3600 -> -13.38938 | R11: =(F11-$F$39)/J11*3600 -> 447.5799 | S11: =(G11-$G$39)/J11*3600 -> -148.77088 | U11: =(F11-$F$39)/L11*10^6*3600/10000 -> 1.3320725 | V11: =(G11-$G$39)/L11*10^6*3600/10000 -> -0.44276698 | X11: =R11/U11/10^4 -> 0.033600266
B12: #4 | C12: -0.9154 | D12: 0.3655 | F12: =-C12*$E$3*$B$5/10^6 -> 0.012912229 | G12: =-D12*$E$3*$B$5/10^6 -> -0.0051555821 | I12: 1.1627 | J12: =I12*(1-0.91) -> 0.104643 | K12: =1-(J12/I12) -> 0.91 | L12: 3486.016 | O12: =(F12-$F$39)/I12*3600 -> 40.973697 | P12: =(G12-$G$39)/I12*3600 -> -12.372906 | R12: =(F12-$F$39)/J12*3600 -> 455.2633 | S12: =(G12-$G$39)/J12*3600 -> -137.47674 | U12: =(F12-$F$39)/L12*10^6*3600/10000 -> 1.3666064 | V12: =(G12-$G$39)/L12*10^6*3600/10000 -> -0.41267677 | X12: =R12/U12/10^4 -> 0.033313418
B13: #5 | C13: -0.7855 | D13: 0.3464 | F13: =-C13*$E$3*$B$5/10^6 -> 0.011079917 | G13: =-D13*$E$3*$B$5/10^6 -> -0.0048861659 | I13: 0.9382 | J13: =I13*(1-0.91) -> 0.084438 | K13: =1-(J13/I13) -> 0.91 | L13: 2961.033 | O13: =(F13-$F$39)/I13*3600 -> 43.747381 | P13: =(G13-$G$39)/I13*3600 -> -14.299808 | R13: =(F13-$F$39)/J13*3600 -> 486.08202 | S13: =(G13-$G$39)/J13*3600 -> -158.88676 | U13: =(F13-$F$39)/L13*10^6*3600/10000 -> 1.3861309 | V13: =(G13-$G$39)/L13*10^6*3600/10000 -> -0.45308782 | X13: =R13/U13/10^4 -> 0.035067541
A14: Average | I14: =AVERAGE(I9:I13) -> 0.95014 | O14: =AVERAGE(O9:O13) -> 43.807555 | P14: =AVERAGE(P9:P13) -> -13.517576 | R14: =AVERAGE(R9:R13) -> 486.75062 | S14: =AVERAGE(S9:S13) -> -150.19529 | U14: =AVERAGE(U9:U13) -> 1.3849749 | V14: =AVERAGE(V9:V13) -> -0.42608222 | X14: =AVERAGE(X9:X13) -> 0.035197069
A15: SD | I15: =STDEV(I9:I13) -> 0.14407886 | O15: =STDEV(O9:O13) -> 3.5731862 | P15: =STDEV(P9:P13) -> 1.6861476 | R15: =STDEV(R9:R13) -> 39.702069 | S15: =STDEV(S9:S13) -> 18.734973 | U15: =STDEV(U9:U13) -> 0.1101194 | V15: =STDEV(V9:V13) -> 0.035875421 | X15: =STDEV(X9:X13) -> 0.0023007476
K16: Fixed
C17: Slope A | D17: Slope R | F17: A rate | G17: R rate | I17: FW (g) | J17: DW (g) | K17: Water content | L17: Rosette area (mm2)
A18: lsf1 | B18: #1 | C18: -0.4654 | D18: 0.182 | F18: =-C18*$E$3*$B$5/10^6 -> 0.0065647275 | G18: =-D18*$E$3*$B$5/10^6 -> -0.0025672119 | I18: 0.4515 | J18: =I18*(1-0.89) -> 0.049665 | K18: =1-(J18/I18) -> 0.89 | L18: 1615.527 | O18: =(F18-$F$39)/I18*3600 -> 54.903899 | P18: =(G18-$G$39)/I18*3600 -> -11.224464 | R18: =(F18-$F$39)/J18*3600 -> 499.12636 | S18: =(G18-$G$39)/J18*3600 -> -102.04058 | U18: =(F18-$F$39)/L18*10^6*3600/10000 -> 1.5344287 | V18: =(G18-$G$39)/L18*10^6*3600/10000 -> -0.31369612 | X18: =R18/U18/10^4 -> 0.032528481
B19: #2 | C19: -0.5112 | D19: 0.2059 | F19: =-C19*$E$3*$B$5/10^6 -> 0.0072107621 | G19: =-D19*$E$3*$B$5/10^6 -> -0.0029043347 | I19: 0.516 | J19: =I19*(1-0.89) -> 0.05676 | K19: =1-(J19/I19) -> 0.89 | L19: 1909.388 | O19: =(F19-$F$39)/I19*3600 -> 52.54813 | P19: =(G19-$G$39)/I19*3600 -> -12.173426 | R19: =(F19-$F$39)/J19*3600 -> 477.71027 | S19: =(G19-$G$39)/J19*3600 -> -110.66751 | U19: =(F19-$F$39)/L19*10^6*3600/10000 -> 1.4200799 | V19: =(G19-$G$39)/L19*10^6*3600/10000 -> -0.32897912 | X19: =R19/U19/10^4 -> 0.033639676
B20: #3 | C20: -0.5538 | D20: 0.2016 | F20: =-C20*$E$3*$B$5/10^6 -> 0.0078116589 | G20: =-D20*$E$3*$B$5/10^6 -> -0.0028436808 | I20: 0.5394 | J20: =I20*(1-0.89) -> 0.059334 | K20: =1-(J20/I20) -> 0.89 | L20: 1966.605 | O20: =(F20-$F$39)/I20*3600 -> 54.278947 | P20: =(G20-$G$39)/I20*3600 -> -11.240515 | R20: =(F20-$F$39)/J20*3600 -> 493.44497 | S20: =(G20-$G$39)/J20*3600 -> -102.1865 | U20: =(F20-$F$39)/L20*10^6*3600/10000 -> 1.4887618 | V20: =(G20-$G$39)/L20*10^6*3600/10000 -> -0.3083046 | X20: =R20/U20/10^4 -> 0.033144656
B21: #4 | C21: -0.4849 | D21: 0.1787 | F21: =-C21*$E$3*$B$5/10^6 -> 0.0068397859 | G21: =-D21*$E$3*$B$5/10^6 -> -0.0025206635 | I21: 0.4283 | J21: =I21*(1-0.89) -> 0.047113 | K21: =1-(J21/I21) -> 0.89 | L21: 1596.912 | O21: =(F21-$F$39)/I21*3600 -> 60.189869 | P21: =(G21-$G$39)/I21*3600 -> -11.441213 | R21: =(F21-$F$39)/J21*3600 -> 547.18063 | S21: =(G21-$G$39)/J21*3600 -> -104.01103 | U21: =(F21-$F$39)/L21*10^6*3600/10000 -> 1.6143232 | V21: =(G21-$G$39)/L21*10^6*3600/10000 -> -0.3068592 | X21: =R21/U21/10^4 -> 0.033895358
B22: #5 | C22: -0.4931 | D22: 0.1959 | F22: =-C22*$E$3*$B$5/10^6 -> 0.0069554515 | G22: =-D22*$E$3*$B$5/10^6 -> -0.0027632791 | I22: 0.5034 | J22: =I22*(1-0.89) -> 0.055374 | K22: =1-(J22/I22) -> 0.89 | L22: 1705.3 | O22: =(F22-$F$39)/I22*3600 -> 52.037578 | P22: =(G22-$G$39)/I22*3600 -> -11.469384 | R22: =(F22-$F$39)/J22*3600 -> 473.06889 | S22: =(G22-$G$39)/J22*3600 -> -104.26712 | U22: =(F22-$F$39)/L22*10^6*3600/10000 -> 1.5361354 | V22: =(G22-$G$39)/L22*10^6*3600/10000 -> -0.33857314 | X22: =R22/U22/10^4 -> 0.030796041
A23: Average | I23: =AVERAGE(I18:I22) -> 0.48772 | O23: =AVERAGE(O18:O22) -> 54.791685 | P23: =AVERAGE(P18:P22) -> -11.5098 | R23: =AVERAGE(R18:R22) -> 498.10622 | S23: =AVERAGE(S18:S22) -> -104.63455 | U23: =AVERAGE(U18:U22) -> 1.5187458 | V23: =AVERAGE(V18:V22) -> -0.31928244 | X23: =AVERAGE(X18:X22) -> 0.032800842
A24: SD | I24: =STDEV(I18:I22) -> 0.046257616 | O24: =STDEV(O18:O22) -> 3.2417018 | P24: =STDEV(P18:P22) -> 0.38751397 | R24: =STDEV(R18:R22) -> 29.470017 | S24: =STDEV(S18:S22) -> 3.5228542 | U24: =STDEV(U18:U22) -> 0.071269544 | V24: =STDEV(V18:V22) -> 0.013894362 | X24: =STDEV(X18:X22) -> 0.0012362464
C25: Slope A | D25: Slope R | F25: A rate | G25: R rate | I25: FW (g) | J25: DW (g) | K25: Water content | L25: Rosette area (mm2)
A26: prr7/prr9 | B26: #1 | C26: -0.6426 | D26: 0.2561 | F26: =-C26*$E$3*$B$5/10^6 -> 0.0090642326 | G26: =-D26*$E$3*$B$5/10^6 -> -0.0036124338 | I26: 0.5754 | J26: =I26*(1-0.89) -> 0.063294 | K26: =1-(J26/I26) -> 0.89 | L26: 2496.333 | O26: =(F26-$F$39)/I26*3600 -> 58.719724 | P26: =(G26-$G$39)/I26*3600 -> -15.346967 | R26: =(F26-$F$39)/J26*3600 -> 533.81567 | S26: =(G26-$G$39)/J26*3600 -> -139.51788 | U26: =(F26-$F$39)/L26*10^6*3600/10000 -> 1.3534784 | V26: =(G26-$G$39)/L26*10^6*3600/10000 -> -0.35374466 | X26: =R26/U26/10^4 -> 0.039440279
B27: #2 | C27: -0.7482 | D27: 0.2465 | F27: =-C27*$E$3*$B$5/10^6 -> 0.01055378 | G27: =-D27*$E$3*$B$5/10^6 -> -0.0034770205 | I27: 0.6435 | J27: =I27*(1-0.89) -> 0.070785 | K27: =1-(J27/I27) -> 0.89 | L27: 2652.403 | O27: =(F27-$F$39)/I27*3600 -> 60.838693 | P27: =(G27-$G$39)/I27*3600 -> -12.965278 | R27: =(F27-$F$39)/J27*3600 -> 553.07902 | S27: =(G27-$G$39)/J27*3600 -> -117.86616 | U27: =(F27-$F$39)/L27*10^6*3600/10000 -> 1.4760087 | V27: =(G27-$G$39)/L27*10^6*3600/10000 -> -0.31455086 | X27: =R27/U27/10^4 -> 0.037471258
B28: #3 | C28: -0.6292 | D28: 0.2255 | F28: =-C28*$E$3*$B$5/10^6 -> 0.0088752181 | G28: =-D28*$E$3*$B$5/10^6 -> -0.0031808037 | I28: 0.538 | J28: =I28*(1-0.89) -> 0.05918 | K28: =1-(J28/I28) -> 0.89 | L28: 2308.301 | O28: =(F28-$F$39)/I28*3600 -> 61.536946 | P28: =(G28-$G$39)/I28*3600 -> -13.525606 | R28: =(F28-$F$39)/J28*3600 -> 559.42678 | S28: =(G28-$G$39)/J28*3600 -> -122.96006 | U28: =(F28-$F$39)/L28*10^6*3600/10000 -> 1.434253 | V28: =(G28-$G$39)/L28*10^6*3600/10000 -> -0.31524381 | X28: =R28/U28/10^4 -> 0.039004748
B29: #4 | C29: -0.6049 | D29: 0.2174 | F29: =-C29*$E$3*$B$5/10^6 -> 0.008532453 | G29: =-D29*$E$3*$B$5/10^6 -> -0.0030665487 | I29: 0.493 | J29: =I29*(1-0.89) -> 0.05423 | K29: =1-(J29/I29) -> 0.89 | L29: 2271.021 | O29: =(F29-$F$39)/I29*3600 -> 64.650959 | P29: =(G29-$G$39)/I29*3600 -> -13.925878 | R29: =(F29-$F$39)/J29*3600 -> 587.73599 | S29: =(G29-$G$39)/J29*3600 -> -126.59889 | U29: =(F29-$F$39)/L29*10^6*3600/10000 -> 1.4034623 | V29: =(G29-$G$39)/L29*10^6*3600/10000 -> -0.30230711 | X29: =R29/U29/10^4 -> 0.041877577
B30: #5 | C30: -0.7544 | D30: 0.2289 | F30: =-C30*$E$3*$B$5/10^6 -> 0.010641234 | G30: =-D30*$E$3*$B$5/10^6 -> -0.0032287626 | I30: 0.6216 | J30: =I30*(1-0.89) -> 0.068376 | K30: =1-(J30/I30) -> 0.89 | L30: 2717.111 | O30: =(F30-$F$39)/I30*3600 -> 63.488634 | P30: =(G30-$G$39)/I30*3600 -> -11.98428 | R30: =(F30-$F$39)/J30*3600 -> 577.1694 | S30: =(G30-$G$39)/J30*3600 -> -108.948 | U30: =(F30-$F$39)/L30*10^6*3600/10000 -> 1.4524447 | V30: =(G30-$G$39)/L30*10^6*3600/10000 -> -0.27416724 | X30: =R30/U30/10^4 -> 0.039737788
A31: Average | I31: =AVERAGE(I26:I30) -> 0.5743 | O31: =AVERAGE(O26:O30) -> 61.846991 | P31: =AVERAGE(P26:P30) -> -13.549602 | R31: =AVERAGE(R26:R30) -> 562.24537 | S31: =AVERAGE(S26:S30) -> -123.1782 | U31: =AVERAGE(U26:U30) -> 1.4239294 | V31: =AVERAGE(V26:V30) -> -0.31200274 | X31: =AVERAGE(X26:X30) -> 0.03950633
A32: SD | I32: =STDEV(I26:I30) -> 0.061144337 | O32: =STDEV(O26:O30) -> 2.3156974 | P32: =STDEV(P26:P30) -> 1.2414052 | R32: =STDEV(R26:R30) -> 21.051795 | S32: =STDEV(S26:S30) -> 11.285502 | U32: =STDEV(U26:U30) -> 0.047471551 | V32: =STDEV(V26:V30) -> 0.028657091 | X32: =STDEV(X26:X30) -> 0.0015869665
C35: Slope A | D35: Slope R | F35: A rate | G35: R rate
A36: Soil | B36: #1 | C36: 0.0215 | D36: 0.0822 | F36: =-C36*$E$3*$B$5/10^6 -> -0.00030326953 | G36: =-D36*$E$3*$B$5/10^6 -> -0.001159477
B37: #2 | C37: 0.0177 | F37: =-C37*$E$3*$B$5/10^6 -> -0.00024966841
B38: #3 | C38: 0.0291 | F38: =-C38*$E$3*$B$5/10^6 -> -0.00041047179
B39: Average | C39: =AVERAGE(C36:C38) -> 0.022766667 | D39: =AVERAGE(D36:D38) -> 0.0822 | F39: =AVERAGE(F36:F38) -> -0.00032113657 | G39: =AVERAGE(G36:G38) -> -0.001159477
A45: Simulated | B45: Photosynthesis at 0.88 of default
C46: Aper area | D46: R per area | E46: AperFw | F46: RperFw
B47: Col | C47: 1.4177 | D47: -0.2547 | E47: 45.0675 | F47: -8.1877
B48: lsf1 | C48: 1.418 | D48: -0.2944 | E48: 53.7457 | F48: -11.296
...

Sheet t-test for L&H 1
A1: Net assimilation per unit rosette area (micromol CO2/h/cm2) | I1: Net assimilation per g FW (micromol CO2/h/g FW)
A2: # | B2: Col | C2: prr7/prr9 | D2: lsf1 | I2: # | J2: Col | K2: prr7/prr9 | L2: lsf1
A3: 1 | B3: 1.2735577 | C3: 1.3534784 | D3: 1.5344287 | I3: 1 | J3: 44.780768 | K3: 58.719724 | L3: 54.903899
A4: 2 | B4: 1.5665071 | C4: 1.4760087 | D4: 1.4200799 | I4: 2 | J4: 49.25374 | K4: 60.838693 | L4: 52.54813
A5: 3 | B5: 1.3320725 | C5: 1.434253 | D5: 1.4887618 | I5: 3 | J5: 40.282191 | K5: 61.536946 | L5: 54.278947
A6: 4 | B6: 1.3666064 | C6: 1.4034623 | D6: 1.6143232 | I6: 4 | J6: 40.973697 | K6: 64.650959 | L6: 60.189869
A7: 5 | B7: 1.3861309 | C7: 1.4524447 | D7: 1.5361354 | I7: 5 | J7: 43.747381 | K7: 63.488634 | L7: 52.037578
A9: prr7/prr9 | B9: =TTEST(B3:B7,C3:C7,2,2) -> 0.48830907 | I9: prr7/prr9 | J9: =TTEST(J3:J7,K3:K7,2,2) -> 1.2692838e-05
A10: lsf1 | B10: =TTEST(B3:B7,D3:D7,2,2) -> 0.052038682 | I10: lsf1 | J10: =TTEST(J3:J7,L3:L7,2,2) -> 0.00094037579
A12: TotMean | B12: =AVERAGE(B3:D7) -> 1.44255 | I12: TotMean | J12: =AVERAGE(J3:L7) -> 53.482077

Sheet L&H 2
A1: WHOLE-PLANT CHAMBER: | D1: AIR:
A2: Diameter (cm) | B2: 12 | D2: Density | E2: =101325/8.314/(20+273.15) -> 41.57351 | F2: mol m-3
A3: Height (cm) | B3: 3
A4: Pot diameter (cm | B4: 7.7
A5: Depth occupied by pot (cm | B5: 1.5
A6: Volume (cm3) | B6: =PI()*(B2/2)^2*B3-PI()*(B4/2)^2*B5 -> 269.44262
F8: micromol/s | K8: Calculated | O8: micromol/h/g FW | R8: micromol/h/g DW | U8: micromol/h/cm2 | X8: m2/gDW
C9: Slope A | D9: Slope R | F9: A rate | G9: R rate | I9: FW (g) | J9: DW (g) | K9: Water content | L9: Rosette area (mm2) | O9: A rate | P9: R rate | R9: A rate | S9: R rate | U9: A rate | V9: R rate | X9: SLA
A10: Col | B10: #1 | C10: -0.9365 | D10: 0.3803 | F10: =-C10*$E$2*$B$6/10^6 -> 0.010490369 | G10: =-D10*$E$2*$B$6/10^6 -> -0.0042599972 | I10: 0.7057 | J10: 0.0672 | K10: =1-(J10/I10) -> 0.9047754 | L10: 1885.869 | O10: =(F10)/I10*3600 -> 53.514707 | P10: =(G10)/I10*3600 -> -21.7316 | R10: =(F10)/J10*3600 -> 561.98406 | S10: =(G10)/J10*3600 -> -228.21414 | U10: =(F10)/L10*10^6*3600/10000 -> 2.0025425 | V10: =(G10)/L10*10^6*3600/10000 -> -0.81320547 | X10: =R10/U10/10^4 -> 0.028063527
B11: #2 | C11: -0.7821 | D11: 0.2633 | F11: =-C11*$E$2*$B$6/10^6 -> 0.0087608304 | G11: =-D11*$E$2*$B$6/10^6 -> -0.0029494012 | I11: 0.5231 | J11: 0.0522 | K11: =1-(J11/I11) -> 0.90021028 | L11: 1662.899 | O11: =(F11)/I11*3600 -> 60.292467 | P11: =(G11)/I11*3600 -> -20.297924 | R11: =(F11)/J11*3600 -> 604.1952 | S11: =(G11)/J11*3600 -> -203.40698 | U11: =(F11)/L11*10^6*3600/10000 -> 1.8966269 | V11: =(G11)/L11*10^6*3600/10000 -> -0.63851408 | X11: =R11/U11/10^4 -> 0.031856303
B12: #3 | C12: -0.784 | D12: 0.2446 | F12: =-C12*$E$2*$B$6/10^6 -> 0.0087821136 | G12: =-D12*$E$2*$B$6/10^6 -> -0.0027399298 | I12: 0.5608 | J12: 0.0565 | K12: =1-(J12/I12) -> 0.89925107 | L12: 1440.254 | O12: =(F12)/I12*3600 -> 56.375908 | P12: =(G12)/I12*3600 -> -17.588708 | R12: =(F12)/J12*3600 -> 559.5683 | S12: =(G12)/J12*3600 -> -174.5796 | U12: =(F12)/L12*10^6*3600/10000 -> 2.1951412 | V12: =(G12)/L12*10^6*3600/10000 -> -0.68486166 | X12: =R12/U12/10^4 -> 0.025491221
B13: #4 | C13: -0.784 | D13: 0.1911 | F13: =-C13*$E$2*$B$6/10^6 -> 0.0087821136 | G13: =-D13*$E$2*$B$6/10^6 -> -0.0021406402 | I13: 0.534 | J13: 0.0551 | K13: =1-(J13/I13) -> 0.89681648 | L13: 1530.799 | O13: =(F13)/I13*3600 -> 59.20526 | P13: =(G13)/I13*3600 -> -14.431282 | R13: =(F13)/J13*3600 -> 573.78601 | S13: =(G13)/J13*3600 -> -139.86034 | U13: =(F13)/L13*10^6*3600/10000 -> 2.0653011 | V13: =(G13)/L13*10^6*3600/10000 -> -0.50341715 | X13: =R13/U13/10^4 -> 0.027782196
B14: #5 | C14: -0.7344 | D14: 0.2905 | F14: =-C14*$E$2*$B$6/10^6 -> 0.0082265105 | G14: =-D14*$E$2*$B$6/10^6 -> -0.0032540867 | I14: 0.5032 | J14: 0.051 | K14: =1-(J14/I14) -> 0.89864865 | L14: 1566.407 | O14: =(F14)/I14*3600 -> 58.854209 | P14: =(G14)/I14*3600 -> -23.28043 | R14: =(F14)/J14*3600 -> 580.69486 | S14: =(G14)/J14*3600 -> -229.70024 | U14: =(F14)/L14*10^6*3600/10000 -> 1.8906605 | V14: =(G14)/L14*10^6*3600/10000 -> -0.74787155 | X14: =R14/U14/10^4 -> 0.030713863
A15: Average | I15: =AVERAGE(I10:I14) -> 0.56536 | J15: =AVERAGE(J10:J14) -> 0.0564 | K15: =AVERAGE(K10:K14) -> 0.89994038 | O15: =AVERAGE(O10:O14) -> 57.64851 | P15: =AVERAGE(P10:P14) -> -19.465989 | R15: =AVERAGE(R10:R14) -> 576.04569 | S15: =AVERAGE(S10:S14) -> -195.15226 | U15: =AVERAGE(U10:U14) -> 2.0100544 | V15: =AVERAGE(V10:V14) -> -0.67757398 | X15: =AVERAGE(X10:X14) -> 0.028781422
A16: SD | I16: =STDEV(I10:I14) -> 0.081162387 | J16: =STDEV(J10:J14) -> 0.0064253405 | K16: =STDEV(K10:K14) -> 0.0029729086 | O16: =STDEV(O10:O14) -> 2.7191696 | P16: =STDEV(P10:P14) -> 3.508829 | R16: =STDEV(R10:R14) -> 17.946795 | S16: =STDEV(S10:S14) -> 38.194312 | U16: =STDEV(U10:U14) -> 0.12697093 | V16: =STDEV(V10:V14) -> 0.11752344 | X16: =STDEV(X10:X14) -> 0.0025262851
K17: Calculated
C18: Slope A | D18: Slope R | F18: A rate | G18: R rate | I18: FW (g) | J18: DW (g) | K18: Water content | L18: Rosette area (mm2)
A19: lsf1 | B19: #1 | C19: -0.6722 | D19: 0.2776 | F19: =-C19*$E$2*$B$6/10^6 -> 0.0075297663 | G19: =-D19*$E$2*$B$6/10^6 -> -0.0031095851 | I19: 0.4548 | J19: 0.0498 | K19: =1-(J19/I19) -> 0.89050132 | L19: 1452.934 | O19: =(F19)/I19*3600 -> 59.602372 | P19: =(G19)/I19*3600 -> -24.61413 | R19: =(F19)/J19*3600 -> 544.32045 | S19: =(G19)/J19*3600 -> -224.78929 | U19: =(F19)/L19*10^6*3600/10000 -> 1.8656841 | V19: =(G19)/L19*10^6*3600/10000 -> -0.77047591 | X19: =R19/U19/10^4 -> 0.029175382
B20: #2 | C20: -0.8313 | D20: 0.2776 | F20: =-C20*$E$2*$B$6/10^6 -> 0.0093119529 | G20: =-D20*$E$2*$B$6/10^6 -> -0.0031095851 | I20: 0.52 | J20: 0.0553 | K20: =1-(J20/I20) -> 0.89365385 | L20: 1745.994 | O20: =(F20)/I20*3600 -> 64.467366 | P20: =(G20)/I20*3600 -> -21.527897 | R20: =(F20)/J20*3600 -> 606.20308 | S20: =(G20)/J20*3600 -> -202.4323 | U20: =(F20)/L20*10^6*3600/10000 -> 1.9199969 | V20: =(G20)/L20*10^6*3600/10000 -> -0.64115377 | X20: =R20/U20/10^4 -> 0.031573128
B21: #3 | C21: -0.7802 | D21: 0.3192 | F21: =-C21*$E$2*$B$6/10^6 -> 0.0087395472 | G21: =-D21*$E$2*$B$6/10^6 -> -0.0035755748 | I21: 0.5334 | J21: 0.0561 | K21: =1-(J21/I21) -> 0.89482565 | L21: 1468.594 | O21: =(F21)/I21*3600 -> 58.984571 | P21: =(G21)/I21*3600 -> -24.132114 | R21: =(F21)/J21*3600 -> 560.82656 | S21: =(G21)/J21*3600 -> -229.44865 | U21: =(F21)/L21*10^6*3600/10000 -> 2.1423464 | V21: =(G21)/L21*10^6*3600/10000 -> -0.87648931 | X21: =R21/U21/10^4 -> 0.026178146
B22: #4 | C22: -0.5767 | D22: 0.1137 | F22: =-C22*$E$2*$B$6/10^6 -> 0.0064600063 | G22: =-D22*$E$2*$B$6/10^6 -> -0.0012736305 | I22: 0.4485 | J22: 0.0522 | K22: =1-(J22/I22) -> 0.88361204 | L22: 1442.334 | O22: =(F22)/I22*3600 -> 51.852893 | P22: =(G22)/I22*3600 -> -10.223121 | R22: =(F22)/J22*3600 -> 445.51767 | S22: =(G22)/J22*3600 -> -87.836587 | U22: =(F22)/L22*10^6*3600/10000 -> 1.6123882 | V22: =(G22)/L22*10^6*3600/10000 -> -0.31789238 | X22: =R22/U22/10^4 -> 0.02763092
B23: #5 | C23: -0.8887 | D23: 0.3827 | F23: =-C23*$E$2*$B$6/10^6 -> 0.009954929 | G23: =-D23*$E$2*$B$6/10^6 -> -0.0042868812 | I23: 0.6686 | J23: 0.0669 | K23: =1-(J23/I23) -> 0.89994017 | L23: 1902.077 | O23: =(F23)/I23*3600 -> 53.601173 | P23: =(G23)/I23*3600 -> -23.08222 | R23: =(F23)/J23*3600 -> 535.69125 | S23: =(G23)/J23*3600 -> -230.68419 | U23: =(F23)/L23*10^6*3600/10000 -> 1.8841374 | V23: =(G23)/L23*10^6*3600/10000 -> -0.81136423 | X23: =R23/U23/10^4 -> 0.028431644
A24: Average | I24: =AVERAGE(I19:I23) -> 0.52506 | J24: =AVERAGE(J19:J23) -> 0.05606 | K24: =AVERAGE(K19:K23) -> 0.89250661 | O24: =AVERAGE(O19:O23) -> 57.701675 | P24: =AVERAGE(P19:P23) -> -20.715896 | R24: =AVERAGE(R19:R23) -> 538.5118 | S24: =AVERAGE(S19:S23) -> -195.0382 | U24: =AVERAGE(U19:U23) -> 1.8849106 | V24: =AVERAGE(V19:V23) -> -0.68347512 | X24: =AVERAGE(X19:X23) -> 0.028597844
A25: SD | I25: =STDEV(I19:I23) -> 0.088736678 | J25: =STDEV(J19:J23) -> 0.0065607164 | K25: =STDEV(K19:K23) -> 0.0060225931 | O25: =STDEV(O19:O23) -> 5.0511238 | P25: =STDEV(P19:P23) -> 5.9838101 | R25: =STDEV(R19:R23) -> 58.6721 | S25: =STDEV(S19:S23) -> 61.005536 | U25: =STDEV(U19:U23) -> 0.18850925 | V25: =STDEV(V19:V23) -> 0.22170988 | X25: =STDEV(X19:X23) -> 0.0020002106
K26: Calculated
C27: Slope A | D27: Slope R | F27: A rate | G27: R rate | I27: FW (g) | J27: DW (g) | K27: Water content | L27: Rosette area (mm2)
A28: prr7/prr9 | B28: #1 | C28: -0.6961 | D28: 0.3144 | F28: =-C28*$E$2*$B$6/10^6 -> 0.0077974863 | G28: =-D28*$E$2*$B$6/10^6 -> -0.0035218068 | I28: 0.4178 | J28: 0.0496 | K28: =1-(J28/I28) -> 0.88128291 | L28: 1495.247 | O28: =(F28)/I28*3600 -> 67.187532 | P28: =(G28)/I28*3600 -> -30.34587 | R28: =(F28)/J28*3600 -> 565.94659 | S28: =(G28)/J28*3600 -> -255.61501 | U28: =(F28)/L28*10^6*3600/10000 -> 1.8773454 | V28: =(G28)/L28*10^6*3600/10000 -> -0.8479204 | X28: =R28/U28/10^4 -> 0.030146109
B29: #2 | C29: -0.7009 | D29: 0.2604 | F29: =-C29*$E$2*$B$6/10^6 -> 0.0078512544 | G29: =-D29*$E$2*$B$6/10^6 -> -0.0029169163 | I29: 0.3822 | J29: 0.0458 | K29: =1-(J29/I29) -> 0.88016745 | L29: 1459.26 | O29: =(F29)/I29*3600 -> 73.95216 | P29: =(G29)/I29*3600 -> -27.474879 | R29: =(F29)/J29*3600 -> 617.12916 | S29: =(G29)/J29*3600 -> -229.27726 | U29: =(F29)/L29*10^6*3600/10000 -> 1.9369075 | V29: =(G29)/L29*10^6*3600/10000 -> -0.71960437 | X29: =R29/U29/10^4 -> 0.031861572
B30: #3 | C30: -0.8247 | D30: 0.3397 | F30: =-C30*$E$2*$B$6/10^6 -> 0.0092380218 | G30: =-D30*$E$2*$B$6/10^6 -> -0.0038052092 | I30: 0.4525 | J30: 0.0531 | K30: =1-(J30/I30) -> 0.88265193 | L30: 1392.879 | O30: =(F30)/I30*3600 -> 73.495864 | P30: =(G30)/I30*3600 -> -30.273487 | R30: =(F30)/J30*3600 -> 626.30656 | S30: =(G30)/J30*3600 -> -257.98028 | U30: =(F30)/L30*10^6*3600/10000 -> 2.3876359 | V30: =(G30)/L30*10^6*3600/10000 -> -0.98348478 | X30: =R30/U30/10^4 -> 0.026231243
B31: #4 | C31: -0.7477 | D31: 0.2996 | F31: =-C31*$E$2*$B$6/10^6 -> 0.0083754928 | G31: =-D31*$E$2*$B$6/10^6 -> -0.003356022 | I31: 0.4683 | J31: 0.0574 | K31: =1-(J31/I31) -> 0.877429 | L31: 1727.438 | O31: =(F31)/I31*3600 -> 64.385595 | P31: =(G31)/I31*3600 -> -25.799016 | R31: =(F31)/J31*3600 -> 525.29223 | S31: =(G31)/J31*3600 -> -210.48222 | U31: =(F31)/L31*10^6*3600/10000 -> 1.745462 | V31: =(G31)/L31*10^6*3600/10000 -> -0.69939871 | X31: =R31/U31/10^4 -> 0.030094739
B32: #5 | C32: -0.752 | D32: 0.3158 | F32: =-C32*$E$2*$B$6/10^6 -> 0.00842366 | G32: =-D32*$E$2*$B$6/10^6 -> -0.0035374891 | I32: 0.4145 | J32: 0.0495 | K32: =1-(J32/I32) -> 0.88057901 | L32: 1521.887 | O32: =(F32)/I32*3600 -> 73.160859 | P32: =(G32)/I32*3600 -> -30.723669 | R32: =(F32)/J32*3600 -> 612.62982 | S32: =(G32)/J32*3600 -> -257.27194 | U32: =(F32)/L32*10^6*3600/10000 -> 1.9926037 | V32: =(G32)/L32*10^6*3600/10000 -> -0.83678754 | X32: =R32/U32/10^4 -> 0.030745192
A33: Average | I33: =AVERAGE(I28:I32) -> 0.42706 | J33: =AVERAGE(J28:J32) -> 0.05108 | K33: =AVERAGE(K28:K32) -> 0.88042206 | O33: =AVERAGE(O28:O32) -> 70.436402 | P33: =AVERAGE(P28:P32) -> -28.923384 | R33: =AVERAGE(R28:R32) -> 589.46087 | S33: =AVERAGE(S28:S32) -> -242.12534 | U33: =AVERAGE(U28:U32) -> 1.9879909 | V33: =AVERAGE(V28:V32) -> -0.81743916 | X33: =AVERAGE(X28:X32) -> 0.029815771
A34: SD | I34: =STDEV(I28:I32) -> 0.033925846 | J34: =STDEV(J28:J32) -> 0.0043757285 | K34: =STDEV(K28:K32) -> 0.0019210203 | O34: =STDEV(O28:O32) -> 4.3678071 | P34: =STDEV(P28:P32) -> 2.1764142 | R34: =STDEV(R28:R32) -> 42.809098 | S34: =STDEV(S28:S32) -> 21.384166 | U34: =STDEV(U28:U32) -> 0.2415624 | V34: =STDEV(V28:V32) -> 0.11443318 | X34: =STDEV(X28:X32) -> 0.002126318
I35: =I33/I15 -> 0.7553771
A39: Simulated | B39: Photosynthesis at 0.79 of default
C40: Aper area | D40: R per area | E40: AperFw | F40: RperFw
B41: Col | C41: 1.1877 | D41: -0.2213 | E41: 57.4541 | F41: -10.7902
B42: lsf1 | C42: 1.1879 | D42: -0.2174 | E42: 61.7416 | F42: -11.399
B43: prr7prr9 | C43: 1.1878 | D43: -0.2182 | E43: 68.6816 | F43: -12.729

Sheet L&H 3
A1: WHOLE-PLANT CHAMBER: | D1: AIR:
A2: Diameter (cm) | B2: 12 | D2: Density | E2: =101325/8.314/(20+273.15) -> 41.57351 | F2: mol m-3
A3: Height (cm) | B3: 3
A4: Pot diameter (cm | B4: 7.7
A5: Depth occupied by pot (cm | B5: 1.5
A6: Volume (cm3) | B6: =PI()*(B2/2)^2*B3-PI()*(B4/2)^2*B5 -> 269.44262
F8: micromol/s | K8: Calculated | O8: micromol/h/g FW | R8: micromol/h/g DW | U8: micromol/h/cm2 | X8: m2/gDW
C9: Slope A | D9: Slope R | F9: A rate | G9: R rate | I9: FW (g) | J9: DW (g) | K9: Water content | L9: Rosette area (mm2) | O9: A rate | P9: R rate | R9: A rate | S9: R rate | U9: A rate | V9: R rate | X9: SLA
A10: Col | B10: #1 | C10: -0.8644 | D10: 0.3813 | F10: =-C10*$E$2*$B$6/10^6 -> 0.0096827283 | G10: =-D10*$E$2*$B$6/10^6 -> -0.0042711989 | I10: 1.3766 | J10: 0.13 | K10: =1-(J10/I10) -> 0.90556443 | L10: 3500.354 | O10: =(F10-$F$33)/I10*3600 -> 28.248142 | P10: =(G10-$F$33)/I10*3600 -> -8.2433135 | R10: =(F10-$F$33)/J10*3600 -> 299.1261 | S10: =(G10-$F$33)/J10*3600 -> -87.290349 | U10: =(F10-$F$33)/L10*10^6*3600/10000 -> 1.1109274 | V10: =(G10-$F$33)/L10*10^6*3600/10000 -> -0.32418851 | X10: =L10/J10/10^6 -> 0.0269258
B11: #2 | C11: -0.8372 | D11: 0.4128 | F11: =-C11*$E$2*$B$6/10^6 -> 0.0093780427 | G11: =-D11*$E$2*$B$6/10^6 -> -0.0046240517 | I11: 1.0903 | J11: 0.0985 | K11: =1-(J11/I11) -> 0.90965789 | L11: 3256.618 | O11: =(F11-$F$33)/I11*3600 -> 34.659749 | P11: =(G11-$F$33)/I11*3600 -> -11.572976 | R11: =(F11-$F$33)/J11*3600 -> 383.64999 | S11: =(G11-$F$33)/J11*3600 -> -128.10168 | U11: =(F11-$F$33)/L11*10^6*3600/10000 -> 1.1603917 | V11: =(G11-$F$33)/L11*10^6*3600/10000 -> -0.38745764 | X11: =L11/J11/10^6 -> 0.033062112
B12: #3 | C12: -0.8911 | D12: 0.3521 | F12: =-C12*$E$2*$B$6/10^6 -> 0.0099818131 | G12: =-D12*$E$2*$B$6/10^6 -> -0.0039441099 | I12: 1.0704 | J12: 0.098 | K12: =1-(J12/I12) -> 0.90844544 | L12: 2727.806 | O12: =(F12-$F$33)/I12*3600 -> 37.334732 | P12: =(G12-$F$33)/I12*3600 -> -9.5013315 | R12: =(F12-$F$33)/J12*3600 -> 407.78671 | S12: =(G12-$F$33)/J12*3600 -> -103.77781 | U12: =(F12-$F$33)/L12*10^6*3600/10000 -> 1.4650271 | V12: =(G12-$F$33)/L12*10^6*3600/10000 -> -0.37283536 | X12: =L12/J12/10^6 -> 0.027834755
B13: #4 | C13: -0.8622 | D13: 0.3445 | F13: =-C13*$E$2*$B$6/10^6 -> 0.0096580846 | G13: =-D13*$E$2*$B$6/10^6 -> -0.0038589772 | I13: 1.0098 | J13: 0.0941 | K13: =1-(J13/I13) -> 0.90681323 | L13: 2914.286 | O13: =(F13-$F$33)/I13*3600 -> 38.421148 | P13: =(G13-$F$33)/I13*3600 -> -9.7680208 | R13: =(F13-$F$33)/J13*3600 -> 412.30261 | S13: =(G13-$F$33)/J13*3600 -> -104.82197 | U13: =(F13-$F$33)/L13*10^6*3600/10000 -> 1.3312926 | V13: =(G13-$F$33)/L13*10^6*3600/10000 -> -0.33846189 | X13: =L13/J13/10^6 -> 0.030970096
B14: #5 | C14: -0.8346 | D14: 0.3942 | F14: =-C14*$E$2*$B$6/10^6 -> 0.0093489184 | G14: =-D14*$E$2*$B$6/10^6 -> -0.0044157005 | I14: 1.0423 | J14: 0.0969 | K14: =1-(J14/I14) -> 0.90703252 | L14: 3019.685 | O14: =(F14-$F$33)/I14*3600 -> 36.155307 | P14: =(G14-$F$33)/I14*3600 -> -11.38631 | R14: =(F14-$F$33)/J14*3600 -> 388.90275 | S14: =(G14-$F$33)/J14*3600 -> -122.47628 | U14: =(F14-$F$33)/L14*10^6*3600/10000 -> 1.2479671 | V14: =(G14-$F$33)/L14*10^6*3600/10000 -> -0.39301951 | X14: =L14/J14/10^6 -> 0.0311629
A15: Average | I15: =AVERAGE(I10:I14) -> 1.11788 | J15: =AVERAGE(J10:J14) -> 0.1035 | K15: =AVERAGE(K10:K14) -> 0.9075027 | O15: =AVERAGE(O10:O14) -> 34.963816 | P15: =AVERAGE(P10:P14) -> -10.09439 | R15: =AVERAGE(R10:R14) -> 378.35363 | S15: =AVERAGE(S10:S14) -> -109.29362 | U15: =AVERAGE(U10:U14) -> 1.2631212 | V15: =AVERAGE(V10:V14) -> -0.36319258 | X15: =AVERAGE(X10:X14) -> 0.029991132
A16: SD | I16: =STDEV(I10:I14) -> 0.14777066 | J16: =STDEV(J10:J14) -> 0.014911573 | K16: =STDEV(K10:K14) -> 0.0015801046 | O16: =STDEV(O10:O14) -> 4.0058324 | P16: =STDEV(P10:P14) -> 1.3910421 | R16: =STDEV(R10:R14) -> 45.921609 | S16: =STDEV(S10:S14) -> 16.294856 | U16: =STDEV(U10:U14) -> 0.1408539 | V16: =STDEV(V10:V14) -> 0.030431674 | X16: =STDEV(X10:X14) -> 0.0025401057
K18: Calculated | O18: micromol/h/g FW | R18: micromol/h/g DW | U18: micromol/h/cm2 | X18: m2/gDW
C19: Slope A | D19: Slope R | F19: A rate | G19: R rate | I19: FW (g) | J19: DW (g) | K19: Water content | L19: Rosette area (mm2) | O19: A rate | P19: R rate | R19: A rate | S19: R rate | U19: A rate | V19: R rate | X19: SLA
A20: prr7/prr9 | B20: #1 | C20: -1.0303 | D20: 0.472 | F20: =-C20*$E$2*$B$6/10^6 -> 0.011541086 | G20: =-D20*$E$2*$B$6/10^6 -> -0.0052871908 | I20: 0.8009 | J20: 0.0889 | K20: =1-(J20/I20) -> 0.88899988 | L20: 3029.776 | O20: =F20/I20*3600 -> 51.876527 | P20: =G20/I20*3600 -> -23.765622 | R20: =F20/J20*3600 -> 467.35557 | S20: =G20/J20*3600 -> -214.10447 | U20: =F20/L20*10^6*3600/10000 -> 1.3713196 | V20: =G20/L20*10^6*3600/10000 -> -0.62822753 | X20: =L20/J20/10^6 -> 0.03408072
B21: #2 | C21: -0.8679 | D21: 0.4892 | F21: =-C21*$E$2*$B$6/10^6 -> 0.0097219342 | G21: =-D21*$E$2*$B$6/10^6 -> -0.0054798597 | I21: 0.8858 | J21: 0.0934 | K21: =1-(J21/I21) -> 0.89455859 | L21: 3330.981 | O21: =F21/I21*3600 -> 39.511135 | P21: =G21/I21*3600 -> -22.270823 | R21: =F21/J21*3600 -> 374.72123 | S21: =G21/J21*3600 -> -211.21515 | U21: =F21/L21*10^6*3600/10000 -> 1.0507104 | V21: =G21/L21*10^6*3600/10000 -> -0.59224279 | X21: =L21/J21/10^6 -> 0.035663608
B22: #3 | C22: -0.9044 | D22: 0.4931 | F22: =-C22*$E$2*$B$6/10^6 -> 0.010130795 | G22: =-D22*$E$2*$B$6/10^6 -> -0.0055235462 | I22: 0.7946 | J22: 0.0874 | K22: =1-(J22/I22) -> 0.89000755 | L22: 2843.353 | O22: =F22/I22*3600 -> 45.898393 | P22: =G22/I22*3600 -> -25.024876 | R22: =F22/J22*3600 -> 417.28676 | S22: =G22/J22*3600 -> -227.51449 | U22: =F22/L22*10^6*3600/10000 -> 1.282671 | V22: =G22/L22*10^6*3600/10000 -> -0.69934216 | X22: =L22/J22/10^6 -> 0.032532643
B23: #4 | C23: -0.8467 | D23: 0.4539 | F23: =-C23*$E$2*$B$6/10^6 -> 0.0094844587 | G23: =-D23*$E$2*$B$6/10^6 -> -0.0050844405 | I23: 0.806 | J23: 0.0896 | K23: =1-(J23/I23) -> 0.88883375 | L23: 3278.557 | O23: =F23/I23*3600 -> 42.362346 | P23: =G23/I23*3600 -> -22.70966 | R23: =F23/J23*3600 -> 381.072 | S23: =G23/J23*3600 -> -204.28556 | U23: =F23/L23*10^6*3600/10000 -> 1.0414353 | V23: =G23/L23*10^6*3600/10000 -> -0.55829396 | X23: =L23/J23/10^6 -> 0.036591038
B24: #5 | C24: -0.8879 | D24: 0.3502 | F24: =-C24*$E$2*$B$6/10^6 -> 0.0099459677 | G24: =-D24*$E$2*$B$6/10^6 -> -0.0039228268 | I24: 0.7107 | J24: 0.0807 | K24: =1-(J24/I24) -> 0.88644998 | L24: 2934.736 | O24: =F24/I24*3600 -> 50.380588 | P24: =G24/I24*3600 -> -19.870798 | R24: =F24/J24*3600 -> 443.68629 | S24: =G24/J24*3600 -> -174.99599 | U24: =F24/L24*10^6*3600/10000 -> 1.2200581 | V24: =G24/L24*10^6*3600/10000 -> -0.48120773 | X24: =L24/J24/10^6 -> 0.036365998
A25: Average | I25: =AVERAGE(I20:I24) -> 0.7996 | J25: =AVERAGE(J20:J24) -> 0.088 | K25: =AVERAGE(K20:K24) -> 0.88976995 | O25: =AVERAGE(O20:O24) -> 46.005798 | P25: =AVERAGE(P20:P24) -> -22.728356 | R25: =AVERAGE(R20:R24) -> 416.82437 | S25: =AVERAGE(S20:S24) -> -206.42313 | U25: =AVERAGE(U20:U24) -> 1.1932389 | V25: =AVERAGE(V20:V24) -> -0.59186283 | X25: =AVERAGE(X20:X24) -> 0.035046801
A26: SD | I26: =STDEV(I20:I24) -> 0.062050987 | J26: =STDEV(J20:J24) -> 0.0046416592 | K26: =STDEV(K20:K24) -> 0.0029782225 | O26: =STDEV(O20:O24) -> 5.2218573 | P26: =STDEV(P20:P24) -> 1.9186745 | R26: =STDEV(R20:R24) -> 39.768346 | S26: =STDEV(S20:S24) -> 19.487471 | U26: =STDEV(U20:U24) -> 0.14473146 | V26: =STDEV(V20:V24) -> 0.081002721 | X26: =STDEV(X20:X24) -> 0.001714621
C29: Slope A | D29: Slope R | F29: A rate | G29: R rate
A30: Soil | B30: #1 | C30: 0.0999 | D30: 0.1128 | F30: =-C30*$E$2*$B$6/10^6 -> -0.0011190474 | G30: =-D30*$E$2*$B$6/10^6 -> -0.001263549
B33: Average | C33: =AVERAGE(C30:C32) -> 0.0999 | D33: =AVERAGE(D30:D32) -> 0.1128 | F33: =AVERAGE(F30:F32) -> -0.0011190474 | G33: =AVERAGE(G30:G32) -> -0.001263549
C36: Simulated | D36: Photosynthesis at 0.88 of default
E37: Aper area | F37: R per area | G37: AperFw | H37: RperFw
D38: Col | E38: 1.4772 | F38: -0.2594 | G38: 49.5868 | H38: -8.8192
D39: prr7prr9 | E39: 1.4772 | F39: -0.2561 | G39: 59.0476 | H39: -10.365

Sheet no GA controls
F8: micromol/s | K8: Calculated | O8: micromol/h/g FW | R8: micromol/h/g DW | U8: micromol/h/cm2 | X8: m2/gDW
C9: Slope A | D9: Slope R | F9: A rate | G9: R rate | I9: FW (g) | J9: DW (g) | K9: Water content | L9: Rosette area (mm2) | O9: A rate | P9: R rate | R9: A rate | S9: R rate | U9: A rate | V9: R rate | X9: SLA
A10: Col | B10: #1 | F10: =-C10*$E$2*$B$6/10^6 -> 0 | G10: =-D10*$E$2*$B$6/10^6 -> 0 | I10: ='[1]Col control no GA'!F6 -> 0.8533 | J10: ='[1]Col control no GA'!G6 -> 0.0738 | K10: =1-(J10/I10) -> 0.91351225 | O10: =(F10-$F$33)/I10*3600 -> 0 | P10: =(G10-$F$33)/I10*3600 -> 0 | R10: =(F10-$F$33)/J10*3600 -> 0 | S10: =(G10-$F$33)/J10*3600 -> 0 | U10: =(F10-$F$33)/L10*10^6*3600/10000 -> #DIV/0! | V10: =(G10-$F$33)/L10*10^6*3600/10000 -> #DIV/0! | X10: =L10/J10/10^6 -> 0
B11: #2 | F11: =-C11*$E$2*$B$6/10^6 -> 0 | G11: =-D11*$E$2*$B$6/10^6 -> 0 | I11: ='[1]Col control no GA'!F7 -> 0.882 | J11: ='[1]Col control no GA'!G7 -> 0.0777 | K11: =1-(J11/I11) -> 0.91190476 | O11: =(F11-$F$33)/I11*3600 -> 0 | P11: =(G11-$F$33)/I11*3600 -> 0 | R11: =(F11-$F$33)/J11*3600 -> 0 | S11: =(G11-$F$33)/J11*3600 -> 0 | U11: =(F11-$F$33)/L11*10^6*3600/10000 -> #DIV/0! | V11: =(G11-$F$33)/L11*10^6*3600/10000 -> #DIV/0! | X11: =L11/J11/10^6 -> 0
B12: #3 | F12: =-C12*$E$2*$B$6/10^6 -> 0 | G12: =-D12*$E$2*$B$6/10^6 -> 0 | I12: ='[1]Col control no GA'!F8 -> 0.8371 | J12: ='[1]Col control no GA'!G8 -> 0.0712 | K12: =1-(J12/I12) -> 0.91494445 | O12: =(F12-$F$33)/I12*3600 -> 0 | P12: =(G12-$F$33)/I12*3600 -> 0 | R12: =(F12-$F$33)/J12*3600 -> 0 | S12: =(G12-$F$33)/J12*3600 -> 0 | U12: =(F12-$F$33)/L12*10^6*3600/10000 -> #DIV/0! | V12: =(G12-$F$33)/L12*10^6*3600/10000 -> #DIV/0! | X12: =L12/J12/10^6 -> 0
B13: #4 | F13: =-C13*$E$2*$B$6/10^6 -> 0 | G13: =-D13*$E$2*$B$6/10^6 -> 0 | I13: ='[1]Col control no GA'!F9 -> 1.09 | J13: ='[1]Col control no GA'!G9 -> 0.0952 | K13: =1-(J13/I13) -> 0.91266055 | O13: =(F13-$F$33)/I13*3600 -> 0 | P13: =(G13-$F$33)/I13*3600 -> 0 | R13: =(F13-$F$33)/J13*3600 -> 0 | S13: =(G13-$F$33)/J13*3600 -> 0 | U13: =(F13-$F$33)/L13*10^6*3600/10000 -> #DIV/0! | V13: =(G13-$F$33)/L13*10^6*3600/10000 -> #DIV/0! | X13: =L13/J13/10^6 -> 0
B14: #5 | F14: =-C14*$E$2*$B$6/10^6 -> 0 | G14: =-D14*$E$2*$B$6/10^6 -> 0 | I14: ='[1]Col control no GA'!F10 -> 0.9434 | J14: ='[1]Col control no GA'!G10 -> 0.0805 | K14: =1-(J14/I14) -> 0.91467034 | O14: =(F14-$F$33)/I14*3600 -> 0 | P14: =(G14-$F$33)/I14*3600 -> 0 | R14: =(F14-$F$33)/J14*3600 -> 0 | S14: =(G14-$F$33)/J14*3600 -> 0 | U14: =(F14-$F$33)/L14*10^6*3600/10000 -> #DIV/0! | V14: =(G14-$F$33)/L14*10^6*3600/10000 -> #DIV/0! | X14: =L14/J14/10^6 -> 0
A15: Average | I15: =AVERAGE(I10:I14) -> 0.92116 | J15: =AVERAGE(J10:J14) -> 0.07968 | K15: =AVERAGE(K10:K14) -> 0.91353847 | O15: =AVERAGE(O10:O14) -> 0 | P15: =AVERAGE(P10:P14) -> 0 | R15: =AVERAGE(R10:R14) -> 0 | S15: =AVERAGE(S10:S14) -> 0 | U15: =AVERAGE(U10:U14) -> #DIV/0! | V15: =AVERAGE(V10:V14) -> #DIV/0! | X15: =AVERAGE(X10:X14) -> 0
A16: SD | I16: =STDEV(I10:I14) -> 0.10272066 | J16: =STDEV(J10:J14) -> 0.0093801386 | K16: =STDEV(K10:K14) -> 0.0012940583 | O16: =STDEV(O10:O14) -> 0 | P16: =STDEV(P10:P14) -> 0 | R16: =STDEV(R10:R14) -> 0 | S16: =STDEV(S10:S14) -> 0 | U16: =STDEV(U10:U14) -> #DIV/0! | V16: =STDEV(V10:V14) -> #DIV/0! | X16: =STDEV(X10:X14) -> 0
K18: Calculated | O18: micromol/h/g FW | R18: micromol/h/g DW | U18: micromol/h/cm2 | X18: m2/gDW
C19: Slope A | D19: Slope R | F19: A rate | G19: R rate | I19: FW (g) | J19: DW (g) | K19: Water content | L19: Rosette area (mm2) | O19: A rate | P19: R rate | R19: A rate | S19: R rate | U19: A rate | V19: R rate | X19: SLA
A20: prr7/prr9 | B20: #1 | F20: =-C20*$E$2*$B$6/10^6 -> 0 | G20: =-D20*$E$2*$B$6/10^6 -> 0 | I20: ='[1]prr7prr9 control no GA'!F6 -> 0.4988 | J20: ='[1]prr7prr9 control no GA'!G6 -> 0.0511 | K20: =1-(J20/I20) -> 0.89755413 | O20: =F20/I20*3600 -> 0 | P20: =G20/I20*3600 -> 0 | R20: =F20/J20*3600 -> 0 | S20: =G20/J20*3600 -> 0 | U20: =F20/L20*10^6*3600/10000 -> #DIV/0! | V20: =G20/L20*10^6*3600/10000 -> #DIV/0! | X20: =L20/J20/10^6 -> 0
B21: #2 | F21: =-C21*$E$2*$B$6/10^6 -> 0 | G21: =-D21*$E$2*$B$6/10^6 -> 0 | I21: ='[1]prr7prr9 control no GA'!F7 -> 0.4938 | J21: ='[1]prr7prr9 control no GA'!G7 -> 0.0558 | K21: =1-(J21/I21) -> 0.88699878 | O21: =F21/I21*3600 -> 0 | P21: =G21/I21*3600 -> 0 | R21: =F21/J21*3600 -> 0 | S21: =G21/J21*3600 -> 0 | U21: =F21/L21*10^6*3600/10000 -> #DIV/0! | V21: =G21/L21*10^6*3600/10000 -> #DIV/0! | X21: =L21/J21/10^6 -> 0
B22: #3 | F22: =-C22*$E$2*$B$6/10^6 -> 0 | G22: =-D22*$E$2*$B$6/10^6 -> 0 | I22: ='[1]prr7prr9 control no GA'!F8 -> 0.4469 | J22: ='[1]prr7prr9 control no GA'!G8 -> 0.0465 | K22: =1-(J22/I22) -> 0.89594988 | O22: =F22/I22*3600 -> 0 | P22: =G22/I22*3600 -> 0 | R22: =F22/J22*3600 -> 0 | S22: =G22/J22*3600 -> 0 | U22: =F22/L22*10^6*3600/10000 -> #DIV/0! | V22: =G22/L22*10^6*3600/10000 -> #DIV/0! | X22: =L22/J22/10^6 -> 0
B23: #4 | F23: =-C23*$E$2*$B$6/10^6 -> 0 | G23: =-D23*$E$2*$B$6/10^6 -> 0 | I23: ='[1]prr7prr9 control no GA'!F9 -> 0.4597 | J23: ='[1]prr7prr9 control no GA'!G9 -> 0.0483 | K23: =1-(J23/I23) -> 0.89493148 | O23: =F23/I23*3600 -> 0 | P23: =G23/I23*3600 -> 0 | R23: =F23/J23*3600 -> 0 | S23: =G23/J23*3600 -> 0 | U23: =F23/L23*10^6*3600/10000 -> #DIV/0! | V23: =G23/L23*10^6*3600/10000 -> #DIV/0! | X23: =L23/J23/10^6 -> 0
B24: #5 | F24: =-C24*$E$2*$B$6/10^6 -> 0 | G24: =-D24*$E$2*$B$6/10^6 -> 0 | I24: ='[1]prr7prr9 control no GA'!F10 -> 0.5225 | J24: ='[1]prr7prr9 control no GA'!G10 -> 0.0538 | K24: =1-(J24/I24) -> 0.89703349 | O24: =F24/I24*3600 -> 0 | P24: =G24/I24*3600 -> 0 | R24: =F24/J24*3600 -> 0 | S24: =G24/J24*3600 -> 0 | U24: =F24/L24*10^6*3600/10000 -> #DIV/0! | V24: =G24/L24*10^6*3600/10000 -> #DIV/0! | X24: =L24/J24/10^6 -> 0
A25: Average | I25: =AVERAGE(I20:I24) -> 0.48434 | J25: =AVERAGE(J20:J24) -> 0.0511 | K25: =AVERAGE(K20:K24) -> 0.89449355 | O25: =AVERAGE(O20:O24) -> 0 | P25: =AVERAGE(P20:P24) -> 0 | R25: =AVERAGE(R20:R24) -> 0 | S25: =AVERAGE(S20:S24) -> 0 | U25: =AVERAGE(U20:U24) -> #DIV/0! | V25: =AVERAGE(V20:V24) -> #DIV/0! | X25: =AVERAGE(X20:X24) -> 0
A26: SD | I26: =STDEV(I20:I24) -> 0.030674305 | J26: =STDEV(J20:J24) -> 0.0038203403 | K26: =STDEV(K20:K24) -> 0.0043099487 | O26: =STDEV(O20:O24) -> 0 | P26: =STDEV(P20:P24) -> 0 | R26: =STDEV(R20:R24) -> 0 | S26: =STDEV(S20:S24) -> 0 | U26: =STDEV(U20:U24) -> #DIV/0! | V26: =STDEV(V20:V24) -> #DIV/0! | X26: =STDEV(X20:X24) -> 0
C29: Slope A | D29: Slope R | F29: A rate | G29: R rate
A30: Soil | B30: #1 | C30: 0.0999 | D30: 0.1128 | F30: =-C30*$E$2*$B$6/10^6 -> 0 | G30: =-D30*$E$2*$B$6/10^6 -> 0
B33: Average | C33: =AVERAGE(C30:C32) -> 0.0999 | D33: =AVERAGE(D30:D32) -> 0.1128 | F33: =AVERAGE(F30:F32) -> 0 | G33: =AVERAGE(G30:G32) -> 0
C36: Simulated | D36: Photosynthesis at 0.88 of default
E37: Aper area | F37: R per area | G37: AperFw | H37: RperFw
D38: Col | E38: 1.4772 | F38: -0.2594 | G38: 49.5868 | H38: -8.8192
D39: prr7prr9 | E39: 1.4772 | F39: -0.2561 | G39: 59.0476 | H39: -10.365

Sheet biomass Anova
A1: FW | C1: Genotype | D1: Col | E1: prr7/prr9
C2: Exp't1 38d | D2: {='L&H 1'!I9:I13} -> 0.8044 | E2: {='L&H 1'!I26:I30} -> 0.5754
C3: Exp't1 38d | D3: 0.8362 | E3: 0.6435
C4: Exp't1 38d | D4: 1.0092 | E4: 0.538
C5: Exp't1 38d | D5: 1.1627 | E5: 0.493
C6: Exp't1 38d | D6: 0.9382 | E6: 0.6216
C7: Exp't3 38d | D7: ='L&H 3'!I10 -> 1.3766 | E7: ='L&H 3'!I20 -> 0.8009
C8: Exp't3 38d | D8: ='L&H 3'!I11 -> 1.0903 | E8: ='L&H 3'!I21 -> 0.8858
C9: Exp't3 38d | D9: ='L&H 3'!I12 -> 1.0704 | E9: ='L&H 3'!I22 -> 0.7946
C10: Exp't3 38d | D10: ='L&H 3'!I13 -> 1.0098 | E10: ='L&H 3'!I23 -> 0.806
C11: Exp't3 38d | D11: ='L&H 3'!I14 -> 1.0423 | E11: ='L&H 3'!I24 -> 0.7107
C12: no GA 35d | D12: ='no GA controls'!I10 -> 0.8533 | E12: ='no GA controls'!I20 -> 0.4988
C13: no GA 35d | D13: ='no GA controls'!I11 -> 0.882 | E13: ='no GA controls'!I21 -> 0.4938
C14: no GA 35d | D14: ='no GA controls'!I12 -> 0.8371 | E14: ='no GA controls'!I22 -> 0.4469
C15: no GA 35d | D15: ='no GA controls'!I13 -> 1.09 | E15: ='no GA controls'!I23 -> 0.4597
C16: no GA 35d | D16: ='no GA controls'!I14 -> 0.9434 | E16: ='no GA controls'!I24 -> 0.5225
C17: Exp't2 39d | D17: ='L&H 2'!I10 -> 0.7057 | E17: ='L&H 2'!I28 -> 0.4178
C18: Exp't2 39d | D18: ='L&H 2'!I11 -> 0.5231 | E18: ='L&H 2'!I29 -> 0.3822
C19: Exp't2 39d | D19: ='L&H 2'!I12 -> 0.5608 | E19: ='L&H 2'!I30 -> 0.4525
C20: Exp't2 39d | D20: ='L&H 2'!I13 -> 0.534 | E20: ='L&H 2'!I31 -> 0.4683
C21: Exp't2 39d | D21: ='L&H 2'!I14 -> 0.5032 | E21: ='L&H 2'!I32 -> 0.4145
L26: Genotype | M26: LH1 | N26: LH2 | O26: LH3
L27: Col | M27: 0.8044 | N27: 0.7057 | O27: 1.3766
C28: Anova: Two-Factor With Replication | L28: Col | M28: 0.8362 | N28: 0.5231 | O28: 1.0903
L29: Col | M29: 1.0092 | N29: 0.5608 | O29: 1.0704
C30: SUMMARY | D30: Col | E30: prr79 | F30: Total | L30: Col | M30: 1.1627 | N30: 0.534 | O30: 1.0098
C31: expt 1 | L31: Col | M31: 0.9382 | N31: 0.5032 | O31: 1.0423
C32: Count | D32: 5 | E32: 5 | F32: 10 | L32: prr79 | M32: 0.5754 | N32: 0.4178 | O32: 0.8009
C33: Sum | D33: 4.7507 | E33: 2.8715 | F33: 7.6222 | L33: prr79 | M33: 0.6435 | N33: 0.3822 | O33: 0.8858
C34: Average | D34: 0.95014 | E34: 0.5743 | F34: 0.76222 | L34: prr79 | M34: 0.538 | N34: 0.4525 | O34: 0.7946
C35: Variance | D35: 0.020758718 | E35: 0.00373863 | F35: 0.050125406 | L35: prr79 | M35: 0.493 | N35: 0.4683 | O35: 0.806
L36: prr79 | M36: 0.6216 | N36: 0.4145 | O36: 0.7107
C37: expt 2
C38: Count | D38: 5 | E38: 5 | F38: 10
C39: Sum | D39: 2.8268 | E39: 2.1353 | F39: 4.9621
C40: Average | D40: 0.56536 | E40: 0.42706 | F40: 0.49621
C41: Variance | D41: 0.006587333 | E41: 0.001150963 | F41: 0.0087522677
C43: expt 3
C44: Count | D44: 5 | E44: 5 | F44: 10
C45: Sum | D45: 5.5894 | E45: 3.998 | F45: 9.5874
...

Sheet Water content Anova
A1: Water contents
A2: LH1 water contents were measured at day 21, 28 and 29 but not 38, so an average water content was used to convert FW data to DW at day 38
C6: Genotype | D6: Col | E6: prr7prr9
C7: Exp't3 38d | D7: ='L&H 3'!K10 -> 0.90556443 | E7: ='L&H 3'!K20 -> 0.88899988
C8: Exp't3 38d | D8: ='L&H 3'!K11 -> 0.90965789 | E8: ='L&H 3'!K21 -> 0.89455859
C9: Exp't3 38d | D9: ='L&H 3'!K12 -> 0.90844544 | E9: ='L&H 3'!K22 -> 0.89000755
C10: Exp't3 38d | D10: ='L&H 3'!K13 -> 0.90681323 | E10: ='L&H 3'!K23 -> 0.88883375
C11: Exp't3 38d | D11: ='L&H 3'!K14 -> 0.90703252 | E11: ='L&H 3'!K24 -> 0.88644998
C12: no GA 35d | D12: ='no GA controls'!K10 -> 0.91351225 | E12: ='no GA controls'!K20 -> 0.89755413
C13: no GA 35d | D13: ='no GA controls'!K11 -> 0.91190476 | E13: ='no GA controls'!K21 -> 0.88699878
C14: no GA 35d | D14: ='no GA controls'!K12 -> 0.91494445 | E14: ='no GA controls'!K22 -> 0.89594988
C15: no GA 35d | D15: ='no GA controls'!K13 -> 0.91266055 | E15: ='no GA controls'!K23 -> 0.89493148
C16: no GA 35d | D16: ='no GA controls'!K14 -> 0.91467034 | E16: ='no GA controls'!K24 -> 0.89703349
C17: GA | D17: =0.01*'[1]Col GA'!H6 -> 0.91785115 | E17: =0.01*'[1]prr7prr9 GA'!H6 -> 0.90239358
C18: GA | D18: =0.01*'[1]Col GA'!H7 -> 0.91819642 | E18: =0.01*'[1]prr7prr9 GA'!H7 -> 0.9008644
C19: GA | D19: =0.01*'[1]Col GA'!H8 -> 0.91130866 | E19: =0.01*'[1]prr7prr9 GA'!H8 -> 0.91298452
C20: GA | D20: =0.01*'[1]Col GA'!H9 -> 0.91984315 | E20: =0.01*'[1]prr7prr9 GA'!H9 -> 0.90527489
C21: GA | D21: =0.01*'[1]Col GA'!H10 -> 0.9191056 | E21: =0.01*'[1]prr7prr9 GA'!H10 -> 0.90419501
C22: Exp't2 39d | D22: ='L&H 2'!K10 -> 0.9047754 | E22: ='L&H 2'!K28 -> 0.88128291
C23: Exp't2 39d | D23: ='L&H 2'!K11 -> 0.90021028 | E23: ='L&H 2'!K29 -> 0.88016745
C24: Exp't2 39d | D24: ='L&H 2'!K12 -> 0.89925107 | E24: ='L&H 2'!K30 -> 0.88265193
C25: Exp't2 39d | D25: ='L&H 2'!K13 -> 0.89681648 | E25: ='L&H 2'!K31 -> 0.877429
C26: Exp't2 39d | D26: ='L&H 2'!K14 -> 0.89864865 | E26: ='L&H 2'!K32 -> 0.88057901
C28: Anova: Two-Factor With Replication
C30: SUMMARY | D30: Col | E30: prr79 | F30: Total
C31: 2
C32: Count | D32: 5 | E32: 5 | F32: 10
C33: Sum | D33: 4.4997019 | E33: 4.4021103 | F33: 8.9018122
C34: Average | D34: 0.89994038 | E34: 0.88042206 | F34: 0.89018122
C35: Variance | D35: 8.8381858e-06 | E35: 3.6903191e-06 | F35: 0.00011139174
C37: 3
C38: Count | D38: 5 | E38: 5 | F38: 10
C39: Sum | D39: 4.5375135 | E39: 4.4488497 | F39: 8.9863633
C40: Average | D40: 0.9075027 | E40: 0.88976995 | F40: 0.89863633
C41: Variance | D41: 2.4967307e-06 | E41: 8.8698094e-06 | F41: 9.2399192e-05
C43: Total
C44: Count | D44: 10 | E44: 10
C45: Sum | D45: 9.0372154 | E45: 8.85096
C46: Average | D46: 0.90372154 | E46: 0.885096
C47: Variance | D47: 2.0923519e-05 | E47: 2.9855335e-05
...

Sheet SLA Anova
A1: Water contents | C1: Genotype | D1: Col | E1: prr7prr9
C2: Exp't1 38d | D2: {='L&H 1'!X9:X13} -> 0.03906883 | E2: {='L&H 1'!X26:X30} -> 0.039440279
C3: Exp't1 38d | D3: 0.034935289 | E3: 0.037471258
C4: Exp't1 38d | D4: 0.033600266 | E4: 0.039004748
C5: Exp't1 38d | D5: 0.033313418 | E5: 0.041877577
C6: Exp't1 38d | D6: 0.035067541 | E6: 0.039737788
C7: Exp't3 38d | D7: ='L&H 3'!X10 -> 0.0269258 | E7: ='L&H 3'!X20 -> 0.03408072
C8: Exp't3 38d | D8: ='L&H 3'!X11 -> 0.033062112 | E8: ='L&H 3'!X21 -> 0.035663608
C9: Exp't3 38d | D9: ='L&H 3'!X12 -> 0.027834755 | E9: ='L&H 3'!X22 -> 0.032532643
C10: Exp't3 38d | D10: ='L&H 3'!X13 -> 0.030970096 | E10: ='L&H 3'!X23 -> 0.036591038
C11: Exp't3 38d | D11: ='L&H 3'!X14 -> 0.0311629 | E11: ='L&H 3'!X24 -> 0.036365998
C12: Exp't2 39d | D12: ='L&H 2'!X10 -> 0.028063527 | E12: ='L&H 2'!X28 -> 0.030146109
C13: Exp't2 39d | D13: ='L&H 2'!X11 -> 0.031856303 | E13: ='L&H 2'!X29 -> 0.031861572
C14: Exp't2 39d | D14: ='L&H 2'!X12 -> 0.025491221 | E14: ='L&H 2'!X30 -> 0.026231243
C15: Exp't2 39d | D15: ='L&H 2'!X13 -> 0.027782196 | E15: ='L&H 2'!X31 -> 0.030094739
C16: Exp't2 39d | D16: ='L&H 2'!X14 -> 0.030713863 | E16: ='L&H 2'!X32 -> 0.030745192
C19: Anova: Two-Factor With Replication
C21: SUMMARY | D21: Col | E21: prr79 | F21: Total
C22: expt 1
C23: Count | D23: 5 | E23: 5 | F23: 10
C24: Sum | D24: 0.17598534 | E24: 0.19753165 | F24: 0.37351699
C25: Average | D25: 0.035197069 | E25: 0.03950633 | F25: 0.037351699
C26: Variance | D26: 5.2934393e-06 | E26: 2.5184625e-06 | F26: 8.6302152e-06
C28: expt 2
C29: Count | D29: 5 | E29: 5 | F29: 10
C30: Sum | D30: 0.14390711 | E30: 0.14907885 | F30: 0.29298596
C31: Average | D31: 0.028781422 | E31: 0.029815771 | F31: 0.029298596
C32: Variance | D32: 6.3821164e-06 | E32: 4.5212282e-06 | F32: 5.1431192e-06
C34: expt 3
C35: Count | D35: 5 | E35: 5 | F35: 10
C36: Sum | D36: 0.14995566 | E36: 0.17523401 | F36: 0.32518967
C37: Average | D37: 0.029991132 | E37: 0.035046801 | F37: 0.032518967
C38: Variance | D38: 6.4521369e-06 | E38: 2.9399253e-06 | F38: 1.1274191e-05
C40: Total
C41: Count | D41: 15 | E41: 15
C42: Sum | D42: 0.46984812 | E42: 0.52184451
C43: Average | D43: 0.031323208 | E43: 0.034789634
C44: Variance | D44: 1.3480019e-05 | E44: 1.9655844e-05
C47: ANOVA
C48: Source of Variation | D48: SS | E48: df | F48: MS | G48: F | H48: P-value | I48: F crit
...
