Workbook

Sheet Read.Me
A1: Carbon assimilation and partitioning, measured using 14CO2
A2: Genotypes Col, prr7prr9; Ws, lhycca1
A3: Labelling in darkness to test C fixation by PEPC without photosynthesis
A4: Labelling protocol | B4: From 'Methods' - PEPC activity and incorporation of labelled 14CO2 into metabolite pools was measured as previously described for whole-plant labelling (Kölling et al. 2013, Kölling et al. 2015) with minor modifications. Near the end of the night (ZT20-21), 28-day-old plants were transferred to a custom built, sealed chamber in the dark. Each replicate consisted of the aerial parts of a single plant. Labelling was initiated through the release of 14CO2 (150 μCi) from NaH14CO3 with the addition of lactic acid. After 1 h, the plants were harvested into 5 ml 80% (v/v) ethanol and incubated for 15 min at 80°C. Following homogenisation, the soluble fraction was collected by centrifugation (2,400g, 12 min), pooled with four sequential 1-ml washes (50% ethanol, 20% ethanol, water, and then 80% ethanol) of the insoluble fraction pellet. The soluble fraction was concentrated under vacuum. A water-soluble sub-fraction was collected by dissolving the near-dry exsiccate in 2 ml water, while the remainder was dissolved in 2 ml 98% ethanol. Basic, acidic, and neutral fractions were separated from the water-soluble fraction by ion-exchange chromatography as described (Quick et al. 1989). Partitioning into protein was measured as described (Kölling et al. 2013). Isotope incorporation into each fraction was measured by liquid scintillation counting.
A6: Sheets in this workbook | B6: Contents
A7: Final Data | B7: mean data, SD and charts
A8: Labelling | B8: Summary of experiment, replicates and timing (ZT)
A9: Harvest Mass | B9: Data on mass of harvested tissue, per replicate
A10: 18 days | B10: Partitioning of 14C label in plants at 18 days - use these data for comparison of lhycca1 to its parent Ws
A11: 28 days | B11: Partitioning of 14C label in plants at 28 days - note the lhycca1 genotype had started flowering at this timepoint
A13: Credits
A14: Experimental design and analysis | B14: Gavin George, Sam Zeeman group at ETH Zurich
A15: Curation | B15: Andrew Millar

Sheet Final Data
B3: 18 Days
C4: ='18 Days'!AL8 -> EtOH | H4: ='18 Days'!AP8 -> Water | L4: ='18 Days'!AS8 -> Neutral | P4: ='18 Days'!AV8 -> Acid | T4: ='18 Days'!AY8 -> Basic | Y4: ='18 Days'!BC8 -> Insol | AC4: ='18 Days'!BF8 -> Starch | AG4: ='18 Days'!BI8 -> Protein | AK4: ='18 Days'!BL8 -> Cell wall | AP4: ='18 Days'!BO8 -> Assimilation
B5: ='18 Days'!AK9 -> Col-0 | C5: ='18 Days'!AL9 -> 0.4478364 | D5: ='18 Days'!AM9 -> ± | E5: ='18 Days'!AN9 -> 0.045435424 | H5: ='18 Days'!AP9 -> 86.592588 | I5: ='18 Days'!AQ9 -> ± | J5: ='18 Days'!AR9 -> 0.80320732 | L5: ='18 Days'!AS9 -> 0.087715704 | M5: ='18 Days'!AT9 -> ± | N5: ='18 Days'!AU9 -> 0.070486028 | P5: ='18 Days'!AV9 -> 40.529264 | Q5: ='18 Days'!AW9 -> ± | R5: ='18 Days'!AX9 -> 2.5262082 | T5: ='18 Days'!AY9 -> 43.741257 | U5: ='18 Days'!AZ9 -> ± | V5: ='18 Days'!BA9 -> 3.5226743 | Y5: ='18 Days'!BC9 -> 12.959575 | Z5: ='18 Days'!BD9 -> ± | AA5: ='18 Days'!BE9 -> 0.83690998 | AC5: ='18 Days'!BF9 -> 0.9177179 | AD5: ='18 Days'!BG9 -> ± | AE5: ='18 Days'!BH9 -> 0.79787156 | AG5: ='18 Days'!BI9 -> 8.7850558 | AH5: ='18 Days'!BJ9 -> ± | AI5: ='18 Days'!BK9 -> 0.76127896 | AK5: ='18 Days'!BL9 -> 3.2568018 | AL5: ='18 Days'!BM9 -> ± | AM5: ='18 Days'!BN9 -> 0.42111814 | AP5: ='18 Days'!BO9 -> 377.7538 | AQ5: ='18 Days'!BP9 -> ± | AR5: ='18 Days'!BQ9 -> 26.558532
B6: ='18 Days'!AK12 -> prr7/9 | C6: ='18 Days'!AL12 -> 0.78863518 | D6: ='18 Days'!AM12 -> ± | E6: ='18 Days'!AN12 -> 0.40244169 | H6: ='18 Days'!AP12 -> 82.504301 | I6: ='18 Days'!AQ12 -> ± | J6: ='18 Days'!AR12 -> 0.87545541 | K6: * | L6: ='18 Days'!AS12 -> 0.19421013 | M6: ='18 Days'!AT12 -> ± | N6: ='18 Days'!AU12 -> 0.13739603 | P6: ='18 Days'!AV12 -> 44.000252 | Q6: ='18 Days'!AW12 -> ± | R6: ='18 Days'!AX12 -> 0.55845764 | T6: ='18 Days'!AY12 -> 34.6561 | U6: ='18 Days'!AZ12 -> ± | V6: ='18 Days'!BA12 -> 1.458755 | W6: * | Y6: ='18 Days'!BC12 -> 16.707064 | Z6: ='18 Days'!BD12 -> ± | AA6: ='18 Days'!BE12 -> 1.2604143 | AB6: * | AC6: ='18 Days'!BF12 -> 0.034317759 | AD6: ='18 Days'!BG12 -> ± | AE6: ='18 Days'!BH12 -> 0.16179621 | AG6: ='18 Days'!BI12 -> 13.719813 | AH6: ='18 Days'!BJ12 -> ± | AI6: ='18 Days'!BK12 -> 1.0717338 | AJ6: * | AK6: ='18 Days'!BL12 -> 2.9529327 | AL6: ='18 Days'!BM12 -> ± | AM6: ='18 Days'!BN12 -> 0.42253707 | AP6: ='18 Days'!BO12 -> 275.65631 | AQ6: ='18 Days'!BP12 -> ± | AR6: ='18 Days'!BQ12 -> 41.816082 | AS6: *
B7: WS | C7: ='18 Days'!AL10 -> 0.44192274 | D7: ='18 Days'!AM10 -> ± | E7: ='18 Days'!AN10 -> 0.032915445 | H7: ='18 Days'!AP10 -> 85.871993 | I7: ='18 Days'!AQ10 -> ± | J7: ='18 Days'!AR10 -> 1.9861423 | L7: ='18 Days'!AS10 -> -0.046192117 | M7: ='18 Days'!AT10 -> ± | N7: ='18 Days'!AU10 -> 0.10293146 | P7: ='18 Days'!AV10 -> 42.887825 | Q7: ='18 Days'!AW10 -> ± | R7: ='18 Days'!AX10 -> 2.1683164 | T7: ='18 Days'!AY10 -> 43.974767 | U7: ='18 Days'!AZ10 -> ± | V7: ='18 Days'!BA10 -> 2.5660557 | Y7: ='18 Days'!BC10 -> 13.686084 | Z7: ='18 Days'!BD10 -> ± | AA7: ='18 Days'!BE10 -> 1.9692422 | AC7: ='18 Days'!BF10 -> 0.19874923 | AD7: ='18 Days'!BG10 -> ± | AE7: ='18 Days'!BH10 -> 0.14054263 | AG7: ='18 Days'!BI10 -> 10.64893 | AH7: ='18 Days'!BJ10 -> ± | AI7: ='18 Days'!BK10 -> 1.2610418 | AK7: ='18 Days'!BL10 -> 2.838405 | AL7: ='18 Days'!BM10 -> ± | AM7: ='18 Days'!BN10 -> 0.72504896 | AP7: ='18 Days'!BO10 -> 385.29836 | AQ7: ='18 Days'!BP10 -> ± | AR7: ='18 Days'!BQ10 -> 11.119471
B8: ='18 Days'!AK11 -> lhy/cca1 | C8: ='18 Days'!AL11 -> 0.38839844 | D8: ='18 Days'!AM11 -> ± | E8: ='18 Days'!AN11 -> 0.011305696 | H8: ='18 Days'!AP11 -> 87.668751 | I8: ='18 Days'!AQ11 -> ± | J8: ='18 Days'!AR11 -> 0.66168594 | L8: ='18 Days'!AS11 -> 0.035017094 | M8: ='18 Days'!AT11 -> ± | N8: ='18 Days'!AU11 -> 0.24217482 | P8: ='18 Days'!AV11 -> 40.895494 | Q8: ='18 Days'!AW11 -> ± | R8: ='18 Days'!AX11 -> 1.9435359 | T8: ='18 Days'!AY11 -> 44.334428 | U8: ='18 Days'!AZ11 -> ± | V8: ='18 Days'!BA11 -> 3.397427 | Y8: ='18 Days'!BC11 -> 11.94285 | Z8: ='18 Days'!BD11 -> ± | AA8: ='18 Days'!BE11 -> 0.67267287 | AC8: ='18 Days'!BF11 -> 0.36242565 | AD8: ='18 Days'!BG11 -> ± | AE8: ='18 Days'!BH11 -> 0.17656799 | AG8: ='18 Days'!BI11 -> 9.5815879 | AH8: ='18 Days'!BJ11 -> ± | AI8: ='18 Days'!BK11 -> 0.30983736 | AK8: ='18 Days'!BL11 -> 1.9988366 | AL8: ='18 Days'!BM11 -> ± | AM8: ='18 Days'!BN11 -> 0.60275108 | AP8: ='18 Days'!BO11 -> 634.13746 | AQ8: ='18 Days'!BP11 -> ± | AR8: ='18 Days'!BQ11 -> 43.207505 | AS8: *
B33: 28 Days
C34: ='28 days'!AL8 -> EtOH | H34: ='28 days'!AP8 -> Water | L34: ='28 days'!AS8 -> Neutral | P34: ='28 days'!AV8 -> Acid | T34: ='28 days'!AY8 -> Basic | Y34: ='28 days'!BC8 -> Insol | AC34: ='28 days'!BF8 -> Starch | AG34: ='28 days'!BI8 -> Protein | AK34: ='28 days'!BL8 -> Cell wall | AP34: ='28 days'!BO8 -> Assimilation
B35: ='28 days'!AK9 -> Col-0 | C35: ='28 days'!AL9 -> 0.58802599 | D35: ='28 days'!AM9 -> ± | E35: ='28 days'!AN9 -> 0.64594863 | H35: ='28 days'!AP9 -> 84.423032 | I35: ='28 days'!AQ9 -> ± | J35: ='28 days'!AR9 -> 0.9454793 | L35: ='28 days'!AS9 -> -0.01128318 | M35: ='28 days'!AT9 -> ± | N35: ='28 days'!AU9 -> 0.046006899 | P35: ='28 days'!AV9 -> 35.313681 | Q35: ='28 days'!AW9 -> ± | R35: ='28 days'!AX9 -> 1.2292815 | T35: ='28 days'!AY9 -> 52.563353 | U35: ='28 days'!AZ9 -> ± | V35: ='28 days'!BA9 -> 1.7231086 | Y35: ='28 days'!BC9 -> 14.988942 | Z35: ='28 days'!BD9 -> ± | AA35: ='28 days'!BE9 -> 1.5344356 | AC35: ='28 days'!BF9 -> 2.397515 | AD35: ='28 days'!BG9 -> ± | AE35: ='28 days'!BH9 -> 1.162512 | AG35: ='28 days'!BI9 -> 6.9612977 | AH35: ='28 days'!BJ9 -> ± | AI35: ='28 days'!BK9 -> 1.2587212 | AK35: ='28 days'!BL9 -> 5.6301291 | AL35: ='28 days'!BM9 -> ± | AM35: ='28 days'!BN9 -> 0.6236448 | AP35: ='28 days'!BO9 -> 236.18149 | AQ35: ='28 days'!BP9 -> ± | AR35: ='28 days'!BQ9 -> 44.992508
B36: ='28 days'!AK12 -> prr7/9 | C36: ='28 days'!AL12 -> 0.38999833 | D36: ='28 days'!AM12 -> ± | E36: ='28 days'!AN12 -> 0.040708305 | H36: ='28 days'!AP12 -> 80.223402 | I36: ='28 days'!AQ12 -> ± | J36: ='28 days'!AR12 -> 0.93199621 | K36: * | L36: ='28 days'!AS12 -> -0.049914728 | M36: ='28 days'!AT12 -> ± | N36: ='28 days'!AU12 -> 0.043263813 | P36: ='28 days'!AV12 -> 42.366843 | Q36: ='28 days'!AW12 -> ± | R36: ='28 days'!AX12 -> 0.4993621 | S36: * | T36: ='28 days'!AY12 -> 39.848397 | U36: ='28 days'!AZ12 -> ± | V36: ='28 days'!BA12 -> 1.5357705 | W36: * | Y36: ='28 days'!BC12 -> 19.3866 | Z36: ='28 days'!BD12 -> ± | AA36: ='28 days'!BE12 -> 0.91755969 | AB36: * | AC36: ='28 days'!BF12 -> 1.7640709 | AD36: ='28 days'!BG12 -> ± | AE36: ='28 days'!BH12 -> 0.77130421 | AG36: ='28 days'!BI12 -> 11.485356 | AH36: ='28 days'!BJ12 -> ± | AI36: ='28 days'!BK12 -> 0.58449178 | AK36: ='28 days'!BL12 -> 6.1371728 | AL36: ='28 days'!BM12 -> ± | AM36: ='28 days'!BN12 -> 1.2115581 | AP36: ='28 days'!BO12 -> 251.14818 | AQ36: ='28 days'!BP12 -> ± | AR36: ='28 days'!BQ12 -> 9.3417551
B37: WS | C37: ='28 days'!AL10 -> 0.25365547 | D37: ='28 days'!AM10 -> ± | E37: ='28 days'!AN10 -> 0.053556533 | H37: ='28 days'!AP10 -> 79.215347 | I37: ='28 days'!AQ10 -> ± | J37: ='28 days'!AR10 -> 0.64200482 | L37: ='28 days'!AS10 -> 0.034457204 | M37: ='28 days'!AT10 -> ± | N37: ='28 days'!AU10 -> 0.0069162165 | P37: ='28 days'!AV10 -> 27.845115 | Q37: ='28 days'!AW10 -> ± | R37: ='28 days'!AX10 -> 0.65826899 | T37: ='28 days'!AY10 -> 55.287674 | U37: ='28 days'!AZ10 -> ± | V37: ='28 days'!BA10 -> 0.57558366 | Y37: ='28 days'!BC10 -> 20.530997 | Z37: ='28 days'!BD10 -> ± | AA37: ='28 days'!BE10 -> 0.63885199 | AC37: ='28 days'!BF10 -> 2.7089373 | AD37: ='28 days'!BG10 -> ± | AE37: ='28 days'!BH10 -> 0.46141917 | AG37: ='28 days'!BI10 -> 10.096631 | AH37: ='28 days'!BJ10 -> ± | AI37: ='28 days'!BK10 -> 0.85873415 | AK37: ='28 days'!BL10 -> 7.7254288 | AL37: ='28 days'!BM10 -> ± | AM37: ='28 days'!BN10 -> 0.65801095 | AP37: ='28 days'!BO10 -> 187.03114 | AQ37: ='28 days'!BP10 -> ± | AR37: ='28 days'!BQ10 -> 8.5049537
B38: ='28 days'!AK11 -> lhy/cca1 (fl) | C38: ='28 days'!AL11 -> 0.37449445 | D38: ='28 days'!AM11 -> ± | E38: ='28 days'!AN11 -> 0.047657029 | F38: * | H38: ='28 days'!AP11 -> 90.393475 | I38: ='28 days'!AQ11 -> ± | J38: ='28 days'!AR11 -> 0.79991851 | K38: * | L38: ='28 days'!AS11 -> -0.064464049 | M38: ='28 days'!AT11 -> ± | N38: ='28 days'!AU11 -> 0.082215569 | P38: ='28 days'!AV11 -> 42.275746 | Q38: ='28 days'!AW11 -> ± | R38: ='28 days'!AX11 -> 1.5321959 | S38: * | T38: ='28 days'!AY11 -> 55.668746 | U38: ='28 days'!AZ11 -> ± | V38: ='28 days'!BA11 -> 1.3454395 | Y38: ='28 days'!BC11 -> 9.2320308 | Z38: ='28 days'!BD11 -> ± | AA38: ='28 days'!BE11 -> 0.84634018 | AB38: * | AC38: ='28 days'!BF11 -> 0.92449503 | AD38: ='28 days'!BG11 -> ± | AE38: ='28 days'!BH11 -> 0.13930665 | AF38: * | AG38: ='28 days'!BI11 -> 5.3005963 | AH38: ='28 days'!BJ11 -> ± | AI38: ='28 days'!BK11 -> 0.54423635 | AJ38: * | AK38: ='28 days'!BL11 -> 3.0069394 | AL38: ='28 days'!BM11 -> ± | AM38: ='28 days'!BN11 -> 0.61400013 | AN38: * | AP38: ='28 days'!BO11 -> 259.67643 | AQ38: ='28 days'!BP11 -> ± | AR38: ='28 days'!BQ11 -> 19.693472 | AS38: *
A58: Col
A59: prr7prr9
A67: EtOH soluble
A68: Water soluble
A69: Water insoluble
A77: Neutral
A78: Acidic
A79: Basic
A87: Starch
A88: Protein
A89: Cell wall

Sheet Labelling
C5: Experiment number 106a | E5: 16.03.15
D7: DAP | E7: plants labelled | F7: Pools | G7: Plants per pool | H7: n
C8: Col-0 | D8: 18 | E8: 12 | F8: 3 | G8: 4 | H8: 3
C9: WS | D9: 18 | E9: 12 | F9: 3 | G9: 4 | H9: 3
C10: lhy/cca1 | D10: 18 | E10: 12 | F10: 3 | G10: 4 | H10: 3
C11: prr7/9 | D11: 18 | E11: 12 | F11: 3 | G11: 4 | H11: 3
D13: Time | E13: ZT
C14: Pulse start | D14: 0.17708333 | E14: "19:15"
C15: Pulse end | D15: 0.21875 | E15: "20:15"
C17: Label | D17: 600 ul | E17: 150 uC
C19: EtOH volume | D19: 3 ml
C21: Experiment number 106a | E21: 16.03.15
D23: DAP | E23: plants labelled | F23: Pools | G23: Plants per pool | H23: n
C24: Col-0 | D24: 28 | E24: 4 | F24: 4 | G24: 1 | H24: 4
C25: WS | D25: 28 | E25: 4 | F25: 4 | G25: 1 | H25: 4
C26: lhy/cca1 | D26: 28 | E26: 4 | F26: 4 | G26: 1 | H26: 4
C27: prr7/9 | D27: 28 | E27: 4 | F27: 4 | G27: 1 | H27: 4
D29: Time | E29: ZT
C30: Pulse start | D30: 0.24305556 | E30: 0.86805556
C31: Pulse end | D31: 0.28472222 | E31: 0.90972222
C33: Label | D33: 600 ul | E33: 150 uC
C35: EtOH volume | D35: 5 ml

Sheet Harvest Mass
A3: Experiment 106a
A5: DAP | B5: Genotype | C5: Sample number | D5: Mass (g) | E5: Mass (mg) | F5: Notes
A6: Experiment 106a
A7: 18 | B7: Col-0 | C7: 1 | D7: 0.067 | E7: =D7*1000 -> 67 | F7: Harvested Col-0 and prr7/9 first alternating between
A8: 18 | B8: Col-0 | C8: 2 | D8: 0.043 | E8: =D8*1000 -> 43
A9: 18 | B9: Col-0 | C9: 3 | D9: 0.0757 | E9: =D9*1000 -> 75.7
A10: 18 | B10: WS | C10: 1 | D10: 0.0334 | E10: =D10*1000 -> 33.4 | F10: Then WS and lhy so effective 10 min chase
A11: 18 | B11: WS | C11: 2 | D11: 0.0266 | E11: =D11*1000 -> 26.6
A12: 18 | B12: WS | C12: 3 | D12: 0.0297 | E12: =D12*1000 -> 29.7
A13: 18 | B13: lhy/cca1 | C13: 1 | D13: 0.0351 | E13: =D13*1000 -> 35.1
A14: 18 | B14: lhy/cca1 | C14: 2 | D14: 0.0249 | E14: =D14*1000 -> 24.9
A15: 18 | B15: lhy/cca1 | C15: 3 | D15: 0.0293 | E15: =D15*1000 -> 29.3
A16: 18 | B16: prr7/9 | C16: 1 | D16: 0.0366 | E16: =D16*1000 -> 36.6
A17: 18 | B17: prr7/9 | C17: 2 | D17: 0.0274 | E17: =D17*1000 -> 27.4
A18: 18 | B18: prr7/9 | C18: 3 | D18: 0.0244 | E18: =D18*1000 -> 24.4
A21: Experiment 106b
A22: 28 | B22: Col-0 | C22: 1 | D22: 0.3097 | E22: =D22*1000 -> 309.7 | F22: This harvest was much faster due to less plants
A23: 28 | B23: Col-0 | C23: 2 | D23: 0.3156 | E23: =D23*1000 -> 315.6 | F23: Col-0 prr first again then WS lhy
A24: 28 | B24: Col-0 | C24: 3 | D24: 0.2043 | E24: =D24*1000 -> 204.3
A25: 28 | B25: Col-0 | C25: 4 | D25: 0.2577 | E25: =D25*1000 -> 257.7
A26: 28 | B26: WS | C26: 1 | D26: 0.2673 | E26: =D26*1000 -> 267.3
A27: 28 | B27: WS | C27: 2 | D27: 0.4418 | E27: =D27*1000 -> 441.8
A28: 28 | B28: WS | C28: 3 | D28: 0.252 | E28: =D28*1000 -> 252
A29: 28 | B29: WS | C29: 4 | D29: 0.275 | E29: =D29*1000 -> 275 | F29: lost some sample during grinding… will probably have to eliminate from calculations
A30: 28 | B30: lhy/cca1 | C30: 1 | D30: 0.0965 | E30: =D30*1000 -> 96.5
A31: 28 | B31: lhy/cca1 | C31: 2 | D31: 0.1125 | E31: =D31*1000 -> 112.5
A32: 28 | B32: lhy/cca1 | C32: 3 | D32: 0.0864 | E32: =D32*1000 -> 86.4
A33: 28 | B33: lhy/cca1 | C33: 4 | D33: 0.0912 | E33: =D33*1000 -> 91.2
A34: 28 | B34: prr7/9 | C34: 1 | D34: 0.14 | E34: =D34*1000 -> 140
A35: 28 | B35: prr7/9 | C35: 2 | D35: 0.1475 | E35: =D35*1000 -> 147.5
A36: 28 | B36: prr7/9 | C36: 3 | D36: 0.1356 | E36: =D36*1000 -> 135.6
A37: 28 | B37: prr7/9 | C37: 4 | D37: 0.1603 | E37: =D37*1000 -> 160.3

Sheet 18 Days
A2: Fill in all rawdata into one table!
A4: Scintillation counting data | D4: Experiment name | E4: Date
F6: lsc | G6: calculation | J6: total counts | O6: Water sol. Dowex | T6: Insoluble digests | BT6: Satndard deviations
A7: no. | B7: sp. | C7: probe name | D7: fraction | E7: solubilized in | F7: dpm | G7: calc dpm | J7: sample | K7: total counts | L7: Assimilation | M7: EtOH | N7: Water | O7: Neutral | P7: Acid | Q7: Basic | R7: recovery water sol % | S7: Insol | T7: Starch | U7: Protein | V7: remaining | W7: total counts | Y7: % | AK7: WT
C8: all blanks | J8: name | K8: sum of sol, insol, EtOH sol of leaf and rosette | M8: leaf | W8: sum of sol, insol, EtOH sol of leaf | Y8: EtOH | Z8: Water | AA8: Neutral | AB8: Acid | AC8: Basic | AD8: Insol | AE8: Starch | AF8: Protein | AG8: Remaining | AL8: EtOH | AP8: Water | AS8: Neutral | AV8: Acid | AY8: Basic | BC8: Insol | BF8: Starch | BI8: Protein | BL8: Cell wall | BO8: Assimilation | BT8: EtOH | BU8: Water | BV8: Neutral | BW8: Acid | BX8: Basic | BY8: Insol | BZ8: Starch | CA8: Protein | CB8: Cell wall | CC8: Assimilation
C9: sol blank | F9: 12.05 | I9: A.t. | J9: Col-0 1 | K9: =G15+G27+G39 -> 23422.6 | L9: =K9/'Harvest Mass'!E7 -> 349.59104 | M9: =G15 -> 116.94 | N9: =G27 -> 20546.66 | O9: =G75 -> 15 | P9: =G99 -> 9790.4 | Q9: =G87 -> 10151.4 | R9: =(O9+P9+Q9)/N9*100 -> 97.129168 | S9: =G39 -> 2759 | T9: =G51 -> 50 | U9: =G63 -> 2083.6 | V9: =S9-T9-U9 -> 625.4 | W9: sum of sol, insol, EtOH sol of rosette | X9: Col-0 1 | Y9: =(M9/$K9)*100 -> 0.4992614 | Z9: =(N9/$K9)*100 -> 87.721517 | AA9: =(O9/$K9)*100 -> 0.064040713 | AB9: =(P9/$K9)*100 -> 41.798946 | AC9: =(Q9/$K9)*100 -> 43.340193 | AD9: =(S9/$K9)*100 -> 11.779222 | AE9: =(T9/$K9)*100 -> 0.21346904 | AF9: =(U9/$K9)*100 -> 8.8956819 | AG9: =(V9/$K9)*100 -> 2.6700708 | AK9: Col-0 | AL9: =AVERAGE(Y9:Y11) -> 0.4478364 | AM9: ± | AN9: =BT9 -> 0.045435424 | AP9: =AVERAGE(Z9:Z11) -> 86.592588 | AQ9: ± | AR9: =BU9 -> 0.80320732 | AS9: =AVERAGE(AA9:AA11) -> 0.087715704 | AT9: ± | AU9: =BV9 -> 0.070486028 | AV9: =AVERAGE(AB9:AB11) -> 40.529264 | AW9: ± | AX9: =BW9 -> 2.5262082 | AY9: =AVERAGE(AC9:AC11) -> 43.741257 | AZ9: ± | BA9: =BX9 -> 3.5226743 | BC9: =AVERAGE(AD9:AD11) -> 12.959575 | BD9: ± | BE9: =BY9 -> 0.83690998 | BF9: =AVERAGE(AE9:AE11) -> 0.9177179 | BG9: ± | BH9: =BZ9 -> 0.79787156 | BI9: =AVERAGE(AF9:AF11) -> 8.7850558 | BJ9: ± | BK9: =CA9 -> 0.76127896 | BL9: =AVERAGE(AG9:AG11) -> 3.2568018 | BM9: ± | BN9: =CB9 -> 0.42111814 | BO9: =AVERAGE(L9:L11) -> 377.7538 | BP9: ± | BQ9: =CC9 -> 26.558532 | BT9: =_xlfn.STDEV.P(Y9:Y11) -> 0.045435424 | BU9: =_xlfn.STDEV.P(Z9:Z11) -> 0.80320732 | BV9: =_xlfn.STDEV.P(AA9:AA11) -> 0.070486028 | BW9: =_xlfn.STDEV.P(AB9:AB11) -> 2.5262082 | BX9: =_xlfn.STDEV.P(AC9:AC11) -> 3.5226743 | BY9: =_xlfn.STDEV.P(AD9:AD11) -> 0.83690998 | BZ9: =_xlfn.STDEV.P(AE9:AE11) -> 0.79787156 | CA9: =_xlfn.STDEV.P(AF9:AF11) -> 0.76127896 | CB9: =_xlfn.STDEV.P(AG9:AG11) -> 0.42111814 | CC9: =_xlfn.STDEV.P(L9:L11) -> 26.558532
C10: EtOH blank | F10: 16.85 | J10: Col-0 2 | K10: =G16+G28+G40 -> 17774.34 | L10: =K10/'Harvest Mass'!E8 -> 413.35674 | M10: =G16 -> 80.96 | N10: =G28 -> 15271.58 | O10: =G76 -> 32.6 | P10: =G100 -> 7605 | Q10: =G88 -> 7046 | R10: =(O10+P10+Q10)/N10*100 -> 96.149842 | S10: =G40 -> 2421.8 | T10: =G52 -> 90 | U10: =G64 -> 1716.5 | V10: =S10-T10-U10 -> 615.3 | X10: Col-0 2 | Y10: =(M10/$K10)*100 -> 0.45548808 | Z10: =(N10/$K10)*100 -> 85.919252 | AA10: =(O10/$K10)*100 -> 0.18341047 | AB10: =(P10/$K10)*100 -> 42.786399 | AC10: =(Q10/$K10)*100 -> 39.641416 | AD10: =(S10/$K10)*100 -> 13.62526 | AE10: =(T10/$K10)*100 -> 0.50634792 | AF10: =(U10/$K10)*100 -> 9.65718 | AG10: =(V10/$K10)*100 -> 3.4617319 | AK10: Ws | AL10: =AVERAGE(Y12:Y14) -> 0.44192274 | AM10: ± | AN10: =BT10 -> 0.032915445 | AP10: =AVERAGE(Z12:Z14) -> 85.871993 | AQ10: ± | AR10: =BU10 -> 1.9861423 | AS10: =AVERAGE(AA12:AA14) -> -0.046192117 | AT10: ± | AU10: =BV10 -> 0.10293146 | AV10: =AVERAGE(AB12:AB14) -> 42.887825 | AW10: ± | AX10: =BW10 -> 2.1683164 | AY10: =AVERAGE(AC12:AC14) -> 43.974767 | AZ10: ± | BA10: =BX10 -> 2.5660557 | BC10: =AVERAGE(AD12:AD14) -> 13.686084 | BD10: ± | BE10: =BY10 -> 1.9692422 | BF10: =AVERAGE(AE12:AE14) -> 0.19874923 | BG10: ± | BH10: =BZ10 -> 0.14054263 | BI10: =AVERAGE(AF12:AF14) -> 10.64893 | BJ10: ± | BK10: =CA10 -> 1.2610418 | BL10: =AVERAGE(AG12:AG14) -> 2.838405 | BM10: ± | BN10: =CB10 -> 0.72504896 | BO10: =AVERAGE(L12:L14) -> 385.29836 | BP10: ± | BQ10: =CC10 -> 11.119471 | BT10: =_xlfn.STDEV.P(Y12:Y14) -> 0.032915445 | BU10: =_xlfn.STDEV.P(Z12:Z14) -> 1.9861423 | BV10: =_xlfn.STDEV.P(AA12:AA14) -> 0.10293146 | BW10: =_xlfn.STDEV.P(AB12:AB14) -> 2.1683164 | BX10: =_xlfn.STDEV.P(AC12:AC14) -> 2.5660557 | BY10: =_xlfn.STDEV.P(AD12:AD14) -> 1.9692422 | BZ10: =_xlfn.STDEV.P(AE12:AE14) -> 0.14054263 | CA10: =_xlfn.STDEV.P(AF12:AF14) -> 1.2610418 | CB10: =_xlfn.STDEV.P(AG12:AG14) -> 0.72504896 | CC10: =_xlfn.STDEV.P(L12:L14) -> 11.119471
C11: NCS blank | F11: 14 | J11: Col-0 3 | K11: =G17+G29+G41 -> 28032.74 | L11: =K11/'Harvest Mass'!E9 -> 370.31361 | M11: =G17 -> 108.98 | N11: =G29 -> 24146.56 | O11: =G77 -> 4.4 | P11: =G101 -> 10372.8 | Q11: =G89 -> 13523.6 | R11: =(O11+P11+Q11)/N11*100 -> 98.982215 | S11: =G41 -> 3777.2 | T11: =G53 -> 570 | U11: =G65 -> 2187.2 | V11: =S11-T11-U11 -> 1020 | X11: Col-0 3 | Y11: =(M11/$K11)*100 -> 0.38875971 | Z11: =(N11/$K11)*100 -> 86.136996 | AA11: =(O11/$K11)*100 -> 0.015695933 | AB11: =(P11/$K11)*100 -> 37.002448 | AC11: =(Q11/$K11)*100 -> 48.242163 | AD11: =(S11/$K11)*100 -> 13.474245 | AE11: =(T11/$K11)*100 -> 2.0333367 | AF11: =(U11/$K11)*100 -> 7.8023054 | AG11: =(V11/$K11)*100 -> 3.6386026 | AK11: lhy/cca1 | AL11: =AVERAGE(Y15:Y17) -> 0.38839844 | AM11: ± | AN11: =BT11 -> 0.011305696 | AP11: =AVERAGE(Z15:Z17) -> 87.668751 | AQ11: ± | AR11: =BU11 -> 0.66168594 | AS11: =AVERAGE(AA16:AA18) -> 0.035017094 | AT11: ± | AU11: =BV11 -> 0.24217482 | AV11: =AVERAGE(AB15:AB17) -> 40.895494 | AW11: ± | AX11: =BW11 -> 1.9435359 | AY11: =AVERAGE(AC15:AC17) -> 44.334428 | AZ11: ± | BA11: =BX11 -> 3.397427 | BC11: =AVERAGE(AD15:AD17) -> 11.94285 | BD11: ± | BE11: =BY11 -> 0.67267287 | BF11: =AVERAGE(AE15:AE17) -> 0.36242565 | BG11: ± | BH11: =BZ11 -> 0.17656799 | BI11: =AVERAGE(AF15:AF17) -> 9.5815879 | BJ11: ± | BK11: =CA11 -> 0.30983736 | BL11: =AVERAGE(AG15:AG17) -> 1.9988366 | BM11: ± | BN11: =CB11 -> 0.60275108 | BO11: =AVERAGE(L15:L17) -> 634.13746 | BP11: ± | BQ11: =CC11 -> 43.207505 | BT11: =_xlfn.STDEV.P(Y15:Y17) -> 0.011305696 | BU11: =_xlfn.STDEV.P(Z15:Z17) -> 0.66168594 | BV11: =_xlfn.STDEV.P(AA15:AA17) -> 0.24217482 | BW11: =_xlfn.STDEV.P(AB15:AB17) -> 1.9435359 | BX11: =_xlfn.STDEV.P(AC15:AC17) -> 3.397427 | BY11: =_xlfn.STDEV.P(AD15:AD17) -> 0.67267287 | BZ11: =_xlfn.STDEV.P(AE15:AE17) -> 0.17656799 | CA11: =_xlfn.STDEV.P(AF15:AF17) -> 0.30983736 | CB11: =_xlfn.STDEV.P(AG15:AG17) -> 0.60275108 | CC11: =_xlfn.STDEV.P(L15:L17) -> 43.207505
C12: acidic | F12: 9.04 | J12: WS 1 | K12: =G18+G30+G42 -> 12644.41 | L12: =K12/'Harvest Mass'!E10 -> 378.57515 | M12: =G18 -> 56.16 | N12: =G30 -> 11152.3 | O12: =G78 -> 11.2 | P12: =G102 -> 5671.4 | Q12: =G90 -> 6019 | R12: =(O12+P12+Q12)/N12*100 -> 104.92544 | S12: =G42 -> 1435.95 | T12: =G54 -> 37.5 | U12: =G66 -> 1138.65 | V12: =S12-T12-U12 -> 259.8 | X12: WS 1 | Y12: =(M12/$K12)*100 -> 0.44414884 | Z12: =(N12/$K12)*100 -> 88.199449 | AA12: =(O12/$K12)*100 -> 0.088576691 | AB12: =(P12/$K12)*100 -> 44.853022 | AC12: =(Q12/$K12)*100 -> 47.602063 | AD12: =(S12/$K12)*100 -> 11.356402 | AE12: =(T12/$K12)*100 -> 0.29657374 | AF12: =(U12/$K12)*100 -> 9.0051651 | AG12: =(V12/$K12)*100 -> 2.0546629 | AK12: prr7/9 | AL12: =AVERAGE(Y18:Y20) -> 0.78863518 | AM12: ± | AN12: =BT12 -> 0.40244169 | AP12: =AVERAGE(Z18:Z20) -> 82.504301 | AQ12: ± | AR12: =BU12 -> 0.87545541 | AS12: =AVERAGE(AA18:AA20) -> 0.19421013 | AT12: ± | AU12: =BV12 -> 0.13739603 | AV12: =AVERAGE(AB18:AB20) -> 44.000252 | AW12: ± | AX12: =BW12 -> 0.55845764 | AY12: =AVERAGE(AC18:AC20) -> 34.6561 | AZ12: ± | BA12: =BX12 -> 1.458755 | BC12: =AVERAGE(AD18:AD20) -> 16.707064 | BD12: ± | BE12: =BY12 -> 1.2604143 | BF12: =AVERAGE(AE18:AE20) -> 0.034317759 | BG12: ± | BH12: =BZ12 -> 0.16179621 | BI12: =AVERAGE(AF18:AF20) -> 13.719813 | BJ12: ± | BK12: =CA12 -> 1.0717338 | BL12: =AVERAGE(AG18:AG20) -> 2.9529327 | BM12: ± | BN12: =CB12 -> 0.42253707 | BO12: =AVERAGE(L18:L20) -> 275.65631 | BP12: ± | BQ12: =CC12 -> 41.816082 | BT12: =_xlfn.STDEV.P(Y18:Y20) -> 0.40244169 | BU12: =_xlfn.STDEV.P(Z18:Z20) -> 0.87545541 | BV12: =_xlfn.STDEV.P(AA18:AA20) -> 0.13739603 | BW12: =_xlfn.STDEV.P(AB18:AB20) -> 0.55845764 | BX12: =_xlfn.STDEV.P(AC18:AC20) -> 1.458755 | BY12: =_xlfn.STDEV.P(AD18:AD20) -> 1.2604143 | BZ12: =_xlfn.STDEV.P(AE18:AE20) -> 0.16179621 | CA12: =_xlfn.STDEV.P(AF18:AF20) -> 1.0717338 | CB12: =_xlfn.STDEV.P(AG18:AG20) -> 0.42253707 | CC12: =_xlfn.STDEV.P(L18:L20) -> 41.816082
C13: basic | F13: 9.56 | J13: WS 2 | K13: =G19+G31+G43 -> 10010.88 | L13: =K13/'Harvest Mass'!E11 -> 376.34887 | M13: =G19 -> 48.16 | N13: =G31 -> 8343.72 | O13: =G79 -> -6.6 | P13: =G103 -> 3991 | Q13: =G91 -> 4211.2 | R13: =(O13+P13+Q13)/N13*100 -> 98.224773 | S13: =G43 -> 1619 | T13: =G55 -> 30 | U13: =G67 -> 1208.3 | V13: =S13-T13-U13 -> 380.7 | X13: WS 2 | Y13: =(M13/$K13)*100 -> 0.48107659 | Z13: =(N13/$K13)*100 -> 83.346519 | AA13: =(O13/$K13)*100 -> -0.06592827 | AB13: =(P13/$K13)*100 -> 39.866625 | AC13: =(Q13/$K13)*100 -> 42.066232 | AD13: =(S13/$K13)*100 -> 16.172404 | AE13: =(T13/$K13)*100 -> 0.29967395 | AF13: =(U13/$K13)*100 -> 12.069868 | AG13: =(V13/$K13)*100 -> 3.8028625
C14: Neutral | F14: 12.13 | J14: WS 3 | K14: =G20+G32+G44 -> 11908.84 | L14: =K14/'Harvest Mass'!E12 -> 400.97104 | M14: =G20 -> 47.7 | N14: =G32 -> 10249.94 | O14: =G80 -> -19.2 | P14: =G104 -> 5233.2 | Q14: =G92 -> 5032.2 | R14: =(O14+P14+Q14)/N14*100 -> 99.963512 | S14: =G44 -> 1611.2 | T14: =G56 -> 0 | U14: =G68 -> 1294.7 | V14: =S14-T14-U14 -> 316.5 | X14: WS 3 | Y14: =(M14/$K14)*100 -> 0.40054279 | Z14: =(N14/$K14)*100 -> 86.070012 | AA14: =(O14/$K14)*100 -> -0.16122477 | AB14: =(P14/$K14)*100 -> 43.943827 | AC14: =(Q14/$K14)*100 -> 42.256005 | AD14: =(S14/$K14)*100 -> 13.529445 | AE14: =(T14/$K14)*100 -> 0 | AF14: =(U14/$K14)*100 -> 10.871756 | AG14: =(V14/$K14)*100 -> 2.6576896
A15: 1 | B15: A.t. | C15: Col-0 1 | D15: EtOH Soluble | E15: EtOH | F15: 75.32 | G15: =(F15-$F$10)*2 -> 116.94 | J15: lhy/cca1 1 | K15: =G21+G33+G45 -> 23187.48 | L15: =K15/'Harvest Mass'!E13 -> 660.61197 | M15: =G21 -> 88.94 | N15: =G33 -> 20215.34 | O15: =G81 -> 0.6 | P15: =G105 -> 8846.2 | Q15: =G93 -> 10546 | R15: =(O15+P15+Q15)/N15*100 -> 95.93111 | S15: =G45 -> 2883.2 | T15: =G57 -> 100 | U15: =G69 -> 2301 | V15: =S15-T15-U15 -> 482.2 | X15: lhy/cca1 1 | Y15: =(M15/$K15)*100 -> 0.38356906 | Z15: =(N15/$K15)*100 -> 87.182134 | AA15: =(O15/$K15)*100 -> 0.0025876033 | AB15: =(P15/$K15)*100 -> 38.150761 | AC15: =(Q15/$K15)*100 -> 45.481441 | AD15: =(S15/$K15)*100 -> 12.434296 | AE15: =(T15/$K15)*100 -> 0.43126722 | AF15: =(U15/$K15)*100 -> 9.9234587 | AG15: =(V15/$K15)*100 -> 2.0795705
A16: 2 | C16: Col-0 2 | D16: EtOH Soluble | E16: EtOH | F16: 57.33 | G16: =(F16-$F$10)*2 -> 80.96 | J16: lhy/cca1 2 | K16: =G22+G34+G46 -> 16647.98 | L16: =K16/'Harvest Mass'!E14 -> 668.59357 | M16: =G22 -> 67.26 | N16: =G34 -> 14750.82 | O16: =G82 -> -40.4 | P16: =G106 -> 7015.8 | Q16: =G94 -> 7958 | R16: =(O16+P16+Q16)/N16*100 -> 101.23776 | S16: =G46 -> 1829.9 | T16: =G58 -> 20 | U16: =G70 -> 1606.2 | V16: =S16-T16-U16 -> 203.7 | X16: lhy/cca1 2 | Y16: =(M16/$K16)*100 -> 0.40401298 | Z16: =(N16/$K16)*100 -> 88.604263 | AA16: =(O16/$K16)*100 -> -0.24267208 | AB16: =(P16/$K16)*100 -> 42.14205 | AC16: =(Q16/$K16)*100 -> 47.801595 | AD16: =(S16/$K16)*100 -> 10.991724 | AE16: =(T16/$K16)*100 -> 0.1201347 | AF16: =(U16/$K16)*100 -> 9.6480174 | AG16: =(V16/$K16)*100 -> 1.2235719
A17: 3 | C17: Col-0 3 | D17: EtOH Soluble | E17: EtOH | F17: 71.34 | G17: =(F17-$F$10)*2 -> 108.98 | I17: L.j. | J17: lhy/cca1 3 | K17: =G23+G35+G47 -> 16794.96 | L17: =K17/'Harvest Mass'!E15 -> 573.20683 | M17: =G23 -> 63.42 | N17: =G35 -> 14648.54 | O17: =G83 -> 58.4 | P17: =G107 -> 7120 | Q17: =G95 -> 6671 | R17: =(O17+P17+Q17)/N17*100 -> 94.544576 | S17: =G47 -> 2083 | T17: =G59 -> 90 | U17: =G71 -> 1540.65 | V17: =S17-T17-U17 -> 452.35 | X17: lhy/cca1 3 | Y17: =(M17/$K17)*100 -> 0.37761328 | Z17: =(N17/$K17)*100 -> 87.219856 | AA17: =(O17/$K17)*100 -> 0.34772336 | AB17: =(P17/$K17)*100 -> 42.39367 | AC17: =(Q17/$K17)*100 -> 39.720249 | AD17: =(S17/$K17)*100 -> 12.40253 | AE17: =(T17/$K17)*100 -> 0.53587505 | AF17: =(U17/$K17)*100 -> 9.1732877 | AG17: =(V17/$K17)*100 -> 2.6933675
A18: 4 | C18: WS 1 | D18: EtOH Soluble | E18: EtOH | F18: 44.93 | G18: =(F18-$F$10)*2 -> 56.16 | J18: prr7/9 1 | K18: =G24+G36+G48 -> 8084.26 | L18: =K18/'Harvest Mass'!E16 -> 220.88142 | M18: =G24 -> 109.46 | N18: =G36 -> 6759 | O18: =G84 -> 0 | P18: =G108 -> 3526 | Q18: =G96 -> 2929.2 | R18: =(O18+P18+Q18)/N18*100 -> 95.505252 | S18: =G48 -> 1215.8 | T18: =G60 -> 20 | U18: =G72 -> 1004.9 | V18: =S18-T18-U18 -> 190.9 | X18: prr7/9 1 | Y18: =(M18/$K18)*100 -> 1.3539891 | Z18: =(N18/$K18)*100 -> 83.60691 | AA18: =(O18/$K18)*100 -> 0 | AB18: =(P18/$K18)*100 -> 43.615618 | AC18: =(Q18/$K18)*100 -> 36.233372 | AD18: =(S18/$K18)*100 -> 15.039101 | AE18: =(T18/$K18)*100 -> 0.24739432 | AF18: =(U18/$K18)*100 -> 12.430328 | AG18: =(V18/$K18)*100 -> 2.3613788
A19: 5 | C19: WS 2 | D19: EtOH Soluble | E19: EtOH | F19: 40.93 | G19: =(F19-$F$10)*2 -> 48.16 | J19: prr7/9 2 | K19: =G25+G37+G49 -> 8832.34 | L19: =K19/'Harvest Mass'!E17 -> 322.34818 | M19: =G25 -> 49.7 | N19: =G37 -> 7281.44 | O19: =G85 -> 26.2 | P19: =G109 -> 3956 | Q19: =G97 -> 3093 | R19: =(O19+P19+Q19)/N19*100 -> 97.167593 | S19: =G49 -> 1501.2 | T19: =G61 -> 0 | U19: =G73 -> 1207.8 | V19: =S19-T19-U19 -> 293.4 | X19: prr7/9 2 | Y19: =(M19/$K19)*100 -> 0.56270479 | Z19: =(N19/$K19)*100 -> 82.440667 | AA19: =(O19/$K19)*100 -> 0.29663713 | AB19: =(P19/$K19)*100 -> 44.789942 | AC19: =(Q19/$K19)*100 -> 35.019032 | AD19: =(S19/$K19)*100 -> 16.996628 | AE19: =(T19/$K19)*100 -> 0 | AF19: =(U19/$K19)*100 -> 13.674745 | AG19: =(V19/$K19)*100 -> 3.321883
A20: 6 | C20: WS 3 | D20: EtOH Soluble | E20: EtOH | F20: 40.7 | G20: =(F20-$F$10)*2 -> 47.7 | J20: prr7/9 3 | K20: =G26+G38+G50 -> 6923.24 | L20: =K20/'Harvest Mass'!E18 -> 283.73934 | M20: =G26 -> 31.1 | N20: =G38 -> 5640.04 | O20: =G86 -> 19.8 | P20: =G110 -> 3018.2 | Q20: =G98 -> 2265 | R20: =(O20+P20+Q20)/N20*100 -> 94.024156 | S20: =G50 -> 1252.1 | T20: =G62 -> -10 | U20: =G74 -> 1042.25 | V20: =S20-T20-U20 -> 219.85 | X20: prr7/9 3 | Y20: =(M20/$K20)*100 -> 0.44921164 | Z20: =(N20/$K20)*100 -> 81.465325 | AA20: =(O20/$K20)*100 -> 0.28599326 | AB20: =(P20/$K20)*100 -> 43.595195 | AC20: =(Q20/$K20)*100 -> 32.715896 | AD20: =(S20/$K20)*100 -> 18.085463 | AE20: =(T20/$K20)*100 -> -0.14444104 | AF20: =(U20/$K20)*100 -> 15.054368 | AG20: =(V20/$K20)*100 -> 3.1755363
A21: 7 | C21: lhy/cca1 1 | D21: EtOH Soluble | E21: EtOH | F21: 61.32 | G21: =(F21-$F$10)*2 -> 88.94
A22: 8 | C22: lhy/cca1 2 | D22: EtOH Soluble | E22: EtOH | F22: 50.48 | G22: =(F22-$F$10)*2 -> 67.26
A23: 9 | C23: lhy/cca1 3 | D23: EtOH Soluble | E23: EtOH | F23: 48.56 | G23: =(F23-$F$10)*2 -> 63.42
A24: 10 | C24: prr7/9 1 | D24: EtOH Soluble | E24: EtOH | F24: 71.58 | G24: =(F24-$F$10)*2 -> 109.46
C25: prr7/9 2 | D25: EtOH Soluble | E25: EtOH | F25: 41.7 | G25: =(F25-$F$10)*2 -> 49.7
C26: prr7/9 3 | D26: EtOH Soluble | E26: EtOH | F26: 32.4 | G26: =(F26-$F$10)*2 -> 31.1
C27: Col-0 1 | D27: Water Soluble | E27: Water | F27: 10290.18 | G27: =(F27-$F$10)*2 -> 20546.66
C28: Col-0 2 | D28: Water Soluble | E28: Water | F28: 7652.64 | G28: =(F28-$F$10)*2 -> 15271.58
C29: Col-0 3 | D29: Water Soluble | E29: Water | F29: 12090.13 | G29: =(F29-$F$10)*2 -> 24146.56
C30: WS 1 | D30: Water Soluble | E30: Water | F30: 5593 | G30: =(F30-$F$10)*2 -> 11152.3
C31: WS 2 | D31: Water Soluble | E31: Water | F31: 4188.71 | G31: =(F31-$F$10)*2 -> 8343.72 | X31: Two-tailed, two-sample t-test with equal variance
C32: WS 3 | D32: Water Soluble | E32: Water | F32: 5141.82 | G32: =(F32-$F$10)*2 -> 10249.94
C33: lhy/cca1 1 | D33: Water Soluble | E33: Water | F33: 10124.52 | G33: =(F33-$F$10)*2 -> 20215.34 | X33: ttest | Y33: EtOH | Z33: Water | AA33: Neutral | AB33: Acid | AC33: Basic | AD33: Insol | AE33: Starch | AF33: Protein | AG33: Remaining | AH33: Assimilation
C34: lhy/cca1 2 | D34: Water Soluble | E34: Water | F34: 7392.26 | G34: =(F34-$F$10)*2 -> 14750.82 | X34: Prr7/9 vs Col0 | Y34: =TTEST(Y9:Y11,Y18:Y20,2,2) -> 0.29983538 | Z34: =TTEST(Z9:Z11,Z18:Z20,2,2) -> 0.0082412011 | AA34: =TTEST(AA9:AA11,AA18:AA20,2,2) -> 0.38464029 | AB34: =TTEST(AB9:AB11,AB18:AB20,2,2) -> 0.13064376 | AC34: =TTEST(AC9:AC11,AC18:AC20,2,2) -> 0.028048332 | AD34: =TTEST(AD9:AD11,AD18:AD20,2,2) -> 0.024831109 | AE34: =TTEST(AE9:AE11,AE18:AE20,2,2) -> 0.19967656 | AF34: =TTEST(AF9:AF11,AF18:AF20,2,2) -> 0.0060514676 | AG34: =TTEST(AG9:AG11,AG18:AG20,2,2) -> 0.51115134 | AH34: =TTEST(L9:L11,L18:L20,2,2) -> 0.043472001
C35: lhy/cca1 3 | D35: Water Soluble | E35: Water | F35: 7341.12 | G35: =(F35-$F$10)*2 -> 14648.54 | X35: Lhy/cca1 vs WS | Y35: =TTEST(Y12:Y14,Y15:Y17,2,2) -> 0.095280645 | Z35: =TTEST(Z12:Z14,Z15:Z17,2,2) -> 0.29159705 | AA35: =TTEST(AA12:AA14,AA15:AA17,2,2) -> 0.68194627 | AB35: =TTEST(AB12:AB14,AB15:AB17,2,2) -> 0.38802734 | AC35: =TTEST(AC12:AC14,AC15:AC17,2,2) -> 0.91066584 | AD35: =TTEST(AD12:AD14,AD15:AD17,2,2) -> 0.30171828 | AE35: =TTEST(AE12:AE14,AE15:AE17,2,2) -> 0.36300821 | AF35: =TTEST(AF12:AF14,AF15:AF17,2,2) -> 0.30969378 | AG35: =TTEST(AG12:AG14,AG15:AG17,2,2) -> 0.27640665 | AH35: =TTEST(L12:L14,L15:L17,2,2) -> 0.0013969929
C36: prr7/9 1 | D36: Water Soluble | E36: Water | F36: 3396.35 | G36: =(F36-$F$10)*2 -> 6759
C37: prr7/9 2 | D37: Water Soluble | E37: Water | F37: 3657.57 | G37: =(F37-$F$10)*2 -> 7281.44
C38: prr7/9 3 | D38: Water Soluble | E38: Water | F38: 2836.87 | G38: =(F38-$F$10)*2 -> 5640.04
C39: Col-0 1 | D39: Insoluble | E39: NCS | F39: 292.75 | G39: =(F39-$F$10)*10 -> 2759
C40: Col-0 2 | D40: Insoluble | E40: NCS | F40: 259.03 | G40: =(F40-$F$10)*10 -> 2421.8
C41: Col-0 3 | D41: Insoluble | E41: NCS | F41: 394.57 | G41: =(F41-$F$10)*10 -> 3777.2
C42: WS 1 | D42: Insoluble | E42: NCS | F42: 208.31 | G42: =(F42-$F$10)*7.5 -> 1435.95
C43: WS 2 | D43: Insoluble | E43: NCS | F43: 178.75 | G43: =(F43-$F$10)*10 -> 1619
...

Sheet 28 days
A2: Fill in all rawdata into one table!
A4: Scintillation counting data | D4: Experiment name | E4: Date
F6: lsc | G6: calculation | J6: total counts | O6: Water sol. Dowex | T6: Insoluble digests
A7: no. | B7: sp. | C7: probe name | D7: fraction | E7: solubilized in | F7: dpm | G7: calc dpm | J7: sample | K7: total counts | L7: Assimilation | M7: EtOH | N7: Water | O7: Neutral | P7: Acid | Q7: Basic | R7: recovery water sol % | S7: Insol | T7: Starch | U7: Protein | V7: remaining | W7: total counts | Y7: % | AK7: WT | BS7: Satndard deviations
C8: all blanks | J8: name | K8: sum of sol, insol, EtOH sol of leaf and rosette | M8: leaf | W8: sum of sol, insol, EtOH sol of leaf | Y8: EtOH | Z8: Water | AA8: Neutral | AB8: Acid | AC8: Basic | AD8: Insol | AE8: Starch | AF8: Protein | AG8: Remaining | AL8: EtOH | AP8: Water | AS8: Neutral | AV8: Acid | AY8: Basic | BC8: Insol | BF8: Starch | BI8: Protein | BL8: Cell wall | BO8: Assimilation
C9: sol blank | F9: 10.72 | I9: A.t. | J9: Col-0 1 | K9: =G15+G31+G47 -> 52870.28 | L9: =K9/'Harvest Mass'!E22 -> 170.7145 | M9: =G15 -> 137.64 | N9: =G31 -> 44728.64 | O9: =G95 -> 8.8 | P9: =G127 -> 17781.6 | Q9: =G111 -> 28506.2 | R9: =(SUM(O9:Q9)/N9*100) -> 103.50549 | S9: =G47 -> 8004 | T9: =G63 -> 820 | U9: =G79 -> 4712.55 | V9: =S9-T9-U9 -> 2471.45 | W9: sum of sol, insol, EtOH sol of rosette | X9: Col-0 1 | Y9: =(M9/$K9)*100 -> 0.2603353 | Z9: =(N9/$K9)*100 -> 84.600725 | AA9: =(O9/$K9)*100 -> 0.016644512 | AB9: =(P9/$K9)*100 -> 33.632506 | AC9: =(Q9/$K9)*100 -> 53.917248 | AD9: =(S9/$K9)*100 -> 15.13894 | AE9: =(T9/$K9)*100 -> 1.5509659 | AF9: =(U9/$K9)*100 -> 8.9134198 | AG9: =(V9/$K9)*100 -> 4.6745544 | AK9: Col-0 | AL9: =AVERAGE(Y9:Y12) -> 0.58802599 | AM9: ± | AN9: =BS10 -> 0.64594863 | AP9: =AVERAGE(Z9:Z12) -> 84.423032 | AQ9: ± | AR9: =BT10 -> 0.9454793 | AS9: =AVERAGE(AA9:AA12) -> -0.01128318 | AT9: ± | AU9: =BU10 -> 0.046006899 | AV9: =AVERAGE(AB9:AB12) -> 35.313681 | AW9: ± | AX9: =BV10 -> 1.2292815 | AY9: =AVERAGE(AC9:AC12) -> 52.563353 | AZ9: ± | BA9: =BW10 -> 1.7231086 | BC9: =AVERAGE(AD9:AD12) -> 14.988942 | BD9: ± | BE9: =BX10 -> 1.5344356 | BF9: =AVERAGE(AE9:AE12) -> 2.397515 | BG9: ± | BH9: =BY10 -> 1.162512 | BI9: =AVERAGE(AF9:AF12) -> 6.9612977 | BJ9: ± | BK9: =BZ10 -> 1.2587212 | BL9: =AVERAGE(AG9:AG12) -> 5.6301291 | BM9: ± | BN9: =CA10 -> 0.6236448 | BO9: =AVERAGE(L9:L12) -> 236.18149 | BP9: ± | BQ9: =CB10 -> 44.992508 | BS9: EtOH | BT9: Water | BU9: Neutral | BV9: Acid | BW9: Base | BX9: Insol | CB9: Assimilation
C10: EtOH blank | F10: 15.33 | J10: Col-0 2 | K10: =G16+G32+G48 -> 71754.52 | L10: =K10/'Harvest Mass'!E23 -> 227.35906 | M10: =G16 -> 142.7 | N10: =G32 -> 59680.72 | O10: =G96 -> 35 | P10: =G128 -> 24917.4 | Q10: =G112 -> 37041.2 | R10: =(SUM(O10:Q10)/N10*100) -> 103.87542 | S10: =G48 -> 11931.1 | T10: =G64 -> 2890 | U10: =G80 -> 5064.45 | V10: =S10-T10-U10 -> 3976.65 | X10: Col-0 2 | Y10: =(M10/$K10)*100 -> 0.19887249 | Z10: =(N10/$K10)*100 -> 83.173464 | AA10: =(O10/$K10)*100 -> 0.048777415 | AB10: =(P10/$K10)*100 -> 34.725896 | AC10: =(Q10/$K10)*100 -> 51.622114 | AD10: =(S10/$K10)*100 -> 16.627663 | AE10: =(T10/$K10)*100 -> 4.0276208 | AF10: =(U10/$K10)*100 -> 7.0580223 | AG10: =(V10/$K10)*100 -> 5.5420202 | AK10: Ws | AL10: =AVERAGE(Y13:Y16) -> 0.25365547 | AM10: ± | AN10: =BS11 -> 0.053556533 | AP10: =AVERAGE(Z13:Z16) -> 79.215347 | AQ10: ± | AR10: =BT11 -> 0.64200482 | AS10: =AVERAGE(AA13:AA16) -> 0.034457204 | AT10: ± | AU10: =BU11 -> 0.0069162165 | AV10: =AVERAGE(AB13:AB16) -> 27.845115 | AW10: ± | AX10: =BV11 -> 0.65826899 | AY10: =AVERAGE(AC13:AC16) -> 55.287674 | AZ10: ± | BA10: =BW11 -> 0.57558366 | BC10: =AVERAGE(AD13:AD16) -> 20.530997 | BD10: ± | BE10: =BX11 -> 0.63885199 | BF10: =AVERAGE(AE13:AE16) -> 2.7089373 | BG10: ± | BH10: =BY11 -> 0.46141917 | BI10: =AVERAGE(AF13:AF16) -> 10.096631 | BJ10: ± | BK10: =BZ11 -> 0.85873415 | BL10: =AVERAGE(AG13:AG16) -> 7.7254288 | BM10: ± | BN10: =CA11 -> 0.65801095 | BO10: =AVERAGE(L13:L16) -> 187.03114 | BP10: ± | BQ10: =CB11 -> 8.5049537 | BS10: =_xlfn.STDEV.P(Y9:Y12) -> 0.64594863 | BT10: =_xlfn.STDEV.P(Z9:Z12) -> 0.9454793 | BU10: =_xlfn.STDEV.P(AA9:AA12) -> 0.046006899 | BV10: =_xlfn.STDEV.P(AB9:AB12) -> 1.2292815 | BW10: =_xlfn.STDEV.P(AC9:AC12) -> 1.7231086 | BX10: =_xlfn.STDEV.P(AD9:AD12) -> 1.5344356 | BY10: =_xlfn.STDEV.P(AE9:AE12) -> 1.162512 | BZ10: =_xlfn.STDEV.P(AF9:AF12) -> 1.2587212 | CA10: =_xlfn.STDEV.P(AG9:AG12) -> 0.6236448 | CB10: =_xlfn.STDEV.P(L9:L12) -> 44.992508
C11: NCS blank | F11: 14 | J11: Col-0 3 | K11: =G17+G33+G49 -> 60349.24 | L11: =K11/'Harvest Mass'!E24 -> 295.3952 | M11: =G17 -> 1029.44 | N11: =G33 -> 51778.5 | O11: =G97 -> -27.2 | P11: =G129 -> 21763 | Q11: =G113 -> 32882.4 | R11: =(SUM(O11:Q11)/N11*100) -> 105.48432 | S11: =G49 -> 7541.3 | T11: =G65 -> 650 | U11: =G81 -> 3306.8 | V11: =S11-T11-U11 -> 3584.5 | X11: Col-0 3 | Y11: =(M11/$K11)*100 -> 1.7058044 | Z11: =(N11/$K11)*100 -> 85.798098 | AA11: =(O11/$K11)*100 -> -0.04507099 | AB11: =(P11/$K11)*100 -> 36.061763 | AC11: =(Q11/$K11)*100 -> 54.48685 | AD11: =(S11/$K11)*100 -> 12.496098 | AE11: =(T11/$K11)*100 -> 1.0770641 | AF11: =(U11/$K11)*100 -> 5.4794393 | AG11: =(V11/$K11)*100 -> 5.9395943 | AK11: lhy/cca1 (fl) | AL11: =AVERAGE(Y17:Y20) -> 0.37449445 | AM11: ± | AN11: =BS12 -> 0.047657029 | AP11: =AVERAGE(Z17:Z20) -> 90.393475 | AQ11: ± | AR11: =BT12 -> 0.79991851 | AS11: =AVERAGE(AA17:AA20) -> -0.064464049 | AT11: ± | AU11: =BU12 -> 0.082215569 | AV11: =AVERAGE(AB17:AB20) -> 42.275746 | AW11: ± | AX11: =BV12 -> 1.5321959 | AY11: =AVERAGE(AC17:AC20) -> 55.668746 | AZ11: ± | BA11: =BW12 -> 1.3454395 | BC11: =AVERAGE(AD17:AD20) -> 9.2320308 | BD11: ± | BE11: =BX12 -> 0.84634018 | BF11: =AVERAGE(AE17:AE20) -> 0.92449503 | BG11: ± | BH11: =BY12 -> 0.13930665 | BI11: =AVERAGE(AF17:AF20) -> 5.3005963 | BJ11: ± | BK11: =BZ12 -> 0.54423635 | BL11: =AVERAGE(AG17:AG20) -> 3.0069394 | BM11: ± | BN11: =CA12 -> 0.61400013 | BO11: =AVERAGE(L17:L20) -> 259.67643 | BP11: ± | BQ11: =CB12 -> 19.693472 | BS11: =_xlfn.STDEV.P(Y13:Y16) -> 0.053556533 | BT11: =_xlfn.STDEV.P(Z13:Z16) -> 0.64200482 | BU11: =_xlfn.STDEV.P(AA13:AA16) -> 0.0069162165 | BV11: =_xlfn.STDEV.P(AB13:AB16) -> 0.65826899 | BW11: =_xlfn.STDEV.P(AC13:AC16) -> 0.57558366 | BX11: =_xlfn.STDEV.P(AD13:AD16) -> 0.63885199 | BY11: =_xlfn.STDEV.P(AE13:AE16) -> 0.46141917 | BZ11: =_xlfn.STDEV.P(AF13:AF16) -> 0.85873415 | CA11: =_xlfn.STDEV.P(AG13:AG16) -> 0.65801095 | CB11: =_xlfn.STDEV.P(L13:L16) -> 8.5049537
C12: acidic | F12: 9.04 | J12: Col-0 4 | K12: =G18+G34+G50 -> 64748.98 | L12: =K12/'Harvest Mass'!E25 -> 251.2572 | M12: =G18 -> 121.14 | N12: =G34 -> 54466.74 | O12: =G98 -> -42.4 | P12: =G130 -> 23850 | Q12: =G114 -> 32521.6 | R12: =(SUM(O12:Q12)/N12*100) -> 103.41944 | S12: =G50 -> 10161.1 | T12: =G66 -> 1900 | U12: =G82 -> 4140.25 | V12: =S12-T12-U12 -> 4120.85 | X12: Col-0 4 | Y12: =(M12/$K12)*100 -> 0.18709175 | Z12: =(N12/$K12)*100 -> 84.119843 | AA12: =(O12/$K12)*100 -> -0.065483657 | AB12: =(P12/$K12)*100 -> 36.834557 | AC12: =(Q12/$K12)*100 -> 50.2272 | AD12: =(S12/$K12)*100 -> 15.693066 | AE12: =(T12/$K12)*100 -> 2.9344092 | AF12: =(U12/$K12)*100 -> 6.3943092 | AG12: =(V12/$K12)*100 -> 6.3643474 | AK12: prr7/9 | AL12: =AVERAGE(Y21:Y24) -> 0.38999833 | AM12: ± | AN12: =BS13 -> 0.040708305 | AP12: =AVERAGE(Z21:Z24) -> 80.223402 | AQ12: ± | AR12: =BT13 -> 0.93199621 | AS12: =AVERAGE(AA21:AA24) -> -0.049914728 | AT12: ± | AU12: =BU13 -> 0.043263813 | AV12: =AVERAGE(AB21:AB24) -> 42.366843 | AW12: ± | AX12: =BV13 -> 0.4993621 | AY12: =AVERAGE(AC21:AC24) -> 39.848397 | AZ12: ± | BA12: =BW13 -> 1.5357705 | BC12: =AVERAGE(AD21:AD24) -> 19.3866 | BD12: ± | BE12: =BX13 -> 0.91755969 | BF12: =AVERAGE(AE21:AE24) -> 1.7640709 | BG12: ± | BH12: =BY13 -> 0.77130421 | BI12: =AVERAGE(AF21:AF24) -> 11.485356 | BJ12: ± | BK12: =BZ13 -> 0.58449178 | BL12: =AVERAGE(AG21:AG24) -> 6.1371728 | BM12: ± | BN12: =CA13 -> 1.2115581 | BO12: =AVERAGE(L21:L24) -> 251.14818 | BP12: ± | BQ12: =CB13 -> 9.3417551 | BS12: =_xlfn.STDEV.P(Y17:Y20) -> 0.047657029 | BT12: =_xlfn.STDEV.P(Z17:Z20) -> 0.79991851 | BU12: =_xlfn.STDEV.P(AA17:AA20) -> 0.082215569 | BV12: =_xlfn.STDEV.P(AB17:AB20) -> 1.5321959 | BW12: =_xlfn.STDEV.P(AC17:AC20) -> 1.3454395 | BX12: =_xlfn.STDEV.P(AD17:AD20) -> 0.84634018 | BY12: =_xlfn.STDEV.P(AE17:AE20) -> 0.13930665 | BZ12: =_xlfn.STDEV.P(AF17:AF20) -> 0.54423635 | CA12: =_xlfn.STDEV.P(AG17:AG20) -> 0.61400013 | CB12: =_xlfn.STDEV.P(L17:L20) -> 19.693472
C13: basic | F13: 9.56 | J13: WS 1 | K13: =G19+G35+G51 -> 48059.08 | L13: =K13/'Harvest Mass'!E26 -> 179.79454 | M13: =G19 -> 135.5 | N13: =G35 -> 37651.08 | O13: =G99 -> 13.2 | P13: =G131 -> 13763 | Q13: =G115 -> 26491.2 | R13: =(SUM(O13:Q13)/N13*100) -> 106.94886 | S13: =G51 -> 10272.5 | T13: =G67 -> 1070 | U13: =G83 -> 5430.9 | V13: =S13-T13-U13 -> 3771.6 | X13: WS 1 | Y13: =(M13/$K13)*100 -> 0.28194464 | Z13: =(N13/$K13)*100 -> 78.343322 | AA13: =(O13/$K13)*100 -> 0.027466194 | AB13: =(P13/$K13)*100 -> 28.637668 | AC13: =(Q13/$K13)*100 -> 55.122154 | AD13: =(S13/$K13)*100 -> 21.374733 | AE13: =(T13/$K13)*100 -> 2.2264263 | AF13: =(U13/$K13)*100 -> 11.300466 | AG13: =(V13/$K13)*100 -> 7.8478406 | BS13: =_xlfn.STDEV.P(Y21:Y24) -> 0.040708305 | BT13: =_xlfn.STDEV.P(Z21:Z24) -> 0.93199621 | BU13: =_xlfn.STDEV.P(AA21:AA24) -> 0.043263813 | BV13: =_xlfn.STDEV.P(AB21:AB24) -> 0.4993621 | BW13: =_xlfn.STDEV.P(AC21:AC24) -> 1.5357705 | BX13: =_xlfn.STDEV.P(AD21:AD24) -> 0.91755969 | BY13: =_xlfn.STDEV.P(AE21:AE24) -> 0.77130421 | BZ13: =_xlfn.STDEV.P(AF21:AF24) -> 0.58449178 | CA13: =_xlfn.STDEV.P(AG21:AG24) -> 1.2115581 | CB13: =_xlfn.STDEV.P(L21:L24) -> 9.3417551
C14: nucleotide | F14: 12.13 | J14: WS 2 | K14: =G20+G36+G52 -> 80553.08 | L14: =K14/'Harvest Mass'!E27 -> 182.32929 | M14: =G20 -> 143.92 | N14: =G36 -> 63985.26 | O14: =G100 -> 25.8 | P14: =G132 -> 21770.2 | Q14: =G116 -> 44046.6 | R14: =(SUM(O14:Q14)/N14*100) -> 102.90276 | S14: =G52 -> 16423.9 | T14: =G68 -> 2070 | U14: =G84 -> 7536.6 | V14: =S14-T14-U14 -> 6817.3 | X14: WS 2 | Y14: =(M14/$K14)*100 -> 0.1786648 | Z14: =(N14/$K14)*100 -> 79.432419 | AA14: =(O14/$K14)*100 -> 0.03202857 | AB14: =(P14/$K14)*100 -> 27.025906 | AC14: =(Q14/$K14)*100 -> 54.680218 | AD14: =(S14/$K14)*100 -> 20.388916 | AE14: =(T14/$K14)*100 -> 2.5697341 | AF14: =(U14/$K14)*100 -> 9.3560668 | AG14: =(V14/$K14)*100 -> 8.4631153
A15: 1 | B15: A.t. | C15: Col-0 1 | D15: EtOH Soluble | E15: EtOH | F15: 84.15 | G15: =(F15-$F$10)*2 -> 137.64 | J15: WS 3 | K15: =G21+G37+G53 -> 50140.34 | L15: =K15/'Harvest Mass'!E28 -> 198.9696 | M15: =G21 -> 150.6 | N15: =G37 -> 40047.24 | O15: =G101 -> 22 | P15: =G133 -> 13975 | Q15: =G117 -> 28109 | R15: =(SUM(O15:Q15)/N15*100) -> 105.14083 | S15: =G53 -> 9942.5 | T15: =G69 -> 1670 | U15: =G85 -> 4830.2 | V15: =S15-T15-U15 -> 3442.3 | X15: WS 3 | Y15: =(M15/$K15)*100 -> 0.30035696 | Z15: =(N15/$K15)*100 -> 79.8703 | AA15: =(O15/$K15)*100 -> 0.043876846 | AB15: =(P15/$K15)*100 -> 27.87177 | AC15: =(Q15/$K15)*100 -> 56.060649 | AD15: =(S15/$K15)*100 -> 19.829343 | AE15: =(T15/$K15)*100 -> 3.3306515 | AF15: =(U15/$K15)*100 -> 9.6333611 | AG15: =(V15/$K15)*100 -> 6.8653304
A16: 2 | C16: Col-0 2 | D16: EtOH Soluble | E16: EtOH | F16: 86.68 | G16: =(F16-$F$10)*2 -> 142.7 | J16: WS 4 | X16: WS4 (dropped)
A17: 3 | C17: Col-0 3 | D17: EtOH Soluble | E17: EtOH | F17: 530.05 | G17: =(F17-$F$10)*2 -> 1029.44 | I17: L.j. | J17: lhy/cca1 1 | K17: =G23+G39+G55 -> 26879.3 | L17: =K17/'Harvest Mass'!E30 -> 278.54197 | M17: =G23 -> 118.62 | N17: =G39 -> 24573.18 | O17: =G103 -> -25.8 | P17: =G135 -> 10864.8 | Q17: =G119 -> 15517.4 | R17: =(SUM(O17:Q17)/N17*100) -> 107.25677 | S17: =G55 -> 2187.5 | T17: =G71 -> 230 | U17: =G87 -> 1306.3 | V17: =S17-T17-U17 -> 651.2 | X17: lhy/cca1 1 | Y17: =(M17/$K17)*100 -> 0.44130614 | Z17: =(N17/$K17)*100 -> 91.420461 | AA17: =(O17/$K17)*100 -> -0.095984642 | AB17: =(P17/$K17)*100 -> 40.420695 | AC17: =(Q17/$K17)*100 -> 57.729926 | AD17: =(S17/$K17)*100 -> 8.1382328 | AE17: =(T17/$K17)*100 -> 0.85567705 | AF17: =(U17/$K17)*100 -> 4.8598736 | AG17: =(V17/$K17)*100 -> 2.4226821
A18: 4 | C18: Col-0 4 | D18: EtOH Soluble | E18: EtOH | F18: 75.9 | G18: =(F18-$F$10)*2 -> 121.14 | J18: lhy/cca1 2 | K18: =G24+G40+G56 -> 26616.66 | L18: =K18/'Harvest Mass'!E31 -> 236.59253 | M18: =G24 -> 105.7 | N18: =G40 -> 24171.06 | O18: =G104 -> -1.8 | P18: =G136 -> 10956 | Q18: =G120 -> 14901 | R18: =(SUM(O18:Q18)/N18*100) -> 106.96759 | S18: =G56 -> 2339.9 | T18: =G72 -> 310 | U18: =G88 -> 1262.55 | V18: =S18-T18-U18 -> 767.35 | X18: lhy/cca1 2 | Y18: =(M18/$K18)*100 -> 0.3971197 | Z18: =(N18/$K18)*100 -> 90.81177 | AA18: =(O18/$K18)*100 -> -0.0067626817 | AB18: =(P18/$K18)*100 -> 41.162189 | AC18: =(Q18/$K18)*100 -> 55.983733 | AD18: =(S18/$K18)*100 -> 8.7911105 | AE18: =(T18/$K18)*100 -> 1.1646841 | AF18: =(U18/$K18)*100 -> 4.7434577 | AG18: =(V18/$K18)*100 -> 2.8829688
A19: 5 | C19: WS 1 | D19: EtOH Soluble | E19: EtOH | F19: 83.08 | G19: =(F19-$F$10)*2 -> 135.5 | J19: lhy/cca1 3 | K19: =G25+G41+G57 -> 21056.3 | L19: =K19/'Harvest Mass'!E32 -> 243.70718 | M19: =G25 -> 67.88 | N19: =G41 -> 18801.82 | O19: =G105 -> -38.6 | P19: =G137 -> 9296.2 | Q19: =G121 -> 11432.2 | R19: =(SUM(O19:Q19)/N19*100) -> 110.04147 | S19: =G57 -> 2186.6 | T19: =G73 -> 180 | U19: =G89 -> 1157.6 | V19: =S19-T19-U19 -> 849 | X19: lhy/cca1 3 | Y19: =(M19/$K19)*100 -> 0.32237383 | Z19: =(N19/$K19)*100 -> 89.293086 | AA19: =(O19/$K19)*100 -> -0.18331806 | AB19: =(P19/$K19)*100 -> 44.149257 | AC19: =(Q19/$K19)*100 -> 54.293489 | AD19: =(S19/$K19)*100 -> 10.38454 | AE19: =(T19/$K19)*100 -> 0.85485104 | AF19: =(U19/$K19)*100 -> 5.497642 | AG19: =(V19/$K19)*100 -> 4.0320474
A20: 6 | C20: WS 2 | D20: EtOH Soluble | E20: EtOH | F20: 87.29 | G20: =(F20-$F$10)*2 -> 143.92 | J20: lhy/cca1 4 | K20: =G26+G42+G58 -> 25523.6 | L20: =K20/'Harvest Mass'!E33 -> 279.86404 | M20: =G26 -> 86.06 | N20: =G42 -> 22983.64 | O20: =G106 -> 7.2 | P20: =G138 -> 11069.8 | Q20: =G122 -> 13953.2 | R20: =(SUM(O20:Q20)/N20*100) -> 108.90442 | S20: =G58 -> 2453.9 | T20: =G74 -> 210 | U20: =G90 -> 1557.3 | V20: =S20-T20-U20 -> 686.6 | X20: lhy/cca1 4 | Y20: =(M20/$K20)*100 -> 0.33717814 | Z20: =(N20/$K20)*100 -> 90.048582 | AA20: =(O20/$K20)*100 -> 0.028209187 | AB20: =(P20/$K20)*100 -> 43.370841 | AC20: =(Q20/$K20)*100 -> 54.667837 | AD20: =(S20/$K20)*100 -> 9.6142394 | AE20: =(T20/$K20)*100 -> 0.82276795 | AF20: =(U20/$K20)*100 -> 6.101412 | AG20: =(V20/$K20)*100 -> 2.6900594
A21: 7 | C21: WS 3 | D21: EtOH Soluble | E21: EtOH | F21: 90.63 | G21: =(F21-$F$10)*2 -> 150.6 | J21: prr7/9 1 | K21: =G27+G43+G59 -> 34218.16 | L21: =K21/'Harvest Mass'!E34 -> 244.41543 | M21: =G27 -> 143.54 | N21: =G43 -> 26916.42 | O21: =G107 -> -34.2 | P21: =G139 -> 14325.4 | Q21: =G123 -> 14375.8 | R21: =(SUM(O21:Q21)/N21*100) -> 106.50376 | S21: =G59 -> 7158.2 | T21: =G75 -> 190 | U21: =G91 -> 4170.3 | V21: =S21-T21-U21 -> 2797.9 | X21: prr7/9 1 | Y21: =(M21/$K21)*100 -> 0.41948486 | Z21: =(N21/$K21)*100 -> 78.661214 | AA21: =(O21/$K21)*100 -> -0.099946929 | AB21: =(P21/$K21)*100 -> 41.864904 | AC21: =(Q21/$K21)*100 -> 42.012195 | AD21: =(S21/$K21)*100 -> 20.919301 | AE21: =(T21/$K21)*100 -> 0.55526072 | AF21: =(U21/$K21)*100 -> 12.187388 | AG21: =(V21/$K21)*100 -> 8.1766524
A22: 8 | C22: WS 4 | D22: EtOH Soluble | E22: EtOH | F22: 127.26 | G22: =(F22-$F$10)*2 -> 223.86 | J22: prr7/9 2 | K22: =G28+G44+G60 -> 38888.3 | L22: =K22/'Harvest Mass'!E35 -> 263.64949 | M22: =G28 -> 159.32 | N22: =G44 -> 31538.78 | O22: =G108 -> -1.6 | P22: =G140 -> 16586.6 | Q22: =G124 -> 14977.2 | R22: =(SUM(O22:Q22)/N22*100) -> 100.07426 | S22: =G60 -> 7190.2 | T22: =G76 -> 670 | U22: =G92 -> 4233.25 | V22: =S22-T22-U22 -> 2286.95 | X22: prr7/9 2 | Y22: =(M22/$K22)*100 -> 0.4096862 | Z22: =(N22/$K22)*100 -> 81.100948 | AA22: =(O22/$K22)*100 -> -0.004114348 | AB22: =(P22/$K22)*100 -> 42.651903 | AC22: =(Q22/$K22)*100 -> 38.513383 | AD22: =(S22/$K22)*100 -> 18.489366 | AE22: =(T22/$K22)*100 -> 1.7228832 | AF22: =(U22/$K22)*100 -> 10.885665 | AG22: =(V22/$K22)*100 -> 5.8808176
A23: 9 | C23: lhy/cca1 1 | D23: EtOH Soluble | E23: EtOH | F23: 74.64 | G23: =(F23-$F$10)*2 -> 118.62 | J23: prr7/9 3 | K23: =G29+G45+G61 -> 34761.28 | L23: =K23/'Harvest Mass'!E36 -> 256.35162 | M23: =G29 -> 142.88 | N23: =G45 -> 27963.4 | O23: =G109 -> -29.8 | P23: =G141 -> 14568.2 | Q23: =G125 -> 13309.4 | R23: =(SUM(O23:Q23)/N23*100) -> 99.586602 | S23: =G61 -> 6655 | T23: =G77 -> 740 | U23: =G93 -> 4150 | V23: =S23-T23-U23 -> 1765 | X23: prr7/9 3 | Y23: =(M23/$K23)*100 -> 0.41103204 | Z23: =(N23/$K23)*100 -> 80.444103 | AA23: =(O23/$K23)*100 -> -0.085727568 | AB23: =(P23/$K23)*100 -> 41.909274 | AC23: =(Q23/$K23)*100 -> 38.288003 | AD23: =(S23/$K23)*100 -> 19.144865 | AE23: =(T23/$K23)*100 -> 2.1288054 | AF23: =(U23/$K23)*100 -> 11.938571 | AG23: =(V23/$K23)*100 -> 5.0774885
A24: 10 | C24: lhy/cca1 2 | D24: EtOH Soluble | E24: EtOH | F24: 68.18 | G24: =(F24-$F$10)*2 -> 105.7 | J24: prr7/9 4 | K24: =G30+G46+G62 -> 38500.24 | L24: =K24/'Harvest Mass'!E37 -> 240.17617 | M24: =G30 -> 123.12 | N24: =G46 -> 31064.82 | O24: =G110 -> -3.8 | P24: =G142 -> 16571 | Q24: =G126 -> 15623.4 | R24: =(SUM(O24:Q24)/N24*100) -> 103.62397 | S24: =G62 -> 7312.3 | T24: =G78 -> 1020 | U24: =G94 -> 4208 | V24: =S24-T24-U24 -> 2084.3 | X24: prr7/9 4 | Y24: =(M24/$K24)*100 -> 0.31979021 | Z24: =(N24/$K24)*100 -> 80.687341 | AA24: =(O24/$K24)*100 -> -0.0098700683 | AB24: =(P24/$K24)*100 -> 43.04129 | AC24: =(Q24/$K24)*100 -> 40.580007 | AD24: =(S24/$K24)*100 -> 18.992869 | AE24: =(T24/$K24)*100 -> 2.6493341 | AF24: =(U24/$K24)*100 -> 10.929802 | AG24: =(V24/$K24)*100 -> 5.4137325
C25: lhy/cca1 3 | D25: EtOH Soluble | E25: EtOH | F25: 49.27 | G25: =(F25-$F$10)*2 -> 67.88
C26: lhy/cca1 4 | D26: EtOH Soluble | E26: EtOH | F26: 58.36 | G26: =(F26-$F$10)*2 -> 86.06
C27: prr7/9 1 | F27: 87.1 | G27: =(F27-$F$10)*2 -> 143.54
C28: prr7/9 2 | F28: 94.99 | G28: =(F28-$F$10)*2 -> 159.32
C29: prr7/9 3 | F29: 86.77 | G29: =(F29-$F$10)*2 -> 142.88
C30: prr7/9 4 | F30: 76.89 | G30: =(F30-$F$10)*2 -> 123.12
C31: Col-0 1 | D31: Water Soluble | E31: Water | F31: 22375.04 | G31: =(F31-$F$9)*2 -> 44728.64
C32: Col-0 2 | D32: Water Soluble | E32: Water | F32: 29851.08 | G32: =(F32-$F$9)*2 -> 59680.72
C33: Col-0 3 | D33: Water Soluble | E33: Water | F33: 25899.97 | G33: =(F33-$F$9)*2 -> 51778.5
C34: Col-0 4 | D34: Water Soluble | E34: Water | F34: 27244.09 | G34: =(F34-$F$9)*2 -> 54466.74 | X34: Two-tailed, two-sample t-test with equal variance
C35: WS 1 | D35: Water Soluble | E35: Water | F35: 18836.26 | G35: =(F35-$F$9)*2 -> 37651.08
C36: WS 2 | D36: Water Soluble | E36: Water | F36: 32003.35 | G36: =(F36-$F$9)*2 -> 63985.26
C37: WS 3 | D37: Water Soluble | E37: Water | F37: 20034.34 | G37: =(F37-$F$9)*2 -> 40047.24 | X37: ttest | Y37: EtOH | Z37: Water | AA37: Neutral | AB37: Acid | AC37: Basic | AD37: Insol | AE37: Starch | AF37: Protein | AG37: Remaining | AH37: Assimilation
C38: WS 4 | D38: Water Soluble | E38: Water | F38: 20359.67 | G38: =(F38-$F$9)*2 -> 40697.9 | X38: Prr7/9 vs Col0 | Y38: =TTEST(Y9:Y12,Y21:Y24,2,2) -> 0.61518103 | Z38: =TTEST(Z9:Z12,Z21:Z24,2,2) -> 0.0015448574 | AA38: =TTEST(AA9:AA12,AA21:AA24,2,2) -> 0.33014592 | AB38: =TTEST(AB9:AB12,AB21:AB24,2,2) -> 9.2579253e-05 | AC38: =TTEST(AC9:AC12,AC21:AC24,2,2) -> 7.5656425e-05 | AD38: =TTEST(AD9:AD12,AD21:AD24,2,2) -> 0.0053188684 | AE38: =TTEST(AE9:AE12,AE21:AE24,2,2) -> 0.46153825 | AF38: =TTEST(AF9:AF12,AF21:AF24,2,2) -> 0.0013235066 | AG38: =TTEST(AG9:AG12,AG21:AG24,2,2) -> 0.54309038 | AH38: =TTEST(L9:L12,L21:L24,2,2) -> 0.59310888
C39: lhy/cca1 1 | D39: Water Soluble | E39: Water | F39: 12297.31 | G39: =(F39-$F$9)*2 -> 24573.18 | X39: Lhy/cca1 vs WS | Y39: =TTEST(Y13:Y16,Y17:Y20,2,2) -> 0.044886523 | Z39: =TTEST(Z13:Z16,Z17:Z20,2,2) -> 1.3670534e-05 | AA39: =TTEST(AA13:AA16,AA17:AA20,2,2) -> 0.13932525 | AB39: =TTEST(AB13:AB16,AB17:AB20,2,2) -> 4.9460867e-05 | AC39: =TTEST(AC13:AC16,AC17:AC20,2,2) -> 0.71343966 | AD39: =TTEST(AD13:AD16,AD17:AD20,2,2) -> 1.5575247e-05 | AE39: =TTEST(AE13:AE16,AE17:AE20,2,2) -> 0.0016255109 | AF39: =TTEST(AF13:AF16,AF17:AF20,2,2) -> 0.00061944793 | AG39: =TTEST(AG13:AG16,AG17:AG20,2,2) -> 0.00042767579 | AH39: =TTEST(L13:L16,L17:L20,2,2) -> 0.003907679
C40: lhy/cca1 2 | D40: Water Soluble | E40: Water | F40: 12096.25 | G40: =(F40-$F$9)*2 -> 24171.06
C41: lhy/cca1 3 | D41: Water Soluble | E41: Water | F41: 9411.63 | G41: =(F41-$F$9)*2 -> 18801.82
C42: lhy/cca1 4 | D42: Water Soluble | E42: Water | F42: 11502.54 | G42: =(F42-$F$9)*2 -> 22983.64
C43: prr7/9 1 | D43: Water Soluble | F43: 13468.93 | G43: =(F43-$F$9)*2 -> 26916.42
...
