Workbook

Sheet Raw data
A1: Summary
B2: Col
A3: DAS | G3: Col | M3: Col | S3: Col | Y3: Col | AE3: Col | AK3: Col | AQ3: Col
A4: DAS | B4: 11 | G4: DAS | H4: 15 | M4: DAS | N4: 18 | S4: DAS | T4: 22 | Y4: DAS | Z4: 25 | AE4: DAS | AF4: 28 | AK4: DAS | AL4: 35 | AQ4: DAS | AR4: 38
A6: 4 | B6: 4 | C6: 4 | D6: 4 | G6: 6 | H6: 6 | I6: 6 | J6: 6 | M6: 8 | N6: 8 | O6: 8 | P6: 8 | S6: 11 | T6: 11 | U6: 12 | V6: 12 | Y6: 15 | Z6: 15 | AA6: 16 | AB6: 16 | AE6: 19 | AF6: 18 | AG6: 19 | AH6: 19 | AK6: 33 | AL6: 32 | AM6: 32 | AN6: 31 | AQ6: 37 | AR6: 36 | AS6: 39 | AT6: 37
A7: 4 | B7: 4 | C7: 4 | D7: 4 | G7: 6 | H7: 7 | I7: 6 | J7: 6 | M7: 8 | N7: 9 | O7: 8 | P7: 9 | S7: 12 | T7: 13 | U7: 12 | V7: 13 | Y7: 16 | Z7: 17 | AA7: 16 | AB7: 16 | AE7: 19 | AF7: 20 | AG7: 19 | AH7: 20 | AK7: 31 | AL7: 29 | AM7: 28 | AQ7: 36 | AR7: 35 | AS7: 35
A8: 4 | B8: 4 | C8: 4 | D8: 4 | G8: 6 | H8: 7 | I8: 6 | J8: 6 | M8: 8 | N8: 8 | O8: 9 | P8: 9 | S8: 12 | T8: 12 | U8: 13 | V8: 13 | Y8: 16 | Z8: 16 | AA8: 16 | AB8: 17 | AE8: 19 | AF8: 20 | AG8: 20 | AH8: 21
A9: 4 | B9: 4 | C9: 4 | D9: 4 | G9: 6 | H9: 6 | I9: 6 | J9: 7 | M9: 9 | N9: 9 | O9: 8 | P9: 9 | S9: 13 | T9: 12 | U9: 12 | V9: 13 | Y9: 16 | Z9: 17 | AA9: 16 | AB9: 16 | AE9: 19 | AF9: 20 | AG9: 19 | AH9: 20
A10: 4 | B10: 4 | C10: 4 | D10: 4 | G10: 6 | H10: 6 | I10: 7 | J10: 6 | M10: 8 | N10: 9 | O10: 8 | P10: 8 | S10: 12 | T10: 12 | U10: 12 | V10: 12 | Y10: 15 | Z10: 16 | AA10: 16 | AB10: 16 | AE10: 18 | AF10: 19 | AG10: 19 | AH10: 19
A11: 4 | B11: 4 | C11: 4 | D11: 4 | G11: 7 | H11: 6 | I11: 6 | J11: 7 | M11: 8 | N11: 8 | O11: 8 | P11: 9 | S11: 12 | T11: 12 | U11: 12 | V11: 13 | Y11: 16 | Z11: 16 | AA11: 14 | AB11: 16 | AE11: 19 | AF11: 19 | AG11: 19 | AH11: 19
A12: Average | B12: =AVERAGE(A6:D11) -> 4 | G12: Average | H12: =AVERAGE(G6:J11) -> 6.25 | M12: Average | N12: =AVERAGE(M6:P11) -> 8.375 | S12: Average | T12: =AVERAGE(S6:V11) -> 12.208333 | Y12: Average | Z12: =AVERAGE(Y6:AB11) -> 15.916667 | AE12: Average | AF12: =AVERAGE(AE6:AH11) -> 19.25 | AK12: Average | AL12: =AVERAGE(AK6:AN11) -> 30.857143 | AQ12: Average | AR12: =AVERAGE(AQ6:AT11) -> 36.428571
A13: SD | B13: =STDEV(A6:D11) -> 0 | G13: SD | H13: =STDEV(G6:J11) -> 0.44232587 | M13: SD | N13: =STDEV(M6:P11) -> 0.49453536 | S13: SD | T13: =STDEV(S6:V11) -> 0.58822997 | Y13: SD | Z13: =STDEV(Y6:AB11) -> 0.65386255 | AE13: SD | AF13: =STDEV(AE6:AH11) -> 0.67566392 | AK13: SD | AL13: =STDEV(AK6:AN11) -> 1.7728105 | AQ13: SD | AR13: =STDEV(AQ6:AT11) -> 1.3972763
A16: pgm | G16: pgm | M16: pgm | S16: pgm | Y16: pgm | AE16: pgm | AK16: pgm | AQ16: pgm
A17: DAS | B17: 11 | G17: DAS | H17: 15 | M17: DAS | N17: 18 | S17: DAS | T17: 22 | Y17: DAS | Z17: 25 | AE17: DAS | AF17: 28 | AK17: DAS | AL17: 35 | AQ17: DAS | AR17: 38
A19: 2 | B19: 2 | C19: 2 | D19: 2 | G19: 4 | H19: 4 | I19: 4 | J19: 4 | M19: 6 | N19: 6 | O19: 6 | P19: 6 | S19: 8 | T19: 8 | U19: 8 | V19: 8 | Y19: 10 | Z19: 9 | AA19: 9 | AB19: 10 | AE19: 12 | AF19: 11 | AG19: 12 | AH19: 12 | AK19: 20 | AL19: 18 | AM19: 20 | AN19: 18 | AQ19: 25 | AR19: 24 | AS19: 23 | AT19: 21
A20: 2 | B20: 2 | C20: 2 | D20: 2 | G20: 4 | H20: 4 | I20: 4 | J20: 5 | M20: 7 | N20: 6 | O20: 6 | P20: 6 | S20: 8 | T20: 8 | U20: 8 | V20: 8 | Y20: 11 | Z20: 11 | AA20: 10 | AB20: 11 | AE20: 13 | AF20: 13 | AG20: 12 | AH20: 13 | AK20: 18 | AL20: 15 | AM20: 17 | AQ20: 21 | AR20: 19 | AS20: 21
A21: 2 | B21: 2 | C21: 2 | D21: 2 | G21: 4 | H21: 4 | I21: 5 | J21: 4 | M21: 6 | N21: 6 | O21: 6 | P21: 6 | S21: 8 | T21: 9 | U21: 8 | V21: 8 | Y21: 11 | Z21: 11 | AA21: 10 | AB21: 10 | AE21: 13 | AF21: 13 | AG21: 12 | AH21: 12
A22: 2 | B22: 2 | C22: 2 | D22: 2 | G22: 4 | H22: 4 | I22: 4 | J22: 4 | M22: 6 | N22: 6 | O22: 6 | P22: 6 | S22: 8 | T22: 9 | U22: 8 | V22: 8 | Y22: 10 | Z22: 11 | AA22: 10 | AB22: 10 | AE22: 13 | AF22: 13 | AG22: 13 | AH22: 13
A23: 2 | B23: 4 | C23: 2 | D23: 2 | G23: 4 | H23: 4 | I23: 4 | J23: 5 | M23: 6 | N23: 6 | O23: 6 | P23: 6 | S23: 8 | T23: 8 | U23: 8 | V23: 9 | Y23: 11 | Z23: 11 | AA23: 10 | AB23: 11 | AE23: 13 | AF23: 13 | AG23: 12 | AH23: 13
A24: 2 | B24: 2 | C24: 2 | D24: 2 | G24: 4 | H24: 4 | I24: 4 | J24: 4 | M24: 6 | N24: 6 | O24: 6 | P24: 6 | S24: 8 | T24: 8 | U24: 9 | V24: 8 | Y24: 10 | Z24: 10 | AA24: 10 | AB24: 10 | AE24: 12 | AF24: 12 | AG24: 13 | AH24: 13
A25: 2 | B25: 2 | C25: 2 | D25: 2 | G25: 4 | H25: 4 | I25: 4 | J25: 4 | M25: 6 | N25: 6 | O25: 6 | P25: 6 | S25: 8 | T25: 8 | U25: 8 | V25: 8 | Y25: 10 | Z25: 10 | AA25: 10 | AB25: 10 | AE25: 12 | AF25: 13 | AG25: 12 | AH25: 11
A26: 2 | B26: 2 | C26: 2 | D26: 2 | G26: 4 | H26: 4 | I26: 4 | J26: 3 | M26: 6 | N26: 6 | O26: 6 | P26: 5 | S26: 8 | T26: 8 | U26: 8 | V26: 7 | Y26: 10 | Z26: 10 | AA26: 11 | AB26: 10 | AE26: 12 | AF26: 13 | AG26: 13 | AH26: 11
A27: 2 | B27: 2 | C27: 2 | D27: 2 | G27: 4 | H27: 4 | I27: 4 | J27: 4 | M27: 5 | N27: 6 | O27: 6 | P27: 6 | S27: 7 | T27: 7 | U27: 8 | V27: 8 | Y27: 8 | Z27: 10 | AA27: 10 | AB27: 11 | AE27: 10 | AF27: 13 | AG27: 12 | AH27: 13
A28: 2 | B28: 2 | C28: 2 | D28: 2 | G28: 4 | H28: 4 | I28: 4 | J28: 4 | M28: 6 | N28: 6 | O28: 6 | P28: 6 | S28: 8 | T28: 8 | U28: 7 | V28: 8 | Y28: 10 | Z28: 10 | AA28: 10 | AB28: 11 | AE28: 12 | AF28: 12 | AG28: 12 | AH28: 12
A29: 2 | B29: 2 | C29: 2 | D29: 2 | G29: 4 | H29: 4 | I29: 4 | J29: 4 | M29: 6 | N29: 6 | O29: 6 | P29: 6 | S29: 8 | T29: 8 | U29: 8 | V29: 8 | Y29: 9 | Z29: 9 | AA29: 10 | AB29: 9 | AE29: 11 | AF29: 11 | AG29: 13 | AH29: 12
A30: 2 | B30: 2 | C30: 2 | D30: 2 | G30: 4 | H30: 4 | I30: 4 | J30: 4 | M30: 6 | N30: 6 | O30: 6 | P30: 6 | S30: 7 | T30: 7 | U30: 8 | V30: 8 | Y30: 9 | Z30: 9 | AA30: 10 | AB30: 9 | AE30: 12 | AF30: 11 | AG30: 12 | AH30: 12
A31: Average | B31: =AVERAGE(A19:D30) -> 2.0416667 | G31: Average | H31: =AVERAGE(G19:J30) -> 4.0416667 | M31: Average | N31: =AVERAGE(M19:P30) -> 5.9791667 | S31: Average | T31: =AVERAGE(S19:V30) -> 7.9583333 | Y31: Average | Z31: =AVERAGE(Y19:AB30) -> 10.041667 | AE31: Average | AF31: =AVERAGE(AE19:AH30) -> 12.25 | AK31: Average | AL31: =AVERAGE(AK19:AN30) -> 18 | AQ31: Average | AR31: =AVERAGE(AQ19:AT30) -> 22
A32: SD | B32: =STDEV(A19:D30) -> 0.28867513 | G32: SD | H32: =STDEV(G19:J30) -> 0.28867513 | M32: SD | N32: =STDEV(M19:P30) -> 0.25176681 | S32: SD | T32: =STDEV(S19:V30) -> 0.45933964 | Y32: SD | Z32: =STDEV(Y19:AB30) -> 0.71334792 | AE32: SD | AF32: =STDEV(AE19:AH30) -> 0.75793673 | AK32: SD | AL32: =STDEV(AK19:AN30) -> 1.7320508 | AQ32: SD | AR32: =STDEV(AQ19:AT30) -> 2.081666
A35: prr7/prr9 | G35: prr7/prr9 | M35: prr7/prr9 | S35: prr7/prr9 | Y35: prr7/prr9 | AE35: prr7/prr9 | AK35: prr7/prr9 | AQ35: prr7/prr9
A36: DAS | B36: 11 | G36: DAS | H36: 15 | M36: DAS | N36: 18 | S36: DAS | T36: 22 | Y36: DAS | Z36: 25 | AE36: DAS | AF36: 28 | AK36: DAS | AL36: 35 | AQ36: DAS | AR36: 38
A38: 4 | B38: 4 | C38: 4 | D38: 4 | E38: 4 | G38: 6 | H38: 6 | I38: 6 | J38: 6 | K38: 6 | M38: 7 | N38: 8 | O38: 8 | P38: 8 | Q38: 8 | S38: 11 | T38: 11 | U38: 11 | V38: 11 | W38: 11 | Y38: 14 | Z38: 15 | AA38: 14 | AB38: 14 | AC38: 14 | AE38: 17 | AF38: 18 | AG38: 18 | AH38: 19 | AI38: 19 | AK38: 30 | AL38: 30 | AM38: 30 | AN38: 30 | AO38: 28 | AQ38: 36 | AR38: 37 | AS38: 35 | AT38: 35 | AU38: 35
A39: 4 | B39: 4 | C39: 4 | D39: 4 | E39: 4 | G39: 6 | H39: 6 | I39: 6 | J39: 6 | K39: 6 | M39: 8 | N39: 7 | O39: 7 | P39: 8 | Q39: 7 | S39: 12 | T39: 10 | U39: 11 | V39: 11 | W39: 11 | Y39: 16 | Z39: 13 | AA39: 14 | AB39: 15 | AC39: 14 | AE39: 19 | AF39: 18 | AG39: 18 | AH39: 19 | AI39: 18 | AK39: 27 | AL39: 23 | AM39: 26 | AQ39: 33 | AR39: 29 | AS39: 33
A40: 4 | B40: 4 | C40: 4 | D40: 4 | E40: 4 | G40: 6 | H40: 6 | I40: 6 | J40: 5 | K40: 5 | M40: 7 | N40: 8 | O40: 7 | P40: 7 | Q40: 7 | S40: 11 | T40: 11 | U40: 12 | V40: 11 | W40: 11 | Y40: 14 | Z40: 14 | AA40: 14 | AB40: 14 | AC40: 14 | AE40: 18 | AF40: 17 | AG40: 19 | AH40: 18 | AI40: 17
A41: 4 | B41: 4 | C41: 4 | D41: 4 | E41: 4 | G41: 6 | H41: 5 | I41: 6 | J41: 6 | K41: 6 | M41: 8 | N41: 7 | O41: 7 | P41: 7 | Q41: 8 | S41: 11 | T41: 10 | U41: 10 | V41: 11 | W41: 11 | Y41: 15 | Z41: 13 | AA41: 13 | AB41: 14 | AC41: 14 | AE41: 18 | AF41: 17 | AG41: 17 | AH41: 18 | AI41: 18
A42: 4 | B42: 4 | C42: 4 | D42: 2 | E42: 4 | G42: 6 | H42: 6 | I42: 6 | J42: 6 | K42: 6 | M42: 7 | N42: 7 | O42: 8 | P42: 7 | Q42: 8 | S42: 11 | T42: 10 | U42: 11 | V42: 10 | W42: 12 | Y42: 14 | Z42: 13 | AA42: 15 | AB42: 13 | AC42: 14 | AE42: 18 | AF42: 18 | AG42: 18 | AH42: 16 | AI42: 18
A43: 4 | B43: 4 | C43: 4 | D43: 4 | E43: 4 | G43: 6 | H43: 6 | I43: 6 | J43: 6 | K43: 6 | M43: 8 | N43: 7 | O43: 8 | P43: 7 | Q43: 8 | S43: 11 | T43: 11 | U43: 11 | V43: 11 | W43: 12 | Y43: 15 | Z43: 14 | AA43: 14 | AB43: 14 | AC43: 15 | AE43: 18 | AF43: 17 | AG43: 18 | AH43: 18 | AI43: 19
A44: 4 | B44: 4 | C44: 4 | D44: 4 | E44: 4 | G44: 6 | H44: 6 | I44: 6 | J44: 6 | K44: 6 | M44: 8 | N44: 8 | O44: 8 | P44: 8 | Q44: 7 | S44: 12 | T44: 11 | U44: 11 | V44: 11 | W44: 11 | Y44: 15 | Z44: 14 | AA44: 15 | AB44: 14 | AC44: 14 | AE44: 19 | AF44: 18 | AG44: 19 | AH44: 18 | AI44: 18
A45: 4 | B45: 4 | C45: 4 | D45: 4 | E45: 4 | G45: 6 | H45: 6 | I45: 6 | J45: 6 | K45: 6 | M45: 8 | N45: 8 | O45: 7 | P45: 8 | Q45: 8 | S45: 11 | T45: 12 | U45: 11 | V45: 11 | W45: 11 | Y45: 14 | Z45: 15 | AA45: 14 | AB45: 14 | AC45: 14 | AE45: 17 | AF45: 18 | AG45: 17 | AH45: 18 | AI45: 18
A46: Average | B46: =AVERAGE(A38:E45) -> 3.95 | G46: Average | H46: =AVERAGE(G38:K45) -> 5.925 | M46: Average | N46: =AVERAGE(M38:Q45) -> 7.55 | S46: Average | T46: =AVERAGE(S38:W45) -> 11.025 | Y46: Average | Z46: =AVERAGE(Y38:AC45) -> 14.15 | AE46: Average | AF46: =AVERAGE(AE38:AI45) -> 17.95 | AK46: Average | AL46: =AVERAGE(AK38:AO45) -> 28 | AQ46: Average | AR46: =AVERAGE(AQ38:AU45) -> 34.125
A47: SD | B47: =STDEV(A38:E45) -> 0.31622777 | G47: SD | H47: =STDEV(G38:K45) -> 0.26674678 | M47: SD | N47: =STDEV(M38:Q45) -> 0.50383147 | S47: SD | T47: =STDEV(S38:W45) -> 0.53048116 | Y47: SD | Z47: =STDEV(Y38:AC45) -> 0.66216428 | AE47: SD | AF47: =STDEV(AE38:AI45) -> 0.71432234 | AK47: SD | AL47: =STDEV(AK38:AO45) -> 2.5634798 | AQ47: SD | AR47: =STDEV(AQ38:AU45) -> 2.4748737
...

Sheet Summary
C1: Genotype | D1: Col | F1: pgm | H1: prr7/prr9 | J1: lhy/cca1
A2: Thermal time | B2: TT after emergence | C2: DAS | D2: LN | E2: SD | F2: LN | G2: SD | H2: LN | I2: SD | J2: LN | K2: SD
A3: =C3*(20.5-3) -> 0 | B3: =MAX(0,A3-110) -> 0 | C3: 0 | D3: 0 | E3: 0 | F3: 0 | G3: 0 | H3: 0 | I3: 0 | J3: 0 | K3: 0
A4: =C4*(20.5-3) -> 192.5 | B4: =MAX(0,A4-110) -> 82.5 | C4: 11 | D4: ='Raw data'!B12 -> 4 | E4: ='Raw data'!B13 -> 0 | F4: ='Raw data'!B31 -> 2.0416667 | G4: ='Raw data'!B32 -> 0.28867513 | H4: ='Raw data'!B46 -> 3.95 | I4: ='Raw data'!B47 -> 0.31622777 | J4: ='Raw data'!B65 -> 3.25 | K4: ='Raw data'!B66 -> 0.97849211
A5: =C5*(20.5-3) -> 262.5 | B5: =MAX(0,A5-110) -> 152.5 | C5: 15 | D5: ='Raw data'!H12 -> 6.25 | E5: ='Raw data'!H13 -> 0.44232587 | F5: ='Raw data'!H31 -> 4.0416667 | G5: ='Raw data'!H32 -> 0.28867513 | H5: ='Raw data'!H46 -> 5.925 | I5: ='Raw data'!H47 -> 0.26674678 | J5: ='Raw data'!H65 -> 5.2916667 | K5: ='Raw data'!H66 -> 0.61741856
A6: =C6*(20.5-3) -> 315 | B6: =MAX(0,A6-110) -> 205 | C6: 18 | D6: ='Raw data'!N12 -> 8.375 | E6: ='Raw data'!N13 -> 0.49453536 | F6: ='Raw data'!N31 -> 5.9791667 | G6: ='Raw data'!N32 -> 0.25176681 | H6: ='Raw data'!N46 -> 7.55 | I6: ='Raw data'!N47 -> 0.50383147 | J6: ='Raw data'!N65 -> 6.7291667 | K6: ='Raw data'!N66 -> 0.49420399
A7: =C7*(20.5-3) -> 385 | B7: =MAX(0,A7-110) -> 275 | C7: 22 | D7: ='Raw data'!T12 -> 12.208333 | E7: ='Raw data'!T13 -> 0.58822997 | F7: ='Raw data'!T31 -> 7.9583333 | G7: ='Raw data'!T32 -> 0.45933964 | H7: ='Raw data'!T46 -> 11.025 | I7: ='Raw data'!T47 -> 0.53048116
A8: =C8*(20.5-3) -> 437.5 | B8: =MAX(0,A8-110) -> 327.5 | C8: 25 | D8: ='Raw data'!Z12 -> 15.916667 | E8: ='Raw data'!Z13 -> 0.65386255 | F8: ='Raw data'!Z31 -> 10.041667 | G8: ='Raw data'!Z32 -> 0.71334792 | H8: ='Raw data'!Z46 -> 14.15 | I8: ='Raw data'!Z47 -> 0.66216428
A9: =C9*(20.5-3) -> 490 | B9: =MAX(0,A9-110) -> 380 | C9: 28 | D9: ='Raw data'!AF12 -> 19.25 | E9: ='Raw data'!AF13 -> 0.67566392 | F9: ='Raw data'!AF31 -> 12.25 | G9: ='Raw data'!AF32 -> 0.75793673 | H9: ='Raw data'!AF46 -> 17.95 | I9: ='Raw data'!AF47 -> 0.71432234
A10: =C10*(20.5-3) -> 612.5 | B10: =MAX(0,A10-110) -> 502.5 | C10: 35 | D10: ='Raw data'!AL12 -> 30.857143 | E10: ='Raw data'!AL13 -> 1.7728105 | F10: ='Raw data'!AL31 -> 18 | G10: ='Raw data'!AL32 -> 1.7320508 | H10: ='Raw data'!AL46 -> 28 | I10: ='Raw data'!AL47 -> 2.5634798
A11: =C11*(20.5-3) -> 665 | B11: =MAX(0,A11-110) -> 555 | C11: 38 | D11: ='Raw data'!AR12 -> 36.428571 | E11: ='Raw data'!AR13 -> 1.3972763 | F11: ='Raw data'!AR31 -> 22 | G11: ='Raw data'!AR32 -> 2.081666 | H11: ='Raw data'!AR46 -> 34.125 | I11: ='Raw data'!AR47 -> 2.4748737

Sheet Sheet3
