Workbook

Sheet Day 21
A1: Date | B1: 41974
A2: Day | B2: 21
A4: Genotype | B4: Col wt | J4: Rosette/FW | K4: Rosette/DW | M4: Rosette/FW
C5: Foil | D5: Foil + FW | E5: Foil + DW | F5: FW (g) | G5: DW (g) | H5: Water (%) | I5: Rosette area (mm2) | J5: SLA(m2/g) | K5: SLA(m2/g) | M5: SLA(cm2/g)
B6: R1 | C6: 0.6079 | D6: 0.6308 | E6: 0.6106 | F6: =D6-C6 -> 0.0229 | G6: =E6-C6 -> 0.0027 | H6: =100-G6/F6*100 -> 88.209607 | I6: 115.443 | J6: =I6/10^6/F6 -> 0.005041179 | K6: =I6/10^6/G6 -> 0.042756667 | M6: =J6*10000 -> 50.41179
B7: R2 | C7: 0.5492 | D7: 0.5697 | E7: 0.5516 | F7: =D7-C7 -> 0.0205 | G7: =E7-C7 -> 0.0024 | H7: =100-G7/F7*100 -> 88.292683 | I7: 118.035 | J7: =I7/10^6/F7 -> 0.0057578049 | K7: =I7/10^6/G7 -> 0.04918125 | M7: =J7*10000 -> 57.578049
B8: R3 | C8: 0.5311 | D8: 0.5633 | E8: 0.5348 | F8: =D8-C8 -> 0.0322 | G8: =E8-C8 -> 0.0037 | H8: =100-G8/F8*100 -> 88.509317 | I8: 175.628 | J8: =I8/10^6/F8 -> 0.0054542857 | K8: =I8/10^6/G8 -> 0.047467027 | M8: =J8*10000 -> 54.542857
B9: R4 | C9: 0.4961 | D9: 0.5208 | E9: 0.499 | F9: =D9-C9 -> 0.0247 | G9: =E9-C9 -> 0.0029 | H9: =100-G9/F9*100 -> 88.259109 | I9: 138.84 | J9: =I9/10^6/F9 -> 0.0056210526 | K9: =I9/10^6/G9 -> 0.047875862 | M9: =J9*10000 -> 56.210526
B10: R5 | C10: 0.6406 | D10: 0.6588 | E10: 0.6429 | F10: =D10-C10 -> 0.0182 | G10: =E10-C10 -> 0.0023 | H10: =100-G10/F10*100 -> 87.362637 | I10: 97.038 | J10: =I10/10^6/F10 -> 0.0053317582 | K10: =I10/10^6/G10 -> 0.042190435 | M10: =J10*10000 -> 53.317582
E11: Average | F11: =AVERAGE(F6:F10) -> 0.0237 | G11: =AVERAGE(G6:G10) -> 0.0028 | H11: =AVERAGE(H6:H10) -> 88.126671 | I11: =AVERAGE(I6:I10) -> 128.9968 | J11: =AVERAGE(J6:J10) -> 0.0054412161 | K11: =AVERAGE(K6:K10) -> 0.045894248 | M11: =AVERAGE(M6:M10) -> 54.412161
E12: SD | F12: =STDEV(F6:F10) -> 0.0053474293 | G12: =STDEV(G6:G10) -> 0.00055677644 | H12: =STDEV(H6:H10) -> 0.44219437 | I12: =STDEV(I6:I10) -> 29.985784 | J12: =STDEV(J6:J10) -> 0.00027602134 | K12: =STDEV(K6:K10) -> 0.00319247 | M12: =STDEV(M6:M10) -> 2.7602134
A14: Genotype | B14: prr7/prr9 | J14: Rosette/FW | K14: Rosette/DW | M14: Rosette/FW
C15: Foil | D15: Foil + FW | E15: Foil + DW | F15: FW (g) | G15: DW (g) | H15: Water (%) | I15: Rosette area (mm2) | J15: SLA(m2/g) | K15: SLA(m2/g) | M15: SLA(cm2/g)
B16: R1 | C16: 0.577 | D16: 0.5927 | E16: 0.5791 | F16: =D16-C16 -> 0.0157 | G16: =E16-C16 -> 0.0021 | H16: =100-G16/F16*100 -> 86.624204 | I16: 77.592 | J16: =I16/10^6/F16 -> 0.0049421656 | K16: =I16/10^6/G16 -> 0.036948571 | M16: =J16*10000 -> 49.421656
B17: R2 | C17: 0.5901 | D17: 0.6045 | E17: 0.5922 | F17: =D17-C17 -> 0.0144 | G17: =E17-C17 -> 0.0021 | H17: =100-G17/F17*100 -> 85.416667 | I17: 76.288 | J17: =I17/10^6/F17 -> 0.0052977778 | K17: =I17/10^6/G17 -> 0.036327619 | M17: =J17*10000 -> 52.977778
B18: R3 | C18: 0.6016 | D18: 0.6158 | E18: 0.6037 | F18: =D18-C18 -> 0.0142 | G18: =E18-C18 -> 0.0021 | H18: =100-G18/F18*100 -> 85.211268 | I18: 81.466 | J18: =I18/10^6/F18 -> 0.0057370423 | K18: =I18/10^6/G18 -> 0.038793333 | M18: =J18*10000 -> 57.370423
B19: R4 | C19: 0.6706 | D19: 0.688 | E19: 0.6729 | F19: =D19-C19 -> 0.0174 | G19: =E19-C19 -> 0.0023 | H19: =100-G19/F19*100 -> 86.781609 | I19: 87.852 | J19: =I19/10^6/F19 -> 0.0050489655 | K19: =I19/10^6/G19 -> 0.038196522 | M19: =J19*10000 -> 50.489655
B20: R5 | C20: 0.5397 | D20: 0.5523 | E20: 0.5416 | F20: =D20-C20 -> 0.0126 | G20: =E20-C20 -> 0.0019 | H20: =100-G20/F20*100 -> 84.920635 | I20: 60.256 | J20: =I20/10^6/F20 -> 0.0047822222 | K20: =I20/10^6/G20 -> 0.031713684 | M20: =J20*10000 -> 47.822222
E21: Average | F21: =AVERAGE(F16:F20) -> 0.01486 | G21: =AVERAGE(G16:G20) -> 0.0021 | H21: =AVERAGE(H16:H20) -> 85.790876 | I21: =AVERAGE(I16:I20) -> 76.6908 | J21: =AVERAGE(J16:J20) -> 0.0051616347 | K21: =AVERAGE(K16:K20) -> 0.036395946 | M21: =AVERAGE(M16:M20) -> 51.616347
E22: SD | F22: =STDEV(F16:F20) -> 0.0017966636 | G22: =STDEV(G16:G20) -> 0.00014142136 | H22: =STDEV(H16:H20) -> 0.8528314 | I22: =STDEV(I16:I20) -> 10.228049 | J22: =STDEV(J16:J20) -> 0.00037230486 | K22: =STDEV(K16:K20) -> 0.0027938852 | M22: =STDEV(M16:M20) -> 3.7230486
A24: Genotype | B24: lsf-1 | J24: Rosette/FW | K24: Rosette/DW | M24: Rosette/FW
C25: Foil | D25: Foil + FW | E25: Foil + DW | F25: FW (g) | G25: DW (g) | H25: Water (%) | I25: Rosette area (mm2) | J25: SLA(m2/g) | K25: SLA(m2/g) | M25: SLA(cm2/g)
B26: R1 | C26: 0.5814 | D26: 0.5932 | E26: 0.5833 | F26: =D26-C26 -> 0.0118 | G26: =E26-C26 -> 0.0019 | H26: =100-G26/F26*100 -> 83.898305 | I26: 54.042 | J26: =I26/10^6/F26 -> 0.0045798305 | K26: =I26/10^6/G26 -> 0.028443158 | M26: =J26*10000 -> 45.798305
B27: R2 | C27: 0.4637 | D27: 0.4756 | E27: 0.4654 | F27: =D27-C27 -> 0.0119 | G27: =E27-C27 -> 0.0017 | H27: =100-G27/F27*100 -> 85.714286 | I27: 59.182 | J27: =I27/10^6/F27 -> 0.0049732773 | K27: =I27/10^6/G27 -> 0.034812941 | M27: =J27*10000 -> 49.732773
B28: R3 | C28: 0.652 | D28: 0.6664 | E28: 0.6542 | F28: =D28-C28 -> 0.0144 | G28: =E28-C28 -> 0.0022 | H28: =100-G28/F28*100 -> 84.722222 | I28: 68.31 | J28: =I28/10^6/F28 -> 0.00474375 | K28: =I28/10^6/G28 -> 0.03105 | M28: =J28*10000 -> 47.4375
B29: R4 | C29: 0.5647 | D29: 0.5846 | E29: 0.5672 | F29: =D29-C29 -> 0.0199 | G29: =E29-C29 -> 0.0025 | H29: =100-G29/F29*100 -> 87.437186 | I29: 98.189 | J29: =I29/10^6/F29 -> 0.0049341206 | K29: =I29/10^6/G29 -> 0.0392756 | M29: =J29*10000 -> 49.341206
B30: R5 | C30: 0.6471 | D30: 0.6648 | E30: 0.6498 | F30: =D30-C30 -> 0.0177 | G30: =E30-C30 -> 0.0027 | H30: =100-G30/F30*100 -> 84.745763 | I30: 80.066 | J30: =I30/10^6/F30 -> 0.0045235028 | K30: =I30/10^6/G30 -> 0.029654074 | M30: =J30*10000 -> 45.235028
E31: Average | F31: =AVERAGE(F26:F30) -> 0.01514 | G31: =AVERAGE(G26:G30) -> 0.0022 | H31: =AVERAGE(H26:H30) -> 85.303552 | I31: =AVERAGE(I26:I30) -> 71.9578 | J31: =AVERAGE(J26:J30) -> 0.0047508962 | K31: =AVERAGE(K26:K30) -> 0.032647155 | M31: =AVERAGE(M26:M30) -> 47.508962
E32: SD | F32: =STDEV(F26:F30) -> 0.0035851081 | G32: =STDEV(G26:G30) -> 0.00041231056 | H32: =STDEV(H26:H30) -> 1.3550727 | I32: =STDEV(I26:I30) -> 17.687016 | J32: =STDEV(J26:J30) -> 0.00020251347 | K32: =STDEV(K26:K30) -> 0.0044104972 | M32: =STDEV(M26:M30) -> 2.0251347
A34: Genotype | B34: pgm | J34: Rosette/FW | K34: Rosette/DW | M34: Rosette/FW
C35: Foil | D35: Foil + FW | E35: Foil + DW | F35: FW (g) | G35: DW (g) | H35: Water (%) | I35: Rosette area (mm2) | J35: SLA(m2/g) | K35: SLA(m2/g) | M35: SLA(cm2/g)
B36: R1 | C36: 0.6132 | D36: 0.6236 | E36: 0.6147 | F36: =D36-C36 -> 0.0104 | G36: =E36-C36 -> 0.0015 | H36: =100-G36/F36*100 -> 85.576923 | I36: 39.109 | J36: =I36/10^6/F36 -> 0.0037604808 | K36: =I36/10^6/G36 -> 0.026072667 | M36: =J36*10000 -> 37.604808
B37: R2 | C37: 0.6198 | D37: 0.6296 | E37: 0.6212 | F37: =D37-C37 -> 0.0098 | G37: =E37-C37 -> 0.0014 | H37: =100-G37/F37*100 -> 85.714286 | I37: 38.098 | J37: =I37/10^6/F37 -> 0.003887551 | K37: =I37/10^6/G37 -> 0.027212857 | M37: =J37*10000 -> 38.87551
B38: R3 | C38: 0.6279 | D38: 0.639 | E38: 0.6294 | F38: =D38-C38 -> 0.0111 | G38: =E38-C38 -> 0.0015 | H38: =100-G38/F38*100 -> 86.486486 | I38: 43.989 | J38: =I38/10^6/F38 -> 0.003962973 | K38: =I38/10^6/G38 -> 0.029326 | M38: =J38*10000 -> 39.62973
B39: R4 | C39: 0.6198 | D39: 0.6308 | E39: 0.6215 | F39: =D39-C39 -> 0.011 | G39: =E39-C39 -> 0.0017 | H39: =100-G39/F39*100 -> 84.545455 | I39: 36.077 | J39: =I39/10^6/F39 -> 0.0032797273 | K39: =I39/10^6/G39 -> 0.021221765 | M39: =J39*10000 -> 32.797273
B40: R5 | C40: 0.6458 | D40: 0.6558 | E40: 0.6472 | F40: =D40-C40 -> 0.01 | G40: =E40-C40 -> 0.0014 | H40: =100-G40/F40*100 -> 86 | I40: 31.283 | J40: =I40/10^6/F40 -> 0.0031283 | K40: =I40/10^6/G40 -> 0.022345 | M40: =J40*10000 -> 31.283
E41: Average | F41: =AVERAGE(F36:F40) -> 0.01046 | G41: =AVERAGE(G36:G40) -> 0.0015 | H41: =AVERAGE(H36:H40) -> 85.66463 | I41: =AVERAGE(I36:I40) -> 37.7112 | J41: =AVERAGE(J36:J40) -> 0.0036038064 | K41: =AVERAGE(K36:K40) -> 0.025235658 | M41: =AVERAGE(M36:M40) -> 36.038064
E42: SD | F42: =STDEV(F36:F40) -> 0.00058137767 | G42: =STDEV(G36:G40) -> 0.00012247449 | H42: =STDEV(H36:H40) -> 0.71600157 | I42: =STDEV(I36:I40) -> 4.6234889 | J42: =STDEV(J36:J40) -> 0.0003758963 | K42: =STDEV(K36:K40) -> 0.0033840819 | M42: =STDEV(M36:M40) -> 3.758963

Sheet Day 30
A1: Date | B1: 41983
A2: Day | B2: 30
A4: Genotype | B4: Col wt | J4: Rosette/FW | K4: Rosette/DW | M4: Rosette/FW
C5: Foil | D5: Foil + FW | E5: Foil + DW | F5: FW (g) | G5: DW (g) | H5: Water (%) | I5: Rosette area (mm2) | J5: SLA(m2/g) | K5: SLA(m2/g) | M5: SLA(cm2/g)
B6: R1 | C6: 0.708 | D6: 0.8284 | E6: 0.7198 | F6: =D6-C6 -> 0.1204 | G6: =E6-C6 -> 0.0118 | H6: =100-G6/F6*100 -> 90.199336 | I6: 483.503 | J6: =I6/10^6/F6 -> 0.0040158056 | K6: =I6/10^6/G6 -> 0.040974831 | M6: =J6*10000 -> 40.158056
B7: R2 | C7: 0.6866 | D7: 0.7925 | E7: 0.6979 | F7: =D7-C7 -> 0.1059 | G7: =E7-C7 -> 0.0113 | H7: =100-G7/F7*100 -> 89.329556 | I7: 422.154 | J7: =I7/10^6/F7 -> 0.0039863456 | K7: =I7/10^6/G7 -> 0.037358761 | M7: =J7*10000 -> 39.863456
B8: R3 | C8: 0.6886 | D8: 0.8202 | E8: 0.7017 | F8: =D8-C8 -> 0.1316 | G8: =E8-C8 -> 0.0131 | H8: =100-G8/F8*100 -> 90.045593 | I8: 573.119 | J8: =I8/10^6/F8 -> 0.0043550076 | K8: =I8/10^6/G8 -> 0.043749542 | M8: =J8*10000 -> 43.550076
B9: R4 | C9: 0.6239 | D9: 0.7238 | E9: 0.6342 | F9: =D9-C9 -> 0.0999 | G9: =E9-C9 -> 0.0103 | H9: =100-G9/F9*100 -> 89.68969 | I9: 384.739 | J9: =I9/10^6/F9 -> 0.0038512412 | K9: =I9/10^6/G9 -> 0.037353301 | M9: =J9*10000 -> 38.512412
B10: R5 | C10: 0.6736 | D10: 0.7937 | E10: 0.6862 | F10: =D10-C10 -> 0.1201 | G10: =E10-C10 -> 0.0126 | H10: =100-G10/F10*100 -> 89.508743 | I10: 487.261 | J10: =I10/10^6/F10 -> 0.0040571274 | K10: =I10/10^6/G10 -> 0.038671508 | M10: =J10*10000 -> 40.571274
E11: Average | F11: =AVERAGE(F6:F10) -> 0.11558 | G11: =AVERAGE(G6:G10) -> 0.01182 | H11: =AVERAGE(H6:H10) -> 89.754583 | I11: =AVERAGE(I6:I10) -> 470.1552 | J11: =AVERAGE(J6:J10) -> 0.0040531055 | K11: =AVERAGE(K6:K10) -> 0.039621588 | M11: =AVERAGE(M6:M10) -> 40.531055
E12: SD | F12: =STDEV(F6:F10) -> 0.012647806 | G12: =STDEV(G6:G10) -> 0.0010986355 | H12: =STDEV(H6:H10) -> 0.36324505 | I12: =STDEV(I6:I10) -> 71.889427 | J12: =STDEV(J6:J10) -> 0.00018557909 | K12: =STDEV(K6:K10) -> 0.0027404121 | M12: =STDEV(M6:M10) -> 1.8557909
A14: Genotype | B14: prr7/prr9 | J14: Rosette/FW | K14: Rosette/DW | M14: Rosette/FW
C15: Foil | D15: Foil + FW | E15: Foil + DW | F15: FW (g) | G15: DW (g) | H15: Water (%) | I15: Rosette area (mm2) | J15: SLA(m2/g) | K15: SLA(m2/g) | M15: SLA(cm2/g)
B16: R1 | C16: 0.7263 | D16: 0.8089 | E16: 0.7362 | F16: =D16-C16 -> 0.0826 | G16: =E16-C16 -> 0.0099 | H16: =100-G16/F16*100 -> 88.014528 | I16: 380.059 | J16: =I16/10^6/F16 -> 0.0046011985 | K16: =I16/10^6/G16 -> 0.038389798 | M16: =J16*10000 -> 46.011985
B17: R2 | C17: 0.6914 | D17: 0.776 | E17: 0.7014 | F17: =D17-C17 -> 0.0846 | G17: =E17-C17 -> 0.01 | H17: =100-G17/F17*100 -> 88.179669 | I17: 411.683 | J17: =I17/10^6/F17 -> 0.0048662293 | K17: =I17/10^6/G17 -> 0.0411683 | M17: =J17*10000 -> 48.662293
B18: R3 | C18: 0.6607 | D18: 0.7431 | E18: 0.6709 | F18: =D18-C18 -> 0.0824 | G18: =E18-C18 -> 0.0102 | H18: =100-G18/F18*100 -> 87.621359 | I18: 413.351 | J18: =I18/10^6/F18 -> 0.0050163956 | K18: =I18/10^6/G18 -> 0.040524608 | M18: =J18*10000 -> 50.163956
B19: R4 | C19: 0.6259 | D19: 0.6841 | E19: 0.6335 | F19: =D19-C19 -> 0.0582 | G19: =E19-C19 -> 0.0076 | H19: =100-G19/F19*100 -> 86.941581 | I19: 267.794 | J19: =I19/10^6/F19 -> 0.0046012715 | K19: =I19/10^6/G19 -> 0.035236053 | M19: =J19*10000 -> 46.012715
B20: R5 | C20: 0.6301 | D20: 0.7268 | E20: 0.641 | F20: =D20-C20 -> 0.0967 | G20: =E20-C20 -> 0.0109 | H20: =100-G20/F20*100 -> 88.728025 | I20: 441.466 | J20: =I20/10^6/F20 -> 0.0045653154 | K20: =I20/10^6/G20 -> 0.040501468 | M20: =J20*10000 -> 45.653154
E21: Average | F21: =AVERAGE(F16:F20) -> 0.0809 | G21: =AVERAGE(G16:G20) -> 0.00972 | H21: =AVERAGE(H16:H20) -> 87.897032 | I21: =AVERAGE(I16:I20) -> 382.8706 | J21: =AVERAGE(J16:J20) -> 0.0047300821 | K21: =AVERAGE(K16:K20) -> 0.039164045 | M21: =AVERAGE(M16:M20) -> 47.300821
E22: SD | F22: =STDEV(F16:F20) -> 0.013997857 | G22: =STDEV(G16:G20) -> 0.0012477981 | H22: =STDEV(H16:H20) -> 0.66579287 | I22: =STDEV(I16:I20) -> 67.902796 | J22: =STDEV(J16:J20) -> 0.00020053847 | K22: =STDEV(K16:K20) -> 0.0024333851 | M22: =STDEV(M16:M20) -> 2.0053847
A24: Genotype | B24: lsf-1 | J24: Rosette/FW | K24: Rosette/DW | M24: Rosette/FW
C25: Foil | D25: Foil + FW | E25: Foil + DW | F25: FW (g) | G25: DW (g) | H25: Water (%) | I25: Rosette area (mm2) | J25: SLA(m2/g) | K25: SLA(m2/g) | M25: SLA(cm2/g)
B26: R1 | C26: 0.642 | D26: 0.73 | E26: 0.6518 | F26: =D26-C26 -> 0.088 | G26: =E26-C26 -> 0.0098 | H26: =100-G26/F26*100 -> 88.863636 | I26: 369.78 | J26: =I26/10^6/F26 -> 0.0042020455 | K26: =I26/10^6/G26 -> 0.037732653 | M26: =J26*10000 -> 42.020455
B27: R2 | C27: 0.6247 | D27: 0.7386 | E27: 0.6367 | F27: =D27-C27 -> 0.1139 | G27: =E27-C27 -> 0.012 | H27: =100-G27/F27*100 -> 89.464442 | I27: 493.954 | J27: =I27/10^6/F27 -> 0.004336734 | K27: =I27/10^6/G27 -> 0.041162833 | M27: =J27*10000 -> 43.36734
B28: R3 | C28: 0.6271 | D28: 0.7284 | E28: 0.6378 | F28: =D28-C28 -> 0.1013 | G28: =E28-C28 -> 0.0107 | H28: =100-G28/F28*100 -> 89.437315 | I28: 410.532 | J28: =I28/10^6/F28 -> 0.0040526357 | K28: =I28/10^6/G28 -> 0.038367477 | M28: =J28*10000 -> 40.526357
B29: R4 | C29: 0.5438 | D29: 0.6388 | E29: 0.5537 | F29: =D29-C29 -> 0.095 | G29: =E29-C29 -> 0.0099 | H29: =100-G29/F29*100 -> 89.578947 | I29: 397.99 | J29: =I29/10^6/F29 -> 0.0041893684 | K29: =I29/10^6/G29 -> 0.04020101 | M29: =J29*10000 -> 41.893684
B30: R5 | C30: 0.6127 | D30: 0.7303 | E30: 0.6251 | F30: =D30-C30 -> 0.1176 | G30: =E30-C30 -> 0.0124 | H30: =100-G30/F30*100 -> 89.455782 | I30: 433.104 | J30: =I30/10^6/F30 -> 0.0036828571 | K30: =I30/10^6/G30 -> 0.034927742 | M30: =J30*10000 -> 36.828571
E31: Average | F31: =AVERAGE(F26:F30) -> 0.10316 | G31: =AVERAGE(G26:G30) -> 0.01096 | H31: =AVERAGE(H26:H30) -> 89.360025 | I31: =AVERAGE(I26:I30) -> 421.072 | J31: =AVERAGE(J26:J30) -> 0.0040927281 | K31: =AVERAGE(K26:K30) -> 0.038478343 | M31: =AVERAGE(M26:M30) -> 40.927281
E32: SD | F32: =STDEV(F26:F30) -> 0.012487314 | G32: =STDEV(G26:G30) -> 0.0011928956 | H32: =STDEV(H26:H30) -> 0.28300834 | I32: =STDEV(I26:I30) -> 46.720698 | J32: =STDEV(J26:J30) -> 0.00025021496 | K32: =STDEV(K26:K30) -> 0.0024160496 | M32: =STDEV(M26:M30) -> 2.5021496
A34: Genotype | B34: pgm | J34: Rosette/FW | K34: Rosette/DW | M34: Rosette/FW
C35: Foil | D35: Foil + FW | E35: Foil + DW | F35: FW (g) | G35: DW (g) | H35: Water (%) | I35: Rosette area (mm2) | J35: SLA(m2/g) | K35: SLA(m2/g) | M35: SLA(cm2/g)
B36: R1 | C36: 0.5353 | D36: 0.5661 | E36: 0.5387 | F36: =D36-C36 -> 0.0308 | G36: =E36-C36 -> 0.0034 | H36: =100-G36/F36*100 -> 88.961039 | I36: 95.331 | J36: =I36/10^6/F36 -> 0.0030951623 | K36: =I36/10^6/G36 -> 0.028038529 | M36: =J36*10000 -> 30.951623
B37: R2 | C37: 0.5486 | D37: 0.5856 | E37: 0.553 | F37: =D37-C37 -> 0.037 | G37: =E37-C37 -> 0.0044 | H37: =100-G37/F37*100 -> 88.108108 | I37: 117.769 | J37: =I37/10^6/F37 -> 0.0031829459 | K37: =I37/10^6/G37 -> 0.026765682 | M37: =J37*10000 -> 31.829459
B38: R3 | C38: 0.5481 | D38: 0.5844 | E38: 0.5521 | F38: =D38-C38 -> 0.0363 | G38: =E38-C38 -> 0.004 | H38: =100-G38/F38*100 -> 88.980716 | I38: 118.076 | J38: =I38/10^6/F38 -> 0.0032527824 | K38: =I38/10^6/G38 -> 0.029519 | M38: =J38*10000 -> 32.527824
B39: R4 | C39: 0.5048 | D39: 0.5441 | E39: 0.5092 | F39: =D39-C39 -> 0.0393 | G39: =E39-C39 -> 0.0044 | H39: =100-G39/F39*100 -> 88.804071 | I39: 116.906 | J39: =I39/10^6/F39 -> 0.0029747074 | K39: =I39/10^6/G39 -> 0.026569545 | M39: =J39*10000 -> 29.747074
B40: R5 | C40: 0.6408 | D40: 0.6794 | E40: 0.645 | F40: =D40-C40 -> 0.0386 | G40: =E40-C40 -> 0.0042 | H40: =100-G40/F40*100 -> 89.119171 | I40: 107.375 | J40: =I40/10^6/F40 -> 0.0027817358 | K40: =I40/10^6/G40 -> 0.025565476 | M40: =J40*10000 -> 27.817358
E41: Average | F41: =AVERAGE(F36:F40) -> 0.0364 | G41: =AVERAGE(G36:G40) -> 0.00408 | H41: =AVERAGE(H36:H40) -> 88.794621 | I41: =AVERAGE(I36:I40) -> 111.0914 | J41: =AVERAGE(J36:J40) -> 0.0030574668 | K41: =AVERAGE(K36:K40) -> 0.027291647 | M41: =AVERAGE(M36:M40) -> 30.574668
E42: SD | F42: =STDEV(F36:F40) -> 0.0033533565 | G42: =STDEV(G36:G40) -> 0.00041472883 | H42: =STDEV(H36:H40) -> 0.39970249 | I42: =STDEV(I36:I40) -> 9.8664379 | J42: =STDEV(J36:J40) -> 0.00018587017 | K42: =STDEV(K36:K40) -> 0.0015245221 | M42: =STDEV(M36:M40) -> 1.8587017

Sheet Day 39 Final
A1: Date | B1: 41992 | E1: # | F1: Plants in pots for gas exchange measurement
A2: Day | B2: 39 | E2: R | F2: Plants on trays
A4: Genotype | B4: Col wt | J4: Rosette/FW | K4: Rosette/DW | M4: Rosette/FW
C5: Foil | D5: Foil + FW | E5: Foil + DW | F5: FW (g) | G5: DW (g) | H5: Water (%) | I5: Rosette area (mm2) | J5: SLA(m2/g) | K5: SLA(m2/g) | M5: SLA(cm2/g)
A6: Gas | B6: #1 | C6: 1.1663 | D6: 1.872 | E6: 1.2335 | F6: =D6-C6 -> 0.7057 | G6: =E6-C6 -> 0.0672 | H6: =100-G6/F6*100 -> 90.47754 | I6: 1885.869 | J6: =I6/10^6/F6 -> 0.0026723381 | K6: =I6/10^6/G6 -> 0.028063527 | M6: =J6*10000 -> 26.723381
A7: Gas | B7: #2 | C7: 0.9825 | D7: 1.5056 | E7: 1.0347 | F7: =D7-C7 -> 0.5231 | G7: =E7-C7 -> 0.0522 | H7: =100-G7/F7*100 -> 90.021028 | I7: 1662.899 | J7: =I7/10^6/F7 -> 0.0031789314 | K7: =I7/10^6/G7 -> 0.031856303 | M7: =J7*10000 -> 31.789314
A8: Gas | B8: #3 | C8: 1.1302 | D8: 1.691 | E8: 1.1867 | F8: =D8-C8 -> 0.5608 | G8: =E8-C8 -> 0.0565 | H8: =100-G8/F8*100 -> 89.925107 | I8: 1440.254 | J8: =I8/10^6/F8 -> 0.0025682133 | K8: =I8/10^6/G8 -> 0.025491221 | M8: =J8*10000 -> 25.682133
A9: Gas | B9: #4 | C9: 1.3095 | D9: 1.8435 | E9: 1.3646 | F9: =D9-C9 -> 0.534 | G9: =E9-C9 -> 0.0551 | H9: =100-G9/F9*100 -> 89.681648 | I9: 1530.799 | J9: =I9/10^6/F9 -> 0.0028666648 | K9: =I9/10^6/G9 -> 0.027782196 | M9: =J9*10000 -> 28.666648
A10: Gas | B10: #5 | C10: 1.0504 | D10: 1.5536 | E10: 1.1014 | F10: =D10-C10 -> 0.5032 | G10: =E10-C10 -> 0.051 | H10: =100-G10/F10*100 -> 89.864865 | I10: 1566.407 | J10: =I10/10^6/F10 -> 0.0031128915 | K10: =I10/10^6/G10 -> 0.030713863 | M10: =J10*10000 -> 31.128915
B11: R1 | C11: 1.1306 | D11: 1.8856 | E11: 1.1927 | F11: =D11-C11 -> 0.755 | G11: =E11-C11 -> 0.0621 | H11: =100-G11/F11*100 -> 91.774834 | I11: 2435.609 | J11: =I11/10^6/F11 -> 0.0032259722 | K11: =I11/10^6/G11 -> 0.039220757 | M11: =J11*10000 -> 32.259722
B12: R2 | C12: 0.9685 | D12: 1.7873 | E12: 1.0356 | F12: =D12-C12 -> 0.8188 | G12: =E12-C12 -> 0.0671 | H12: =100-G12/F12*100 -> 91.805081 | I12: 2716.496 | J12: =I12/10^6/F12 -> 0.0033176551 | K12: =I12/10^6/G12 -> 0.040484292 | M12: =J12*10000 -> 33.176551
B13: R3 | C13: 1.0061 | D13: 1.6017 | E13: 1.0556 | F13: =D13-C13 -> 0.5956 | G13: =E13-C13 -> 0.0495 | H13: =100-G13/F13*100 -> 91.689053 | I13: 1814.61 | J13: =I13/10^6/F13 -> 0.0030466924 | K13: =I13/10^6/G13 -> 0.036658788 | M13: =J13*10000 -> 30.466924
B14: R4 | C14: 1.1024 | D14: 1.8614 | E14: 1.1645 | F14: =D14-C14 -> 0.759 | G14: =E14-C14 -> 0.0621 | H14: =100-G14/F14*100 -> 91.818182 | I14: 2426.598 | J14: =I14/10^6/F14 -> 0.0031970988 | K14: =I14/10^6/G14 -> 0.039075652 | M14: =J14*10000 -> 31.970988
B15: R5 | C15: 1.1221 | D15: 1.9405 | E15: 1.1888 | F15: =D15-C15 -> 0.8184 | G15: =E15-C15 -> 0.0667 | H15: =100-G15/F15*100 -> 91.849951 | I15: 2417.672 | J15: =I15/10^6/F15 -> 0.0029541447 | K15: =I15/10^6/G15 -> 0.036246957 | M15: =J15*10000 -> 29.541447
E16: Average# | F16: =AVERAGE(F6:F10) -> 0.56536 | G16: =AVERAGE(G6:G10) -> 0.0564 | H16: =AVERAGE(H6:H10) -> 89.994038 | I16: =AVERAGE(I6:I15) -> 1989.7213 | J16: =AVERAGE(J6:J10) -> 0.0028798078 | K16: =AVERAGE(K6:K10) -> 0.028781422 | M16: =AVERAGE(M6:M10) -> 28.798078
E17: SD# | F17: =STDEV(F6:F10) -> 0.081162387 | G17: =STDEV(G6:G10) -> 0.0064253405 | H17: =STDEV(H6:H10) -> 0.29729086 | I17: =STDEV(I6:I15) -> 464.39942 | J17: =STDEV(J6:J10) -> 0.00026651008 | K17: =STDEV(K6:K10) -> 0.0025262851 | M17: =STDEV(M6:M10) -> 2.6651008
E18: AverageR | F18: =AVERAGE(F11:F15) -> 0.74936 | G18: =AVERAGE(G11:G15) -> 0.0615 | H18: =AVERAGE(H11:H15) -> 91.78742 | I18: =AVERAGE(I11:I15) -> 2362.197 | J18: =AVERAGE(J11:J15) -> 0.0031483126 | K18: =AVERAGE(K11:K15) -> 0.038337289 | M18: =AVERAGE(M11:M15) -> 31.483126
E19: SD R | F19: =STDEV(F11:F15) -> 0.091317183 | G19: =STDEV(G11:G15) -> 0.0071260087 | H19: =STDEV(H11:H15) -> 0.061242918 | I19: =STDEV(I11:I15) -> 330.90542 | J19: =STDEV(J11:J15) -> 0.00014587309 | K19: =STDEV(K11:K15) -> 0.0018112271 | M19: =STDEV(M11:M15) -> 1.4587309
E20: Average | F20: =AVERAGE(F6:F15) -> 0.65736 | G20: =AVERAGE(G6:G15) -> 0.05895 | H20: =AVERAGE(H6:H15) -> 90.890729 | I20: =AVERAGE(I6:I15) -> 1989.7213 | J20: =AVERAGE(J6:J15) -> 0.0030140602 | K20: =AVERAGE(K6:K15) -> 0.033559355 | M20: =AVERAGE(M6:M15) -> 30.140602
E21: SD | F21: =STDEV(F6:F15) -> 0.12664239 | G21: =STDEV(G6:G15) -> 0.0069384997 | H21: =STDEV(H6:H15) -> 0.96661394 | I21: =STDEV(I6:I15) -> 464.39942 | J21: =STDEV(J6:J15) -> 0.000247086 | K21: =STDEV(K6:K15) -> 0.0054460703 | M21: =STDEV(M6:M15) -> 2.47086
A23: Genotype | B23: prr7/prr9 | J23: Rosette/FW | K23: Rosette/DW | M23: Rosette/FW
C24: Foil | D24: Foil + FW | E24: Foil + DW | F24: FW (g) | G24: DW (g) | H24: Water (%) | I24: Rosette area (mm2) | J24: SLA(m2/g) | K24: SLA(m2/g) | M24: SLA(cm2/g)
A25: Gas | B25: #1 | C25: 0.9605 | D25: 1.3783 | E25: 1.0101 | F25: =D25-C25 -> 0.4178 | G25: =E25-C25 -> 0.0496 | H25: =100-G25/F25*100 -> 88.128291 | I25: 1495.247 | J25: =I25/10^6/F25 -> 0.0035788583 | K25: =I25/10^6/G25 -> 0.030146109 | M25: =J25*10000 -> 35.788583
A26: Gas | B26: #2 | C26: 1.0862 | D26: 1.4684 | E26: 1.132 | F26: =D26-C26 -> 0.3822 | G26: =E26-C26 -> 0.0458 | H26: =100-G26/F26*100 -> 88.016745 | I26: 1459.26 | J26: =I26/10^6/F26 -> 0.0038180534 | K26: =I26/10^6/G26 -> 0.031861572 | M26: =J26*10000 -> 38.180534
A27: Gas | B27: #3 | C27: 1.1027 | D27: 1.5552 | E27: 1.1558 | F27: =D27-C27 -> 0.4525 | G27: =E27-C27 -> 0.0531 | H27: =100-G27/F27*100 -> 88.265193 | I27: 1392.879 | J27: =I27/10^6/F27 -> 0.0030781856 | K27: =I27/10^6/G27 -> 0.026231243 | M27: =J27*10000 -> 30.781856
A28: Gas | B28: #4 | C28: 0.9657 | D28: 1.434 | E28: 1.0231 | F28: =D28-C28 -> 0.4683 | G28: =E28-C28 -> 0.0574 | H28: =100-G28/F28*100 -> 87.7429 | I28: 1727.438 | J28: =I28/10^6/F28 -> 0.0036887423 | K28: =I28/10^6/G28 -> 0.030094739 | M28: =J28*10000 -> 36.887423
A29: Gas | B29: #5 | C29: 1.136 | D29: 1.5505 | E29: 1.1855 | F29: =D29-C29 -> 0.4145 | G29: =E29-C29 -> 0.0495 | H29: =100-G29/F29*100 -> 88.057901 | I29: 1521.887 | J29: =I29/10^6/F29 -> 0.0036716212 | K29: =I29/10^6/G29 -> 0.030745192 | M29: =J29*10000 -> 36.716212
B30: R1 | C30: 1.0113 | D30: 1.5157 | E30: 1.0603 | F30: =D30-C30 -> 0.5044 | G30: =E30-C30 -> 0.049 | H30: =100-G30/F30*100 -> 90.285488 | I30: 2124.119 | J30: =I30/10^6/F30 -> 0.0042111796 | K30: =I30/10^6/G30 -> 0.043349367 | M30: =J30*10000 -> 42.111796
B31: R2 | C31: 1.0981 | D31: 1.6395 | E31: 1.1525 | F31: =D31-C31 -> 0.5414 | G31: =E31-C31 -> 0.0544 | H31: =100-G31/F31*100 -> 89.951976 | I31: 2218.403 | J31: =I31/10^6/F31 -> 0.0040975305 | K31: =I31/10^6/G31 -> 0.040779467 | M31: =J31*10000 -> 40.975305
E32: Average# | F32: =AVERAGE(F25:F29) -> 0.42706 | G32: =AVERAGE(G25:G29) -> 0.05108 | H32: =AVERAGE(H25:H29) -> 88.042206 | I32: =AVERAGE(I25:I29) -> 1519.3422 | J32: =AVERAGE(J25:J29) -> 0.0035670922 | K32: =AVERAGE(K25:K29) -> 0.029815771 | M32: =AVERAGE(M25:M29) -> 35.670922
E33: SD# | F33: =STDEV(F25:F29) -> 0.033925846 | G33: =STDEV(G25:G29) -> 0.0043757285 | H33: =STDEV(H25:H29) -> 0.19210203 | I33: =STDEV(I25:I29) -> 125.98981 | J33: =STDEV(J25:J29) -> 0.00028630169 | K33: =STDEV(K25:K29) -> 0.002126318 | M33: =STDEV(M25:M29) -> 2.8630169
E34: AverageR | F34: =AVERAGE(F30:F31) -> 0.5229 | G34: =AVERAGE(G30:G31) -> 0.0517 | H34: =AVERAGE(H30:H31) -> 90.118732 | I34: =AVERAGE(I30:I31) -> 2171.261 | J34: =AVERAGE(J30:J31) -> 0.004154355 | K34: =AVERAGE(K30:K31) -> 0.042064417 | M34: =AVERAGE(M30:M31) -> 41.54355
E35: SD R | F35: =STDEV(F30:F31) -> 0.026162951 | G35: =STDEV(G30:G31) -> 0.0038183766 | H35: =STDEV(H30:H31) -> 0.23582814 | I35: =STDEV(I30:I31) -> 66.668856 | J35: =STDEV(J30:J31) -> 8.036208e-05 | K35: =STDEV(K30:K31) -> 0.001817194 | M35: =STDEV(M30:M31) -> 0.8036208
E36: Average | F36: =AVERAGE(F25:F31) -> 0.45444286 | G36: =AVERAGE(G25:G31) -> 0.051257143 | H36: =AVERAGE(H25:H31) -> 88.635499 | I36: =AVERAGE(I25:I31) -> 1705.6047 | J36: =AVERAGE(J25:J31) -> 0.0037348816 | K36: =AVERAGE(K25:K31) -> 0.033315384 | M36: =AVERAGE(M25:M31) -> 37.348816
E37: SD | F37: =STDEV(F25:F31) -> 0.055392865 | G37: =STDEV(G25:G31) -> 0.0039097558 | H37: =STDEV(H25:H31) -> 1.0298196 | I37: =STDEV(I25:I31) -> 335.42973 | J37: =STDEV(J25:J31) -> 0.00037126251 | K37: =STDEV(K25:K31) -> 0.0062678376 | M37: =STDEV(M25:M31) -> 3.7126251
A39: Genotype | B39: lsf-1 | J39: Rosette/FW | K39: Rosette/DW | M39: Rosette/FW
C40: Foil | D40: Foil + FW | E40: Foil + DW | F40: FW (g) | G40: DW (g) | H40: Water (%) | I40: Rosette area (mm2) | J40: SLA(m2/g) | K40: SLA(m2/g) | M40: SLA(cm2/g)
A41: Gas | B41: #1 | C41: 0.8955 | D41: 1.3503 | E41: 0.9453 | F41: =D41-C41 -> 0.4548 | G41: =E41-C41 -> 0.0498 | H41: =100-G41/F41*100 -> 89.050132 | I41: 1452.934 | J41: =I41/10^6/F41 -> 0.0031946658 | K41: =I41/10^6/G41 -> 0.029175382 | M41: =J41*10000 -> 31.946658
A42: Gas | B42: #2 | C42: 0.8182 | D42: 1.3382 | E42: 0.8735 | F42: =D42-C42 -> 0.52 | G42: =E42-C42 -> 0.0553 | H42: =100-G42/F42*100 -> 89.365385 | I42: 1745.994 | J42: =I42/10^6/F42 -> 0.0033576808 | K42: =I42/10^6/G42 -> 0.031573128 | M42: =J42*10000 -> 33.576808
A43: Gas | B43: #3 | C43: 1.0062 | D43: 1.5396 | E43: 1.0623 | F43: =D43-C43 -> 0.5334 | G43: =E43-C43 -> 0.0561 | H43: =100-G43/F43*100 -> 89.482565 | I43: 1468.594 | J43: =I43/10^6/F43 -> 0.0027532696 | K43: =I43/10^6/G43 -> 0.026178146 | M43: =J43*10000 -> 27.532696
...

Sheet Summary
A1: g FW | B1: Col | D1: prr7prr9 | F1: lsf | H1: pgm
A2: Day | B2: Mean | C2: SD | D2: Mean | E2: SD | F2: Mean | G2: SD | H2: Mean | I2: SD
A3: 0 | B3: 0 | C3: 0 | D3: 0 | E3: 0 | F3: 0 | G3: 0 | H3: 0 | I3: 0
A4: 21 | B4: ='Day 21'!F11 -> 0.0237 | C4: ='Day 21'!F12 -> 0.0053474293 | D4: ='Day 21'!F21 -> 0.01486 | E4: ='Day 21'!F22 -> 0.0017966636 | F4: ='Day 21'!F31 -> 0.01514 | G4: ='Day 21'!F32 -> 0.0035851081 | H4: ='Day 21'!F41 -> 0.01046 | I4: ='Day 21'!F42 -> 0.00058137767
A5: 30 | B5: ='Day 30'!F11 -> 0.11558 | C5: ='Day 30'!F12 -> 0.012647806 | D5: ='Day 30'!F21 -> 0.0809 | E5: ='Day 30'!F22 -> 0.013997857 | F5: ='Day 30'!F31 -> 0.10316 | G5: ='Day 30'!F32 -> 0.012487314 | H5: ='Day 30'!F41 -> 0.0364 | I5: ='Day 30'!F42 -> 0.0033533565
A6: 39 | B6: ='Day 39 Final'!F20 -> 0.65736 | C6: ='Day 39 Final'!F21 -> 0.12664239 | D6: ='Day 39 Final'!F36 -> 0.45444286 | E6: ='Day 39 Final'!F37 -> 0.055392865 | F6: ='Day 39 Final'!F56 -> 0.55083636 | G6: ='Day 39 Final'!F57 -> 0.073239351 | H6: ='Day 39 Final'!F73 -> 0.1640375 | I6: ='Day 39 Final'!F74 -> 0.015541368
A9: g DW | B9: Col | D9: prr7prr9 | F9: lsf | H9: pgm
A10: Day | B10: Mean | C10: SD | D10: Mean | E10: SD | F10: Mean | G10: SD | H10: Mean | I10: SD
A11: 0 | B11: 0 | C11: 0 | D11: 0 | E11: 0 | F11: 0 | G11: 0 | H11: 0 | I11: 0
A12: 21 | B12: ='Day 21'!G11 -> 0.0028 | C12: ='Day 21'!G12 -> 0.00055677644 | D12: ='Day 21'!G21 -> 0.0021 | E12: ='Day 21'!G22 -> 0.00014142136 | F12: ='Day 21'!G31 -> 0.0022 | G12: ='Day 21'!G32 -> 0.00041231056 | H12: ='Day 21'!G41 -> 0.0015 | I12: ='Day 21'!G42 -> 0.00012247449
A13: 30 | B13: ='Day 30'!G11 -> 0.01182 | C13: ='Day 30'!G12 -> 0.0010986355 | D13: ='Day 30'!G21 -> 0.00972 | E13: ='Day 30'!G22 -> 0.0012477981 | F13: ='Day 30'!G31 -> 0.01096 | G13: ='Day 30'!G32 -> 0.0011928956 | H13: ='Day 30'!G41 -> 0.00408 | I13: ='Day 30'!G42 -> 0.00041472883
A14: 39 | B14: ='Day 39 Final'!G20 -> 0.05895 | C14: ='Day 39 Final'!G21 -> 0.0069384997 | D14: ='Day 39 Final'!G36 -> 0.051257143 | E14: ='Day 39 Final'!G37 -> 0.0039097558 | F14: ='Day 39 Final'!G56 -> 0.054945455 | G14: ='Day 39 Final'!G57 -> 0.0056439992 | H14: ='Day 39 Final'!G73 -> 0.0158375 | I14: ='Day 39 Final'!G74 -> 0.0013762657
A17: Area (mm2) | B17: Col | D17: prr7prr9 | F17: lsf | H17: pgm
A18: Day | B18: Mean | C18: SD | D18: Mean | E18: SD | F18: Mean | G18: SD | H18: Mean | I18: SD
A19: 0 | B19: 0 | C19: 0 | D19: 0 | E19: 0 | F19: 0 | G19: 0 | H19: 0 | I19: 0
A20: 21 | B20: ='Day 21'!I11 -> 128.9968 | C20: ='Day 21'!I12 -> 29.985784 | D20: ='Day 21'!I21 -> 76.6908 | E20: ='Day 21'!I22 -> 10.228049 | F20: ='Day 21'!I31 -> 71.9578 | G20: ='Day 21'!I32 -> 17.687016 | H20: ='Day 21'!I41 -> 37.7112 | I20: ='Day 21'!I42 -> 4.6234889
A21: 30 | B21: ='Day 30'!I11 -> 470.1552 | C21: ='Day 30'!I12 -> 71.889427 | D21: ='Day 30'!I21 -> 382.8706 | E21: ='Day 30'!I22 -> 67.902796 | F21: ='Day 30'!I31 -> 421.072 | G21: ='Day 30'!I32 -> 46.720698 | H21: ='Day 30'!I41 -> 111.0914 | I21: ='Day 30'!I42 -> 9.8664379
A22: 39 | B22: ='Day 39 Final'!I20 -> 1989.7213 | C22: ='Day 39 Final'!I21 -> 464.39942 | D22: ='Day 39 Final'!I36 -> 1705.6047 | E22: ='Day 39 Final'!I37 -> 335.42973 | F22: ='Day 39 Final'!I56 -> 1787.1018 | G22: ='Day 39 Final'!I57 -> 244.66717 | H22: ='Day 39 Final'!I73 -> 488.81425 | I22: ='Day 39 Final'!I74 -> 66.176795
