Workbook

Sheet Raw data
A1: Date | B1: 41964
A2: DAS | B2: 11
A4: Plant no. | B4: Col wt | C4: prr7/prr9 | D4: lsf-1 | E4: pgm
A5: #1 | B5: 4 | C5: 4 | D5: 4 | E5: 4
A6: #2 | B6: 4 | C6: 4 | D6: 4 | E6: 2
A7: #3 | B7: 2 | C7: 2 | D7: 4 | E7: 2
A8: #4 | B8: 4 | C8: 2 | D8: 4 | E8: 2
A9: #5 | B9: 4 | C9: 2 | D9: 2 | E9: 2
A10: #6 | B10: 4 | C10: 4 | D10: 4 | E10: 2
A11: #7 | B11: 4 | C11: 2 | D11: 4 | E11: 4
A12: #8 | B12: 4 | C12: 4 | D12: 2 | E12: 2
A13: #9 | B13: 4 | C13: 4 | D13: 2 | E13: 2
A14: #10 | B14: 4 | C14: 4 | D14: 2 | E14: 2
A15: #11 | B15: 4 | C15: 2 | D15: 4 | E15: 2
A16: #12 | B16: 4 | C16: 2 | D16: 2 | E16: 2
A18: average | B18: =AVERAGE(B5:B16) -> 3.8333333 | C18: =AVERAGE(C5:C16) -> 3 | D18: =AVERAGE(D5:D16) -> 3.1666667 | E18: =AVERAGE(E5:E16) -> 2.3333333
A19: SD | B19: =STDEV(B5:B16) -> 0.57735027 | C19: =STDEV(C5:C16) -> 1.0444659 | D19: =STDEV(D5:D16) -> 1.0298573 | E19: =STDEV(E5:E16) -> 0.77849894

Sheet Raw data (2)
A1: Summary
B2: Col | AF2: Numbered plants transferred tp pots
A3: DAS | F3: Col | K3: Col | P3: Col | U3: Col | Z3: Col | AE3: Col | AJ3: Col | AO3: Col
A4: DAS | B4: 11 | F4: DAS | G4: 15 | K4: DAS | L4: 18 | P4: DAS | Q4: 22 | U4: DAS | V4: 25 | Z4: DAS | AA4: 28 | AE4: DAS | AF4: 31 | AJ4: DAS | AK4: 35 | AO4: DAS | AP4: 39
F6: 6 | G6: 6 | H6: 5 | I6: 6 | K6: 7 | L6: 8 | M6: 7 | N6: 8 | P6: 11 | Q6: 11 | R6: 10 | S6: 11 | U6: 14 | V6: 15 | W6: 14 | X6: 15 | Z6: 18 | AA6: 18 | AB6: 17 | AC6: 18 | AE6: 22 | AJ6: 28 | AO6: 36
F7: 6 | G7: 6 | H7: 6 | I7: 6 | K7: 8 | L7: 8 | M7: 8 | N7: 7 | P7: 11 | Q7: 11 | R7: 12 | S7: 11 | U7: 15 | V7: 14 | W7: 15 | X7: 14 | Z7: 18 | AA7: 18 | AB7: 19 | AC7: 17 | AE7: 22 | AF7: 22 | AH7: 21 | AJ7: 26 | AK7: 27 | AM7: 26 | AO7: 32 | AP7: 35 | AR7: 34
F8: 7 | G8: 6 | H8: 6 | I8: 6 | K8: 9 | L8: 8 | M8: 7 | N8: 8 | P8: 12 | Q8: 11 | R8: 10 | S8: 11 | U8: 16 | V8: 15 | W8: 14 | X8: 15 | Z8: 19 | AA8: 18 | AB8: 18 | AC8: 18 | AE8: 22 | AJ8: 26 | AO8: 34
F9: 6 | G9: 6 | H9: 5 | I9: 6 | K9: 7 | L9: 8 | M9: 7 | N9: 8 | P9: 11 | Q9: 11 | R9: 10 | S9: 11 | U9: 14 | V9: 14 | W9: 13 | X9: 14 | Z9: 18 | AA9: 18 | AB9: 16 | AC9: 18 | AE9: 21 | AF9: 21 | AH9: 20 | AJ9: 26 | AK9: 26 | AM9: 25 | AO9: 34 | AP9: 35 | AR9: 31
F10: 6 | G10: 6 | H10: 6 | I10: 6 | K10: 8 | L10: 8 | M10: 8 | N10: 7 | P10: 11 | Q10: 11 | R10: 11 | S10: 11 | U10: 14 | V10: 15 | W10: 15 | X10: 13 | Z10: 18 | AA10: 18 | AB10: 18 | AC10: 17 | AE10: 21 | AJ10: 27 | AO10: 33
F11: 6 | G11: 6 | H11: 6 | I11: 6 | K11: 8 | L11: 8 | M11: 8 | N11: 7 | P11: 11 | Q11: 11 | R11: 11 | S11: 11 | U11: 15 | V11: 14 | W11: 13 | X11: 13 | Z11: 18 | AA11: 18 | AB11: 17 | AC11: 16 | AF11: 22 | AK11: 27 | AP11: 34
A12: Average | B12: =AVERAGE(A6:D11) -> #DIV/0! | F12: Average | G12: =AVERAGE(F6:I11) -> 5.9583333 | K12: Average | L12: =AVERAGE(K6:N11) -> 7.7083333 | P12: Average | Q12: =AVERAGE(P6:S11) -> 10.958333 | U12: Average | V12: =AVERAGE(U6:X11) -> 14.291667 | Z12: Average | AA12: =AVERAGE(Z6:AC11) -> 17.75 | AE12: Average | AF12: =AVERAGE(AE6:AH11) -> 21.4 | AJ12: Average | AK12: =AVERAGE(AJ6:AM11) -> 26.4 | AO12: Average | AP12: =AVERAGE(AO6:AR11) -> 33.8
A13: SD | B13: =STDEV(A6:D11) -> #DIV/0! | F13: SD | G13: =STDEV(F6:I11) -> 0.35864075 | K13: SD | L13: =STDEV(K6:N11) -> 0.55003294 | P13: SD | Q13: =STDEV(P6:S11) -> 0.46430562 | U13: SD | V13: =STDEV(U6:X11) -> 0.80645044 | Z13: SD | AA13: =STDEV(Z6:AC11) -> 0.73720978 | AE13: SD | AF13: =STDEV(AE6:AH11) -> 0.6992059 | AJ13: SD | AK13: =STDEV(AJ6:AM11) -> 0.84327404 | AO13: SD | AP13: =STDEV(AO6:AR11) -> 1.4757296
A16: pgm | F16: pgm | K16: pgm | P16: pgm | U16: pgm | Z16: pgm | AE16: pgm | AJ16: pgm | AO16: pgm
A17: DAS | B17: 11 | F17: DAS | G17: 15 | K17: DAS | L17: 18 | P17: DAS | Q17: 22 | U17: DAS | V17: 25 | Z17: DAS | AA17: 28 | AE17: DAS | AF17: 31 | AJ17: DAS | AK17: 35 | AO17: DAS | AP17: 39
F19: 4 | G19: 4 | H19: 4 | I19: 4 | K19: 6 | L19: 6 | M19: 6 | N19: 6 | P19: 8 | Q19: 8 | R19: 8 | S19: 8 | U19: 11 | V19: 11 | W19: 9 | X19: 11 | Z19: 12 | AA19: 13 | AB19: 11 | AC19: 13 | AE19: 13 | AJ19: 17 | AO19: 21
F20: 4 | G20: 4 | H20: 4 | I20: 5 | K20: 6 | L20: 6 | M20: 6 | N20: 6 | P20: 8 | Q20: 8 | R20: 8 | S20: 7 | U20: 10 | V20: 10 | W20: 11 | X20: 11 | Z20: 13 | AA20: 13 | AB20: 13 | AC20: 13 | AE20: 15 | AJ20: 19 | AO20: 23
F21: 4 | G21: 4 | H21: 4 | I21: 4 | K21: 6 | L21: 6 | M21: 6 | N21: 6 | P21: 8 | Q21: 7 | R21: 8 | S21: 8 | U21: 11 | V21: 10 | W21: 10 | X21: 11 | Z21: 13 | AA21: 12 | AB21: 13 | AC21: 13 | AE21: 15 | AG21: 15 | AH21: 16 | AJ21: 19 | AL21: 18 | AM21: 18 | AO21: 22 | AQ21: 21 | AR21: 22
F22: 4 | G22: 4 | H22: 4 | I22: 5 | K22: 6 | L22: 6 | M22: 7 | N22: 7 | P22: 7 | Q22: 8 | R22: 8 | S22: 9 | U22: 9 | V22: 11 | W22: 11 | X22: 11 | Z22: 12 | AA22: 13 | AB22: 13 | AC22: 13 | AE22: 15 | AG22: 16 | AJ22: 18 | AL22: 19 | AO22: 23 | AQ22: 23
F23: 4 | G23: 4 | H23: 4 | I23: 4 | K23: 6 | L23: 7 | M23: 6 | N23: 6 | P23: 8 | Q23: 9 | R23: 8 | S23: 8 | U23: 11 | V23: 11 | W23: 11 | X23: 10 | Z23: 13 | AA23: 14 | AB23: 13 | AC23: 12 | AE23: 16 | AJ23: 19 | AO23: 22
F24: 4 | G24: 4 | H24: 4 | I24: 4 | K24: 6 | L24: 6 | M24: 6 | N24: 6 | P24: 8 | Q24: 8 | R24: 8 | S24: 8 | U24: 11 | V24: 10 | W24: 11 | X24: 11 | Z24: 13 | AA24: 12 | AB24: 13 | AC24: 13
A25: Average | B25: =AVERAGE(A19:D24) -> #DIV/0! | F25: Average | G25: =AVERAGE(F19:I24) -> 4.0833333 | K25: Average | L25: =AVERAGE(K19:N24) -> 6.125 | P25: Average | Q25: =AVERAGE(P19:S24) -> 7.9583333 | U25: Average | V25: =AVERAGE(U19:X24) -> 10.583333 | Z25: Average | AA25: =AVERAGE(Z19:AC24) -> 12.75 | AE25: Average | AF25: =AVERAGE(AE19:AH24) -> 15.125 | AJ25: Average | AK25: =AVERAGE(AJ19:AM24) -> 18.375 | AO25: Average | AP25: =AVERAGE(AO19:AR24) -> 22.125
A26: SD | B26: =STDEV(A19:D24) -> #DIV/0! | F26: SD | G26: =STDEV(F19:I24) -> 0.28232985 | K26: SD | L26: =STDEV(K19:N24) -> 0.33783196 | P26: SD | Q26: =STDEV(P19:S24) -> 0.46430562 | U26: SD | V26: =STDEV(U19:X24) -> 0.65386255 | Z26: SD | AA26: =STDEV(Z19:AC24) -> 0.60791876 | AE26: SD | AF26: =STDEV(AE19:AH24) -> 0.99103121 | AJ26: SD | AK26: =STDEV(AJ19:AM24) -> 0.74402381 | AO26: SD | AP26: =STDEV(AO19:AR24) -> 0.83452296
A29: prr7/prr9 | F29: prr7/prr9 | K29: prr7/prr9 | P29: prr7/prr9 | U29: prr7/prr9 | Z29: prr7/prr9 | AE29: prr7/prr9 | AJ29: prr7/prr9 | AO29: prr7/prr9
A30: DAS | B30: 11 | F30: DAS | G30: 15 | K30: DAS | L30: 18 | P30: DAS | Q30: 22 | U30: DAS | V30: 25 | Z30: DAS | AA30: 28 | AE30: DAS | AF30: 31 | AJ30: DAS | AK30: 35 | AO30: DAS | AP30: 39
F32: 4 | G32: 5 | H32: 4 | I32: 5 | L32: 7 | M32: 6 | N32: 6 | Q32: 10 | R32: 8 | S32: 9 | V32: 13 | W32: 11 | X32: 12 | AA32: 16 | AB32: 13 | AC32: 16 | AG32: 20 | AL32: 26 | AQ32: 32
F33: 5 | G33: 5 | H33: 5 | I33: 5 | K33: 7 | L33: 7 | M33: 6 | N33: 6 | P33: 9 | Q33: 10 | R33: 10 | S33: 10 | U33: 12 | V33: 13 | W33: 12 | X33: 12 | Z33: 15 | AA33: 17 | AB33: 16 | AC33: 16 | AG33: 19 | AL33: 24 | AQ33: 30
F34: 5 | G34: 5 | H34: 5 | I34: 5 | K34: 7 | L34: 7 | M34: 7 | N34: 7 | P34: 10 | Q34: 9 | R34: 10 | S34: 10 | U34: 13 | V34: 13 | W34: 13 | X34: 13 | Z34: 16 | AA34: 16 | AB34: 17 | AC34: 16 | AG34: 20 | AH34: 19 | AL34: 25 | AM34: 24 | AQ34: 32 | AR34: 31
F35: 5 | G35: 6 | H35: 6 | I35: 5 | K35: 8 | L35: 7 | M35: 7 | N35: 7 | P35: 10 | Q35: 11 | R35: 11 | S35: 10 | U35: 13 | V35: 13 | W35: 13 | X35: 13 | Z35: 16 | AA35: 17 | AB35: 17 | AC35: 16 | AE35: 20 | AG35: 21 | AJ35: 24 | AL35: 25 | AO35: 30 | AQ35: 30
F36: 5 | G36: 5 | H36: 5 | I36: 5 | K36: 6 | L36: 7 | M36: 7 | N36: 7 | P36: 10 | Q36: 9 | R36: 10 | S36: 9 | U36: 12 | V36: 12 | W36: 12 | X36: 12 | Z36: 16 | AA36: 16 | AB36: 16 | AC36: 14 | AG36: 20 | AL36: 25 | AQ36: 31
F37: 5 | G37: 5 | H37: 4 | I37: 4 | K37: 7 | L37: 6 | P37: 9 | Q37: 9 | U37: 12 | V37: 12 | Z37: 16 | AA37: 16
A38: Average | B38: =AVERAGE(A32:D37) -> #DIV/0! | F38: Average | G38: =AVERAGE(F32:I37) -> 4.9166667 | K38: Average | L38: =AVERAGE(K32:N37) -> 6.7619048 | P38: Average | Q38: =AVERAGE(P32:S37) -> 9.6666667 | U38: Average | V38: =AVERAGE(U32:X37) -> 12.428571 | Z38: Average | AA38: =AVERAGE(Z32:AC37) -> 15.904762 | AE38: Average | AF38: =AVERAGE(AE32:AH37) -> 19.857143 | AJ38: Average | AK38: =AVERAGE(AJ32:AM37) -> 24.714286 | AO38: Average | AP38: =AVERAGE(AO32:AR37) -> 30.857143
A39: SD | B39: =STDEV(A32:D37) -> #DIV/0! | F39: SD | G39: =STDEV(F32:I37) -> 0.50361016 | K39: SD | L39: =STDEV(K32:N37) -> 0.53895843 | P39: SD | Q39: =STDEV(P32:S37) -> 0.73029674 | U39: SD | V39: =STDEV(U32:X37) -> 0.5976143 | Z39: SD | AA39: =STDEV(Z32:AC37) -> 0.94365046 | AE39: SD | AF39: =STDEV(AE32:AH37) -> 0.69006556 | AJ39: SD | AK39: =STDEV(AJ32:AM37) -> 0.75592895 | AO39: SD | AP39: =STDEV(AO32:AR37) -> 0.89973541
A42: lsf | F42: lsf | K42: lsf | P42: lsf | U42: lsf | Z42: lsf | AE42: lsf | AJ42: lsf | AO42: lsf
A43: DAS | B43: 11 | F43: DAS | G43: 15 | K43: DAS | L43: 18 | P43: DAS | Q43: 22 | U43: DAS | V43: 25 | Z43: DAS | AA43: 28 | AE43: DAS | AF43: 31 | AJ43: DAS | AK43: 35 | AO43: DAS | AP43: 39
F45: 6 | G45: 5 | H45: 5 | I45: 5 | K45: 8 | L45: 7 | M45: 7 | N45: 7 | P45: 10 | Q45: 10 | R45: 9 | S45: 9 | U45: 13 | V45: 13 | W45: 13 | X45: 12 | Z45: 17 | AA45: 16 | AB45: 15 | AC45: 15 | AE45: 20 | AG45: 19 | AH45: 20 | AJ45: 24 | AL45: 24 | AM45: 25 | AO45: 28 | AQ45: 30 | AR45: 31
F46: 5 | G46: 5 | H46: 6 | I46: 5 | K46: 7 | L46: 7 | M46: 7 | N46: 7 | P46: 11 | Q46: 11 | R46: 10 | S46: 11 | U46: 13 | V46: 13 | W46: 13 | X46: 11 | Z46: 17 | AA46: 16 | AB46: 16 | AC46: 14 | AH46: 20 | AM46: 26 | AR46: 32
F47: 6 | G47: 6 | H47: 5 | I47: 6 | K47: 7 | L47: 8 | M47: 7 | N47: 7 | P47: 11 | Q47: 11 | R47: 10 | S47: 11 | U47: 13 | V47: 14 | W47: 13 | X47: 13 | Z47: 16 | AA47: 17 | AB47: 16 | AC47: 16 | AF47: 21 | AH47: 20 | AK47: 26 | AM47: 24 | AP47: 31 | AR47: 31
F48: 6 | G48: 5 | H48: 6 | I48: 5 | K48: 7 | L48: 7 | M48: 7 | N48: 7 | P48: 10 | Q48: 10 | R48: 10 | S48: 10 | U48: 14 | V48: 13 | W48: 13 | X48: 13 | Z48: 17 | AA48: 16 | AB48: 17 | AC48: 16 | AH48: 21 | AM48: 25 | AR48: 32
F49: 6 | G49: 6 | H49: 6 | I49: 5 | K49: 7 | L49: 7 | M49: 7 | N49: 7 | P49: 10 | Q49: 10 | R49: 10 | S49: 10 | U49: 13 | V49: 13 | W49: 13 | X49: 12 | Z49: 16 | AA49: 15 | AB49: 16 | AC49: 16 | AE49: 21 | AG49: 19 | AH49: 20 | AJ49: 25 | AL49: 25 | AM49: 26 | AO49: 31 | AQ49: 31 | AR49: 31
F50: 5 | G50: 6 | H50: 5 | I50: 5 | K50: 6 | L50: 7 | M50: 7 | N50: 6 | P50: 9 | Q50: 10 | R50: 9 | S50: 9 | U50: 13 | V50: 13 | W50: 12 | X50: 12 | Z50: 15 | AA50: 16 | AB50: 15 | AC50: 15 | AH50: 21 | AM50: 28 | AR50: 33
...

Sheet Summary
C1: Genotype | D1: Col | F1: prr7/prr9 | H1: lsf | J1: pgm
A2: Thermal time | B2: TT after emergence | C2: DAS | D2: LN | E2: SD | F2: LN | G2: SD | H2: LN | I2: SD | J2: LN | K2: SD
A3: =C3*(20.5-3) -> 0 | B3: =MAX(0,A3-110) -> 0 | C3: 0 | D3: 0 | E3: 0 | F3: 0 | G3: 0 | H3: 0 | I3: 0 | J3: 0 | K3: 0
A4: =C4*(20.5-3) -> 192.5 | B4: =MAX(0,A4-110) -> 82.5 | C4: 11 | D4: ='Raw data'!B18 -> 3.8333333 | E4: ='Raw data'!B19 -> 0.57735027 | F4: ='Raw data'!C18 -> 3 | G4: ='Raw data'!C19 -> 1.0444659 | H4: ='Raw data'!D18 -> 3.1666667 | I4: ='Raw data'!D19 -> 1.0298573 | J4: ='Raw data'!E18 -> 2.3333333 | K4: ='Raw data'!E19 -> 0.77849894
A5: =C5*(20.5-3) -> 262.5 | B5: =MAX(0,A5-110) -> 152.5 | C5: 15 | D5: ='Raw data (2)'!G12 -> 5.9583333 | E5: ='Raw data (2)'!G13 -> 0.35864075 | F5: ='Raw data (2)'!G38 -> 4.9166667 | G5: ='Raw data (2)'!G39 -> 0.50361016 | H5: ='Raw data (2)'!G51 -> 5.4583333 | I5: ='Raw data (2)'!G52 -> 0.50897738 | J5: ='Raw data (2)'!G25 -> 4.0833333 | K5: ='Raw data (2)'!G26 -> 0.28232985
A6: =C6*(20.5-3) -> 315 | B6: =MAX(0,A6-110) -> 205 | C6: 18 | D6: ='Raw data (2)'!L12 -> 7.7083333 | E6: ='Raw data (2)'!L13 -> 0.55003294 | F6: ='Raw data (2)'!L38 -> 6.7619048 | G6: ='Raw data (2)'!L39 -> 0.53895843 | H6: ='Raw data (2)'!L51 -> 7 | I6: ='Raw data (2)'!L52 -> 0.41702883 | J6: ='Raw data (2)'!L25 -> 6.125 | K6: ='Raw data (2)'!L26 -> 0.33783196
A7: =C7*(20.5-3) -> 385 | B7: =MAX(0,A7-110) -> 275 | C7: 22 | D7: ='Raw data (2)'!Q12 -> 10.958333 | E7: ='Raw data (2)'!Q13 -> 0.46430562 | F7: ='Raw data (2)'!Q38 -> 9.6666667 | G7: ='Raw data (2)'!Q39 -> 0.73029674 | H7: ='Raw data (2)'!Q51 -> 10.041667 | I7: ='Raw data (2)'!Q52 -> 0.69025305 | J7: ='Raw data (2)'!Q25 -> 7.9583333 | K7: ='Raw data (2)'!Q26 -> 0.46430562
A8: =C8*(20.5-3) -> 437.5 | B8: =MAX(0,A8-110) -> 327.5 | C8: 25 | D8: ='Raw data (2)'!V12 -> 14.291667 | E8: ='Raw data (2)'!V13 -> 0.80645044 | F8: ='Raw data (2)'!V38 -> 12.428571 | G8: ='Raw data (2)'!V39 -> 0.5976143 | H8: ='Raw data (2)'!V51 -> 12.833333 | I8: ='Raw data (2)'!V52 -> 0.63702206 | J8: ='Raw data (2)'!V25 -> 10.583333 | K8: ='Raw data (2)'!V26 -> 0.65386255
A9: =C9*(20.5-3) -> 490 | B9: =MAX(0,A9-110) -> 380 | C9: 28 | D9: ='Raw data (2)'!AA12 -> 17.75 | E9: ='Raw data (2)'!AA13 -> 0.73720978 | F9: ='Raw data (2)'!AA38 -> 15.904762 | G9: ='Raw data (2)'!AA39 -> 0.94365046 | H9: ='Raw data (2)'!AA51 -> 15.875 | I9: ='Raw data (2)'!AA52 -> 0.7974143 | J9: ='Raw data (2)'!AA25 -> 12.75 | K9: ='Raw data (2)'!AA26 -> 0.60791876
A10: =C10*(20.5-3) -> 542.5 | B10: =MAX(0,A10-110) -> 432.5 | C10: 31 | D10: ='Raw data (2)'!AF12 -> 21.4 | E10: ='Raw data (2)'!AF13 -> 0.6992059 | F10: ='Raw data (2)'!AF38 -> 19.857143 | G10: ='Raw data (2)'!AF39 -> 0.69006556 | H10: ='Raw data (2)'!AF51 -> 20.181818 | I10: ='Raw data (2)'!AF52 -> 0.75075719 | J10: ='Raw data (2)'!AF25 -> 15.125 | K10: ='Raw data (2)'!AF26 -> 0.99103121
A11: =C11*(20.5-3) -> 612.5 | B11: =MAX(0,A11-110) -> 502.5 | C11: 35 | D11: ='Raw data (2)'!AK12 -> 26.4 | E11: ='Raw data (2)'!AK13 -> 0.84327404 | F11: ='Raw data (2)'!AK38 -> 24.714286 | G11: ='Raw data (2)'!AK39 -> 0.75592895 | H11: ='Raw data (2)'!AK51 -> 25.272727 | I11: ='Raw data (2)'!AK52 -> 1.1908744 | J11: ='Raw data (2)'!AK25 -> 18.375 | K11: ='Raw data (2)'!AK26 -> 0.74402381
A12: =C12*(20.5-3) -> 682.5 | B12: =MAX(0,A12-110) -> 572.5 | C12: 39 | D12: ='Raw data (2)'!AP12 -> 33.8 | E12: ='Raw data (2)'!AP13 -> 1.4757296 | F12: ='Raw data (2)'!AP38 -> 30.857143 | G12: ='Raw data (2)'!AP39 -> 0.89973541 | H12: ='Raw data (2)'!AP51 -> 31 | I12: ='Raw data (2)'!AP52 -> 1.2649111 | J12: ='Raw data (2)'!AP25 -> 22.125 | K12: ='Raw data (2)'!AP26 -> 0.83452296
A37: Average of Col, prr7/prr9,lsf | J37: Average of Col, prr7/prr9,lsf
A38: =AVERAGE(0.0422,0.0384,0.039) -> 0.039866667 | J38: =AVERAGE(0.0825,0.0769,0.0779) -> 0.0791
A39: Phyllochron | J39: Phyllochron
A40: =1/A38 -> 25.083612 | J40: =1/J38 -> 12.642225
A42: Phyllochron of pgm | J42: Phyllochron of pgm
A43: =1/0.0331 -> 30.21148 | J43: =1/0.0485 -> 20.618557
A45: Increase in pgm relative to the others | J45: Increase in pgm relative to the others
A46: =A43/A40 -> 1.204431 | J46: =J43/J40 -> 1.6309278

Sheet Sheet3
