Workbook

Sheet Metadata
A1: Data | B1: Laurel and Hardy 2 (Nov 2014)
A2: Temperature | B2: 18.5 | C2: Note lower temperature in this experiment
A3: Light | B3: 145
A4: Photoperiod | B4: 12
A5: CO2 level | B5: 42
A6: Photosynthetic 'efficiency' | B6: 0.79
A7: Water content | B7: 0.9 | C7: WT
B8: 0.8925 | C8: lsf1
B9: 0.8804 | C9: prr7/prr9
A10: Starch synthesis | B10: 0.55 of TiMet AGPase activity data
A12: Model | B12: FM 1.1.1.1 (FM v1 + toy starch + fixed starch synthesis + malate/fumarate), now "FMv2" from DDS sims in last sheet
B13: cvRMSEs all from YHC sims, not used
A16: With the clock | B16: NOT USED
D17: micromol CO2/g FW/h | E17: micromol CO2/g FW/h | F17: micromol CO2/cm2/h | G17: micromol CO2/cm2/h | I17: lsf-1 (A)
B18: cvRMSE | C18: nRMSE | D18: AperFW | E18: RperFW | F18: Aperarea | G18: Rperarea | I18: P.ksX = 10*P.ksX;
A19: Col | B19: 0.1282 | C19: 0.0537 | D19: 57.4716 | E19: -10.2513 | F19: 1.1876 | G19: -0.2102 | I19: P.kdS = 0.045*P.kdS;
A20: lsf1 (A) | B20: 0.2058 | C20: 0.0857 | D20: 61.6882 | E20: -12.5139 | F20: 1.188 | G20: -0.2388
A21: lsf1 (B) | B21: 0.1188 | C21: 0.0495 | D21: 61.6767 | E21: -12.4874 | F21: 1.1879 | G21: -0.2383 | I21: lsf-1 (B)
A22: prr7prr9 (starch only) | B22: 0.1895 | C22: 0.0791 | D22: 68.6643 | E22: -12.4131 | F22: 1.1877 | G22: -0.2129 | I22: P.ksX = 10*P.ksX;
A23: prr7prr9 (starch +m+f) | B23: 0.0691 | C23: 0.0288 | D23: 68.7539 | E23: -12.2638 | F23: 1.1879 | G23: -0.2101 | I23: P.kdS = 0.05*P.kdS;
A26: Model | B26: FM 1.2.1 (FM v1 + fixed starch synthesis + malate/fumarate)
B27: This is the version used, but with DDS updates
A28: Without the clock
B29: incorrect data, old sims | D29: micromol CO2/g FW/h | E29: micromol CO2/g FW/h | F29: micromol CO2/cm2/h | G29: micromol CO2/cm2/h
B30: cvRMSE | C30: nRMSE | D30: AperFW | E30: RperFW | F30: Aperarea | G30: Rperarea
A31: Col | B31: 0.1583 | C31: 0.0663 | D31: 57.4541 | E31: -10.7902 | F31: 1.1877 | G31: -0.2213
A32: lsf1 | B32: 0.1256 | C32: 0.0523 | D32: 61.7416 | E32: -11.399 | F32: 1.1879 | G32: -0.2174
A33: prr7prr9 (starch only) | B33: 0.454 | C33: 0.1894 | D33: 68.6455 | E33: -12.8806 | F33: 1.1877 | G33: -0.2211
A34: prr7prr9 (starch +m+f) | B34: 0.2142 | C34: 0.0894 | D34: 68.6816 | E34: -12.729 | F34: 1.1878 | G34: -0.2182
A36: Sheets in this worksheet | B36: Contents
A37: [various]_not_used | B37: Earlier simulation versions, discounted when the effect of low growth temperature on prr7prr9 became clear, so the clock model for 21C could not be applied to this experiment
A38: Biomass_without clock [model] | B38: Fresh (not dry) rosette leaf biomass, measured in samples of 5 plants each on multiple days, as mean and SD; simulation outputs from FMv2 for Col Wild Type plants, lsf1, and two simulations for prr7prr9, where the mutation affects only starch degradation, or both starch degradation and malate/fumarate store mobilisation - all with calibrated not default starch degradation
A39: Starch_without clock | B39: Starch levels in carbon units (not C6) measured on 27-28 days, mean and SD, simulations as above
A40: M + F_without clock | B40: Malate and fumarate levels in carbon units (not C4) measured on 27-28 days, mean and SD, simulations as above
A41: plot_LH2_biomass_and_carbon_poo[ls] | B41: Simulation data from FMv2 runs in the conditions above, from the Matlab output file
A43: Credits
A44: Experimental setup, physiological data, sampling and model construction | B44: Yin Hoon Chew, Millar group University of Edinburgh
A45: Model refinement and final simulations | B45: Daniel Seaton, Millar group University of Edinburgh
A46: Starch, M+F and other metabolite analysis | B46: Virginie Mengin et al, Stitt group, MPIMP

Sheet Biomass_not_used
B1: Biomass (Data) | H1: Biomass (simulation)
A2: Day | B2: 21 | C2: 30 | D2: 39 | H2: Day | I2: Col | J2: lsf-1 (A) | K2: lsf-1 (B) | L2: prr7/prr9 (starch defect) | M2: prr7/prr9 (starch+store)
A3: Col | B3: 0.02037 | C3: 0.11558 | D3: 0.65736 | H3: =1/24 -> 0.041666667 | I3: 0 | J3: 0 | K3: 0 | L3: 0 | M3: 0
A4: SD | B4: 0.005347 | C4: 0.012648 | D4: 0.126642 | H4: =H3+1/24 -> 0.083333333 | I4: 0 | J4: 0 | K4: 0 | L4: 0 | M4: 0
A5: lsf-1 | B5: 0.01514 | C5: 0.10316 | D5: 0.550836 | H5: =H4+1/24 -> 0.125 | I5: 0 | J5: 0 | K5: 0 | L5: 0 | M5: 0
A6: SD | B6: 0.003585 | C6: 0.012487 | D6: 0.164038 | H6: =H5+1/24 -> 0.16666667 | I6: 0 | J6: 0 | K6: 0 | L6: 0 | M6: 0
A7: prr7/prr9 | B7: 0.01486 | C7: 0.0809 | D7: 0.454443 | H7: =H6+1/24 -> 0.20833333 | I7: 0 | J7: 0 | K7: 0 | L7: 0 | M7: 0
A8: SD | B8: 0.001797 | C8: 0.013998 | D8: 0.055393 | H8: =H7+1/24 -> 0.25 | I8: 0 | J8: 0 | K8: 0 | L8: 0 | M8: 0
H9: =H8+1/24 -> 0.29166667 | I9: 0 | J9: 0 | K9: 0 | L9: 0 | M9: 0
H10: =H9+1/24 -> 0.33333333 | I10: 0 | J10: 0 | K10: 0 | L10: 0 | M10: 0
H11: =H10+1/24 -> 0.375 | I11: 0 | J11: 0 | K11: 0 | L11: 0 | M11: 0
H12: =H11+1/24 -> 0.41666667 | I12: 0 | J12: 0 | K12: 0 | L12: 0 | M12: 0
H13: =H12+1/24 -> 0.45833333 | I13: 0 | J13: 0 | K13: 0 | L13: 0 | M13: 0
H14: =H13+1/24 -> 0.5 | I14: 0 | J14: 0 | K14: 0 | L14: 0 | M14: 0
H15: =H14+1/24 -> 0.54166667 | I15: 0 | J15: 0 | K15: 0 | L15: 0 | M15: 0
H16: =H15+1/24 -> 0.58333333 | I16: 0 | J16: 0 | K16: 0 | L16: 0 | M16: 0
H17: =H16+1/24 -> 0.625 | I17: 0 | J17: 0 | K17: 0 | L17: 0 | M17: 0
H18: =H17+1/24 -> 0.66666667 | I18: 0 | J18: 0 | K18: 0 | L18: 0 | M18: 0
H19: =H18+1/24 -> 0.70833333 | I19: 0 | J19: 0 | K19: 0 | L19: 0 | M19: 0
H20: =H19+1/24 -> 0.75 | I20: 0 | J20: 0 | K20: 0 | L20: 0 | M20: 0
... H44: =H43+1/24 -> 1.75 | I44: 0 | J44: 0 | K44: 0 | L44: 0 | M44: 0
B45: NOTE - MF sim removed to test PPT link… | H45: =H44+1/24 -> 1.7916667 | I45: 0 | J45: 0 | K45: 0 | L45: 0 | M45: 0
H46: =H45+1/24 -> 1.8333333 | I46: 0 | J46: 0 | K46: 0 | L46: 0 | M46: 0
H47: =H46+1/24 -> 1.875 | I47: 0 | J47: 0 | K47: 0 | L47: 0 | M47: 0
H48: =H47+1/24 -> 1.9166667 | I48: 0 | J48: 0 | K48: 0 | L48: 0 | M48: 0
H49: =H48+1/24 -> 1.9583333 | I49: 0 | J49: 0 | K49: 0 | L49: 0 | M49: 0
H50: =H49+1/24 -> 2 | I50: 0 | J50: 0 | K50: 0 | L50: 0 | M50: 0
H51: =H50+1/24 -> 2.0416667 | I51: 0 | J51: 0 | K51: 0 | L51: 0 | M51: 0
H52: =H51+1/24 -> 2.0833333 | I52: 0 | J52: 0 | K52: 0 | L52: 0 | M52: 0
H53: =H52+1/24 -> 2.125 | I53: 0 | J53: 0 | K53: 0 | L53: 0 | M53: 0
H54: =H53+1/24 -> 2.1666667 | I54: 0 | J54: 0 | K54: 0 | L54: 0 | M54: 0
H55: =H54+1/24 -> 2.2083333 | I55: 0 | J55: 0 | K55: 0 | L55: 0 | M55: 0
H56: =H55+1/24 -> 2.25 | I56: 0 | J56: 0 | K56: 0 | L56: 0 | M56: 0
H57: =H56+1/24 -> 2.2916667 | I57: 0 | J57: 0 | K57: 0 | L57: 0 | M57: 0
... H962: =H961+1/24 -> 40 | I962: 0.81 | J962: 0.5422 | K962: 0.5817 | L962: 0.5827 | M962: 0.5071

Sheet Starch_not_used
A1: In C6 | G1: in C6 | P1: In C | V1: in C
B2: Starch (data) | G2: Starch (simulation) | Q2: Starch (data) | V2: Starch (simulation)
A3: Hour | B3: 0 | C3: 12 | D3: 24 | G3: Hour | H3: Col | I3: lsf-1 (A) | J3: lsf-1 (B) | K3: prr7/prr9 (starch defect) | L3: prr7/prr9 (starch+store) | P3: Hour | Q3: 0 | R3: 12 | S3: 24 | V3: Hour | W3: Col | X3: lsf-1 (A) | Y3: lsf-1 (B) | Z3: prr7/prr9 (starch defect) | AA3: prr7/prr9 (starch+store)
A4: Col | B4: 2.16 | C4: 40.97 | D4: 3.24 | G4: 0 | H4: 2.9308 | I4: 32.2891 | J4: 26.2307 | K4: 19.3871 | L4: 19.457 | P4: Col | Q4: =B4*6 -> 12.96 | R4: =C4*6 -> 245.82 | S4: =D4*6 -> 19.44 | V4: 0 | W4: =H4*6 -> 17.5848 | X4: =I4*6 -> 193.7346 | Y4: =J4*6 -> 157.3842 | Z4: =K4*6 -> 116.3226 | AA4: =L4*6 -> 116.742
A5: SD | B5: 0.41 | C5: 2.66 | D5: 0.42 | G5: =G4+1 -> 1 | H5: 6.5204 | I5: 35.6654 | J5: 29.7057 | K5: 23.4158 | L5: 23.4911 | P5: SD | Q5: =B5*6 -> 2.46 | R5: =C5*6 -> 15.96 | S5: =D5*6 -> 2.52 | V5: =V4+1 -> 1 | W5: =H5*6 -> 39.1224 | X5: =I5*6 -> 213.9924 | Y5: =J5*6 -> 178.2342 | Z5: =K5*6 -> 140.4948 | AA5: =L5*6 -> 140.9466
A6: lsf-1 | B6: 29.7 | C6: 58.44 | D6: 36.09 | G6: =G5+1 -> 2 | H6: 10.0364 | I6: 38.9708 | J6: 33.1086 | K6: 27.3611 | L6: 27.4406 | P6: lsf-1 | Q6: =B6*6 -> 178.2 | R6: =C6*6 -> 350.64 | S6: =D6*6 -> 216.54 | V6: =V5+1 -> 2 | W6: =H6*6 -> 60.2184 | X6: =I6*6 -> 233.8248 | Y6: =J6*6 -> 198.6516 | Z6: =K6*6 -> 164.1666 | AA6: =L6*6 -> 164.6436
A7: SD | B7: 1.19 | C7: 1.28 | D7: 4.18 | G7: =G6+1 -> 3 | H7: 13.4827 | I7: 42.2083 | J7: 36.4422 | K7: 31.2268 | L7: 31.3099 | P7: SD | Q7: =B7*6 -> 7.14 | R7: =C7*6 -> 7.68 | S7: =D7*6 -> 25.08 | V7: =V6+1 -> 3 | W7: =H7*6 -> 80.8962 | X7: =I7*6 -> 253.2498 | Y7: =J7*6 -> 218.6532 | Z7: =K7*6 -> 187.3608 | AA7: =L7*6 -> 187.8594
A8: prr7/prr9 | B8: 3.6 | C8: 47.64 | D8: 7.15 | G8: =G7+1 -> 4 | H8: 16.8605 | I8: 45.3799 | J8: 39.7083 | K8: 35.0148 | L8: 35.1013 | P8: prr7/prr9 | Q8: =B8*6 -> 21.6 | R8: =C8*6 -> 285.84 | S8: =D8*6 -> 42.9 | V8: =V7+1 -> 4 | W8: =H8*6 -> 101.163 | X8: =I8*6 -> 272.2794 | Y8: =J8*6 -> 238.2498 | Z8: =K8*6 -> 210.0888 | AA8: =L8*6 -> 210.6078
A9: SD | B9: 0.42 | C9: 5.38 | D9: 0.71 | G9: =G8+1 -> 5 | H9: 20.1709 | I9: 48.4867 | J9: 42.9081 | K9: 38.7265 | L9: 38.8163 | P9: SD | Q9: =B9*6 -> 2.52 | R9: =C9*6 -> 32.28 | S9: =D9*6 -> 4.26 | V9: =V8+1 -> 5 | W9: =H9*6 -> 121.0254 | X9: =I9*6 -> 290.9202 | Y9: =J9*6 -> 257.4486 | Z9: =K9*6 -> 232.359 | AA9: =L9*6 -> 232.8978
G10: =G9+1 -> 6 | H10: 23.4152 | I10: 51.5298 | J10: 46.0426 | K10: 42.363 | L10: 42.456 | V10: =V9+1 -> 6 | W10: =H10*6 -> 140.4912 | X10: =I10*6 -> 309.1788 | Y10: =J10*6 -> 276.2556 | Z10: =K10*6 -> 254.178 | AA10: =L10*6 -> 254.736
E11: lsf-1 (A) | G11: =G10+1 -> 7 | H11: 26.5946 | I11: 54.5104 | J11: 49.1131 | K11: 45.9258 | L11: 46.0219 | V11: =V10+1 -> 7 | W11: =H11*6 -> 159.5676 | X11: =I11*6 -> 327.0624 | Y11: =J11*6 -> 294.6786 | Z11: =K11*6 -> 275.5548 | AA11: =L11*6 -> 276.1314
E12: P.ksX = 10*P.ksX; | G12: =G11+1 -> 8 | H12: 29.7105 | I12: 57.4296 | J12: 52.1209 | K12: 49.4165 | L12: 49.5152 | V12: =V11+1 -> 8 | W12: =H12*6 -> 178.263 | X12: =I12*6 -> 344.5776 | Y12: =J12*6 -> 312.7254 | Z12: =K12*6 -> 296.499 | AA12: =L12*6 -> 297.0912
E13: P.kdS = 0.045*P.kdS; | G13: =G12+1 -> 9 | H13: 32.7681 | I13: 60.2887 | J13: 55.0671 | K13: 52.8363 | L13: 52.9377 | V13: =V12+1 -> 9 | W13: =H13*6 -> 196.6086 | X13: =I13*6 -> 361.7322 | Y13: =J13*6 -> 330.4026 | Z13: =K13*6 -> 317.0178 | AA13: =L13*6 -> 317.6262
G14: =G13+1 -> 10 | H14: 35.7726 | I14: 63.104 | J14: 57.9703 | K14: 56.2053 | L14: 56.3014 | V14: =V13+1 -> 10 | W14: =H14*6 -> 214.6356 | X14: =I14*6 -> 378.624 | Y14: =J14*6 -> 347.8218 | Z14: =K14*6 -> 337.2318 | AA14: =L14*6 -> 337.8084
E15: lsf-1 (B) | G15: =G14+1 -> 11 | H15: 38.7205 | I15: 65.8719 | J15: 60.8208 | K15: 59.5111 | L15: 59.6086 | V15: =V14+1 -> 11 | W15: =H15*6 -> 232.323 | X15: =I15*6 -> 395.2314 | Y15: =J15*6 -> 364.9248 | Z15: =K15*6 -> 357.0666 | AA15: =L15*6 -> 357.6516
E16: P.ksX = 10*P.ksX; | G16: =G15+1 -> 12 | H16: 41.6132 | I16: 68.5885 | J16: 63.6185 | K16: 62.7553 | L16: 62.854 | V16: =V15+1 -> 12 | W16: =H16*6 -> 249.6792 | X16: =I16*6 -> 411.531 | Y16: =J16*6 -> 381.711 | Z16: =K16*6 -> 376.5318 | AA16: =L16*6 -> 377.124
E17: P.kdS = 0.05*P.kdS; | G17: =G16+1 -> 13 | H17: 37.5832 | I17: 66.3255 | J17: 61.2478 | K17: 58.5713 | L17: 58.6792 | V17: =V16+1 -> 13 | W17: =H17*6 -> 225.4992 | X17: =I17*6 -> 397.953 | Y17: =J17*6 -> 367.4868 | Z17: =K17*6 -> 351.4278 | AA17: =L17*6 -> 352.0752
G18: =G17+1 -> 14 | H18: 33.676 | I18: 63.9773 | J18: 58.7966 | K18: 54.4754 | L18: 54.5902 | V18: =V17+1 -> 14 | W18: =H18*6 -> 202.056 | X18: =I18*6 -> 383.8638 | Y18: =J18*6 -> 352.7796 | Z18: =K18*6 -> 326.8524 | AA18: =L18*6 -> 327.5412
G19: =G18+1 -> 15 | H19: 29.9022 | I19: 61.5404 | J19: 56.2615 | K19: 50.4759 | L19: 50.5953 | V19: =V18+1 -> 15 | W19: =H19*6 -> 179.4132 | X19: =I19*6 -> 369.2424 | Y19: =J19*6 -> 337.569 | Z19: =K19*6 -> 302.8554 | AA19: =L19*6 -> 303.5718
G20: =G19+1 -> 16 | H20: 26.2649 | I20: 59.0032 | J20: 53.6314 | K20: 46.5735 | L20: 46.6954 | V20: =V19+1 -> 16 | W20: =H20*6 -> 157.5894 | X20: =I20*6 -> 354.0192 | Y20: =J20*6 -> 321.7884 | Z20: =K20*6 -> 279.441 | AA20: =L20*6 -> 280.1724
G21: =G20+1 -> 17 | H21: 22.7737 | I21: 56.3592 | J21: 50.8997 | K21: 42.7762 | L21: 42.8987 | V21: =V20+1 -> 17 | W21: =H21*6 -> 136.6422 | X21: =I21*6 -> 338.1552 | Y21: =J21*6 -> 305.3982 | Z21: =K21*6 -> 256.6572 | AA21: =L21*6 -> 257.3922
G22: =G21+1 -> 18 | H22: 19.4266 | I22: 53.5742 | J22: 48.0339 | K22: 39.0739 | L22: 39.1951 | V22: =V21+1 -> 18 | W22: =H22*6 -> 116.5596 | X22: =I22*6 -> 321.4452 | Y22: =J22*6 -> 288.2034 | Z22: =K22*6 -> 234.4434 | AA22: =L22*6 -> 235.1706
G23: =G22+1 -> 19 | H23: 16.2347 | I23: 50.6291 | J23: 45.0151 | K23: 35.4738 | L23: 35.5921 | V23: =V22+1 -> 19 | W23: =H23*6 -> 97.4082 | X23: =I23*6 -> 303.7746 | Y23: =J23*6 -> 270.0906 | Z23: =K23*6 -> 212.8428 | AA23: =L23*6 -> 213.5526
G24: =G23+1 -> 20 | H24: 13.2071 | I24: 47.4887 | J24: 41.8085 | K24: 31.9787 | L24: 32.0924 | V24: =V23+1 -> 20 | W24: =H24*6 -> 79.2426 | X24: =I24*6 -> 284.9322 | Y24: =J24*6 -> 250.851 | Z24: =K24*6 -> 191.8722 | AA24: =L24*6 -> 192.5544
G25: =G24+1 -> 21 | H25: 10.354 | I25: 44.1027 | J25: 38.364 | K25: 28.5917 | L25: 28.6993 | V25: =V24+1 -> 21 | W25: =H25*6 -> 62.124 | X25: =I25*6 -> 264.6162 | Y25: =J25*6 -> 230.184 | Z25: =K25*6 -> 171.5502 | AA25: =L25*6 -> 172.1958
G26: =G25+1 -> 22 | H26: 7.6856 | I26: 40.3947 | J26: 34.6036 | K26: 25.3165 | L26: 25.4166 | V26: =V25+1 -> 22 | W26: =H26*6 -> 46.1136 | X26: =I26*6 -> 242.3682 | Y26: =J26*6 -> 207.6216 | Z26: =K26*6 -> 151.899 | AA26: =L26*6 -> 152.4996
G27: =G26+1 -> 23 | H27: 5.2065 | I27: 36.2444 | J27: 30.4003 | K27: 22.1572 | L27: 22.2487 | V27: =V26+1 -> 23 | W27: =H27*6 -> 31.239 | X27: =I27*6 -> 217.4664 | Y27: =J27*6 -> 182.4018 | Z27: =K27*6 -> 132.9432 | AA27: =L27*6 -> 133.4922
G28: =G27+1 -> 24 | H28: 2.9026 | I28: 31.4371 | J28: 25.5157 | K28: 19.1191 | L28: 19.2008 | V28: =V27+1 -> 24 | W28: =H28*6 -> 17.4156 | X28: =I28*6 -> 188.6226 | Y28: =J28*6 -> 153.0942 | Z28: =K28*6 -> 114.7146 | AA28: =L28*6 -> 115.2048

Sheet M+F_not_used
A1: In C4 | G1: in C4 | P1: In C | V1: in C
B2: M+F (data) | G2: M+F (simulation) | Q2: M+F (data) | V2: M+F (simulation)
A3: Hour | B3: 0 | C3: 12 | D3: 24 | G3: Hour | H3: Col | I3: lsf-1 (A) | J3: lsf-1 (B) | K3: prr7/prr9 (starch defect) | L3: prr7/prr9 (starch+store) | P3: Hour | Q3: 0 | R3: 12 | S3: 24 | V3: Hour | W3: Col | X3: lsf-1 (A) | Y3: lsf-1 (B) | Z3: prr7/prr9 (starch defect) | AA3: prr7/prr9 (starch+store)
A4: Col | B4: 6.37 | C4: 16.89 | D4: 6.5 | G4: 0 | H4: 6.8444 | I4: 7.4286 | J4: 7.4097 | K4: 8.2191 | L4: 29.8967 | P4: Col | Q4: =B4*4 -> 25.48 | R4: =C4*4 -> 67.56 | S4: =D4*4 -> 26 | V4: 0 | W4: =H4*4 -> 27.3776 | X4: =I4*4 -> 29.7144 | Y4: =J4*4 -> 29.6388 | Z4: =K4*4 -> 32.8764 | AA4: =L4*4 -> 119.5868
A5: SD | B5: 0.97 | C5: 0.95 | D5: 0.67 | G5: =G4+1 -> 1 | H5: 7.8216 | I5: 8.4792 | J5: 8.4599 | K5: 9.3876 | L5: 30.7048 | P5: SD | Q5: =B5*4 -> 3.88 | R5: =C5*4 -> 3.8 | S5: =D5*4 -> 2.68 | V5: =V4+1 -> 1 | W5: =H5*4 -> 31.2864 | X5: =I5*4 -> 33.9168 | Y5: =J5*4 -> 33.8396 | Z5: =K5*4 -> 37.5504 | AA5: =L5*4 -> 122.8192
A6: lsf-1 | B6: 6.81 | C6: 18.8 | D6: 7.54 | G6: =G5+1 -> 2 | H6: 8.7783 | I6: 9.5079 | J6: 9.4883 | K6: 10.5317 | L6: 31.4944 | P6: lsf-1 | Q6: =B6*4 -> 27.24 | R6: =C6*4 -> 75.2 | S6: =D6*4 -> 30.16 | V6: =V5+1 -> 2 | W6: =H6*4 -> 35.1132 | X6: =I6*4 -> 38.0316 | Y6: =J6*4 -> 37.9532 | Z6: =K6*4 -> 42.1268 | AA6: =L6*4 -> 125.9776
A7: SD | B7: 1.44 | C7: 0.44 | D7: 0.35 | G7: =G6+1 -> 3 | H7: 9.7158 | I7: 10.5157 | J7: 10.4958 | K7: 11.6526 | L7: 32.2664 | P7: SD | Q7: =B7*4 -> 5.76 | R7: =C7*4 -> 1.76 | S7: =D7*4 -> 1.4 | V7: =V6+1 -> 3 | W7: =H7*4 -> 38.8632 | X7: =I7*4 -> 42.0628 | Y7: =J7*4 -> 41.9832 | Z7: =K7*4 -> 46.6104 | AA7: =L7*4 -> 129.0656
A8: prr7/prr9 | B8: 14.64 | C8: 34.49 | D8: 16.11 | G8: =G7+1 -> 4 | H8: 10.6344 | I8: 11.503 | J8: 11.4829 | K8: 12.7508 | L8: 33.0216 | P8: prr7/prr9 | Q8: =B8*4 -> 58.56 | R8: =C8*4 -> 137.96 | S8: =D8*4 -> 64.44 | V8: =V7+1 -> 4 | W8: =H8*4 -> 42.5376 | X8: =I8*4 -> 46.012 | Y8: =J8*4 -> 45.9316 | Z8: =K8*4 -> 51.0032 | AA8: =L8*4 -> 132.0864
A9: SD | B9: 1.15 | C9: 4.59 | D9: 2.24 | G9: =G8+1 -> 5 | H9: 11.5343 | I9: 12.4704 | J9: 12.45 | K9: 13.8267 | L9: 33.7602 | P9: SD | Q9: =B9*4 -> 4.6 | R9: =C9*4 -> 18.36 | S9: =D9*4 -> 8.96 | V9: =V8+1 -> 5 | W9: =H9*4 -> 46.1372 | X9: =I9*4 -> 49.8816 | Y9: =J9*4 -> 49.8 | Z9: =K9*4 -> 55.3068 | AA9: =L9*4 -> 135.0408
G10: =G9+1 -> 6 | H10: 12.416 | I10: 13.418 | J10: 13.3975 | K10: 14.8808 | L10: 34.4825 | V10: =V9+1 -> 6 | W10: =H10*4 -> 49.664 | X10: =I10*4 -> 53.672 | Y10: =J10*4 -> 53.59 | Z10: =K10*4 -> 59.5232 | AA10: =L10*4 -> 137.93
G11: =G10+1 -> 7 | H11: 13.2797 | I11: 14.3462 | J11: 14.3255 | K11: 15.9133 | L11: 35.1889 | V11: =V10+1 -> 7 | W11: =H11*4 -> 53.1188 | X11: =I11*4 -> 57.3848 | Y11: =J11*4 -> 57.302 | Z11: =K11*4 -> 63.6532 | AA11: =L11*4 -> 140.7556
G12: =G11+1 -> 8 | H12: 14.1259 | I12: 15.2555 | J12: 15.2347 | K12: 16.9248 | L12: 35.8796 | V12: =V11+1 -> 8 | W12: =H12*4 -> 56.5036 | X12: =I12*4 -> 61.022 | Y12: =J12*4 -> 60.9388 | Z12: =K12*4 -> 67.6992 | AA12: =L12*4 -> 143.5184
G13: =G12+1 -> 9 | H13: 14.9567 | I13: 16.1463 | J13: 16.1253 | K13: 17.9157 | L13: 36.5549 | V13: =V12+1 -> 9 | W13: =H13*4 -> 59.8268 | X13: =I13*4 -> 64.5852 | Y13: =J13*4 -> 64.5012 | Z13: =K13*4 -> 71.6628 | AA13: =L13*4 -> 146.2196
G14: =G13+1 -> 10 | H14: 15.7741 | I14: 17.0228 | J14: 17.0027 | K14: 18.8926 | L14: 37.2225 | V14: =V13+1 -> 10 | W14: =H14*4 -> 63.0964 | X14: =I14*4 -> 68.0912 | Y14: =J14*4 -> 68.0108 | Z14: =K14*4 -> 75.5704 | AA14: =L14*4 -> 148.89
G15: =G14+1 -> 11 | H15: 16.5764 | I15: 17.8843 | J15: 17.8642 | K15: 19.8512 | L15: 37.8827 | V15: =V14+1 -> 11 | W15: =H15*4 -> 66.3056 | X15: =I15*4 -> 71.5372 | Y15: =J15*4 -> 71.4568 | Z15: =K15*4 -> 79.4048 | AA15: =L15*4 -> 151.5308
G16: =G15+1 -> 12 | H16: 17.3637 | I16: 18.7298 | J16: 18.7097 | K16: 20.792 | L16: 38.5312 | V16: =V15+1 -> 12 | W16: =H16*4 -> 69.4548 | X16: =I16*4 -> 74.9192 | Y16: =J16*4 -> 74.8388 | Z16: =K16*4 -> 83.168 | AA16: =L16*4 -> 154.1248
G17: =G16+1 -> 13 | H17: 16.4374 | I17: 17.7763 | J17: 17.7548 | K17: 19.6973 | L17: 37.7619 | V17: =V16+1 -> 13 | W17: =H17*4 -> 65.7496 | X17: =I17*4 -> 71.1052 | Y17: =J17*4 -> 71.0192 | Z17: =K17*4 -> 78.7892 | AA17: =L17*4 -> 151.0476
G18: =G17+1 -> 14 | H18: 15.5187 | I18: 16.8215 | J18: 16.799 | K18: 18.609 | L18: 36.9967 | V18: =V17+1 -> 14 | W18: =H18*4 -> 62.0748 | X18: =I18*4 -> 67.286 | Y18: =J18*4 -> 67.196 | Z18: =K18*4 -> 74.436 | AA18: =L18*4 -> 147.9868
G19: =G18+1 -> 15 | H19: 14.6085 | I19: 15.8672 | J19: 15.844 | K19: 17.5282 | L19: 36.2384 | V19: =V18+1 -> 15 | W19: =H19*4 -> 58.434 | X19: =I19*4 -> 63.4688 | Y19: =J19*4 -> 63.376 | Z19: =K19*4 -> 70.1128 | AA19: =L19*4 -> 144.9536
G20: =G19+1 -> 16 | H20: 13.7064 | I20: 14.9134 | J20: 14.8897 | K20: 16.4546 | L20: 35.487 | V20: =V19+1 -> 16 | W20: =H20*4 -> 54.8256 | X20: =I20*4 -> 59.6536 | Y20: =J20*4 -> 59.5588 | Z20: =K20*4 -> 65.8184 | AA20: =L20*4 -> 141.948
G21: =G20+1 -> 17 | H21: 12.8141 | I21: 13.9623 | J21: 13.9386 | K21: 15.3904 | L21: 34.7476 | V21: =V20+1 -> 17 | W21: =H21*4 -> 51.2564 | X21: =I21*4 -> 55.8492 | Y21: =J21*4 -> 55.7544 | Z21: =K21*4 -> 61.5616 | AA21: =L21*4 -> 138.9904
... G28: =G27+1 -> 24 | H28: 6.7375 | I28: 7.3126 | J28: 7.2952 | K28: 8.0946 | L28: 29.7201 | V28: =V27+1 -> 24 | W28: =H28*4 -> 26.95 | X28: =I28*4 -> 29.2504 | Y28: =J28*4 -> 29.1808 | Z28: =K28*4 -> 32.3784 | AA28: =L28*4 -> 118.8804
Q30: M+F + starch (data)
P31: Hour | Q31: 0 | R31: 12 | S31: 24 | U31: Turnover
P32: Col | Q32: =Q4+Starch_not_used!Q4 -> 38.44 | R32: =R4+Starch_not_used!R4 -> 313.38 | S32: =S4+Starch_not_used!S4 -> 45.44 | U32: =(R32-S32)/R32 -> 0.85500032
P34: lsf-1 | Q34: =Q6+Starch_not_used!Q6 -> 205.44 | R34: =R6+Starch_not_used!R6 -> 425.84 | S34: =S6+Starch_not_used!S6 -> 246.7 | U34: =(R34-S34)/R34 -> 0.42067443
P36: prr7/prr9 | Q36: =Q8+Starch_not_used!Q8 -> 80.16 | R36: =R8+Starch_not_used!R8 -> 423.8 | S36: =S8+Starch_not_used!S8 -> 107.34 | U36: =(R36-S36)/R36 -> 0.74672015

Sheet Biomass_without clock
B1: Biomass (Data) | H1: Biomass (simulation) - from plot_LH2 sheet, FW columns
A2: Day | B2: 21 | C2: 30 | D2: 39 | H2: Day | I2: Col | J2: lsf-1 | K2: prr7/prr9 (starch defect) | L2: prr7/prr9 (starch+store)
A3: Col | B3: 0.02037 | C3: 0.11558 | D3: 0.65736 | H3: =1/24 -> 0.041666667 | I3: =plot_LH2_biomass_and_carbon_poo!K3 -> 0 | J3: =plot_LH2_biomass_and_carbon_poo!X3 -> 0 | K3: =plot_LH2_biomass_and_carbon_poo!AK3 -> 0 | L3: =plot_LH2_biomass_and_carbon_poo!AX3 -> 0
A4: SD | B4: 0.005347 | C4: 0.012648 | D4: 0.126642 | H4: =H3+1/24 -> 0.083333333 | I4: =plot_LH2_biomass_and_carbon_poo!K4 -> 0 | J4: =plot_LH2_biomass_and_carbon_poo!X4 -> 0 | K4: =plot_LH2_biomass_and_carbon_poo!AK4 -> 0 | L4: =plot_LH2_biomass_and_carbon_poo!AX4 -> 0
A5: lsf-1 | B5: 0.01514 | C5: 0.10316 | D5: 0.550836 | H5: =H4+1/24 -> 0.125 | I5: =plot_LH2_biomass_and_carbon_poo!K5 -> 0 | J5: =plot_LH2_biomass_and_carbon_poo!X5 -> 0 | K5: =plot_LH2_biomass_and_carbon_poo!AK5 -> 0 | L5: =plot_LH2_biomass_and_carbon_poo!AX5 -> 0
A6: SD | B6: 0.003585 | C6: 0.012487 | D6: 0.164038 | H6: =H5+1/24 -> 0.16666667 | I6: =plot_LH2_biomass_and_carbon_poo!K6 -> 0 | J6: =plot_LH2_biomass_and_carbon_poo!X6 -> 0 | K6: =plot_LH2_biomass_and_carbon_poo!AK6 -> 0 | L6: =plot_LH2_biomass_and_carbon_poo!AX6 -> 0
A7: prr7/prr9 | B7: 0.01486 | C7: 0.0809 | D7: 0.454443 | E7: =D7/D3 -> 0.69131526 | F7: of WT mass | H7: =H6+1/24 -> 0.20833333 | I7: =plot_LH2_biomass_and_carbon_poo!K7 -> 0 | J7: =plot_LH2_biomass_and_carbon_poo!X7 -> 0 | K7: =plot_LH2_biomass_and_carbon_poo!AK7 -> 0 | L7: =plot_LH2_biomass_and_carbon_poo!AX7 -> 0
A8: SD | B8: 0.001797 | C8: 0.013998 | D8: 0.055393 | H8: =H7+1/24 -> 0.25 | I8: =plot_LH2_biomass_and_carbon_poo!K8 -> 0 | J8: =plot_LH2_biomass_and_carbon_poo!X8 -> 0 | K8: =plot_LH2_biomass_and_carbon_poo!AK8 -> 0 | L8: =plot_LH2_biomass_and_carbon_poo!AX8 -> 0
E9: n=5 each | H9: =H8+1/24 -> 0.29166667 | I9: =plot_LH2_biomass_and_carbon_poo!K9 -> 0 | J9: =plot_LH2_biomass_and_carbon_poo!X9 -> 0 | K9: =plot_LH2_biomass_and_carbon_poo!AK9 -> 0 | L9: =plot_LH2_biomass_and_carbon_poo!AX9 -> 0
E10: two-tailed p = 0.0111 | H10: =H9+1/24 -> 0.33333333 | I10: =plot_LH2_biomass_and_carbon_poo!K10 -> 0 | J10: =plot_LH2_biomass_and_carbon_poo!X10 -> 0 | K10: =plot_LH2_biomass_and_carbon_poo!AK10 -> 0 | L10: =plot_LH2_biomass_and_carbon_poo!AX10 -> 0
H11: =H10+1/24 -> 0.375 | I11: =plot_LH2_biomass_and_carbon_poo!K11 -> 0 | J11: =plot_LH2_biomass_and_carbon_poo!X11 -> 0 | K11: =plot_LH2_biomass_and_carbon_poo!AK11 -> 0 | L11: =plot_LH2_biomass_and_carbon_poo!AX11 -> 0
H12: =H11+1/24 -> 0.41666667 | I12: =plot_LH2_biomass_and_carbon_poo!K12 -> 0 | J12: =plot_LH2_biomass_and_carbon_poo!X12 -> 0 | K12: =plot_LH2_biomass_and_carbon_poo!AK12 -> 0 | L12: =plot_LH2_biomass_and_carbon_poo!AX12 -> 0
H13: =H12+1/24 -> 0.45833333 | I13: =plot_LH2_biomass_and_carbon_poo!K13 -> 0 | J13: =plot_LH2_biomass_and_carbon_poo!X13 -> 0 | K13: =plot_LH2_biomass_and_carbon_poo!AK13 -> 0 | L13: =plot_LH2_biomass_and_carbon_poo!AX13 -> 0
H14: =H13+1/24 -> 0.5 | I14: =plot_LH2_biomass_and_carbon_poo!K14 -> 0 | J14: =plot_LH2_biomass_and_carbon_poo!X14 -> 0 | K14: =plot_LH2_biomass_and_carbon_poo!AK14 -> 0 | L14: =plot_LH2_biomass_and_carbon_poo!AX14 -> 0
H15: =H14+1/24 -> 0.54166667 | I15: =plot_LH2_biomass_and_carbon_poo!K15 -> 0 | J15: =plot_LH2_biomass_and_carbon_poo!X15 -> 0 | K15: =plot_LH2_biomass_and_carbon_poo!AK15 -> 0 | L15: =plot_LH2_biomass_and_carbon_poo!AX15 -> 0
H16: =H15+1/24 -> 0.58333333 | I16: =plot_LH2_biomass_and_carbon_poo!K16 -> 0 | J16: =plot_LH2_biomass_and_carbon_poo!X16 -> 0 | K16: =plot_LH2_biomass_and_carbon_poo!AK16 -> 0 | L16: =plot_LH2_biomass_and_carbon_poo!AX16 -> 0
H17: =H16+1/24 -> 0.625 | I17: =plot_LH2_biomass_and_carbon_poo!K17 -> 0 | J17: =plot_LH2_biomass_and_carbon_poo!X17 -> 0 | K17: =plot_LH2_biomass_and_carbon_poo!AK17 -> 0 | L17: =plot_LH2_biomass_and_carbon_poo!AX17 -> 0
H18: =H17+1/24 -> 0.66666667 | I18: =plot_LH2_biomass_and_carbon_poo!K18 -> 0 | J18: =plot_LH2_biomass_and_carbon_poo!X18 -> 0 | K18: =plot_LH2_biomass_and_carbon_poo!AK18 -> 0 | L18: =plot_LH2_biomass_and_carbon_poo!AX18 -> 0
H19: =H18+1/24 -> 0.70833333 | I19: =plot_LH2_biomass_and_carbon_poo!K19 -> 0 | J19: =plot_LH2_biomass_and_carbon_poo!X19 -> 0 | K19: =plot_LH2_biomass_and_carbon_poo!AK19 -> 0 | L19: =plot_LH2_biomass_and_carbon_poo!AX19 -> 0
H20: =H19+1/24 -> 0.75 | I20: =plot_LH2_biomass_and_carbon_poo!K20 -> 0 | J20: =plot_LH2_biomass_and_carbon_poo!X20 -> 0 | K20: =plot_LH2_biomass_and_carbon_poo!AK20 -> 0 | L20: =plot_LH2_biomass_and_carbon_poo!AX20 -> 0
H21: =H20+1/24 -> 0.79166667 | I21: =plot_LH2_biomass_and_carbon_poo!K21 -> 0 | J21: =plot_LH2_biomass_and_carbon_poo!X21 -> 0 | K21: =plot_LH2_biomass_and_carbon_poo!AK21 -> 0 | L21: =plot_LH2_biomass_and_carbon_poo!AX21 -> 0
H22: =H21+1/24 -> 0.83333333 | I22: =plot_LH2_biomass_and_carbon_poo!K22 -> 0 | J22: =plot_LH2_biomass_and_carbon_poo!X22 -> 0 | K22: =plot_LH2_biomass_and_carbon_poo!AK22 -> 0 | L22: =plot_LH2_biomass_and_carbon_poo!AX22 -> 0
... H962: =H961+1/24 -> 40 | I962: =plot_LH2_biomass_and_carbon_poo!K962 -> 0.82806301 | J962: =plot_LH2_biomass_and_carbon_poo!X962 -> 0.56505361 | K962: =plot_LH2_biomass_and_carbon_poo!AK962 -> 0.6781627 | L962: =plot_LH2_biomass_and_carbon_poo!AX962 -> 0.58951993

Sheet Starch_without clock
A1: In C6 | G1: in C6 | H1: plot_LH2 sheet "starchC6" | I1: Rows 674-698 | M1: In C | S1: in C
B2: Starch (data) | G2: Starch (simulation) | N2: Starch (data) | S2: Starch (simulation)
A3: Hour | B3: 0 | C3: 12 | D3: 24 | G3: Hour | H3: Col | I3: lsf-1 | J3: prr7/prr9 (starch defect) | K3: prr7/prr9 (starch+store) | M3: Hour | N3: 0 | O3: 12 | P3: 24 | Q3: ave 0,24 | S3: Hour | T3: Col | U3: lsf-1 | V3: prr7/prr9 (starch defect) | W3: prr7/prr9 (starch+store)
A4: Col | B4: 2.16 | C4: 40.97 | D4: 3.24 | G4: 0 | H4: =plot_LH2_biomass_and_carbon_poo!L674 -> 3.3151951 | I4: =plot_LH2_biomass_and_carbon_poo!Y674 -> 29.225745 | J4: =plot_LH2_biomass_and_carbon_poo!AL674 -> 5.6169372 | K4: =plot_LH2_biomass_and_carbon_poo!AY674 -> 5.6336532 | M4: Col | N4: =B4*6 -> 12.96 | O4: =C4*6 -> 245.82 | P4: =D4*6 -> 19.44 | Q4: =AVERAGE(N4,P4) -> 16.2 | S4: 0 | T4: =H4*6 -> 19.891171 | U4: =I4*6 -> 175.35447 | V4: =J4*6 -> 33.701623 | W4: =K4*6 -> 33.801919
A5: SD | B5: 0.41 | C5: 2.66 | D5: 0.42 | G5: =G4+1 -> 1 | H5: =plot_LH2_biomass_and_carbon_poo!L675 -> 6.8930659 | I5: =plot_LH2_biomass_and_carbon_poo!Y675 -> 32.744424 | J5: =plot_LH2_biomass_and_carbon_poo!AL675 -> 9.8835859 | K5: =plot_LH2_biomass_and_carbon_poo!AY675 -> 9.9059978 | M5: SD | N5: =B5*6 -> 2.46 | O5: =C5*6 -> 15.96 | P5: =D5*6 -> 2.52 | S5: =S4+1 -> 1 | T5: =H5*6 -> 41.358395 | U5: =I5*6 -> 196.46655 | V5: =J5*6 -> 59.301515 | W5: =K5*6 -> 59.435987
A6: lsf-1 | B6: 29.7 | C6: 58.44 | D6: 36.09 | G6: =G5+1 -> 2 | H6: =plot_LH2_biomass_and_carbon_poo!L676 -> 10.398616 | I6: =plot_LH2_biomass_and_carbon_poo!Y676 -> 36.189336 | J6: =plot_LH2_biomass_and_carbon_poo!AL676 -> 14.063827 | K6: =plot_LH2_biomass_and_carbon_poo!AY676 -> 14.091364 | M6: lsf-1 | N6: =B6*6 -> 178.2 | O6: =C6*6 -> 350.64 | P6: =D6*6 -> 216.54 | Q6: =AVERAGE(N6,P6) -> 197.37 | S6: =S5+1 -> 2 | T6: =H6*6 -> 62.391697 | U6: =I6*6 -> 217.13602 | V6: =J6*6 -> 84.382963 | W6: =K6*6 -> 84.548183
A7: SD | B7: 1.19 | C7: 1.28 | D7: 4.18 | G7: =G6+1 -> 3 | H7: =plot_LH2_biomass_and_carbon_poo!L677 -> 13.834676 | I7: =plot_LH2_biomass_and_carbon_poo!Y677 -> 39.56369 | J7: =plot_LH2_biomass_and_carbon_poo!AL677 -> 18.161114 | K7: =plot_LH2_biomass_and_carbon_poo!AY677 -> 18.193085 | M7: SD | N7: =B7*6 -> 7.14 | O7: =C7*6 -> 7.68 | P7: =D7*6 -> 25.08 | S7: =S6+1 -> 3 | T7: =H7*6 -> 83.008054 | U7: =I7*6 -> 237.38214 | V7: =J7*6 -> 108.96668 | W7: =K7*6 -> 109.15851
A8: prr7/prr9 | B8: 3.6 | C8: 47.64 | D8: 7.15 | G8: =G7+1 -> 4 | H8: =plot_LH2_biomass_and_carbon_poo!L678 -> 17.20243 | I8: =plot_LH2_biomass_and_carbon_poo!Y678 -> 42.869568 | J8: =plot_LH2_biomass_and_carbon_poo!AL678 -> 22.176862 | K8: =plot_LH2_biomass_and_carbon_poo!AY678 -> 22.213127 | M8: prr7/prr9 | N8: =B8*6 -> 21.6 | O8: =C8*6 -> 285.84 | P8: =D8*6 -> 42.9 | Q8: =AVERAGE(N8,P8) -> 32.25 | S8: =S7+1 -> 4 | T8: =H8*6 -> 103.21458 | U8: =I8*6 -> 257.21741 | V8: =J8*6 -> 133.06117 | W8: =K8*6 -> 133.27876
A9: SD | B9: 0.42 | C9: 5.38 | D9: 0.71 | G9: =G8+1 -> 5 | H9: =plot_LH2_biomass_and_carbon_poo!L679 -> 20.503044 | I9: =plot_LH2_biomass_and_carbon_poo!Y679 -> 46.108141 | J9: =plot_LH2_biomass_and_carbon_poo!AL679 -> 26.112462 | K9: =plot_LH2_biomass_and_carbon_poo!AY679 -> 26.152882 | M9: SD | N9: =B9*6 -> 2.52 | O9: =C9*6 -> 32.28 | P9: =D9*6 -> 4.26 | S9: =S8+1 -> 5 | T9: =H9*6 -> 123.01826 | U9: =I9*6 -> 276.64884 | V9: =J9*6 -> 156.67477 | W9: =K9*6 -> 156.91729
G10: =G9+1 -> 6 | H10: =plot_LH2_biomass_and_carbon_poo!L680 -> 23.737663 | I10: =plot_LH2_biomass_and_carbon_poo!Y680 -> 49.28056 | J10: =plot_LH2_biomass_and_carbon_poo!AL680 -> 29.96928 | K10: =plot_LH2_biomass_and_carbon_poo!AY680 -> 30.013722 | S10: =S9+1 -> 6 | T10: =H10*6 -> 142.42598 | U10: =I10*6 -> 295.68336 | V10: =J10*6 -> 179.81568 | W10: =K10*6 -> 180.08233
G11: =G10+1 -> 7 | H11: =plot_LH2_biomass_and_carbon_poo!L681 -> 26.907662 | I11: =plot_LH2_biomass_and_carbon_poo!Y681 -> 52.387959 | J11: =plot_LH2_biomass_and_carbon_poo!AL681 -> 33.748931 | K11: =plot_LH2_biomass_and_carbon_poo!AY681 -> 33.796992 | S11: =S10+1 -> 7 | T11: =H11*6 -> 161.44597 | U11: =I11*6 -> 314.32775 | V11: =J11*6 -> 202.49359 | W11: =K11*6 -> 202.78195
G12: =G11+1 -> 8 | H12: =plot_LH2_biomass_and_carbon_poo!L682 -> 30.014281 | I12: =plot_LH2_biomass_and_carbon_poo!Y682 -> 55.431658 | J12: =plot_LH2_biomass_and_carbon_poo!AL682 -> 37.452925 | K12: =plot_LH2_biomass_and_carbon_poo!AY682 -> 37.504456 | S12: =S11+1 -> 8 | T12: =H12*6 -> 180.08568 | U12: =I12*6 -> 332.58995 | V12: =J12*6 -> 224.71755 | W12: =K12*6 -> 225.02674
G13: =G12+1 -> 9 | H13: =plot_LH2_biomass_and_carbon_poo!L683 -> 33.063521 | I13: =plot_LH2_biomass_and_carbon_poo!Y683 -> 58.41294 | J13: =plot_LH2_biomass_and_carbon_poo!AL683 -> 41.088118 | K13: =plot_LH2_biomass_and_carbon_poo!AY683 -> 41.137669 | S13: =S12+1 -> 9 | T13: =H13*6 -> 198.38112 | U13: =I13*6 -> 350.47764 | V13: =J13*6 -> 246.52871 | W13: =K13*6 -> 246.82601
G14: =G13+1 -> 10 | H14: =plot_LH2_biomass_and_carbon_poo!L684 -> 36.059335 | I14: =plot_LH2_biomass_and_carbon_poo!Y684 -> 61.3475 | J14: =plot_LH2_biomass_and_carbon_poo!AL684 -> 44.660341 | K14: =plot_LH2_biomass_and_carbon_poo!AY684 -> 44.7124 | S14: =S13+1 -> 10 | T14: =H14*6 -> 216.35601 | U14: =I14*6 -> 368.085 | V14: =J14*6 -> 267.96204 | W14: =K14*6 -> 268.2744
G15: =G14+1 -> 11 | H15: =plot_LH2_biomass_and_carbon_poo!L685 -> 38.998684 | I15: =plot_LH2_biomass_and_carbon_poo!Y685 -> 64.232347 | J15: =plot_LH2_biomass_and_carbon_poo!AL685 -> 48.165262 | K15: =plot_LH2_biomass_and_carbon_poo!AY685 -> 48.219652 | S15: =S14+1 -> 11 | T15: =H15*6 -> 233.9921 | U15: =I15*6 -> 385.39408 | V15: =J15*6 -> 288.99157 | W15: =K15*6 -> 289.31791
G16: =G15+1 -> 12 | H16: =plot_LH2_biomass_and_carbon_poo!L686 -> 41.882956 | I16: =plot_LH2_biomass_and_carbon_poo!Y686 -> 67.063627 | J16: =plot_LH2_biomass_and_carbon_poo!AL686 -> 51.60454 | K16: =plot_LH2_biomass_and_carbon_poo!AY686 -> 51.661118 | S16: =S15+1 -> 12 | T16: =H16*6 -> 251.29774 | U16: =I16*6 -> 402.38176 | V16: =J16*6 -> 309.62724 | W16: =K16*6 -> 309.96671
G17: =G16+1 -> 13 | H17: =plot_LH2_biomass_and_carbon_poo!L687 -> 38.572265 | I17: =plot_LH2_biomass_and_carbon_poo!Y687 -> 63.801587 | J17: =plot_LH2_biomass_and_carbon_poo!AL687 -> 47.655498 | K17: =plot_LH2_biomass_and_carbon_poo!AY687 -> 47.721152 | S17: =S16+1 -> 13 | T17: =H17*6 -> 231.43359 | U17: =I17*6 -> 382.80952 | V17: =J17*6 -> 285.93299 | W17: =K17*6 -> 286.32691
G18: =G17+1 -> 14 | H18: =plot_LH2_biomass_and_carbon_poo!L688 -> 35.276262 | I18: =plot_LH2_biomass_and_carbon_poo!Y688 -> 60.548752 | J18: =plot_LH2_biomass_and_carbon_poo!AL688 -> 43.723621 | K18: =plot_LH2_biomass_and_carbon_poo!AY688 -> 43.795992 | S18: =S17+1 -> 14 | T18: =H18*6 -> 211.65757 | U18: =I18*6 -> 363.29251 | V18: =J18*6 -> 262.34173 | W18: =K18*6 -> 262.77595
G19: =G18+1 -> 15 | H19: =plot_LH2_biomass_and_carbon_poo!L689 -> 31.997843 | I19: =plot_LH2_biomass_and_carbon_poo!Y689 -> 57.310138 | J19: =plot_LH2_biomass_and_carbon_poo!AL689 -> 39.812499 | K19: =plot_LH2_biomass_and_carbon_poo!AY689 -> 39.889354 | S19: =S18+1 -> 15 | T19: =H19*6 -> 191.98706 | U19: =I19*6 -> 343.86083 | V19: =J19*6 -> 238.875 | W19: =K19*6 -> 239.33613
G20: =G19+1 -> 16 | H20: =plot_LH2_biomass_and_carbon_poo!L690 -> 28.736783 | I20: =plot_LH2_biomass_and_carbon_poo!Y690 -> 54.085573 | J20: =plot_LH2_biomass_and_carbon_poo!AL690 -> 35.921868 | K20: =plot_LH2_biomass_and_carbon_poo!AY690 -> 36.001019 | S20: =S19+1 -> 16 | T20: =H20*6 -> 172.4207 | U20: =I20*6 -> 324.51344 | V20: =J20*6 -> 215.53121 | W20: =K20*6 -> 216.00611
G21: =G20+1 -> 17 | H21: =plot_LH2_biomass_and_carbon_poo!L691 -> 25.496818 | I21: =plot_LH2_biomass_and_carbon_poo!Y691 -> 50.882663 | J21: =plot_LH2_biomass_and_carbon_poo!AL691 -> 32.056438 | K21: =plot_LH2_biomass_and_carbon_poo!AY691 -> 32.135707 | S21: =S20+1 -> 17 | T21: =H21*6 -> 152.98091 | U21: =I21*6 -> 305.29598 | V21: =J21*6 -> 192.33863 | W21: =K21*6 -> 192.81424
... G28: =G27+1 -> 24 | H28: =plot_LH2_biomass_and_carbon_poo!L698 -> 3.2504045 | I28: =plot_LH2_biomass_and_carbon_poo!Y698 -> 28.791303 | J28: =plot_LH2_biomass_and_carbon_poo!AL698 -> 5.508563 | K28: =plot_LH2_biomass_and_carbon_poo!AY698 -> 5.5322726 | S28: =S27+1 -> 24 | T28: =H28*6 -> 19.502427 | U28: =I28*6 -> 172.74782 | V28: =J28*6 -> 33.051378 | W28: =K28*6 -> 33.193635

Sheet M+F _without clock
A1: In C4 | G1: in C4 - from plot_LH2 sheet, 'malatefumarateC4' columns, rows from 674 = hour from 671 | M1: In C | S1: in C
B2: M+F (data) | G2: M+F (simulation) | N2: M+F (data) | S2: M+F (simulation)
A3: Hour | B3: 0 | C3: 12 | D3: 24 | G3: Hour | H3: Col | I3: lsf-1 | J3: prr7/prr9 (starch defect) | K3: prr7/prr9 (starch+store) | M3: Hour | N3: 0 | O3: 12 | P3: 24 | Q3: ave 0,24 | S3: Hour | T3: Col | U3: lsf-1 | V3: prr7/prr9 (starch defect) | W3: prr7/prr9 (starch+store)
A4: Col | B4: 6.37 | C4: 16.89 | D4: 6.5 | G4: 0 | H4: =plot_LH2_biomass_and_carbon_poo!M674 -> 6.8368528 | I4: =plot_LH2_biomass_and_carbon_poo!Z674 -> 7.5952362 | J4: =plot_LH2_biomass_and_carbon_poo!AM674 -> 8.2096269 | K4: =plot_LH2_biomass_and_carbon_poo!AZ674 -> 29.714091 | M4: Col | N4: =B4*4 -> 25.48 | O4: =C4*4 -> 67.56 | P4: =D4*4 -> 26 | Q4: =AVERAGE(N4,P4) -> 25.74 | S4: 0 | T4: =H4*4 -> 27.347411 | U4: =I4*4 -> 30.380945 | V4: =J4*4 -> 32.838508 | W4: =K4*4 -> 118.85636
A5: SD | B5: 0.97 | C5: 0.95 | D5: 0.67 | G5: =G4+1 -> 1 | H5: =plot_LH2_biomass_and_carbon_poo!M675 -> 7.8125757 | I5: =plot_LH2_biomass_and_carbon_poo!Z675 -> 8.6704339 | J5: =plot_LH2_biomass_and_carbon_poo!AM675 -> 9.3805816 | K5: =plot_LH2_biomass_and_carbon_poo!AZ675 -> 30.527462 | M5: SD | N5: =B5*4 -> 3.88 | O5: =C5*4 -> 3.8 | P5: =D5*4 -> 2.68 | S5: =S4+1 -> 1 | T5: =H5*4 -> 31.250303 | U5: =I5*4 -> 34.681735 | V5: =J5*4 -> 37.522326 | W5: =K5*4 -> 122.10985
A6: lsf-1 | B6: 6.81 | C6: 18.8 | D6: 7.54 | G6: =G5+1 -> 2 | H6: =plot_LH2_biomass_and_carbon_poo!M676 -> 8.768234 | I6: =plot_LH2_biomass_and_carbon_poo!Z676 -> 9.7231739 | J6: =plot_LH2_biomass_and_carbon_poo!AM676 -> 10.527436 | K6: =plot_LH2_biomass_and_carbon_poo!AZ676 -> 31.322564 | M6: lsf-1 | N6: =B6*4 -> 27.24 | O6: =C6*4 -> 75.2 | P6: =D6*4 -> 30.16 | Q6: =AVERAGE(N6,P6) -> 28.7 | S6: =S5+1 -> 2 | T6: =H6*4 -> 35.072936 | U6: =I6*4 -> 38.892696 | V6: =J6*4 -> 42.109744 | W6: =K6*4 -> 125.29026
A7: SD | B7: 1.44 | C7: 0.44 | D7: 0.35 | G7: =G6+1 -> 3 | H7: =plot_LH2_biomass_and_carbon_poo!M677 -> 9.7046492 | I7: =plot_LH2_biomass_and_carbon_poo!Z677 -> 10.754425 | J7: =plot_LH2_biomass_and_carbon_poo!AM677 -> 11.651196 | K7: =plot_LH2_biomass_and_carbon_poo!AZ677 -> 32.100267 | M7: SD | N7: =B7*4 -> 5.76 | O7: =C7*4 -> 1.76 | P7: =D7*4 -> 1.4 | S7: =S6+1 -> 3 | T7: =H7*4 -> 38.818597 | U7: =I7*4 -> 43.017698 | V7: =J7*4 -> 46.604782 | W7: =K7*4 -> 128.40107
A8: prr7/prr9 | B8: 14.64 | C8: 34.49 | D8: 16.11 | G8: =G7+1 -> 4 | H8: =plot_LH2_biomass_and_carbon_poo!M678 -> 10.62215 | I8: =plot_LH2_biomass_and_carbon_poo!Z678 -> 11.764816 | J8: =plot_LH2_biomass_and_carbon_poo!AM678 -> 12.752255 | K8: =plot_LH2_biomass_and_carbon_poo!AZ678 -> 32.861032 | M8: prr7/prr9 | N8: =B8*4 -> 58.56 | O8: =C8*4 -> 137.96 | P8: =D8*4 -> 64.44 | Q8: =AVERAGE(N8,P8) -> 61.5 | S8: =S7+1 -> 4 | T8: =H8*4 -> 42.488601 | U8: =I8*4 -> 47.059264 | V8: =J8*4 -> 51.00902 | W8: =K8*4 -> 131.44413
A9: SD | B9: 1.15 | C9: 4.59 | D9: 2.24 | G9: =G8+1 -> 5 | H9: =plot_LH2_biomass_and_carbon_poo!M679 -> 11.52106 | I9: =plot_LH2_biomass_and_carbon_poo!Z679 -> 12.754705 | J9: =plot_LH2_biomass_and_carbon_poo!AM679 -> 13.831002 | K9: =plot_LH2_biomass_and_carbon_poo!AZ679 -> 33.60515 | M9: SD | N9: =B9*4 -> 4.6 | O9: =C9*4 -> 18.36 | P9: =D9*4 -> 8.96 | S9: =S8+1 -> 5 | T9: =H9*4 -> 46.08424 | U9: =I9*4 -> 51.018819 | V9: =J9*4 -> 55.324008 | W9: =K9*4 -> 134.4206
G10: =G9+1 -> 6 | H10: =plot_LH2_biomass_and_carbon_poo!M680 -> 12.401697 | I10: =plot_LH2_biomass_and_carbon_poo!Z680 -> 13.724442 | J10: =plot_LH2_biomass_and_carbon_poo!AM680 -> 14.887818 | K10: =plot_LH2_biomass_and_carbon_poo!AZ680 -> 34.332909 | S10: =S9+1 -> 6 | T10: =H10*4 -> 49.606786 | U10: =I10*4 -> 54.897766 | V10: =J10*4 -> 59.551272 | W10: =K10*4 -> 137.33164
G11: =G10+1 -> 7 | H11: =plot_LH2_biomass_and_carbon_poo!M681 -> 13.264447 | I11: =plot_LH2_biomass_and_carbon_poo!Z681 -> 14.674371 | J11: =plot_LH2_biomass_and_carbon_poo!AM681 -> 15.923159 | K11: =plot_LH2_biomass_and_carbon_poo!AZ681 -> 35.04459 | S11: =S10+1 -> 7 | T11: =H11*4 -> 53.057788 | U11: =I11*4 -> 58.697484 | V11: =J11*4 -> 63.692634 | W11: =K11*4 -> 140.17836
G12: =G11+1 -> 8 | H12: =plot_LH2_biomass_and_carbon_poo!M682 -> 14.109658 | I12: =plot_LH2_biomass_and_carbon_poo!Z682 -> 15.604895 | J12: =plot_LH2_biomass_and_carbon_poo!AM682 -> 16.937449 | K12: =plot_LH2_biomass_and_carbon_poo!AZ682 -> 35.740602 | S12: =S11+1 -> 8 | T12: =H12*4 -> 56.438631 | U12: =I12*4 -> 62.419578 | V12: =J12*4 -> 67.749795 | W12: =K12*4 -> 142.96241
G13: =G12+1 -> 9 | H13: =plot_LH2_biomass_and_carbon_poo!M683 -> 14.939855 | I13: =plot_LH2_biomass_and_carbon_poo!Z683 -> 16.516402 | J13: =plot_LH2_biomass_and_carbon_poo!AM683 -> 17.933481 | K13: =plot_LH2_biomass_and_carbon_poo!AZ683 -> 36.421445 | S13: =S12+1 -> 9 | T13: =H13*4 -> 59.759421 | U13: =I13*4 -> 66.065609 | V13: =J13*4 -> 71.733923 | W13: =K13*4 -> 145.68578
G14: =G13+1 -> 10 | H14: =plot_LH2_biomass_and_carbon_poo!M684 -> 15.756444 | I14: =plot_LH2_biomass_and_carbon_poo!Z684 -> 17.413371 | J14: =plot_LH2_biomass_and_carbon_poo!AM684 -> 18.91339 | K14: =plot_LH2_biomass_and_carbon_poo!AZ684 -> 37.099397 | S14: =S13+1 -> 10 | T14: =H14*4 -> 63.025777 | U14: =I14*4 -> 69.653483 | V14: =J14*4 -> 75.653558 | W14: =K14*4 -> 148.39759
G15: =G14+1 -> 11 | H15: =plot_LH2_biomass_and_carbon_poo!M685 -> 16.55779 | I15: =plot_LH2_biomass_and_carbon_poo!Z685 -> 18.294998 | J15: =plot_LH2_biomass_and_carbon_poo!AM685 -> 19.875003 | K15: =plot_LH2_biomass_and_carbon_poo!AZ685 -> 37.76525 | S15: =S14+1 -> 11 | T15: =H15*4 -> 66.231161 | U15: =I15*4 -> 73.179994 | V15: =J15*4 -> 79.500012 | W15: =K15*4 -> 151.061
G16: =G15+1 -> 12 | H16: =plot_LH2_biomass_and_carbon_poo!M686 -> 17.344273 | I16: =plot_LH2_biomass_and_carbon_poo!Z686 -> 19.160222 | J16: =plot_LH2_biomass_and_carbon_poo!AM686 -> 20.818778 | K16: =plot_LH2_biomass_and_carbon_poo!AZ686 -> 38.419351 | S16: =S15+1 -> 12 | T16: =H16*4 -> 69.377092 | U16: =I16*4 -> 76.640888 | V16: =J16*4 -> 83.275111 | W16: =K16*4 -> 153.6774
G17: =G16+1 -> 13 | H17: =plot_LH2_biomass_and_carbon_poo!M687 -> 16.434595 | I17: =plot_LH2_biomass_and_carbon_poo!Z687 -> 18.164515 | J17: =plot_LH2_biomass_and_carbon_poo!AM687 -> 19.727458 | K17: =plot_LH2_biomass_and_carbon_poo!AZ687 -> 37.661437 | S17: =S16+1 -> 13 | T17: =H17*4 -> 65.73838 | U17: =I17*4 -> 72.65806 | V17: =J17*4 -> 78.909831 | W17: =K17*4 -> 150.64575
G18: =G17+1 -> 14 | H18: =plot_LH2_biomass_and_carbon_poo!M688 -> 15.528567 | I18: =plot_LH2_biomass_and_carbon_poo!Z688 -> 17.171711 | J18: =plot_LH2_biomass_and_carbon_poo!AM688 -> 18.640446 | K18: =plot_LH2_biomass_and_carbon_poo!AZ688 -> 36.904408 | S18: =S17+1 -> 14 | T18: =H18*4 -> 62.114268 | U18: =I18*4 -> 68.686842 | V18: =J18*4 -> 74.561783 | W18: =K18*4 -> 147.61763
G19: =G18+1 -> 15 | H19: =plot_LH2_biomass_and_carbon_poo!M689 -> 14.627418 | I19: =plot_LH2_biomass_and_carbon_poo!Z689 -> 16.183238 | J19: =plot_LH2_biomass_and_carbon_poo!AM689 -> 17.559223 | K19: =plot_LH2_biomass_and_carbon_poo!AZ689 -> 36.151144 | S19: =S18+1 -> 15 | T19: =H19*4 -> 58.509673 | U19: =I19*4 -> 64.732953 | V19: =J19*4 -> 70.23689 | W19: =K19*4 -> 144.60458
G20: =G19+1 -> 16 | H20: =plot_LH2_biomass_and_carbon_poo!M690 -> 13.731084 | I20: =plot_LH2_biomass_and_carbon_poo!Z690 -> 15.199047 | J20: =plot_LH2_biomass_and_carbon_poo!AM690 -> 16.483712 | K20: =plot_LH2_biomass_and_carbon_poo!AZ690 -> 35.401589 | S20: =S19+1 -> 16 | T20: =H20*4 -> 54.924337 | U20: =I20*4 -> 60.796188 | V20: =J20*4 -> 65.934847 | W20: =K20*4 -> 141.60636
G21: =G20+1 -> 17 | H21: =plot_LH2_biomass_and_carbon_poo!M691 -> 12.841494 | I21: =plot_LH2_biomass_and_carbon_poo!Z691 -> 14.221258 | J21: =plot_LH2_biomass_and_carbon_poo!AM691 -> 15.416228 | K21: =plot_LH2_biomass_and_carbon_poo!AZ691 -> 34.661013 | S21: =S20+1 -> 17 | T21: =H21*4 -> 51.365974 | U21: =I21*4 -> 56.885032 | V21: =J21*4 -> 61.664913 | W21: =K21*4 -> 138.64405
... G28: =G27+1 -> 24 | H28: =plot_LH2_biomass_and_carbon_poo!M698 -> 6.7301724 | I28: =plot_LH2_biomass_and_carbon_poo!Z698 -> 7.4779427 | J28: =plot_LH2_biomass_and_carbon_poo!AM698 -> 8.0811457 | K28: =plot_LH2_biomass_and_carbon_poo!AZ698 -> 29.547735 | S28: =S27+1 -> 24 | T28: =H28*4 -> 26.92069 | U28: =I28*4 -> 29.911771 | V28: =J28*4 -> 32.324583 | W28: =K28*4 -> 118.19094

Sheet plot_LH2_biomass_and_carbon_poo
A1: simulation | B1: WT | C1: WT | D1: WT | E1: WT | F1: WT | G1: WT | H1: WT | I1: WT | J1: WT | K1: WT | L1: WT | M1: WT | N1: WT | O1: lsf1 | P1: lsf1 | Q1: lsf1 | R1: lsf1 | S1: lsf1 | T1: lsf1 | U1: lsf1 | V1: lsf1 | W1: lsf1 | X1: lsf1 | Y1: lsf1 | Z1: lsf1 | AA1: lsf1 | AB1: prr7prr9_noMF | AC1: prr7prr9_noMF | AD1: prr7prr9_noMF | AE1: prr7prr9_noMF | AF1: prr7prr9_noMF | AG1: prr7prr9_noMF | AH1: prr7prr9_noMF | AI1: prr7prr9_noMF | AJ1: prr7prr9_noMF | AK1: prr7prr9_noMF | AL1: prr7prr9_noMF | AM1: prr7prr9_noMF | AN1: prr7prr9_noMF | AO1: prr7prr9 | AP1: prr7prr9 | AQ1: prr7prr9 | AR1: prr7prr9 | AS1: prr7prr9 | AT1: prr7prr9 | AU1: prr7prr9 | AV1: prr7prr9 | AW1: prr7prr9 | AX1: prr7prr9 | AY1: prr7prr9 | AZ1: prr7prr9 | BA1: prr7prr9
A2: variable | B2: Total_shoot | C2: Starch_carbon | D2: MF_carbon | E2: starch | F2: sucrose | G2: NPP | H2: Gas_exchange_perFW | I2: starch_perFW | J2: sucrose_perFW | K2: FW | L2: starchC6 | M2: malatefumarateC4 | N2: sugar | O2: Total_shoot | P2: Starch_carbon | Q2: MF_carbon | R2: starch | S2: sucrose | T2: NPP | U2: Gas_exchange_perFW | V2: starch_perFW | W2: sucrose_perFW | X2: FW | Y2: starchC6 | Z2: malatefumarateC4 | AA2: sugar | AB2: Total_shoot | AC2: Starch_carbon | AD2: MF_carbon | AE2: starch | AF2: sucrose | AG2: NPP | AH2: Gas_exchange_perFW | AI2: starch_perFW | AJ2: sucrose_perFW | AK2: FW | AL2: starchC6 | AM2: malatefumarateC4 | AN2: sugar | AO2: Total_shoot | AP2: Starch_carbon | AQ2: MF_carbon | AR2: starch | AS2: sucrose | AT2: NPP | AU2: Gas_exchange_perFW | AV2: starch_perFW | AW2: sucrose_perFW | AX2: FW | AY2: starchC6 | AZ2: malatefumarateC4 | BA2: sugar
A3: 0 | B3: 0 | C3: 0 | D3: 0 | E3: 0 | F3: 0 | G3: 0 | K3: 0 | O3: 0 | P3: 0 | Q3: 0 | R3: 0 | S3: 0 | T3: 0 | X3: 0 | AB3: 0 | AC3: 0 | AD3: 0 | AE3: 0 | AF3: 0 | AG3: 0 | AK3: 0 | AO3: 0 | AP3: 0 | AQ3: 0 | AR3: 0 | AS3: 0 | AT3: 0 | AX3: 0
A4: 1 | B4: 0 | C4: 0 | D4: 0 | E4: 0 | F4: 0 | G4: 0 | K4: 0 | O4: 0 | P4: 0 | Q4: 0 | R4: 0 | S4: 0 | T4: 0 | X4: 0 | AB4: 0 | AC4: 0 | AD4: 0 | AE4: 0 | AF4: 0 | AG4: 0 | AK4: 0 | AO4: 0 | AP4: 0 | AQ4: 0 | AR4: 0 | AS4: 0 | AT4: 0 | AX4: 0
A5: 2 | B5: 0 | C5: 0 | D5: 0 | E5: 0 | F5: 0 | G5: 0 | K5: 0 | O5: 0 | P5: 0 | Q5: 0 | R5: 0 | S5: 0 | T5: 0 | X5: 0 | AB5: 0 | AC5: 0 | AD5: 0 | AE5: 0 | AF5: 0 | AG5: 0 | AK5: 0 | AO5: 0 | AP5: 0 | AQ5: 0 | AR5: 0 | AS5: 0 | AT5: 0 | AX5: 0
A6: 3 | B6: 0 | C6: 0 | D6: 0 | E6: 0 | F6: 0 | G6: 0 | K6: 0 | O6: 0 | P6: 0 | Q6: 0 | R6: 0 | S6: 0 | T6: 0 | X6: 0 | AB6: 0 | AC6: 0 | AD6: 0 | AE6: 0 | AF6: 0 | AG6: 0 | AK6: 0 | AO6: 0 | AP6: 0 | AQ6: 0 | AR6: 0 | AS6: 0 | AT6: 0 | AX6: 0
A7: 4 | B7: 0 | C7: 0 | D7: 0 | E7: 0 | F7: 0 | G7: 0 | K7: 0 | O7: 0 | P7: 0 | Q7: 0 | R7: 0 | S7: 0 | T7: 0 | X7: 0 | AB7: 0 | AC7: 0 | AD7: 0 | AE7: 0 | AF7: 0 | AG7: 0 | AK7: 0 | AO7: 0 | AP7: 0 | AQ7: 0 | AR7: 0 | AS7: 0 | AT7: 0 | AX7: 0
A8: 5 | B8: 0 | C8: 0 | D8: 0 | E8: 0 | F8: 0 | G8: 0 | K8: 0 | O8: 0 | P8: 0 | Q8: 0 | R8: 0 | S8: 0 | T8: 0 | X8: 0 | AB8: 0 | AC8: 0 | AD8: 0 | AE8: 0 | AF8: 0 | AG8: 0 | AK8: 0 | AO8: 0 | AP8: 0 | AQ8: 0 | AR8: 0 | AS8: 0 | AT8: 0 | AX8: 0
A9: 6 | B9: 0 | C9: 0 | D9: 0 | E9: 0 | F9: 0 | G9: 0 | K9: 0 | O9: 0 | P9: 0 | Q9: 0 | R9: 0 | S9: 0 | T9: 0 | X9: 0 | AB9: 0 | AC9: 0 | AD9: 0 | AE9: 0 | AF9: 0 | AG9: 0 | AK9: 0 | AO9: 0 | AP9: 0 | AQ9: 0 | AR9: 0 | AS9: 0 | AT9: 0 | AX9: 0
A10: 7 | B10: 0 | C10: 0 | D10: 0 | E10: 0 | F10: 0 | G10: 0 | K10: 0 | O10: 0 | P10: 0 | Q10: 0 | R10: 0 | S10: 0 | T10: 0 | X10: 0 | AB10: 0 | AC10: 0 | AD10: 0 | AE10: 0 | AF10: 0 | AG10: 0 | AK10: 0 | AO10: 0 | AP10: 0 | AQ10: 0 | AR10: 0 | AS10: 0 | AT10: 0 | AX10: 0
A11: 8 | B11: 0 | C11: 0 | D11: 0 | E11: 0 | F11: 0 | G11: 0 | K11: 0 | O11: 0 | P11: 0 | Q11: 0 | R11: 0 | S11: 0 | T11: 0 | X11: 0 | AB11: 0 | AC11: 0 | AD11: 0 | AE11: 0 | AF11: 0 | AG11: 0 | AK11: 0 | AO11: 0 | AP11: 0 | AQ11: 0 | AR11: 0 | AS11: 0 | AT11: 0 | AX11: 0
A12: 9 | B12: 0 | C12: 0 | D12: 0 | E12: 0 | F12: 0 | G12: 0 | K12: 0 | O12: 0 | P12: 0 | Q12: 0 | R12: 0 | S12: 0 | T12: 0 | X12: 0 | AB12: 0 | AC12: 0 | AD12: 0 | AE12: 0 | AF12: 0 | AG12: 0 | AK12: 0 | AO12: 0 | AP12: 0 | AQ12: 0 | AR12: 0 | AS12: 0 | AT12: 0 | AX12: 0
A13: 10 | B13: 0 | C13: 0 | D13: 0 | E13: 0 | F13: 0 | G13: 0 | K13: 0 | O13: 0 | P13: 0 | Q13: 0 | R13: 0 | S13: 0 | T13: 0 | X13: 0 | AB13: 0 | AC13: 0 | AD13: 0 | AE13: 0 | AF13: 0 | AG13: 0 | AK13: 0 | AO13: 0 | AP13: 0 | AQ13: 0 | AR13: 0 | AS13: 0 | AT13: 0 | AX13: 0
A14: 11 | B14: 0 | C14: 0 | D14: 0 | E14: 0 | F14: 0 | G14: 0 | K14: 0 | O14: 0 | P14: 0 | Q14: 0 | R14: 0 | S14: 0 | T14: 0 | X14: 0 | AB14: 0 | AC14: 0 | AD14: 0 | AE14: 0 | AF14: 0 | AG14: 0 | AK14: 0 | AO14: 0 | AP14: 0 | AQ14: 0 | AR14: 0 | AS14: 0 | AT14: 0 | AX14: 0
... A172: 169 | B172: 0 | C172: 0 | D172: 0 | E172: 0 | F172: 0 | G172: 0 | K172: 0 | O172: 0 | P172: 0 | Q172: 0 | R172: 0 | S172: 0 | T172: 0 | X172: 0 | AB172: 0 | AC172: 0 | AD172: 0 | AE172: 0 | AF172: 0 | AG172: 0 | AK172: 0 | AO172: 0 | AP172: 0 | AQ172: 0 | AR172: 0 | AS172: 0 | AT172: 0 | AX172: 0
A173: 170 | B173: 1.599997e-05 | C173: 4e-07 | D173: 1.6e-07 | E173: 4e-07 | F173: 2e-07 | G173: 2.399669e-07 | H173: 0.0014997959 | I173: 0.0025000047 | J173: 0.0012500023 | K173: 0.0001599997 | L173: 34.722287 | M173: 20.833372 | N173: 8.6805718 | O173: 1.599997e-05 | P173: 4e-07 | Q173: 1.6e-07 | R173: 4e-07 | S173: 2e-07 | T173: 2.399669e-07 | U173: 0.0016497755 | V173: 0.0027500052 | W173: 0.0013750026 | X173: 0.00014545427 | Y173: 38.194516 | Z173: 22.91671 | AA173: 9.548629 | AB173: 1.599997e-05 | AC173: 4e-07 | AD173: 1.6e-07 | AE173: 4e-07 | AF173: 2e-07 | AG173: 2.399669e-07 | AH173: 0.0017997551 | AI173: 0.0030000056 | AJ173: 0.0015000028 | AK173: 0.00013333308 | AL173: 41.666745 | AM173: 25.000047 | AN173: 10.416686 | AO173: 1.599997e-05 | AP173: 4e-07 | AQ173: 1.6e-07 | AR173: 4e-07 | AS173: 2e-07 | AT173: 2.399669e-07 | AU173: 0.0017997551 | AV173: 0.0030000056 | AW173: 0.0015000028 | AX173: 0.00013333308 | AY173: 41.666745 | AZ173: 25.000047 | BA173: 10.416686
A174: 171 | B174: 1.6236081e-05 | C174: 4.7380713e-07 | D174: 1.7476143e-07 | E174: 4.7380713e-07 | F174: 3.4150688e-07 | G174: 3.1058019e-07 | H174: 0.0019129012 | I174: 0.0029182358 | J174: 0.0021033824 | K174: 0.00016236081 | L174: 40.531052 | M174: 22.424519 | N174: 14.606822 | O174: 1.6236081e-05 | P174: 4.7380713e-07 | Q174: 1.7476143e-07 | R174: 4.7380713e-07 | S174: 3.4150688e-07 | T174: 3.1058019e-07 | U174: 0.0021041913 | V174: 0.0032100593 | W174: 0.0023137207 | X174: 0.00014760074 | Y174: 44.584158 | Z174: 24.66697 | AA174: 16.067505 | AB174: 1.6236081e-05 | AC174: 4.7380713e-07 | AD174: 1.7476143e-07 | AE174: 4.7380713e-07 | AF174: 3.4150688e-07 | AG174: 3.1058019e-07 | AH174: 0.0022954814 | AI174: 0.0035018829 | AJ174: 0.0025240589 | AK174: 0.00013530068 | AL174: 48.637263 | AM174: 26.909422 | AN174: 17.528187 | AO174: 1.6236081e-05 | AP174: 4.7380713e-07 | AQ174: 1.7476143e-07 | AR174: 4.7380713e-07 | AS174: 3.4150688e-07 | AT174: 3.1058019e-07 | AU174: 0.0022954814 | AV174: 0.0035018829 | AW174: 0.0025240589 | AX174: 0.00013530068 | AY174: 48.637263 | AZ174: 26.909422 | BA174: 17.528187
A175: 172 | B175: 1.6476206e-05 | C175: 5.4870652e-07 | D175: 1.897413e-07 | E175: 5.4870652e-07 | F175: 4.7484809e-07 | G175: 3.0493389e-07 | H175: 0.001850753 | I175: 0.0033302965 | J175: 0.0028820233 | K175: 0.00016476206 | L175: 46.254118 | M175: 23.991833 | N175: 20.014051 | O175: 1.6476206e-05 | P175: 5.4870652e-07 | Q175: 1.897413e-07 | R175: 5.4870652e-07 | S175: 4.7484809e-07 | T175: 3.0493389e-07 | U175: 0.0020358284 | V175: 0.0036633261 | W175: 0.0031702256 | X175: 0.00014978369 | Y175: 50.87953 | Z175: 26.391016 | AA175: 22.015456 | AB175: 1.6476206e-05 | AC175: 5.4870652e-07 | AD175: 1.897413e-07 | AE175: 5.4870652e-07 | AF175: 4.7484809e-07 | AG175: 3.0493389e-07 | AH175: 0.0022209037 | AI175: 0.0039963558 | AJ175: 0.0034584279 | AK175: 0.00013730172 | AL175: 55.504942 | AM175: 28.790199 | AN175: 24.016861 | AO175: 1.6476206e-05 | AP175: 5.4870652e-07 | AQ175: 1.897413e-07 | AR175: 5.4870652e-07 | AS175: 4.7484809e-07 | AT175: 3.0493389e-07 | AU175: 0.0022209037 | AV175: 0.0039963558 | AW175: 0.0034584279 | AX175: 0.00013730172 | AY175: 55.504942 | AZ175: 28.790199 | BA175: 24.016861
A176: 173 | B176: 1.6720413e-05 | C176: 6.2478087e-07 | D176: 2.0495617e-07 | E176: 6.2478087e-07 | F176: 6.0075563e-07 | G176: 3.0024712e-07 | H176: 0.001795692 | I176: 0.0037366353 | J176: 0.0035929473 | K176: 0.00016720413 | L176: 51.897713 | M176: 25.53717 | N176: 24.951023 | O176: 1.6720413e-05 | P176: 6.2478087e-07 | Q176: 2.0495617e-07 | R176: 6.2478087e-07 | S176: 6.0075563e-07 | T176: 3.0024712e-07 | U176: 0.0019752612 | V176: 0.0041102989 | W176: 0.003952242 | X176: 0.00015200376 | Y176: 57.087484 | Z176: 28.090887 | AA176: 27.446125 | AB176: 1.6720413e-05 | AC176: 6.2478087e-07 | AD176: 2.0495617e-07 | AE176: 6.2478087e-07 | AF176: 6.0075563e-07 | AG176: 3.0024712e-07 | AH176: 0.0021548304 | AI176: 0.0044839624 | AJ176: 0.0043115367 | AK176: 0.00013933678 | AL176: 62.277255 | AM176: 30.644604 | AN176: 29.941227 | AO176: 1.6720413e-05 | AP176: 6.2478087e-07 | AQ176: 2.0495617e-07 | AR176: 6.2478087e-07 | AS176: 6.0075563e-07 | AT176: 3.0024712e-07 | AU176: 0.0021548304 | AV176: 0.0044839624 | AW176: 0.0043115367 | AX176: 0.00013933678 | AY176: 62.277255 | AZ176: 30.644604 | BA176: 29.941227
A177: 174 | B177: 1.6968772e-05 | C177: 7.0204862e-07 | D177: 2.2040972e-07 | E177: 7.0204862e-07 | F177: 7.1977946e-07 | G177: 2.9618362e-07 | H177: 0.0017454629 | I177: 0.0041372977 | J177: 0.0042417888 | K177: 0.00016968772 | L177: 57.462469 | M177: 27.060705 | N177: 29.456867 | O177: 1.6968772e-05 | P177: 7.0204862e-07 | Q177: 2.2040972e-07 | R177: 7.0204862e-07 | S177: 7.1977946e-07 | T177: 2.9618362e-07 | U177: 0.0019200092 | V177: 0.0045510275 | W177: 0.0046659677 | X177: 0.00015426156 | Y177: 63.208716 | Z177: 29.766775 | AA177: 32.402553 | AB177: 1.6968772e-05 | AC177: 7.0204862e-07 | AD177: 2.2040972e-07 | AE177: 7.0204862e-07 | AF177: 7.1977946e-07 | AG177: 2.9618362e-07 | AH177: 0.0020945555 | AI177: 0.0049647573 | AJ177: 0.0050901465 | AK177: 0.00014140643 | AL177: 68.954962 | AM177: 32.472846 | AN177: 35.34824 | AO177: 1.6968772e-05 | AP177: 7.0204862e-07 | AQ177: 2.2040972e-07 | AR177: 7.0204862e-07 | AS177: 7.1977946e-07 | AT177: 2.9618362e-07 | AU177: 0.0020945555 | AV177: 0.0049647573 | AW177: 0.0050901465 | AX177: 0.00014140643 | AY177: 68.954962 | AZ177: 32.472846 | BA177: 35.34824
A178: 175 | B178: 1.7221353e-05 | C178: 7.8052848e-07 | D178: 2.361057e-07 | E178: 7.8052848e-07 | F178: 8.3245063e-07 | G178: 2.9270803e-07 | H178: 0.0016996808 | I178: 0.0045323297 | J178: 0.0048338284 | K178: 0.00017221353 | L178: 62.949024 | M178: 28.562615 | N178: 33.568253 | O178: 1.7221353e-05 | P178: 7.8052848e-07 | Q178: 2.361057e-07 | R178: 7.8052848e-07 | S178: 8.3245063e-07 | T178: 2.9270803e-07 | U178: 0.0018696489 | V178: 0.0049855627 | W178: 0.0053172112 | X178: 0.00015655775 | Y178: 69.243926 | Z178: 31.418877 | AA178: 36.925078 | AB178: 1.7221353e-05 | AC178: 7.8052848e-07 | AD178: 2.361057e-07 | AE178: 7.8052848e-07 | AF178: 8.3245063e-07 | AG178: 2.9270803e-07 | AH178: 0.002039617 | AI178: 0.0054387956 | AJ178: 0.0058005941 | AK178: 0.00014351127 | AL178: 75.538828 | AM178: 34.275138 | AN178: 40.281903 | AO178: 1.7221353e-05 | AP178: 7.8052848e-07 | AQ178: 2.361057e-07 | AR178: 7.8052848e-07 | AS178: 8.3245063e-07 | AT178: 2.9270803e-07 | AU178: 0.002039617 | AV178: 0.0054387956 | AW178: 0.0058005941 | AX178: 0.00014351127 | AY178: 75.538828 | AZ178: 34.275138 | BA178: 40.281903
A179: 176 | B179: 1.7478227e-05 | C179: 8.6023948e-07 | D179: 2.520479e-07 | E179: 8.6023948e-07 | F179: 9.3926835e-07 | G179: 2.8978366e-07 | H179: 0.0016579694 | I179: 0.0049217776 | J179: 0.0053739337 | K179: 0.00017478227 | L179: 68.358022 | M179: 30.04308 | N179: 37.318984 | O179: 1.7478227e-05 | P179: 8.6023948e-07 | Q179: 2.520479e-07 | R179: 8.6023948e-07 | S179: 9.3926835e-07 | T179: 2.8978366e-07 | U179: 0.0018237663 | V179: 0.0054139554 | W179: 0.0059113271 | X179: 0.00015889297 | Y179: 75.193825 | Z179: 33.047388 | AA179: 41.050883 | AB179: 1.7478227e-05 | AC179: 8.6023948e-07 | AD179: 2.520479e-07 | AE179: 8.6023948e-07 | AF179: 9.3926835e-07 | AG179: 2.8978366e-07 | AH179: 0.0019895633 | AI179: 0.0059061331 | AJ179: 0.0064487205 | AK179: 0.00014565189 | AL179: 82.029627 | AM179: 36.051696 | AN179: 44.782781 | AO179: 1.7478227e-05 | AP179: 8.6023948e-07 | AQ179: 2.520479e-07 | AR179: 8.6023948e-07 | AS179: 9.3926835e-07 | AT179: 2.8978366e-07 | AU179: 0.0019895633 | AV179: 0.0059061331 | AW179: 0.0064487205 | AX179: 0.00014565189 | AY179: 82.029627 | AZ179: 36.051696 | BA179: 44.782781
A180: 177 | B180: 1.7739469e-05 | C180: 9.4120092e-07 | D180: 2.6824018e-07 | E180: 9.4120092e-07 | F180: 1.0406982e-06 | G180: 2.8737545e-07 | H180: 0.0016199778 | I180: 0.0053056883 | J180: 0.0058665694 | K180: 0.00017739469 | L180: 73.690115 | M180: 31.50228 | N180: 40.740065 | O180: 1.7739469e-05 | P180: 9.4120092e-07 | Q180: 2.6824018e-07 | R180: 9.4120092e-07 | S180: 1.0406982e-06 | T180: 2.8737545e-07 | U180: 0.0017819756 | V180: 0.0058362571 | W180: 0.0064532264 | X180: 0.0001612679 | Y180: 81.059127 | Z180: 34.652508 | AA180: 44.814072 | AB180: 1.7739469e-05 | AC180: 9.4120092e-07 | AD180: 2.6824018e-07 | AE180: 9.4120092e-07 | AF180: 1.0406982e-06 | AG180: 2.8737545e-07 | AH180: 0.0019439733 | AI180: 0.006366826 | AJ180: 0.0070398833 | AK180: 0.00014782891 | AL180: 88.428138 | AM180: 37.802736 | AN180: 48.888078 | AO180: 1.7739469e-05 | AP180: 9.4120092e-07 | AQ180: 2.6824018e-07 | AR180: 9.4120092e-07 | AS180: 1.0406982e-06 | AT180: 2.8737545e-07 | AU180: 0.0019439733 | AV180: 0.006366826 | AW180: 0.0070398833 | AX180: 0.00014782891 | AY180: 88.428138 | AZ180: 37.802736 | BA180: 48.888078
A181: 178 | B181: 1.8005151e-05 | C181: 1.0234324e-06 | D181: 2.8468648e-07 | E181: 1.0234324e-06 | F181: 1.1371734e-06 | G181: 2.8545056e-07 | H181: 0.0015853828 | I181: 0.0056841089 | J181: 0.0063158225 | K181: 0.00018005151 | L181: 78.945958 | M181: 32.940397 | N181: 43.859878 | O181: 1.8005151e-05 | P181: 1.0234324e-06 | Q181: 2.8468648e-07 | R181: 1.0234324e-06 | S181: 1.1371734e-06 | T181: 2.8545056e-07 | U181: 0.001743921 | V181: 0.0062525198 | W181: 0.0069474047 | X181: 0.00016368319 | Y181: 86.840553 | Z181: 36.234437 | AA181: 48.245866 | AB181: 1.8005151e-05 | AC181: 1.0234324e-06 | AD181: 2.8468648e-07 | AE181: 1.0234324e-06 | AF181: 1.1371734e-06 | AG181: 2.8545056e-07 | AH181: 0.0019024593 | AI181: 0.0068209307 | AJ181: 0.007578987 | AK181: 0.00015004293 | AL181: 94.735149 | AM181: 39.528477 | AN181: 52.631854 | AO181: 1.8005151e-05 | AP181: 1.0234324e-06 | AQ181: 2.8468648e-07 | AR181: 1.0234324e-06 | AS181: 1.1371734e-06 | AT181: 2.8545056e-07 | AU181: 0.0019024593 | AV181: 0.0068209307 | AW181: 0.007578987 | AX181: 0.00015004293 | AY181: 94.735149 | AZ181: 39.528477 | BA181: 52.631854
A182: 179 | B182: 1.8275351e-05 | C182: 1.1069539e-06 | D182: 3.0139078e-07 | E182: 1.1069539e-06 | F182: 1.2290961e-06 | G182: 2.8397845e-07 | H182: 0.0015538879 | I182: 0.0060570871 | J182: 0.006725431 | K182: 0.00018275351 | L182: 84.12621 | M182: 34.357615 | N182: 46.704382 | O182: 1.8275351e-05 | P182: 1.1069539e-06 | Q182: 3.0139078e-07 | R182: 1.1069539e-06 | S182: 1.2290961e-06 | T182: 2.8397845e-07 | U182: 0.0017092766 | V182: 0.0066627958 | W182: 0.0073979741 | X182: 0.00016613955 | Y182: 92.538831 | Z182: 37.793377 | AA182: 51.37482 | AB182: 1.8275351e-05 | AC182: 1.1069539e-06 | AD182: 3.0139078e-07 | AE182: 1.1069539e-06 | AF182: 1.2290961e-06 | AG182: 2.8397845e-07 | AH182: 0.0018646654 | AI182: 0.0072685045 | AJ182: 0.0080705172 | AK182: 0.00015229459 | AL182: 100.95145 | AM182: 41.229138 | AN182: 56.045258 | AO182: 1.8275351e-05 | AP182: 1.1069539e-06 | AQ182: 3.0139078e-07 | AR182: 1.1069539e-06 | AS182: 1.2290961e-06 | AT182: 2.8397845e-07 | AU182: 0.0018646654 | AV182: 0.0072685045 | AW182: 0.0080705172 | AX182: 0.00015229459 | AY182: 100.95145 | AZ182: 41.229138 | BA182: 56.045258
A183: 180 | B183: 1.8550143e-05 | C183: 1.0220874e-06 | D183: 2.8632124e-07 | E183: 1.0220874e-06 | F183: 1.0907251e-06 | G183: -1.4491789e-07 | H183: -0.00078122251 | I183: 0.0055098628 | J183: 0.0058798746 | K183: 0.00018550143 | L183: 76.525872 | M183: 32.156226 | N183: 40.832462 | O183: 1.8550143e-05 | P183: 1.0552961e-06 | Q183: 2.8632124e-07 | R183: 1.0552961e-06 | S183: 1.0575165e-06 | T183: -1.4491789e-07 | U183: -0.00085934476 | V183: 0.006257772 | W183: 0.0062709391 | X183: 0.00016863766 | Y183: 86.9135 | Z183: 35.371848 | AA183: 43.548188 | AB183: 1.8550143e-05 | AC183: 1.0248548e-06 | AD183: 2.8632124e-07 | AE183: 1.0248548e-06 | AF183: 1.0879578e-06 | AG183: -1.4491789e-07 | AH183: -0.00093746702 | AI183: 0.0066297374 | AJ183: 0.0070379474 | AK183: 0.00015458453 | AL183: 92.079687 | AM183: 38.587471 | AN183: 48.874635 | AO183: 1.8550143e-05 | AP183: 1.0248548e-06 | AQ183: 2.9611644e-07 | AR183: 1.0248548e-06 | AS183: 1.0781626e-06 | AT183: -1.4491789e-07 | AU183: -0.00093746702 | AV183: 0.0066297374 | AW183: 0.0069745827 | AX183: 0.00015458453 | AY183: 92.079687 | AZ183: 39.907568 | BA183: 48.434602
